Workbook

Sheet Summary_RTD
A1: 20251027~20251102 | B1: CP/FT | C1: Total IC | D1: Throughput | E1: Yield | G1: 20251027~20251102 | H1: CP/FT | I1: RTD No. | K1: Total IC | L1: Throughput | M1: Yield
A2: RL7047 | B2: CP | C2: 0 | D2: 0 | G2: RL7047 | H2: CP | I2: RL7047 | K2: 0 | L2: 0
A3: RL7032 Merlin8p | B3: CP | C3: 51254 | D3: 41506 | E3: 0.8098 | G3: RL7032 Merlin8p | H3: CP | I3: RL7032 | K3: 51254 | L3: 41506 | M3: 0.8098
A4: RL7002 Mac9q | B4: CP | C4: 0 | D4: 0 | G4: RL7002 Mac9q | H4: CP | I4: RL7002 | K4: 0 | L4: 0
A5: RL6990 Dora | B5: CP | C5: 0 | D5: 0 | G5: RL6990 Dora | H5: CP | I5: RL6990 | K5: 0 | L5: 0
A6: RL6982 Merlin9 | B6: CP | C6: 188222 | D6: 169294 | E6: 0.8994 | G6: RL6982 Merlin9 | H6: CP | I6: RL6982 | K6: 188222 | L6: 169294 | M6: 0.8994
B7: FT1 | C7: 205388 | D7: 204175 | E7: 0.9941 | H7: FT1 | I7: RTD2865PNJ_SG_TA01 | K7: 4653 | L7: 4260 | M7: 0.9155
A8: RL6963 Mac8q | B8: CP | C8: 91488 | D8: 82894 | E8: 0.9061 | I8: RTD2875QDA_TA01 | K8: 69435 | L8: 69145 | M8: 0.9958
B9: FT1 | C9: 86649 | D9: 86353 | E9: 0.9966 | I9: RTD2875QDA_HD_TA01 | K9: 123296 | L9: 122804 | M9: 0.996
B10: FT2 | C10: 43427 | D10: 43422 | E10: 0.9999 | I10: RTD2874MDA_TA01 | K10: 8004 | L10: 7966 | M10: 0.9953
A11: RL6896 Dante | B11: CP | C11: 0 | D11: 0 | G11: RL6963 Mac8q | H11: CP | I11: RL6963 | K11: 91488 | L11: 82894 | M11: 0.9061
B12: FT1 | C12: 10262 | D12: 10226 | E12: 0.9965 | H12: FT1 | I12: RTD2864FLV_TA01 | K12: 76334 | L12: 76078 | M12: 0.9966
A13: RL6866 Mac8p | B13: CP | C13: 0 | D13: 0 | I13: RTD2851FCA_TA01 | K13: 10315 | L13: 10275 | M13: 0.9961
A14: RL6856 Merlin8 | B14: CP | C14: 53392 | D14: 45952 | E14: 0.8607 | H14: FT2 | I14: RTD2841FLW_TA01 | K14: 43427 | L14: 43422 | M14: 0.9999
B15: FT1 | C15: 44350 | D15: 44229 | E15: 0.9973 | G15: RL6896 Dante | H15: CP | I15: RL6896 | K15: 0 | L15: 0
B16: FT2 | C16: 22448 | D16: 22430 | E16: 0.9992 | H16: FT1 | I16: AXD2801VPF | K16: 10262 | L16: 10226 | M16: 0.9965
A17: RL6750 H5C2 | B17: CP | C17: 0 | D17: 0 | G17: RL6866 Mac8p | H17: CP | I17: RL6866 | K17: 0 | L17: 0
B18: FT1 | C18: 0 | D18: 0 | G18: RL6856 Merlin8 | H18: CP | I18: RL6856 | K18: 53392 | L18: 45952 | M18: 0.8607
A19: RL6748 Merlin7 | B19: CP | C19: 331854 | D19: 288720 | E19: 0.87 | H19: FT1 | I19: RTD2886NSS_SC_FT1_TA01 | K19: 39576 | L19: 39466 | M19: 0.9972
B20: FT1 | C20: 213991 | D20: 213560 | E20: 0.998 | I20: RTD2818AWA_SC_FT1_TA01 | K20: 1910 | L20: 1909 | M20: 0.9995
B21: FT2 | C21: 0 | D21: 0 | I21: RTD2885PDM_FT1_TA01 | K21: 2864 | L21: 2854 | M21: 0.9965
A22: RL6746 MIO | B22: CP | C22: 0 | D22: 0 | H22: FT2 | I22: RTD2885PDM | K22: 14771 | L22: 14768 | M22: 0.9998
A23: RL6708 Bridge | B23: CP | C23: 0 | D23: 0 | I23: RTD2886NSP_SC_FT2_TA01 | K23: 7677 | L23: 7662 | M23: 0.998
B24: FT1 | C24: 0 | D24: 0 | G24: RL6750 H5C2 | H24: CP | I24: RL6750 | K24: 0 | L24: 0
A25: RL6681 ATSC3 | B25: CP | C25: 0 | D25: 0 | G25: RL6748 Merlin7 | H25: CP | I25: RL6748 | K25: 331854 | L25: 288720 | M25: 0.87
B26: FT1 | C26: 0 | D26: 0 | H26: FT1 | I26: RTD2881PSP_SDY_TA01 | K26: 825 | L26: 824 | M26: 0.9988
A27: RL6672 Merlin6 | B27: CP | C27: 0 | D27: 0 | I27: RTD2885NCH_WC_TA01 | K27: 2200 | L27: 2160 | M27: 0.9818
B28: FT1 | C28: 0 | D28: 0 | I28: RTD2875PSP_SC_TA01 | K28: 210966 | L28: 210576 | M28: 0.9982
B29: FT2 | C29: 0 | D29: 0 | G29: RL6746 MIO | H29: CP | I29: RL6746 | K29: 0 | L29: 0
A30: RL6641 Mac7p | B30: CP | C30: 1493 | D30: 1352 | E30: 0.9056 | G30: RL6708 Bridge | H30: CP | I30: RL6708 | K30: 0 | L30: 0
B31: FT1 | C31: 96487 | D31: 96006 | E31: 0.995 | G31: RL6681 ATSC3 | H31: CP | I31: RL6681 | K31: 0 | L31: 0
A32: RL6617 Merlin5 | B32: CP | C32: 0 | D32: 0 | G32: RL6672 Merlin6 | H32: CP | I32: RL6672 | K32: 0 | L32: 0
B33: FT1 | C33: 0 | D33: 0 | G33: RL6641 Mac7p | H33: CP | I33: RL6641 | K33: 1493 | L33: 1352 | M33: 0.9056
B34: FT2 | C34: 0 | D34: 0 | H34: FT1 | I34: RTD2841ACS_PS_TA01 | K34: 1270 | L34: 1265 | M34: 0.9961
I35: RTD2841ACM_PS_TA01 | K35: 35003 | L35: 34851 | M35: 0.9957
I36: RTD2841ASM_PS_TA01 | K36: 22535 | L36: 22435 | M36: 0.9956
I37: RTD2841ASS_PS_TA01 | K37: 37679 | L37: 37455 | M37: 0.9941
G38: RL6617 Merlin5 | H38: CP | I38: RL6617 | K38: 0 | L38: 0

Sheet Top_all
A1: Project | B1: CP/FT | C1: RTD No. | E1: ECN Ver. | G1: summary | H1: Y25_W44 | J1: Top1 | K1: Top2 | L1: Top3 | M1: Top4 | N1: Top5 | O1: Top6 | P1: Top7 | Q1: Top8 | R1: Top9 | S1: Top10 | Y1: Project | Z1: CP/FT | AA1: RTD No. | AC1: ECN Ver. | AD1: Total IC | AE1: Throughput | AF1: Yield | AG1: Top1 | AH1: Top2 | AI1: Top3 | AJ1: Top4 | AK1: Top5 | AL1: Top6 | AM1: Top7 | AN1: Top8 | AO1: Top9 | AP1: Top10
A2: RL7032 Merlin8p | B2: CP | C2: RL7032 | E2: V01 | F2: Total IC | G2: 51254 | H2: 51254 | I2: Test item | J2: cp_mode3_saf_comp_retest | K2: cp_mode2_saf_spc25_comp_retest | L2: all_bist_mp_HV | M2: PowerShort | N2: scpu_bisr_bist_drf_vddr_mp_X7_2000M | O2: scpu_bisr_bist_drf_vddr_mp_X9_2000M | P2: cp_mode1_saf_comp | Q2: cp_mode0_saf_comp | R2: scpu_bisr_bist_drf_vddr_mp_X1 | S2: cp_mode3_bf_comp_retest | Y2: RL7032 Merlin8p | Z2: CP | AA2: RL7032 | AC2: V01 | AD2: 51254 | AE2: 41506 | AF2: 0.8098 | AG2: cp_mode3_saf_comp_retest(1427ea,2.78%) | AH2: cp_mode2_saf_spc25_comp_retest(1131ea,2.21%) | AI2: all_bist_mp_HV(1121ea,2.19%) | AJ2: PowerShort(924ea,1.80%) | AK2: scpu_bisr_bist_drf_vddr_mp_X7_2000M(730ea,1.42%) | AL2: scpu_bisr_bist_drf_vddr_mp_X9_2000M(689ea,1.34%) | AM2: cp_mode1_saf_comp(414ea,0.81%) | AN2: cp_mode0_saf_comp(412ea,0.80%) | AO2: scpu_bisr_bist_drf_vddr_mp_X1(381ea,0.74%) | AP2: cp_mode3_bf_comp_retest(380ea,0.74%)
F3: Throughput | G3: 41506 | H3: 41506 | I3: q'ty | J3: 1427 | K3: 1131 | L3: 1121 | M3: 924 | N3: 730 | O3: 689 | P3: 414 | Q3: 412 | R3: 381 | S3: 380 | Y3: RL6982 Merlin9 | Z3: CP | AA3: RL6982 | AC3: V04 | AD3: 188222 | AE3: 169294 | AF3: 0.8994 | AG3: cp_mode2_saf_spc30_comp(4858ea,2.58%) | AH3: cp_mode3_saf_comp(2768ea,1.47%) | AI3: all_bist_wo_ETN_HV(2541ea,1.35%) | AJ3: cp_mode1_saf_comp(1805ea,0.96%) | AK3: cp_mode0_saf_comp(1609ea,0.85%) | AL3: SCPU_L3_BISR_HV(688ea,0.37%) | AM3: scpu_bist_all_1p2_HV(524ea,0.28%) | AN3: cp_mode3_tdf_c5_cov92_comp_HV(411ea,0.22%) | AO3: all_bisr_drf_mp_BISR_HV(379ea,0.20%) | AP3: PowerShort(322ea,0.17%)
F4: Yield | G4: 0.8098 | H4: 0.8098 | I4: % | J4: 0.0278 | K4: 0.0221 | L4: 0.0219 | M4: 0.018 | N4: 0.0142 | O4: 0.0134 | P4: 0.0081 | Q4: 0.008 | R4: 0.0074 | S4: 0.0074 | Z4: FT1 | AA4: RTD2865PNJ_SG_TA01 | AC4: V01 | AD4: 4653 | AE4: 4260 | AF4: 0.9155 | AG4: DDR4_1p5G_3200_SS_single_RW_FT(385ea,8.27%) | AH4: Efuse_Z0_MR(3ea,0.06%) | AI4: OS_500uA(2ea,0.04%) | AJ4: FW_SCPU(1ea,0.02%) | AK4: FW_MD_DOMAIN(1ea,0.02%) | AL4: FW_MEMC(1ea,0.02%)
A5: RL6982 Merlin9 | B5: CP | C5: RL6982 | E5: V04 | F5: Total IC | G5: 188222 | H5: 188222 | I5: Test item | J5: cp_mode2_saf_spc30_comp | K5: cp_mode3_saf_comp | L5: all_bist_wo_ETN_HV | M5: cp_mode1_saf_comp | N5: cp_mode0_saf_comp | O5: SCPU_L3_BISR_HV | P5: scpu_bist_all_1p2_HV | Q5: cp_mode3_tdf_c5_cov92_comp_HV | R5: all_bisr_drf_mp_BISR_HV | S5: PowerShort | Z5: FT1 | AA5: RTD2875QDA_TA01 | AC5: V03 | AD5: 69435 | AE5: 69145 | AF5: 0.9958 | AG5: DDR4_2G_3000_SS_single_RW_FT(67ea,0.10%) | AH5: FW_other(52ea,0.07%) | AI5: DDR4_2G_3000_SS_FRC_ZQp5p(48ea,0.07%) | AJ5: USB2_disconnect_mea(22ea,0.03%) | AK5: OS_500uA(22ea,0.03%) | AL5: PowerShort(17ea,0.02%) | AM5: SIF_FT01(8ea,0.01%) | AN5: IDDQ(6ea,0.01%) | AO5: scpu_bist_all_1p2_HV(5ea,0.01%) | AP5: USB2_disconnect_trim_RT(5ea,0.01%)
F6: Throughput | G6: 169294 | H6: 169294 | I6: q'ty | J6: 4858 | K6: 2768 | L6: 2541 | M6: 1805 | N6: 1609 | O6: 688 | P6: 524 | Q6: 411 | R6: 379 | S6: 322 | Z6: FT1 | AA6: RTD2875QDA_HD_TA01 | AC6: V03 | AD6: 123296 | AE6: 122804 | AF6: 0.996 | AG6: DDR4_2G_3000_SS_single_RW_FT(130ea,0.11%) | AH6: DDR4_2G_3000_SS_FRC_ZQp5p(98ea,0.08%) | AI6: FW_other(63ea,0.05%) | AJ6: OS_500uA(49ea,0.04%) | AK6: PowerShort(34ea,0.03%) | AL6: USB2_disconnect_mea(16ea,0.01%) | AM6: Wire_Bond_Leak(12ea,0.01%) | AN6: FW_MULTI_CORE_TEST(11ea,0.01%) | AO6: all_bisr_drf(9ea,0.01%) | AP6: USB2_disconnect_trim_RT(8ea,0.01%)
F7: Yield | G7: 0.8994 | H7: 0.8994 | I7: % | J7: 0.0258 | K7: 0.0147 | L7: 0.0135 | M7: 0.0096 | N7: 0.0085 | O7: 0.0037 | P7: 0.0028 | Q7: 0.0022 | R7: 0.002 | S7: 0.0017 | Z7: FT1 | AA7: RTD2874MDA_TA01 | AC7: V03 | AD7: 8004 | AE7: 7966 | AF7: 0.9953 | AG7: DDR4_2G_3000_SS_single_RW_FT(13ea,0.16%) | AH7: FW_other(8ea,0.10%) | AI7: scpu_bist_all_1p2_HV(5ea,0.06%) | AJ7: DDR4_2G_3000_SS_FRC_ZQp5p(4ea,0.05%) | AK7: PowerShort(2ea,0.02%) | AL7: all_bisr_drf(2ea,0.02%) | AM7: Wire_Bond_Leak(1ea,0.01%) | AN7: FW_MULTI_CORE_TEST(1ea,0.01%) | AO7: USB2_FT_OTG(1ea,0.01%) | AP7: FW_VE(1ea,0.01%)
B8: FT1 | C8: RTD2865PNJ_SG_TA01 | E8: V01 | F8: Total IC | G8: 4653 | H8: 4653 | I8: Test item | J8: DDR4_1p5G_3200_SS_single_RW_FT | K8: Efuse_Z0_MR | L8: OS_500uA | M8: FW_SCPU | N8: FW_MD_DOMAIN | O8: FW_MEMC | Y8: RL6963 Mac8q | Z8: CP | AA8: RL6963 | AC8: V07 | AD8: 91488 | AE8: 82894 | AF8: 0.9061 | AG8: cp_mode1_saf_comp_B(2346ea,2.56%) | AH8: cp_mode0_saf_comp(1251ea,1.37%) | AI8: cp_mode2_saf_comp_B(1055ea,1.15%) | AJ8: all_bist_m_0217_p1_BIST_LDOoff_OC700_HV(951ea,1.04%) | AK8: IDD(396ea,0.43%) | AL8: os(291ea,0.32%) | AM8: PowerShort(249ea,0.27%) | AN8: cp_mode1_tdf_cov70_comp_HV(234ea,0.26%) | AO8: GPIO_01_GPOH(181ea,0.20%) | AP8: all_bist_m_0217_p2_GPU_BIST_LDOoff_HV(132ea,0.14%)
F9: Throughput | G9: 4260 | H9: 4260 | I9: q'ty | J9: 385 | K9: 3 | L9: 2 | M9: 1 | N9: 1 | O9: 1 | Z9: FT1 | AA9: RTD2864FLV_TA01 | AC9: V10 | AD9: 76334 | AE9: 76078 | AF9: 0.9966 | AG9: FW_other(88ea,0.12%) | AH9: FW_HDMI_4K60(50ea,0.07%) | AI9: D4_2666M_FRC_4K60_uhd_LB_FT(25ea,0.03%) | AJ9: all_bist_m_0217_p1_BIST_LDOon_HV(24ea,0.03%) | AK9: os(22ea,0.03%) | AL9: power_short(5ea,0.01%) | AM9: all_bist_m_0217_p1_BIST_LDOon_LV(4ea,0.01%) | AN9: FW_Multi_core_test_1(4ea,0.01%) | AO9: PIF_LVDS_FT(4ea,0.01%) | AP9: FW_HDMI_480P(3ea,0.00%)
F10: Yield | G10: 0.9155 | H10: 0.9155 | I10: % | J10: 0.0827 | K10: 0.0006 | L10: 0.0004 | M10: 0.0002 | N10: 0.0002 | O10: 0.0002 | Z10: FT1 | AA10: RTD2851FCA_TA01 | AC10: V10 | AD10: 10315 | AE10: 10275 | AF10: 0.9961 | AG10: FW_other(9ea,0.09%) | AH10: D4_2666M_FRC_4K60_uhd_LB_FT(9ea,0.09%) | AI10: FW_HDMI_4K60(7ea,0.07%) | AJ10: os(4ea,0.04%) | AK10: all_bist_m_0217_p1_BIST_LDOon_LV(2ea,0.02%) | AL10: all_bist_m_0217_p1_BIST_LDOon_HV(2ea,0.02%) | AM10: all_bist_m_0217_p5_scpu_bist_LDOon_HV(2ea,0.02%) | AN10: FW_Multi_core_test_1(1ea,0.01%) | AO10: FW_VE_Encode(1ea,0.01%) | AP10: FW_MD_Domain(1ea,0.01%)
B11: FT1 | C11: RTD2875QDA_TA01 | E11: V03 | F11: Total IC | G11: 69435 | H11: 69435 | I11: Test item | J11: DDR4_2G_3000_SS_single_RW_FT | K11: FW_other | L11: DDR4_2G_3000_SS_FRC_ZQp5p | M11: USB2_disconnect_mea | N11: OS_500uA | O11: PowerShort | P11: SIF_FT01 | Q11: IDDQ | R11: scpu_bist_all_1p2_HV | S11: USB2_disconnect_trim_RT | Z11: FT2 | AA11: RTD2841FLW_TA01 | AC11: V02 | AD11: 43427 | AE11: 43422 | AF11: 0.9999 | AG11: USB2_Swing(3ea,0.01%) | AH11: Wire_bond_leak(2ea,0.00%)
F12: Throughput | G12: 69145 | H12: 69145 | I12: q'ty | J12: 67 | K12: 52 | L12: 48 | M12: 22 | N12: 22 | O12: 17 | P12: 8 | Q12: 6 | R12: 5 | S12: 5 | Y12: RL6896 Dante | Z12: FT1 | AA12: AXD2801VPF | AC12: V08 | AD12: 10262 | AE12: 10226 | AF12: 0.9965 | AG12: HDMI2p1_12g_TX_check_Done_Result(24ea,0.23%) | AH12: DDR3_FRC_CA_n6PI(4ea,0.04%) | AI12: HDMI2p0_6G_RX(3ea,0.03%) | AJ12: (1ea,0.01%) | AK12: DDR3_MD(1ea,0.01%) | AL12: DDR3_MD_n4(1ea,0.01%) | AM12: HDMI2p1_6G_TX_check_Done_Result(1ea,0.01%) | AN12: DDR3_FRC_corner1(1ea,0.01%)
F13: Yield | G13: 0.9958 | H13: 0.9958 | I13: % | J13: 0.001 | K13: 0.0007 | L13: 0.0007 | M13: 0.0003 | N13: 0.0003 | O13: 0.0002 | P13: 0.0001 | Q13: 0.0001 | R13: 0.0001 | S13: 0.0001 | Y13: RL6856 Merlin8 | Z13: CP | AA13: RL6856 | AC13: V11 | AD13: 53392 | AE13: 45952 | AF13: 0.8607 | AG13: cp_mode2_saf_comp_24ns(1495ea,2.80%) | AH13: all_bist_mp_gpu_HV(1263ea,2.37%) | AI13: cp_mode3_saf_comp_VT(1138ea,2.13%) | AJ13: cp_mode1_saf_comp(569ea,1.07%) | AK13: cp_mode0_saf_comp(524ea,0.98%) | AL13: all_bist_mp_gpu_LV(365ea,0.68%) | AM13: IDD(258ea,0.48%) | AN13: cp_mode1_sdd_maskL2D_hv_cov0to92_comp_HV(198ea,0.37%) | AO13: os(195ea,0.37%) | AP13: cp_mode2_0_tdf_c6_comp_HV(158ea,0.30%)
B14: FT1 | C14: RTD2875QDA_HD_TA01 | E14: V03 | F14: Total IC | G14: 123296 | H14: 123296 | I14: Test item | J14: DDR4_2G_3000_SS_single_RW_FT | K14: DDR4_2G_3000_SS_FRC_ZQp5p | L14: FW_other | M14: OS_500uA | N14: PowerShort | O14: USB2_disconnect_mea | P14: Wire_Bond_Leak | Q14: FW_MULTI_CORE_TEST | R14: all_bisr_drf | S14: USB2_disconnect_trim_RT | Z14: FT1 | AA14: RTD2886NSS_SC_FT1_TA01 | AC14: V09 | AD14: 39576 | AE14: 39466 | AF14: 0.9972 | AG14: FW_other(80ea,0.20%) | AH14: HDMI_12G_ALL_Port(4ea,0.01%) | AI14: OS_500uA(4ea,0.01%) | AJ14: set-error-bin(4ea,0.01%) | AK14: Thermal_IDD_comp_4K(3ea,0.01%) | AL14: ddr_single_rw(3ea,0.01%) | AM14: VDC01_SNR_FT01(3ea,0.01%) | AN14: Power_Short(2ea,0.01%) | AO14: PIF_PP_FT_tt(2ea,0.01%) | AP14: IFD_FT02_SNR(1ea,0.00%)
F15: Throughput | G15: 122804 | H15: 122804 | I15: q'ty | J15: 130 | K15: 98 | L15: 63 | M15: 49 | N15: 34 | O15: 16 | P15: 12 | Q15: 11 | R15: 9 | S15: 8 | Z15: FT1 | AA15: RTD2818AWA_SC_FT1_TA01 | AC15: V09 | AD15: 1910 | AE15: 1909 | AF15: 0.9995 | AG15: OS_500uA(1ea,0.05%)
F16: Yield | G16: 0.996 | H16: 0.996 | I16: % | J16: 0.0011 | K16: 0.0008 | L16: 0.0005 | M16: 0.0004 | N16: 0.0003 | O16: 0.0001 | P16: 0.0001 | Q16: 0.0001 | R16: 0.0001 | S16: 0.0001 | Z16: FT1 | AA16: RTD2885PDM_FT1_TA01 | AC16: V07 | AD16: 2864 | AE16: 2854 | AF16: 0.9965 | AG16: FW_M8(4ea,0.14%) | AH16: DDR_single_RW_D4(4ea,0.14%) | AI16: ETN_TX_FT0(2ea,0.07%)
B17: FT1 | C17: RTD2874MDA_TA01 | E17: V03 | F17: Total IC | G17: 8004 | H17: 8004 | I17: Test item | J17: DDR4_2G_3000_SS_single_RW_FT | K17: FW_other | L17: scpu_bist_all_1p2_HV | M17: DDR4_2G_3000_SS_FRC_ZQp5p | N17: PowerShort | O17: all_bisr_drf | P17: Wire_Bond_Leak | Q17: FW_MULTI_CORE_TEST | R17: USB2_FT_OTG | S17: FW_VE | Z17: FT2 | AA17: RTD2885PDM | AC17: V04 | AD17: 14771 | AE17: 14768 | AF17: 0.9998 | AG17: OS(2ea,0.01%) | AH17: IDDQ(1ea,0.01%)
F18: Throughput | G18: 7966 | H18: 7966 | I18: q'ty | J18: 13 | K18: 8 | L18: 5 | M18: 4 | N18: 2 | O18: 2 | P18: 1 | Q18: 1 | R18: 1 | S18: 1 | Z18: FT2 | AA18: RTD2886NSP_SC_FT2_TA01 | AC18: V04 | AD18: 7677 | AE18: 7662 | AF18: 0.998 | AG18: USB2_Disconnect_trim(15ea,0.20%)
F19: Yield | G19: 0.9953 | H19: 0.9953 | I19: % | J19: 0.0016 | K19: 0.001 | L19: 0.0006 | M19: 0.0005 | N19: 0.0002 | O19: 0.0002 | P19: 0.0001 | Q19: 0.0001 | R19: 0.0001 | S19: 0.0001 | Y19: RL6748 Merlin7 | Z19: CP | AA19: RL6748 | AC19: V25 | AD19: 261525 | AE19: 226627 | AF19: 0.8666 | AG19: cp_mode0_saf_0to90_comp_C(9195ea,3.52%) | AH19: all_bist_mp_scpu_all_bist_1106_CLK144_GPU_ETN_HV(6838ea,2.61%) | AI19: cp_mode2_saf_0to90_comp_C_slow(5841ea,2.23%) | AJ19: cp_mode1_saf_0to90_comp_C(4295ea,1.64%) | AK19: cp_mode0_2_sdd_se0_a75_lp14_dsu_lp28_cat_cs1013_comp_LV(916ea,0.35%) | AL19: IDD(906ea,0.35%) | AM19: cp_mode0_0_tdf_lp8_cat_comp_C_LV(845ea,0.32%) | AN19: PowerShort(820ea,0.31%) | AO19: cp_mode0_tdf_se0_l3mcp_ttr_cov70_comp_HV(808ea,0.31%) | AP19: cp_mode2_tdf_lp6_cov70_comp_disp700_hdmi700_HV_slow(424ea,0.16%)
A20: RL6963 Mac8q | B20: CP | C20: RL6963 | E20: V07 | F20: Total IC | G20: 91488 | H20: 91488 | I20: Test item | J20: cp_mode1_saf_comp_B | K20: cp_mode0_saf_comp | L20: cp_mode2_saf_comp_B | M20: all_bist_m_0217_p1_BIST_LDOoff_OC700_HV | N20: IDD | O20: os | P20: PowerShort | Q20: cp_mode1_tdf_cov70_comp_HV | R20: GPIO_01_GPOH | S20: all_bist_m_0217_p2_GPU_BIST_LDOoff_HV | Z20: CP | AA20: RL6748 | AC20: V25 | AD20: 70329 | AE20: 62093 | AF20: 0.8829 | AG20: cp_mode0_saf_0to90_comp_C(2153ea,3.06%) | AH20: all_bist_mp_scpu_all_bist_1106_CLK144_GPU_ETN_HV(1703ea,2.42%) | AI20: cp_mode2_saf_0to90_comp_C_slow(1383ea,1.97%) | AJ20: cp_mode1_saf_0to90_comp_C(1049ea,1.49%) | AK20: IDD(280ea,0.40%) | AL20: PowerShort(168ea,0.24%) | AM20: cp_mode1_0_tdf_dtv126m_comp_LV(167ea,0.24%) | AN20: cp_mode0_tdf_se0_l3mcp_ttr_cov70_comp_HV(136ea,0.19%) | AO20: cp_mode0_2_sdd_se0_a75_lp14_dsu_lp28_cat_cs1013_comp_LV(116ea,0.16%) | AP20: cp_mode0_0_tdf_lp8_cat_comp_C_LV(107ea,0.15%)
F21: Throughput | G21: 82894 | H21: 82894 | I21: q'ty | J21: 2346 | K21: 1251 | L21: 1055 | M21: 951 | N21: 396 | O21: 291 | P21: 249 | Q21: 234 | R21: 181 | S21: 132 | Z21: FT1 | AA21: RTD2881PSP_SDY_TA01 | AC21: V03 | AD21: 825 | AE21: 824 | AF21: 0.9988 | AG21: HDMI21_12G_144hz(1ea,0.12%)
F22: Yield | G22: 0.9061 | H22: 0.9061 | I22: % | J22: 0.0256 | K22: 0.0137 | L22: 0.0115 | M22: 0.0104 | N22: 0.0043 | O22: 0.0032 | P22: 0.0027 | Q22: 0.0026 | R22: 0.002 | S22: 0.0014 | Z22: FT1 | AA22: RTD2885NCH_WC_TA01 | AC22: V22 | AD22: 2200 | AE22: 2160 | AF22: 0.9818 | AG22: FW_MD_Domain(33ea,1.50%) | AH22: FW_other(7ea,0.32%)
B23: FT1 | C23: RTD2864FLV_TA01 | E23: V10 | F23: Total IC | G23: 76334 | H23: 76334 | I23: Test item | J23: FW_other | K23: FW_HDMI_4K60 | L23: D4_2666M_FRC_4K60_uhd_LB_FT | M23: all_bist_m_0217_p1_BIST_LDOon_HV | N23: os | O23: power_short | P23: all_bist_m_0217_p1_BIST_LDOon_LV | Q23: FW_Multi_core_test_1 | R23: PIF_LVDS_FT | S23: FW_HDMI_480P | Z23: FT1 | AA23: RTD2875PSP_SC_TA01 | AC23: V12 | AD23: 210966 | AE23: 210576 | AF23: 0.9982 | AG23: FW_other(157ea,0.07%) | AH23: OS_500uA(50ea,0.02%) | AI23: Read_IDDQ_New(45ea,0.02%) | AJ23: HDMI20_6G_VB(34ea,0.02%) | AK23: FW_MTEST(18ea,0.01%) | AL23: HDMI20_1p5G(14ea,0.01%) | AM23: Power_Short(10ea,0.00%) | AN23: BB_FT01(9ea,0.00%) | AO23: FW_VDE(7ea,0.00%) | AP23: FW_ETN(5ea,0.00%)
F24: Throughput | G24: 76078 | H24: 76078 | I24: q'ty | J24: 88 | K24: 50 | L24: 25 | M24: 24 | N24: 22 | O24: 5 | P24: 4 | Q24: 4 | R24: 4 | S24: 3 | Y24: RL6641 Mac7p | Z24: CP | AA24: RL6641 | AC24: V16 | AD24: 1493 | AE24: 1352 | AF24: 0.9056 | AG24: cp_saf_mode2_comp_30_dummy_pattern_s2(29ea,1.94%) | AH24: cp_saf_mode6_comp_tmax2_B_cut_s2(22ea,1.47%) | AI24: all_bist_etn_HV(21ea,1.41%) | AJ24: cp_saf_mode0_comp_tmax2_B_cut_s2(14ea,0.94%) | AK24: cp_saf_mode1_comp_tmax2_B_cut_s2(9ea,0.60%) | AL24: PowerShort(8ea,0.54%) | AM24: cp_tdf_mode0_comp_MCP2_V05ECN_DFTts69M_cc_LV(5ea,0.33%) | AN24: IDD(5ea,0.33%) | AO24: cp_tdf_mode6_comp_lp6_MCP2_30_dummy_pattern_LV_s2(4ea,0.27%) | AP24: GPIO_01_GPOH(2ea,0.13%)
F25: Yield | G25: 0.9966 | H25: 0.9966 | I25: % | J25: 0.0012 | K25: 0.0007 | L25: 0.0003 | M25: 0.0003 | N25: 0.0003 | O25: 0.0001 | P25: 0.0001 | Q25: 0.0001 | R25: 0.0001 | S25: 0 | Z25: FT1 | AA25: RTD2841ACS_PS_TA01 | AC25: V26 | AD25: 1270 | AE25: 1265 | AF25: 0.9961 | AG25: HDMI_6G(2ea,0.16%) | AH25: FW_VE (1ea,0.08%) | AI25: FW_other(1ea,0.08%) | AJ25: DDR4_FRC_1p5G_8G4G(1ea,0.08%)
B26: FT1 | C26: RTD2851FCA_TA01 | E26: V10 | F26: Total IC | G26: 10315 | H26: 10315 | I26: Test item | J26: FW_other | K26: D4_2666M_FRC_4K60_uhd_LB_FT | L26: FW_HDMI_4K60 | M26: os | N26: all_bist_m_0217_p1_BIST_LDOon_LV | O26: all_bist_m_0217_p1_BIST_LDOon_HV | P26: all_bist_m_0217_p5_scpu_bist_LDOon_HV | Q26: FW_Multi_core_test_1 | R26: FW_VE_Encode | S26: FW_MD_Domain | Z26: FT1 | AA26: RTD2841ACM_PS_TA01 | AC26: V26 | AD26: 35003 | AE26: 34851 | AF26: 0.9957 | AG26: PowerShort(31ea,0.09%) | AH26: FW_other(31ea,0.09%) | AI26: HDMI_6G(23ea,0.07%) | AJ26: FW_VE (17ea,0.05%) | AK26: DDR4_FRC_1G_8G(12ea,0.03%) | AL26: os_DDR4_8G1G(11ea,0.03%) | AM26: FW_ACPU (7ea,0.02%) | AN26: ETN_TX_FT0(4ea,0.01%) | AO26: USB_Squelch_0X8(4ea,0.01%) | AP26: FW_VE_Encode (3ea,0.01%)
F27: Throughput | G27: 10275 | H27: 10275 | I27: q'ty | J27: 9 | K27: 9 | L27: 7 | M27: 4 | N27: 2 | O27: 2 | P27: 2 | Q27: 1 | R27: 1 | S27: 1 | Z27: FT1 | AA27: RTD2841ASM_PS_TA01 | AC27: V26 | AD27: 22535 | AE27: 22435 | AF27: 0.9956 | AG27: DDR4_FRC_1G_8G(28ea,0.12%) | AH27: FW_VE (17ea,0.08%) | AI27: HDMI_6G(11ea,0.05%) | AJ27: FW_other(9ea,0.04%) | AK27: FW_ACPU (9ea,0.04%) | AL27: FW_MD_DOMAIN (4ea,0.02%) | AM27: os_DDR4_8G1G(3ea,0.01%) | AN27: HDMI_250M(2ea,0.01%) | AO27: YPP03(2ea,0.01%) | AP27: chip_id(2ea,0.01%)
F28: Yield | G28: 0.9961 | H28: 0.9961 | I28: % | J28: 0.0009 | K28: 0.0009 | L28: 0.0007 | M28: 0.0004 | N28: 0.0002 | O28: 0.0002 | P28: 0.0002 | Q28: 0.0001 | R28: 0.0001 | S28: 0.0001 | Z28: FT1 | AA28: RTD2841ASS_PS_TA01 | AC28: V26 | AD28: 37679 | AE28: 37455 | AF28: 0.9941 | AG28: DDR4_FRC_1p5G_8G4G(74ea,0.20%) | AH28: HDMI_6G(51ea,0.14%) | AI28: Thermal_sensor(25ea,0.07%) | AJ28: FW_VE (19ea,0.05%) | AK28: FW_other(13ea,0.03%) | AL28: FW_ACPU (12ea,0.03%) | AM28: YPP03(6ea,0.02%) | AN28: chip_id(6ea,0.02%) | AO28: PowerShort(4ea,0.01%) | AP28: FW_MD_DOMAIN (3ea,0.01%)
B29: FT2 | C29: RTD2841FLW_TA01 | E29: V02 | F29: Total IC | G29: 43427 | H29: 43427 | I29: Test item | J29: USB2_Swing | K29: Wire_bond_leak
F30: Throughput | G30: 43422 | H30: 43422 | I30: q'ty | J30: 3 | K30: 2
F31: Yield | G31: 0.9999 | H31: 0.9999 | I31: % | J31: 0.0001 | K31: 0
A32: RL6896 Dante | B32: FT1 | C32: AXD2801VPF | E32: V08 | F32: Total IC | G32: 10262 | H32: 10262 | I32: Test item | J32: HDMI2p1_12g_TX_check_Done_Result | K32: DDR3_FRC_CA_n6PI | L32: HDMI2p0_6G_RX | N32: DDR3_MD | O32: DDR3_MD_n4 | P32: HDMI2p1_6G_TX_check_Done_Result | Q32: DDR3_FRC_corner1
F33: Throughput | G33: 10226 | H33: 10226 | I33: q'ty | J33: 24 | K33: 4 | L33: 3 | M33: 1 | N33: 1 | O33: 1 | P33: 1 | Q33: 1
F34: Yield | G34: 0.9965 | H34: 0.9965 | I34: % | J34: 0.0023 | K34: 0.0004 | L34: 0.0003 | M34: 0.0001 | N34: 0.0001 | O34: 0.0001 | P34: 0.0001 | Q34: 0.0001
A35: RL6856 Merlin8 | B35: CP | C35: RL6856 | E35: V11 | F35: Total IC | G35: 53392 | H35: 53392 | I35: Test item | J35: cp_mode2_saf_comp_24ns | K35: all_bist_mp_gpu_HV | L35: cp_mode3_saf_comp_VT | M35: cp_mode1_saf_comp | N35: cp_mode0_saf_comp | O35: all_bist_mp_gpu_LV | P35: IDD | Q35: cp_mode1_sdd_maskL2D_hv_cov0to92_comp_HV | R35: os | S35: cp_mode2_0_tdf_c6_comp_HV
F36: Throughput | G36: 45952 | H36: 45952 | I36: q'ty | J36: 1495 | K36: 1263 | L36: 1138 | M36: 569 | N36: 524 | O36: 365 | P36: 258 | Q36: 198 | R36: 195 | S36: 158
F37: Yield | G37: 0.8607 | H37: 0.8607 | I37: % | J37: 0.028 | K37: 0.0237 | L37: 0.0213 | M37: 0.0107 | N37: 0.0098 | O37: 0.0068 | P37: 0.0048 | Q37: 0.0037 | R37: 0.0037 | S37: 0.003
B38: FT1 | C38: RTD2886NSS_SC_FT1_TA01 | E38: V09 | F38: Total IC | G38: 39576 | H38: 39576 | I38: Test item | J38: FW_other | K38: HDMI_12G_ALL_Port | L38: OS_500uA | M38: set-error-bin | N38: Thermal_IDD_comp_4K | O38: ddr_single_rw | P38: VDC01_SNR_FT01 | Q38: Power_Short | R38: PIF_PP_FT_tt | S38: IFD_FT02_SNR
F39: Throughput | G39: 39466 | H39: 39466 | I39: q'ty | J39: 80 | K39: 4 | L39: 4 | M39: 4 | N39: 3 | O39: 3 | P39: 3 | Q39: 2 | R39: 2 | S39: 1
F40: Yield | G40: 0.9972 | H40: 0.9972 | I40: % | J40: 0.002 | K40: 0.0001 | L40: 0.0001 | M40: 0.0001 | N40: 0.0001 | O40: 0.0001 | P40: 0.0001 | Q40: 0.0001 | R40: 0.0001 | S40: 0
...

Sheet RL7032_TA01_V01_summary_raw_da
A1: 1 | B1: PASS BIN | C1: 41506 | D1: 0.8098 | N1: Project | O1: RL7032 | P1: RL7032 | Q1: RL7032 | R1: RL7032 | S1: RL7032 | T1: RL7032 | U1: RL7032 | V1: RL7032 | W1: RL7032 | X1: RL7032 | Y1: RL7032 | Z1: RL7032 | AA1: RL7032 | AB1: RL7032 | AC1: RL7032 | AD1: RL7032 | AE1: RL7032 | AF1: RL7032 | AG1: RL7032 | AH1: RL7032 | AI1: RL7032 | AJ1: RL7032 | AK1: RL7032 | AL1: RL7032 | AM1: RL7032 | AN1: RL7032 | AO1: RL7032 | AP1: RL7032 | AQ1: RL7032 | AR1: RL7032 | AS1: RL7032 | AT1: RL7032 | AU1: RL7032 | AV1: RL7032 | AW1: RL7032 | AX1: RL7032 | AY1: RL7032 | AZ1: RL7032 | BA1: RL7032 | BB1: RL7032 | BC1: RL7032 | BD1: RL7032 | BE1: RL7032 | BF1: RL7032 | BG1: RL7032 | BH1: RL7032 | BI1: RL7032 | BJ1: RL7032 | BK1: RL7032
A2: Top_all | B2: BIN1 | C2: 41506 | D2: 0.8098 | N2: Product | O2: RL7032 | P2: RL7032 | Q2: RL7032 | R2: RL7032 | S2: RL7032 | T2: RL7032 | U2: RL7032 | V2: RL7032 | W2: RL7032 | X2: RL7032 | Y2: RL7032 | Z2: RL7032 | AA2: RL7032 | AB2: RL7032 | AC2: RL7032 | AD2: RL7032 | AE2: RL7032 | AF2: RL7032 | AG2: RL7032 | AH2: RL7032 | AI2: RL7032 | AJ2: RL7032 | AK2: RL7032 | AL2: RL7032 | AM2: RL7032 | AN2: RL7032 | AO2: RL7032 | AP2: RL7032 | AQ2: RL7032 | AR2: RL7032 | AS2: RL7032 | AT2: RL7032 | AU2: RL7032 | AV2: RL7032 | AW2: RL7032 | AX2: RL7032 | AY2: RL7032 | AZ2: RL7032 | BA2: RL7032 | BB2: RL7032 | BC2: RL7032 | BD2: RL7032 | BE2: RL7032 | BF2: RL7032 | BG2: RL7032 | BH2: RL7032 | BI2: RL7032 | BJ2: RL7032 | BK2: RL7032
B3: IDD | C3: 142 | D3: 0.0028 | N3: Short Lot ID | O3: PAFP5 | P3: PAFP5 | Q3: PAFP5 | R3: PAFP5 | S3: PAFP5 | T3: PAFP5 | U3: PAFP5 | V3: PAFP5 | W3: PAFP5 | X3: PAFP5 | Y3: PAEU7 | Z3: PACZ2 | AA3: PAFP5 | AB3: PAFP5 | AC3: PAFP5 | AD3: PAFP5 | AE3: PAEU7 | AF3: PAEU7 | AG3: PAEU7 | AH3: PAFP5 | AI3: PACZ2 | AJ3: PAEU7 | AK3: PAFP5 | AL3: PACZ2 | AM3: PAFP5 | AN3: PAEU7 | AO3: PAEU7 | AP3: PAFP5 | AQ3: PAFP5 | AR3: PAEU7 | AS3: PAFP5 | AT3: PAEU7 | AU3: PAEU7 | AV3: PAEU7 | AW3: PAEU7 | AX3: PACZ2 | AY3: PAEU7 | AZ3: PAEU7 | BA3: PAEU7 | BB3: PAEU7 | BC3: PAEU7 | BD3: PAEU7 | BE3: PAEU7 | BF3: PACZ2 | BG3: PAEU7 | BH3: PAEU7 | BI3: PAEU7 | BJ3: PAEU7 | BK3: PAEU7
B4: OS | C4: 1136 | D4: 0.0222 | N4: Lot ID | O4: PAFP5 | P4: PAFP5 | Q4: PAFP5 | R4: PAFP5 | S4: PAFP5 | T4: PAFP5 | U4: PAFP5 | V4: PAFP5 | W4: PAFP5 | X4: PAFP5 | Y4: PAEU7 | Z4: PACZ2 | AA4: PAFP5 | AB4: PAFP5 | AC4: PAFP5 | AD4: PAFP5 | AE4: PAEU7 | AF4: PAEU7 | AG4: PAEU7 | AH4: PAFP5 | AI4: PACZ2 | AJ4: PAEU7 | AK4: PAFP5 | AL4: PACZ2 | AM4: PAFP5 | AN4: PAEU7 | AO4: PAEU7 | AP4: PAFP5 | AQ4: PAFP5 | AR4: PAEU7 | AS4: PAFP5 | AT4: PAEU7 | AU4: PAEU7 | AV4: PAEU7 | AW4: PAEU7 | AX4: PACZ2 | AY4: PAEU7 | AZ4: PAEU7 | BA4: PAEU7 | BB4: PAEU7 | BC4: PAEU7 | BD4: PAEU7 | BE4: PAEU7 | BF4: PACZ2 | BG4: PAEU7 | BH4: PAEU7 | BI4: PAEU7 | BJ4: PAEU7 | BK4: PAEU7
B5: OTP | C5: 38 | D5: 0.0007 | N5: Wafer ID | O5: PELR18-01E1 | P5: PELR18-02D4 | Q5: PELR18-08H1 | R5: PELR18-18C1 | S5: PELR18-04C2 | T5: PELR18-10H1 | U5: PELR18-05B5 | V5: PELR18-07A3 | W5: PELR18-03C7 | X5: PELR18-09G4 | Y5: PEMY80-18C4 | Z5: PELR05-16F4 | AA5: PELR18-19B4 | AB5: PELR18-06B0 | AC5: PELR18-20C1 | AD5: PELR18-15E0 | AE5: PEMY80-13F5 | AF5: PEMY80-24A0 | AG5: PEMY80-03D2 | AH5: PELR18-14E5 | AI5: PELR05-18E2 | AJ5: PEMY80-10A1 | AK5: PELR18-11G4 | AL5: PELR05-17E7 | AM5: PELR18-12F7 | AN5: PEMY80-15E3 | AO5: PEMY80-23A5 | AP5: PELR18-16D3 | AQ5: PELR18-13F2 | AR5: PEMY80-22B2 | AS5: PELR18-17C6 | AT5: PEMY80-21B7 | AU5: PEMY80-12G2 | AV5: PEMY80-11G7 | AW5: PEMY80-17D1 | AX5: PELR05-14G6 | AY5: PEMY80-25G6 | AZ5: PEMY80-06B3 | BA5: PEMY80-16D6 | BB5: PEMY80-07A6 | BC5: PEMY80-14F0 | BD5: PEMY80-19B7 | BE5: PEMY80-04C5 | BF5: PELR05-15G1 | BG5: PEMY80-05C0 | BH5: PEMY80-20C4 | BI5: PEMY80-08A1 | BJ5: PEMY80-09G7 | BK5: PEMY80-02D7
B6: SD | C6: 16 | D6: 0.0003 | N6: Wafer NO. | O6: 1 | P6: 2 | Q6: 8 | R6: 18 | S6: 4 | T6: 10 | U6: 5 | V6: 7 | W6: 3 | X6: 9 | Y6: 18 | Z6: 16 | AA6: 19 | AB6: 6 | AC6: 20 | AD6: 15 | AE6: 13 | AF6: 24 | AG6: 3 | AH6: 14 | AI6: 18 | AJ6: 10 | AK6: 11 | AL6: 17 | AM6: 12 | AN6: 15 | AO6: 23 | AP6: 16 | AQ6: 13 | AR6: 22 | AS6: 17 | AT6: 21 | AU6: 12 | AV6: 11 | AW6: 17 | AX6: 14 | AY6: 25 | AZ6: 6 | BA6: 16 | BB6: 7 | BC6: 14 | BD6: 19 | BE6: 4 | BF6: 15 | BG6: 5 | BH6: 20 | BI6: 8 | BJ6: 9 | BK6: 2
B7: OC | C7: 1424 | D7: 0.0278 | N7: Re-Test | O7: 1 | P7: 1 | Q7: 1 | R7: 1 | S7: 1 | T7: 1 | U7: 1 | V7: 1 | W7: 1 | X7: 1 | Y7: 1 | Z7: 2 | AA7: 1 | AB7: 1 | AC7: 1 | AD7: 1 | AE7: 1 | AF7: 1 | AG7: 1 | AH7: 1 | AI7: 2 | AJ7: 1 | AK7: 1 | AL7: 2 | AM7: 1 | AN7: 1 | AO7: 1 | AP7: 1 | AQ7: 1 | AR7: 1 | AS7: 1 | AT7: 1 | AU7: 1 | AV7: 1 | AW7: 1 | AX7: 2 | AY7: 1 | AZ7: 1 | BA7: 1 | BB7: 1 | BC7: 1 | BD7: 1 | BE7: 2 | BF7: 2 | BG7: 1 | BH7: 1 | BI7: 1 | BJ7: 1 | BK7: 1
B8: DIC | C8: 45 | D8: 0.0009 | N8: ProbeCard | O8: JP10647 | P8: JP10647 | Q8: JP10647 | R8: JP10647 | S8: JP10647 | T8: JP10647 | U8: JP10647 | V8: JP10647 | W8: JP10647 | X8: JP10647 | Y8: JP10646 | Z8: JP10646 | AA8: JP10647 | AB8: JP10647 | AC8: JP10647 | AD8: JP10647 | AE8: JP10646 | AF8: JP10646 | AG8: JP10646 | AH8: JP10647 | AI8: JP10646 | AJ8: JP10646 | AK8: JP10647 | AL8: JP10646 | AM8: JP10647 | AN8: JP10646 | AO8: JP10646 | AP8: JP10647 | AQ8: JP10647 | AR8: JP10646 | AS8: JP10647 | AT8: JP10646 | AU8: JP10646 | AV8: JP10646 | AW8: JP10646 | AX8: JP10646 | AY8: JP10646 | AZ8: JP10646 | BA8: JP10646 | BB8: JP10646 | BC8: JP10646 | BD8: JP10646 | BE8: JP10646 | BF8: JP10646 | BG8: JP10646 | BH8: JP10646 | BI8: JP10646 | BJ8: JP10646 | BK8: JP10646
B9: BIST | C9: 1972 | D9: 0.0385 | N9: Yield | O9: 0.7151 | P9: 0.7208 | Q9: 0.7514 | R9: 0.7533 | S9: 0.762 | T9: 0.7686 | U9: 0.7734 | V9: 0.7801 | W9: 0.7849 | X9: 0.7849 | Y9: 0.7859 | Z9: 0.7897 | AA9: 0.7964 | AB9: 0.7992 | AC9: 0.8011 | AD9: 0.8021 | AE9: 0.8031 | AF9: 0.8031 | AG9: 0.8069 | AH9: 0.8078 | AI9: 0.8078 | AJ9: 0.8078 | AK9: 0.8088 | AL9: 0.8098 | AM9: 0.8098 | AN9: 0.8117 | AO9: 0.8126 | AP9: 0.8126 | AQ9: 0.8136 | AR9: 0.8145 | AS9: 0.8145 | AT9: 0.8174 | AU9: 0.8203 | AV9: 0.8203 | AW9: 0.8212 | AX9: 0.826 | AY9: 0.8365 | AZ9: 0.8375 | BA9: 0.8384 | BB9: 0.8403 | BC9: 0.8413 | BD9: 0.8432 | BE9: 0.8509 | BF9: 0.8566 | BG9: 0.8566 | BH9: 0.8576 | BI9: 0.8585 | BJ9: 0.8681 | BK9: 0.8767
B10: SCAN | C10: 4936 | D10: 0.0963 | N10: CP | O10: CP1 | P10: CP1 | Q10: CP1 | R10: CP1 | S10: CP1 | T10: CP1 | U10: CP1 | V10: CP1 | W10: CP1 | X10: CP1 | Y10: CP1 | Z10: CP1 | AA10: CP1 | AB10: CP1 | AC10: CP1 | AD10: CP1 | AE10: CP1 | AF10: CP1 | AG10: CP1 | AH10: CP1 | AI10: CP1 | AJ10: CP1 | AK10: CP1 | AL10: CP1 | AM10: CP1 | AN10: CP1 | AO10: CP1 | AP10: CP1 | AQ10: CP1 | AR10: CP1 | AS10: CP1 | AT10: CP1 | AU10: CP1 | AV10: CP1 | AW10: CP1 | AX10: CP1 | AY10: CP1 | AZ10: CP1 | BA10: CP1 | BB10: CP1 | BC10: CP1 | BD10: CP1 | BE10: CP1 | BF10: CP1 | BG10: CP1 | BH10: CP1 | BI10: CP1 | BJ10: CP1 | BK10: CP1
B11: OTHER | C11: 35 | D11: 0.0007 | N11: Starttime | O11: 2025-10-28 03:04:45 | P11: 2025-10-28 09:55:33 | Q11: 2025-10-30 07:46:35 | R11: 2025-11-01 23:57:42 | S11: 2025-10-29 04:35:10 | T11: 2025-10-30 20:19:43 | U11: 2025-10-29 12:01:12 | V11: 2025-10-30 01:22:13 | W11: 2025-10-28 16:32:19 | X11: 2025-10-30 13:55:34 | Y11: 2025-10-31 14:42:37 | Z11: 2025-10-31 09:30:39 | AA11: 2025-11-02 06:29:52 | AB11: 2025-10-29 18:22:41 | AC11: 2025-11-02 12:30:47 | AD11: 2025-11-01 04:53:14 | AE11: 2025-10-29 17:41:48 | AF11: 2025-11-02 03:23:58 | AG11: 2025-10-27 01:08:01 | AH11: 2025-10-31 22:10:31 | AI11: 2025-10-31 12:37:26 | AJ11: 2025-10-28 22:34:05 | AK11: 2025-10-31 03:06:00 | AL11: 2025-10-31 11:10:25 | AM11: 2025-10-31 09:17:12 | AN11: 2025-10-30 14:04:51 | AO11: 2025-11-01 21:25:52 | AP11: 2025-11-01 11:39:05 | AQ11: 2025-10-31 16:07:30 | AR11: 2025-11-01 15:30:13 | AS11: 2025-11-01 17:59:14 | AT11: 2025-11-01 08:48:44 | AU11: 2025-10-29 11:56:09 | AV11: 2025-10-29 05:11:49 | AW11: 2025-10-31 02:11:11 | AX11: 2025-10-30 05:59:52 | AY11: 2025-11-02 09:29:59 | AZ11: 2025-10-27 21:20:35 | BA11: 2025-10-30 20:10:48 | BB11: 2025-10-28 03:20:10 | BC11: 2025-10-30 08:02:51 | BD11: 2025-10-31 20:58:45 | BE11: 2025-11-02 15:39:12 | BF11: 2025-10-31 08:12:00 | BG11: 2025-10-27 15:20:26 | BH11: 2025-11-01 02:54:43 | BI11: 2025-10-28 10:00:08 | BJ11: 2025-10-28 16:28:12 | BK11: 2025-10-26 19:11:09
B12: POR | C12: 4 | D12: 0.0001 | N12: Endtime | O12: 2025-10-28 09:47:44 | P12: 2025-10-28 16:29:21 | Q12: 2025-10-30 13:43:55 | R12: 2025-11-02 06:03:19 | S12: 2025-10-29 11:57:44 | T12: 2025-10-31 02:57:46 | U12: 2025-10-29 17:57:33 | V12: 2025-10-30 07:36:36 | W12: 2025-10-29 04:19:38 | X12: 2025-10-30 19:57:03 | Y12: 2025-10-31 20:56:30 | Z12: 2025-10-31 11:08:11 | AA12: 2025-11-02 12:19:02 | AB12: 2025-10-30 00:41:41 | AC12: 2025-11-02 18:32:47 | AD12: 2025-11-01 11:11:43 | AE12: 2025-10-29 23:25:23 | AF12: 2025-11-02 09:26:39 | AG12: 2025-10-27 06:44:52 | AH12: 2025-11-01 04:01:36 | AI12: 2025-10-31 14:25:55 | AJ12: 2025-10-29 04:20:37 | AK12: 2025-10-31 09:00:45 | AL12: 2025-10-31 12:35:13 | AM12: 2025-10-31 15:40:16 | AN12: 2025-10-30 20:08:34 | AO12: 2025-11-02 03:21:44 | AP12: 2025-11-01 17:39:57 | AQ12: 2025-10-31 21:57:33 | AR12: 2025-11-01 21:23:38 | AS12: 2025-11-01 23:54:31 | AT12: 2025-11-01 14:28:23 | AU12: 2025-10-29 17:39:34 | AV12: 2025-10-29 11:53:55 | AW12: 2025-10-31 07:58:43 | AX12: 2025-10-30 07:33:58 | AY12: 2025-11-02 15:25:41 | AZ12: 2025-10-28 03:08:00 | BA12: 2025-10-31 02:08:57 | BB12: 2025-10-28 09:53:22 | BC12: 2025-10-30 14:02:37 | BD12: 2025-11-01 02:50:14 | BE12: 2025-11-02 16:42:17 | BF12: 2025-10-31 09:24:47 | BG12: 2025-10-27 21:18:22 | BH12: 2025-11-01 08:46:04 | BI12: 2025-10-28 16:23:02 | BJ12: 2025-10-28 22:30:01 | BK12: 2025-10-27 01:05:46
A13: 1 | B13: PASS BIN | C13: 41506 | D13: 0.8098 | E13: PASS BIN | N13: Week | O13: 202544 | P13: 202544 | Q13: 202544 | R13: 202544 | S13: 202544 | T13: 202544 | U13: 202544 | V13: 202544 | W13: 202544 | X13: 202544 | Y13: 202544 | Z13: 202544 | AA13: 202544 | AB13: 202544 | AC13: 202544 | AD13: 202544 | AE13: 202544 | AF13: 202544 | AG13: 202544 | AH13: 202544 | AI13: 202544 | AJ13: 202544 | AK13: 202544 | AL13: 202544 | AM13: 202544 | AN13: 202544 | AO13: 202544 | AP13: 202544 | AQ13: 202544 | AR13: 202544 | AS13: 202544 | AT13: 202544 | AU13: 202544 | AV13: 202544 | AW13: 202544 | AX13: 202544 | AY13: 202544 | AZ13: 202544 | BA13: 202544 | BB13: 202544 | BC13: 202544 | BD13: 202544 | BE13: 202544 | BF13: 202544 | BG13: 202544 | BH13: 202544 | BI13: 202544 | BJ13: 202544 | BK13: 202544
B14: BIN1 | C14: 41506 | D14: 0.8098 | E14: PASS BIN | N14: Month | O14: 2025-10 | P14: 2025-10 | Q14: 2025-10 | R14: 2025-11 | S14: 2025-10 | T14: 2025-10 | U14: 2025-10 | V14: 2025-10 | W14: 2025-10 | X14: 2025-10 | Y14: 2025-10 | Z14: 2025-10 | AA14: 2025-11 | AB14: 2025-10 | AC14: 2025-11 | AD14: 2025-11 | AE14: 2025-10 | AF14: 2025-11 | AG14: 2025-10 | AH14: 2025-11 | AI14: 2025-10 | AJ14: 2025-10 | AK14: 2025-10 | AL14: 2025-10 | AM14: 2025-10 | AN14: 2025-10 | AO14: 2025-11 | AP14: 2025-11 | AQ14: 2025-10 | AR14: 2025-11 | AS14: 2025-11 | AT14: 2025-11 | AU14: 2025-10 | AV14: 2025-10 | AW14: 2025-10 | AX14: 2025-10 | AY14: 2025-11 | AZ14: 2025-10 | BA14: 2025-10 | BB14: 2025-10 | BC14: 2025-10 | BD14: 2025-11 | BE14: 2025-11 | BF14: 2025-10 | BG14: 2025-10 | BH14: 2025-11 | BI14: 2025-10 | BJ14: 2025-10 | BK14: 2025-10
B15: IDD | C15: 142 | D15: 0.0028 | E15: IDD | N15: Program | O15: RL7032_TA01 | P15: RL7032_TA01 | Q15: RL7032_TA01 | R15: RL7032_TA01 | S15: RL7032_TA01 | T15: RL7032_TA01 | U15: RL7032_TA01 | V15: RL7032_TA01 | W15: RL7032_TA01 | X15: RL7032_TA01 | Y15: RL7032_TA01 | Z15: RL7032_TA01 | AA15: RL7032_TA01 | AB15: RL7032_TA01 | AC15: RL7032_TA01 | AD15: RL7032_TA01 | AE15: RL7032_TA01 | AF15: RL7032_TA01 | AG15: RL7032_TA01 | AH15: RL7032_TA01 | AI15: RL7032_TA01 | AJ15: RL7032_TA01 | AK15: RL7032_TA01 | AL15: RL7032_TA01 | AM15: RL7032_TA01 | AN15: RL7032_TA01 | AO15: RL7032_TA01 | AP15: RL7032_TA01 | AQ15: RL7032_TA01 | AR15: RL7032_TA01 | AS15: RL7032_TA01 | AT15: RL7032_TA01 | AU15: RL7032_TA01 | AV15: RL7032_TA01 | AW15: RL7032_TA01 | AX15: RL7032_TA01 | AY15: RL7032_TA01 | AZ15: RL7032_TA01 | BA15: RL7032_TA01 | BB15: RL7032_TA01 | BC15: RL7032_TA01 | BD15: RL7032_TA01 | BE15: RL7032_TA01 | BF15: RL7032_TA01 | BG15: RL7032_TA01 | BH15: RL7032_TA01 | BI15: RL7032_TA01 | BJ15: RL7032_TA01 | BK15: RL7032_TA01
B16: OS | C16: 1136 | D16: 0.0222 | E16: OS | N16: Version(ECN) | O16: RL7032_TA01_V01 | P16: RL7032_TA01_V01 | Q16: RL7032_TA01_V01 | R16: RL7032_TA01_V01 | S16: RL7032_TA01_V01 | T16: RL7032_TA01_V01 | U16: RL7032_TA01_V01 | V16: RL7032_TA01_V01 | W16: RL7032_TA01_V01 | X16: RL7032_TA01_V01 | Y16: RL7032_TA01_V01 | Z16: RL7032_TA01_V01 | AA16: RL7032_TA01_V01 | AB16: RL7032_TA01_V01 | AC16: RL7032_TA01_V01 | AD16: RL7032_TA01_V01 | AE16: RL7032_TA01_V01 | AF16: RL7032_TA01_V01 | AG16: RL7032_TA01_V01 | AH16: RL7032_TA01_V01 | AI16: RL7032_TA01_V01 | AJ16: RL7032_TA01_V01 | AK16: RL7032_TA01_V01 | AL16: RL7032_TA01_V01 | AM16: RL7032_TA01_V01 | AN16: RL7032_TA01_V01 | AO16: RL7032_TA01_V01 | AP16: RL7032_TA01_V01 | AQ16: RL7032_TA01_V01 | AR16: RL7032_TA01_V01 | AS16: RL7032_TA01_V01 | AT16: RL7032_TA01_V01 | AU16: RL7032_TA01_V01 | AV16: RL7032_TA01_V01 | AW16: RL7032_TA01_V01 | AX16: RL7032_TA01_V01 | AY16: RL7032_TA01_V01 | AZ16: RL7032_TA01_V01 | BA16: RL7032_TA01_V01 | BB16: RL7032_TA01_V01 | BC16: RL7032_TA01_V01 | BD16: RL7032_TA01_V01 | BE16: RL7032_TA01_V01 | BF16: RL7032_TA01_V01 | BG16: RL7032_TA01_V01 | BH16: RL7032_TA01_V01 | BI16: RL7032_TA01_V01 | BJ16: RL7032_TA01_V01 | BK16: RL7032_TA01_V01
B17: OTP | C17: 38 | D17: 0.0007 | E17: OTP | N17: Pass Die | O17: 748 | P17: 754 | Q17: 786 | R17: 788 | S17: 797 | T17: 804 | U17: 809 | V17: 816 | W17: 821 | X17: 821 | Y17: 822 | Z17: 826 | AA17: 833 | AB17: 836 | AC17: 838 | AD17: 839 | AE17: 840 | AF17: 840 | AG17: 844 | AH17: 845 | AI17: 845 | AJ17: 845 | AK17: 846 | AL17: 847 | AM17: 847 | AN17: 849 | AO17: 850 | AP17: 850 | AQ17: 851 | AR17: 852 | AS17: 852 | AT17: 855 | AU17: 858 | AV17: 858 | AW17: 859 | AX17: 864 | AY17: 875 | AZ17: 876 | BA17: 877 | BB17: 879 | BC17: 880 | BD17: 882 | BE17: 890 | BF17: 896 | BG17: 896 | BH17: 897 | BI17: 898 | BJ17: 908 | BK17: 917
B18: HDMI | C18: 2 | D18: 0 | E18: SD | N18: Total Die | O18: 1046 | P18: 1046 | Q18: 1046 | R18: 1046 | S18: 1046 | T18: 1046 | U18: 1046 | V18: 1046 | W18: 1046 | X18: 1046 | Y18: 1046 | Z18: 1046 | AA18: 1046 | AB18: 1046 | AC18: 1046 | AD18: 1046 | AE18: 1046 | AF18: 1046 | AG18: 1046 | AH18: 1046 | AI18: 1046 | AJ18: 1046 | AK18: 1046 | AL18: 1046 | AM18: 1046 | AN18: 1046 | AO18: 1046 | AP18: 1046 | AQ18: 1046 | AR18: 1046 | AS18: 1046 | AT18: 1046 | AU18: 1046 | AV18: 1046 | AW18: 1046 | AX18: 1046 | AY18: 1046 | AZ18: 1046 | BA18: 1046 | BB18: 1046 | BC18: 1046 | BD18: 1046 | BE18: 1046 | BF18: 1046 | BG18: 1046 | BH18: 1046 | BI18: 1046 | BJ18: 1046 | BK18: 1046
B19: PLL | C19: 1 | D19: 0 | E19: SD | I19: PASS BIN | M19: 0.81684748 | N19: 1.633695 | O19: 0.71510516 | P19: 0.7208413 | Q19: 0.75143403 | R19: 0.75334608 | S19: 0.76195029 | T19: 0.76864245 | U19: 0.77342256 | V19: 0.78011472 | W19: 0.78489484 | X19: 0.78489484 | Y19: 0.78585086 | Z19: 0.78967495 | AA19: 0.79636711 | AB19: 0.79923518 | AC19: 0.80114723 | AD19: 0.80210325 | AE19: 0.80305927 | AF19: 0.80305927 | AG19: 0.80688337 | AH19: 0.80783939 | AI19: 0.80783939 | AJ19: 0.80783939 | AK19: 0.80879541 | AL19: 0.80975143 | AM19: 0.80975143 | AN19: 0.81166348 | AO19: 0.8126195 | AP19: 0.8126195 | AQ19: 0.81357553 | AR19: 0.81453155 | AS19: 0.81453155 | AT19: 0.81739962 | AU19: 0.82026769 | AV19: 0.82026769 | AW19: 0.82122371 | AX19: 0.82600382 | AY19: 0.83652008 | AZ19: 0.8374761 | BA19: 0.83843212 | BB19: 0.84034417 | BC19: 0.84130019 | BD19: 0.84321224 | BE19: 0.85086042 | BF19: 0.85659656 | BG19: 0.85659656 | BH19: 0.85755258 | BI19: 0.8585086 | BJ19: 0.86806883 | BK19: 0.87667304
B20: VDC | C20: 0 | D20: 0 | E20: SD | I20: IDD | M20: 0.00229738 | N20: 0.00459476 | O20: 0 | P20: 0.00478011 | Q20: 0.00095602 | R20: 0 | S20: 0.00286807 | T20: 0.00382409 | U20: 0.00286807 | V20: 0.00286807 | W20: 0.00478011 | X20: 0.00191205 | Y20: 0.00286807 | Z20: 0.00478011 | AA20: 0 | AB20: 0.00095602 | AC20: 0.00286807 | AD20: 0.00095602 | AE20: 0.00191205 | AF20: 0.00478011 | AG20: 0.00478011 | AH20: 0.00382409 | AI20: 0.00095602 | AJ20: 0.00286807 | AK20: 0.00286807 | AL20: 0.00095602 | AM20: 0.00191205 | AN20: 0.00382409 | AO20: 0.00478011 | AP20: 0.00286807 | AQ20: 0.00095602 | AR20: 0.00095602 | AS20: 0.00095602 | AT20: 0.00286807 | AU20: 0.00382409 | AV20: 0.00478011 | AW20: 0.00573614 | AX20: 0.00191205 | AY20: 0.00191205 | AZ20: 0.00286807 | BA20: 0.00191205 | BB20: 0.00286807 | BC20: 0.00573614 | BD20: 0.00382409 | BE20: 0.00191205 | BF20: 0 | BG20: 0.00764818 | BH20: 0.00478011 | BI20: 0.00095602 | BJ20: 0.00191205 | BK20: 0.00382409
B21: USB | C21: 0 | D21: 0 | E21: SD | I21: OS | M21: 0.01670283 | N21: 0.03340566 | O21: 0.01625239 | P21: 0.00478011 | Q21: 0.02581262 | R21: 0.03919694 | S21: 0.03537285 | T21: 0.02868069 | U21: 0.02581262 | V21: 0.01912046 | W21: 0.0210325 | X21: 0.05066922 | Y21: 0.00956023 | Z21: 0.00573614 | AA21: 0.05927342 | AB21: 0.03154876 | AC21: 0.03154876 | AD21: 0.02007648 | AE21: 0.02868069 | AF21: 0.01147228 | AG21: 0.02390057 | AH21: 0.03537285 | AI21: 0.00669216 | AJ21: 0.02772467 | AK21: 0.0248566 | AL21: 0.01051625 | AM21: 0.01912046 | AN21: 0.01434034 | AO21: 0.01625239 | AP21: 0.03250478 | AQ21: 0.02007648 | AR21: 0.01720841 | AS21: 0.03728489 | AT21: 0.0248566 | AU21: 0.02772467 | AV21: 0.01720841 | AW21: 0.03154876 | AX21: 0.01147228 | AY21: 0.01816444 | AZ21: 0.02390057 | BA21: 0.00956023 | BB21: 0.01912046 | BC21: 0.00382409 | BD21: 0.03154876 | BE21: 0.02676864 | BF21: 0.00956023 | BG21: 0.00860421 | BH21: 0.01912046 | BI21: 0.01816444 | BJ21: 0.0210325 | BK21: 0.01338432
B22: ADC | C22: 0 | D22: 0 | E22: SD | I22: OTP | M22: 0.000485 | N22: 0.00097 | O22: 0 | P22: 0 | Q22: 0 | R22: 0 | S22: 0 | T22: 0 | U22: 0 | V22: 0 | W22: 0 | X22: 0.00095602 | Y22: 0 | Z22: 0 | AA22: 0 | AB22: 0 | AC22: 0.00191205 | AD22: 0 | AE22: 0 | AF22: 0.00095602 | AG22: 0.00191205 | AH22: 0 | AI22: 0 | AJ22: 0.00095602 | AK22: 0 | AL22: 0 | AM22: 0 | AN22: 0 | AO22: 0 | AP22: 0 | AQ22: 0.00095602 | AR22: 0.00286807 | AS22: 0 | AT22: 0.00382409 | AU22: 0 | AV22: 0.00095602 | AW22: 0.00478011 | AX22: 0 | AY22: 0 | AZ22: 0.00095602 | BA22: 0 | BB22: 0.00095602 | BC22: 0 | BD22: 0.00191205 | BE22: 0.00095602 | BF22: 0 | BG22: 0.00095602 | BH22: 0 | BI22: 0.00286807 | BJ22: 0.00573614 | BK22: 0.00191205
B23: PIF | C23: 0 | D23: 0 | E23: SD | I23: HDMI | M23: 0.00034035 | N23: 0.0006807 | O23: 0 | P23: 0 | Q23: 0 | R23: 0 | S23: 0 | T23: 0 | U23: 0 | V23: 0 | W23: 0 | X23: 0 | Y23: 0 | Z23: 0 | AA23: 0 | AB23: 0 | AC23: 0 | AD23: 0 | AE23: 0 | AF23: 0.00095602 | AG23: 0 | AH23: 0 | AI23: 0 | AJ23: 0 | AK23: 0 | AL23: 0 | AM23: 0 | AN23: 0 | AO23: 0 | AP23: 0 | AQ23: 0 | AR23: 0 | AS23: 0 | AT23: 0 | AU23: 0 | AV23: 0.00095602 | AW23: 0 | AX23: 0 | AY23: 0 | AZ23: 0 | BA23: 0 | BB23: 0 | BC23: 0 | BD23: 0 | BE23: 0 | BF23: 0 | BG23: 0 | BH23: 0 | BI23: 0 | BJ23: 0 | BK23: 0
B24: TCON | C24: 0 | D24: 0 | E24: SD | I24: PLL | M24: 0.00057009 | N24: 0.00114018 | O24: 0 | P24: 0 | Q24: 0 | R24: 0 | S24: 0 | T24: 0 | U24: 0 | V24: 0 | W24: 0 | X24: 0 | Y24: 0 | Z24: 0 | AA24: 0 | AB24: 0 | AC24: 0 | AD24: 0 | AE24: 0 | AF24: 0 | AG24: 0 | AH24: 0 | AI24: 0 | AJ24: 0 | AK24: 0 | AL24: 0 | AM24: 0 | AN24: 0 | AO24: 0 | AP24: 0 | AQ24: 0 | AR24: 0 | AS24: 0 | AT24: 0 | AU24: 0 | AV24: 0 | AW24: 0 | AX24: 0.00095602 | AY24: 0 | AZ24: 0 | BA24: 0 | BB24: 0 | BC24: 0 | BD24: 0 | BE24: 0 | BF24: 0 | BG24: 0 | BH24: 0 | BI24: 0 | BJ24: 0 | BK24: 0
B25: LDO | C25: 0 | D25: 0 | E25: SD | I25: VDC | M25: 0.00326739 | N25: 0.00653478 | O25: 0 | P25: 0 | Q25: 0 | R25: 0 | S25: 0 | T25: 0 | U25: 0 | V25: 0 | W25: 0 | X25: 0 | Y25: 0 | Z25: 0 | AA25: 0 | AB25: 0 | AC25: 0 | AD25: 0 | AE25: 0 | AF25: 0 | AG25: 0 | AH25: 0 | AI25: 0 | AJ25: 0 | AK25: 0 | AL25: 0 | AM25: 0 | AN25: 0 | AO25: 0 | AP25: 0 | AQ25: 0 | AR25: 0 | AS25: 0 | AT25: 0 | AU25: 0 | AV25: 0 | AW25: 0 | AX25: 0 | AY25: 0 | AZ25: 0 | BA25: 0 | BB25: 0 | BC25: 0 | BD25: 0 | BE25: 0 | BF25: 0 | BG25: 0 | BH25: 0 | BI25: 0 | BJ25: 0 | BK25: 0
B26: SARADC | C26: 0 | D26: 0 | E26: SD | I26: USB | M26: 3.404e-05 | N26: 6.808e-05 | O26: 0 | P26: 0 | Q26: 0 | R26: 0 | S26: 0 | T26: 0 | U26: 0 | V26: 0 | W26: 0 | X26: 0 | Y26: 0 | Z26: 0 | AA26: 0 | AB26: 0 | AC26: 0 | AD26: 0 | AE26: 0 | AF26: 0 | AG26: 0 | AH26: 0 | AI26: 0 | AJ26: 0 | AK26: 0 | AL26: 0 | AM26: 0 | AN26: 0 | AO26: 0 | AP26: 0 | AQ26: 0 | AR26: 0 | AS26: 0 | AT26: 0 | AU26: 0 | AV26: 0 | AW26: 0 | AX26: 0 | AY26: 0 | AZ26: 0 | BA26: 0 | BB26: 0 | BC26: 0 | BD26: 0 | BE26: 0 | BF26: 0 | BG26: 0 | BH26: 0 | BI26: 0 | BJ26: 0 | BK26: 0
B27: SD_OTHER | C27: 6 | D27: 0.0001 | E27: SD | I27: ADC | M27: 8.51e-06 | N27: 1.702e-05 | O27: 0 | P27: 0 | Q27: 0 | R27: 0 | S27: 0 | T27: 0 | U27: 0 | V27: 0 | W27: 0 | X27: 0 | Y27: 0 | Z27: 0 | AA27: 0 | AB27: 0 | AC27: 0 | AD27: 0 | AE27: 0 | AF27: 0 | AG27: 0 | AH27: 0 | AI27: 0 | AJ27: 0 | AK27: 0 | AL27: 0 | AM27: 0 | AN27: 0 | AO27: 0 | AP27: 0 | AQ27: 0 | AR27: 0 | AS27: 0 | AT27: 0 | AU27: 0 | AV27: 0 | AW27: 0 | AX27: 0 | AY27: 0 | AZ27: 0 | BA27: 0 | BB27: 0 | BC27: 0 | BD27: 0 | BE27: 0 | BF27: 0 | BG27: 0 | BH27: 0 | BI27: 0 | BJ27: 0 | BK27: 0
B28: GPIO | C28: 2 | D28: 0 | E28: SD | I28: PIF | M28: 0.00025526 | N28: 0.00051052 | O28: 0 | P28: 0 | Q28: 0 | R28: 0 | S28: 0 | T28: 0 | U28: 0 | V28: 0 | W28: 0 | X28: 0 | Y28: 0 | Z28: 0 | AA28: 0 | AB28: 0 | AC28: 0 | AD28: 0 | AE28: 0 | AF28: 0 | AG28: 0 | AH28: 0 | AI28: 0 | AJ28: 0 | AK28: 0 | AL28: 0 | AM28: 0 | AN28: 0 | AO28: 0 | AP28: 0 | AQ28: 0 | AR28: 0 | AS28: 0 | AT28: 0 | AU28: 0 | AV28: 0 | AW28: 0 | AX28: 0 | AY28: 0 | AZ28: 0 | BA28: 0 | BB28: 0 | BC28: 0 | BD28: 0 | BE28: 0 | BF28: 0 | BG28: 0 | BH28: 0 | BI28: 0 | BJ28: 0 | BK28: 0
B29: ETN | C29: 0 | D29: 0 | E29: SD | I29: TCON | M29: 8.51e-06 | N29: 1.702e-05 | O29: 0 | P29: 0 | Q29: 0 | R29: 0 | S29: 0 | T29: 0 | U29: 0 | V29: 0 | W29: 0 | X29: 0 | Y29: 0 | Z29: 0 | AA29: 0 | AB29: 0 | AC29: 0 | AD29: 0 | AE29: 0 | AF29: 0 | AG29: 0 | AH29: 0 | AI29: 0 | AJ29: 0 | AK29: 0 | AL29: 0 | AM29: 0 | AN29: 0 | AO29: 0 | AP29: 0 | AQ29: 0 | AR29: 0 | AS29: 0 | AT29: 0 | AU29: 0 | AV29: 0 | AW29: 0 | AX29: 0 | AY29: 0 | AZ29: 0 | BA29: 0 | BB29: 0 | BC29: 0 | BD29: 0 | BE29: 0 | BF29: 0 | BG29: 0 | BH29: 0 | BI29: 0 | BJ29: 0 | BK29: 0
B30: EARC | C30: 2 | D30: 0 | E30: SD | I30: LDO | M30: 2.553e-05 | N30: 5.106e-05 | O30: 0 | P30: 0 | Q30: 0 | R30: 0 | S30: 0 | T30: 0 | U30: 0 | V30: 0 | W30: 0 | X30: 0 | Y30: 0 | Z30: 0 | AA30: 0 | AB30: 0 | AC30: 0 | AD30: 0 | AE30: 0 | AF30: 0 | AG30: 0 | AH30: 0 | AI30: 0 | AJ30: 0 | AK30: 0 | AL30: 0 | AM30: 0 | AN30: 0 | AO30: 0 | AP30: 0 | AQ30: 0 | AR30: 0 | AS30: 0 | AT30: 0 | AU30: 0 | AV30: 0 | AW30: 0 | AX30: 0 | AY30: 0 | AZ30: 0 | BA30: 0 | BB30: 0 | BC30: 0 | BD30: 0 | BE30: 0 | BF30: 0 | BG30: 0 | BH30: 0 | BI30: 0 | BJ30: 0 | BK30: 0
... B44: POR | C44: 4 | D44: 0.0001 | E44: POR | I44: SAF | M44: 0.07342268 | N44: 0.14684536 | O44: 0.07361377 | P44: 0.0793499 | Q44: 0.05927342 | R44: 0.05066922 | S44: 0.0793499 | T44: 0.06022945 | U44: 0.08413002 | V44: 0.07839388 | W44: 0.06692161 | X44: 0.07552581 | Y44: 0.09273423 | Z44: 0.07170172 | AA44: 0.06500956 | AB44: 0.05066922 | AC44: 0.06214149 | AD44: 0.06787763 | AE44: 0.08699809 | AF44: 0.06596558 | AG44: 0.08030593 | AH44: 0.06118547 | AI44: 0.05258126 | AJ44: 0.0707457 | AK44: 0.0707457 | AL44: 0.06978967 | AM44: 0.06405354 | AN44: 0.0707457 | AO44: 0.06978967 | AP44: 0.07648184 | AQ44: 0.08126195 | AR44: 0.06978967 | AS44: 0.07170172 | AT44: 0.08604207 | AU44: 0.06692161 | AV44: 0.08030593 | AW44: 0.05736138 | AX44: 0.07265774 | AY44: 0.08126195 | AZ44: 0.06596558 | BA44: 0.06692161 | BB44: 0.0707457 | BC44: 0.06692161 | BD44: 0.05353728 | BE44: 0.05353728 | BF44: 0.05449331 | BG44: 0.05353728 | BH44: 0.06405354 | BI44: 0.06787763 | BJ44: 0.04875717 | BK44: 0.06500956
I45: SDD_LV | M45: 0.00325888 | N45: 0.00651776 | O45: 0.00478011 | P45: 0.00191205 | Q45: 0.00382409 | R45: 0.00191205 | S45: 0.00286807 | T45: 0 | U45: 0.00382409 | V45: 0.00095602 | W45: 0.00573614 | X45: 0.00478011 | Y45: 0.00286807 | Z45: 0.00382409 | AA45: 0.00573614 | AB45: 0.00382409 | AC45: 0.00286807 | AD45: 0.00191205 | AE45: 0.00478011 | AF45: 0.00382409 | AG45: 0.00191205 | AH45: 0.00382409 | AI45: 0.00286807 | AJ45: 0.00669216 | AK45: 0.00286807 | AL45: 0.00095602 | AM45: 0.00286807 | AN45: 0.00573614 | AO45: 0.00286807 | AP45: 0.00095602 | AQ45: 0.00095602 | AR45: 0.00764818 | AS45: 0.00191205 | AT45: 0.00286807 | AU45: 0.00956023 | AV45: 0.00478011 | AW45: 0.00669216 | AX45: 0.00095602 | AY45: 0.00095602 | AZ45: 0.00286807 | BA45: 0.00478011 | BB45: 0.00286807 | BC45: 0.00382409 | BD45: 0.00573614 | BE45: 0.00860421 | BF45: 0.00286807 | BG45: 0.00860421 | BH45: 0.00669216 | BI45: 0.00095602 | BJ45: 0.00573614 | BK45: 0.00095602
I46: TDF_HV | M46: 0.01131674 | N46: 0.02263348 | O46: 0.02772467 | P46: 0.01051625 | Q46: 0.02390057 | R46: 0.01816444 | S46: 0.01338432 | T46: 0.01625239 | U46: 0.02198853 | V46: 0.01147228 | W46: 0.00956023 | X46: 0.01338432 | Y46: 0.01051625 | Z46: 0.02198853 | AA46: 0.01338432 | AB46: 0.01147228 | AC46: 0.02198853 | AD46: 0.01912046 | AE46: 0.01338432 | AF46: 0.00860421 | AG46: 0.01529637 | AH46: 0.0124283 | AI46: 0.01338432 | AJ46: 0.02007648 | AK46: 0.0124283 | AL46: 0.00956023 | AM46: 0.01434034 | AN46: 0.00764818 | AO46: 0.00956023 | AP46: 0.01434034 | AQ46: 0.00956023 | AR46: 0.01051625 | AS46: 0.01720841 | AT46: 0.01147228 | AU46: 0.01720841 | AV46: 0.0210325 | AW46: 0.00956023 | AX46: 0.00860421 | AY46: 0.00860421 | AZ46: 0.01147228 | BA46: 0.00286807 | BB46: 0.01147228 | BC46: 0.00573614 | BD46: 0.00956023 | BE46: 0.01338432 | BF46: 0.00478011 | BG46: 0.01625239 | BH46: 0.00764818 | BI46: 0.00669216 | BJ46: 0.01051625 | BK46: 0.00860421
I47: BF | M47: 0.00493512 | N47: 0.00987024 | O47: 0.02581262 | P47: 0.0458891 | Q47: 0.03250478 | R47: 0.01912046 | S47: 0.0124283 | T47: 0.03059273 | U47: 0.01720841 | V47: 0.04015296 | W47: 0.0210325 | X47: 0.00956023 | Y47: 0.00191205 | Z47: 0.00191205 | AA47: 0.00573614 | AB47: 0.01816444 | AC47: 0.00669216 | AD47: 0.00956023 | AE47: 0.00095602 | AF47: 0 | AG47: 0.00095602 | AH47: 0.01338432 | AI47: 0 | AJ47: 0.00286807 | AK47: 0.01434034 | AL47: 0.00095602 | AM47: 0.00478011 | AN47: 0.00095602 | AO47: 0.00095602 | AP47: 0.00095602 | AQ47: 0.02294455 | AR47: 0.00095602 | AS47: 0.01338432 | AT47: 0.00095602 | AU47: 0.00286807 | AV47: 0 | AW47: 0.00191205 | AX47: 0 | AY47: 0 | AZ47: 0.00095602 | BA47: 0 | BB47: 0.00095602 | BC47: 0.00095602 | BD47: 0.00191205 | BE47: 0 | BF47: 0 | BG47: 0.00095602 | BH47: 0.00095602 | BI47: 0.00095602 | BJ47: 0.00095602 | BK47: 0.00095602
I48: OTHER | M48: 0.00075729 | N48: 0.00151458 | O48: 0.00095602 | P48: 0.00095602 | Q48: 0 | R48: 0.00095602 | S48: 0 | T48: 0.00095602 | U48: 0.00191205 | V48: 0 | W48: 0 | X48: 0.00095602 | Y48: 0 | Z48: 0.00095602 | AA48: 0.00095602 | AB48: 0 | AC48: 0.00191205 | AD48: 0 | AE48: 0.00095602 | AF48: 0.00095602 | AG48: 0.00095602 | AH48: 0.00095602 | AI48: 0.00191205 | AJ48: 0.00191205 | AK48: 0 | AL48: 0.00095602 | AM48: 0.00095602 | AN48: 0.00095602 | AO48: 0 | AP48: 0 | AQ48: 0.00191205 | AR48: 0.00191205 | AS48: 0 | AT48: 0 | AU48: 0 | AV48: 0.00095602 | AW48: 0 | AX48: 0.00095602 | AY48: 0 | AZ48: 0.00095602 | BA48: 0 | BB48: 0 | BC48: 0.00191205 | BD48: 0 | BE48: 0 | BF48: 0 | BG48: 0.00095602 | BH48: 0.00286807 | BI48: 0 | BJ48: 0 | BK48: 0
I49: POR | M49: 0.00016167 | N49: 0.00032334 | O49: 0 | P49: 0 | Q49: 0 | R49: 0 | S49: 0 | T49: 0 | U49: 0.00095602 | V49: 0 | W49: 0 | X49: 0 | Y49: 0 | Z49: 0 | AA49: 0 | AB49: 0 | AC49: 0 | AD49: 0 | AE49: 0.00095602 | AF49: 0 | AG49: 0 | AH49: 0 | AI49: 0 | AJ49: 0 | AK49: 0 | AL49: 0 | AM49: 0 | AN49: 0 | AO49: 0 | AP49: 0 | AQ49: 0 | AR49: 0 | AS49: 0 | AT49: 0 | AU49: 0 | AV49: 0 | AW49: 0 | AX49: 0 | AY49: 0.00095602 | AZ49: 0 | BA49: 0 | BB49: 0 | BC49: 0 | BD49: 0 | BE49: 0 | BF49: 0 | BG49: 0 | BH49: 0 | BI49: 0 | BJ49: 0.00095602 | BK49: 0
A50: 2025-10-27-2025-11-02 | J50: 49
A51: Order | B51: Item | C51: Bin | D51: Test program | E51: Test voltage | F51: Fail Type | G51: Fail Type | H51: q'ty | I51: % | J51: >10% | K51: >avg*2 | L51: Max | M51: Avg % | N51: Highlight %
A52: TOP | B52: PASS BIN | D52: PASS BIN | F52: PASS BIN | G52: PASS BIN | H52: 41506 | I52: 0.8098 | M52: 0.81684748 | N52: wafer_count=113 | O52: 0.71510516 | P52: 0.7208413 | Q52: 0.75143403 | R52: 0.75334608 | S52: 0.76195029 | T52: 0.76864245 | U52: 0.77342256 | V52: 0.78011472 | W52: 0.78489484 | X52: 0.78489484 | Y52: 0.78585086 | Z52: 0.78967495 | AA52: 0.79636711 | AB52: 0.79923518 | AC52: 0.80114723 | AD52: 0.80210325 | AE52: 0.80305927 | AF52: 0.80305927 | AG52: 0.80688337 | AH52: 0.80783939 | AI52: 0.80783939 | AJ52: 0.80783939 | AK52: 0.80879541 | AL52: 0.80975143 | AM52: 0.80975143 | AN52: 0.81166348 | AO52: 0.8126195 | AP52: 0.8126195 | AQ52: 0.81357553 | AR52: 0.81453155 | AS52: 0.81453155 | AT52: 0.81739962 | AU52: 0.82026769 | AV52: 0.82026769 | AW52: 0.82122371 | AX52: 0.82600382 | AY52: 0.83652008 | AZ52: 0.8374761 | BA52: 0.83843212 | BB52: 0.84034417 | BC52: 0.84130019 | BD52: 0.84321224 | BE52: 0.85086042 | BF52: 0.85659656 | BG52: 0.85659656 | BH52: 0.85755258 | BI52: 0.8585086 | BJ52: 0.86806883 | BK52: 0.87667304
A53: TOP | B53: PASS BIN | C53: 1 | D53: PASS BIN | F53: PASS BIN | G53: PASS BIN | H53: 41506 | I53: 0.80980997 | J53: 49 | K53: 0 | L53: 0.87667304 | M53: 0.81684748 | N53: 1.633695 | O53: 0.71510516 | P53: 0.7208413 | Q53: 0.75143403 | R53: 0.75334608 | S53: 0.76195029 | T53: 0.76864245 | U53: 0.77342256 | V53: 0.78011472 | W53: 0.78489484 | X53: 0.78489484 | Y53: 0.78585086 | Z53: 0.78967495 | AA53: 0.79636711 | AB53: 0.79923518 | AC53: 0.80114723 | AD53: 0.80210325 | AE53: 0.80305927 | AF53: 0.80305927 | AG53: 0.80688337 | AH53: 0.80783939 | AI53: 0.80783939 | AJ53: 0.80783939 | AK53: 0.80879541 | AL53: 0.80975143 | AM53: 0.80975143 | AN53: 0.81166348 | AO53: 0.8126195 | AP53: 0.8126195 | AQ53: 0.81357553 | AR53: 0.81453155 | AS53: 0.81453155 | AT53: 0.81739962 | AU53: 0.82026769 | AV53: 0.82026769 | AW53: 0.82122371 | AX53: 0.82600382 | AY53: 0.83652008 | AZ53: 0.8374761 | BA53: 0.83843212 | BB53: 0.84034417 | BC53: 0.84130019 | BD53: 0.84321224 | BE53: 0.85086042 | BF53: 0.85659656 | BG53: 0.85659656 | BH53: 0.85755258 | BI53: 0.8585086 | BJ53: 0.86806883 | BK53: 0.87667304
...

Sheet RL6963_V07_summary_raw_data
A1: 1 | B1: PASS BIN | C1: 82894 | D1: 0.9061 | N1: Project | O1: RL6963 | P1: RL6963 | Q1: RL6963 | R1: RL6963 | S1: RL6963 | T1: RL6963 | U1: RL6963 | V1: RL6963 | W1: RL6963 | X1: RL6963 | Y1: RL6963 | Z1: RL6963 | AA1: RL6963 | AB1: RL6963 | AC1: RL6963 | AD1: RL6963 | AE1: RL6963 | AF1: RL6963 | AG1: RL6963 | AH1: RL6963 | AI1: RL6963 | AJ1: RL6963 | AK1: RL6963 | AL1: RL6963 | AM1: RL6963 | AN1: RL6963 | AO1: RL6963 | AP1: RL6963 | AQ1: RL6963 | AR1: RL6963 | AS1: RL6963 | AT1: RL6963 | AU1: RL6963 | AV1: RL6963 | AW1: RL6963 | AX1: RL6963 | AY1: RL6963 | AZ1: RL6963 | BA1: RL6963 | BB1: RL6963 | BC1: RL6963 | BD1: RL6963 | BE1: RL6963 | BF1: RL6963 | BG1: RL6963 | BH1: RL6963 | BI1: RL6963 | BJ1: RL6963
A2: Top_all | B2: BIN1 | C2: 82894 | D2: 0.9061 | N2: Product | O2: RL6963 | P2: RL6963 | Q2: RL6963 | R2: RL6963 | S2: RL6963 | T2: RL6963 | U2: RL6963 | V2: RL6963 | W2: RL6963 | X2: RL6963 | Y2: RL6963 | Z2: RL6963 | AA2: RL6963 | AB2: RL6963 | AC2: RL6963 | AD2: RL6963 | AE2: RL6963 | AF2: RL6963 | AG2: RL6963 | AH2: RL6963 | AI2: RL6963 | AJ2: RL6963 | AK2: RL6963 | AL2: RL6963 | AM2: RL6963 | AN2: RL6963 | AO2: RL6963 | AP2: RL6963 | AQ2: RL6963 | AR2: RL6963 | AS2: RL6963 | AT2: RL6963 | AU2: RL6963 | AV2: RL6963 | AW2: RL6963 | AX2: RL6963 | AY2: RL6963 | AZ2: RL6963 | BA2: RL6963 | BB2: RL6963 | BC2: RL6963 | BD2: RL6963 | BE2: RL6963 | BF2: RL6963 | BG2: RL6963 | BH2: RL6963 | BI2: RL6963 | BJ2: RL6963
B3: OTP | C3: 26 | D3: 0.0003 | N3: Short Lot ID | O3: PAGM2 | P3: PAHD0 | Q3: PAHD0 | R3: PAGM2 | S3: PAGM2 | T3: PAGM2 | U3: PAHD0 | V3: PAGM2 | W3: PAHD0 | X3: PAGM2 | Y3: PAGM2 | Z3: PAGM2 | AA3: PAHD0 | AB3: PAGM2 | AC3: PAHD0 | AD3: PAGM2 | AE3: PAHC9 | AF3: PAGM2 | AG3: PAHD0 | AH3: PAHC9 | AI3: PAGM2 | AJ3: PAHC9 | AK3: PAGM2 | AL3: PAHD0 | AM3: PAHD0 | AN3: PAHC9 | AO3: PAHC9 | AP3: PAGM2 | AQ3: PAHD0 | AR3: PAGM2 | AS3: PAGM2 | AT3: PAHC9 | AU3: PAHD0 | AV3: PAHD0 | AW3: PAHD0 | AX3: PAHC9 | AY3: PAHD0 | AZ3: PAHC9 | BA3: PAHC9 | BB3: PAHD0 | BC3: PAHC9 | BD3: PAHC9 | BE3: PAHC9 | BF3: PAGM2 | BG3: PAHD0 | BH3: PAHC9 | BI3: PAHC9 | BJ3: PAHC9
B4: SCAN | C4: 5589 | D4: 0.0611 | N4: Lot ID | O4: PAGM2 | P4: PAHD0 | Q4: PAHD0 | R4: PAGM2 | S4: PAGM2 | T4: PAGM2 | U4: PAHD0 | V4: PAGM2 | W4: PAHD0 | X4: PAGM2 | Y4: PAGM2 | Z4: PAGM2 | AA4: PAHD0 | AB4: PAGM2 | AC4: PAHD0 | AD4: PAGM2 | AE4: PAHC9 | AF4: PAGM2 | AG4: PAHD0 | AH4: PAHC9 | AI4: PAGM2 | AJ4: PAHC9 | AK4: PAGM2 | AL4: PAHD0 | AM4: PAHD0 | AN4: PAHC9 | AO4: PAHC9 | AP4: PAGM2 | AQ4: PAHD0 | AR4: PAGM2 | AS4: PAGM2 | AT4: PAHC9 | AU4: PAHD0 | AV4: PAHD0 | AW4: PAHD0 | AX4: PAHC9 | AY4: PAHD0 | AZ4: PAHC9 | BA4: PAHC9 | BB4: PAHD0 | BC4: PAHC9 | BD4: PAHC9 | BE4: PAHC9 | BF4: PAGM2 | BG4: PAHD0 | BH4: PAHC9 | BI4: PAHC9 | BJ4: PAHC9
B5: SD | C5: 253 | D5: 0.0028 | N5: Wafer ID | O5: PERU72-03E4 | P5: PEQS30-09G2 | Q5: PEQS30-01D7 | R5: PERU72-07C0 | S5: PERU72-12A1 | T5: PERU72-08B3 | U5: PEQS30-12F5 | V5: PERU72-15F5 | W5: PEQS30-15D6 | X5: PERU72-01F6 | Y5: PERU72-02F1 | Z5: PERU72-17E3 | AA5: PEQS30-13F0 | AB5: PERU72-04D7 | AC5: PEQS30-04C0 | AD5: PERU72-14G2 | AE5: PERS89-11B1 | AF5: PERU72-06C5 | AG5: PEQS30-02D2 | AH5: PERS89-02F4 | AI5: PERU72-09A6 | AJ5: PERS89-04E2 | AK5: PERU72-16F0 | AL5: PEQS30-10G7 | AM5: PEQS30-07A1 | AN5: PERS89-01G1 | AO5: PERS89-14G5 | AP5: PERU72-11A6 | AQ5: PEQS30-03C5 | AR5: PERU72-10B3 | AS5: PERU72-13G7 | AT5: PERS89-13H2 | AU5: PEQS30-08G7 | AV5: PEQS30-16D1 | AW5: PEQS30-06A6 | AX5: PERS89-05D5 | AY5: PEQS30-14E3 | AZ5: PERS89-06D0 | BA5: PERS89-03E7 | BB5: PEQS30-11G2 | BC5: PERS89-07C3 | BD5: PERS89-10B6 | BE5: PERS89-09B1 | BF5: PERU72-05D2 | BG5: PEQS30-05B3 | BH5: PERS89-08B6 | BI5: PERS89-15G0 | BJ5: PERS89-12A4
B6: DIC | C6: 43 | D6: 0.0005 | N6: Wafer NO. | O6: 3 | P6: 9 | Q6: 1 | R6: 7 | S6: 12 | T6: 8 | U6: 12 | V6: 15 | W6: 15 | X6: 1 | Y6: 2 | Z6: 17 | AA6: 13 | AB6: 4 | AC6: 4 | AD6: 14 | AE6: 11 | AF6: 6 | AG6: 2 | AH6: 2 | AI6: 9 | AJ6: 4 | AK6: 16 | AL6: 10 | AM6: 7 | AN6: 1 | AO6: 14 | AP6: 11 | AQ6: 3 | AR6: 10 | AS6: 13 | AT6: 13 | AU6: 8 | AV6: 16 | AW6: 6 | AX6: 5 | AY6: 14 | AZ6: 6 | BA6: 3 | BB6: 11 | BC6: 7 | BD6: 10 | BE6: 9 | BF6: 5 | BG6: 5 | BH6: 8 | BI6: 15 | BJ6: 12
B7: BIST | C7: 1623 | D7: 0.0177 | N7: Re-Test | O7: 1 | P7: 1 | Q7: 1 | R7: 1 | S7: 1 | T7: 1 | U7: 1 | V7: 1 | W7: 1 | X7: 1 | Y7: 1 | Z7: 1 | AA7: 1 | AB7: 1 | AC7: 1 | AD7: 1 | AE7: 1 | AF7: 1 | AG7: 1 | AH7: 1 | AI7: 1 | AJ7: 1 | AK7: 1 | AL7: 1 | AM7: 1 | AN7: 1 | AO7: 1 | AP7: 1 | AQ7: 1 | AR7: 1 | AS7: 1 | AT7: 1 | AU7: 1 | AV7: 1 | AW7: 1 | AX7: 1 | AY7: 1 | AZ7: 1 | BA7: 1 | BB7: 1 | BC7: 1 | BD7: 1 | BE7: 1 | BF7: 1 | BG7: 1 | BH7: 1 | BI7: 1 | BJ7: 1
B8: OTHER | C8: 81 | D8: 0.0009 | N8: ProbeCard | O8: JP09000 | P8: JP10346 | Q8: JP10346 | R8: JP09000 | S8: JP09000 | T8: JP09000 | U8: JP10346 | V8: JP09000 | W8: JP10346 | X8: JP09000 | Y8: JP09000 | Z8: JP09000 | AA8: JP10346 | AB8: JP09000 | AC8: JP10346 | AD8: JP09000 | AE8: JP10208 | AF8: JP09000 | AG8: JP10346 | AH8: JP10208 | AI8: JP09000 | AJ8: JP10208 | AK8: JP09000 | AL8: JP10346 | AM8: JP10346 | AN8: JP10208 | AO8: JP10208 | AP8: JP09000 | AQ8: JP10346 | AR8: JP09000 | AS8: JP09000 | AT8: JP10208 | AU8: JP10346 | AV8: JP10346 | AW8: JP10346 | AX8: JP10208 | AY8: JP10346 | AZ8: JP10208 | BA8: JP10208 | BB8: JP10346 | BC8: JP10208 | BD8: JP10208 | BE8: JP10208 | BF8: JP09000 | BG8: JP10346 | BH8: JP10208 | BI8: JP10208 | BJ8: JP10208
B9: IDD | C9: 434 | D9: 0.0047 | N9: Yield | O9: 0.8274 | P9: 0.8814 | Q9: 0.8867 | R9: 0.8877 | S9: 0.8919 | T9: 0.8924 | U9: 0.8951 | V9: 0.8951 | W9: 0.8972 | X9: 0.8972 | Y9: 0.8972 | Z9: 0.8977 | AA9: 0.8987 | AB9: 0.8987 | AC9: 0.8993 | AD9: 0.9003 | AE9: 0.9003 | AF9: 0.9003 | AG9: 0.9008 | AH9: 0.9024 | AI9: 0.9029 | AJ9: 0.905 | AK9: 0.9077 | AL9: 0.9082 | AM9: 0.9082 | AN9: 0.9103 | AO9: 0.9103 | AP9: 0.9108 | AQ9: 0.9108 | AR9: 0.9108 | AS9: 0.9113 | AT9: 0.9134 | AU9: 0.915 | AV9: 0.915 | AW9: 0.915 | AX9: 0.9161 | AY9: 0.9166 | AZ9: 0.9182 | BA9: 0.9182 | BB9: 0.9187 | BC9: 0.9208 | BD9: 0.9208 | BE9: 0.9218 | BF9: 0.9234 | BG9: 0.9239 | BH9: 0.9281 | BI9: 0.9281 | BJ9: 0.9339
