Workbook

Sheet Summary_RTD
A1: 20250714~20250720 | B1: CP/FT | C1: Total IC | D1: Throughput | E1: Yield | G1: 20250714~20250720 | H1: CP/FT | I1: RTD No. | K1: Total IC | L1: Throughput | M1: Yield
A2: RL6982 Merlin9 | B2: CP | C2: 371989 | D2: 334478 | E2: 0.8992 | G2: RL6982 Merlin9 | H2: CP | I2: RL6982 | K2: 371989 | L2: 334478 | M2: 0.8992
B3: FT1 | C3: 244130 | D3: 242948 | E3: 0.9952 | H3: FT1 | I3: RTD2875QDA_TA01 | K3: 104745 | L3: 104233 | M3: 0.9951
A4: RL6963 Mac8q | B4: CP | C4: 230626 | D4: 205871 | E4: 0.8927 | I4: RTD2875QDA_HD_TA01 | K4: 38172 | L4: 37976 | M4: 0.9949
B5: FT1 | C5: 138569 | D5: 137585 | E5: 0.9929 | I5: RTD2874MDA_HD_TA01 | K5: 60589 | L5: 60317 | M5: 0.9955
B6: FT2 | C6: 77922 | D6: 77889 | E6: 0.9996 | I6: RTD2874MDA_TA01 | K6: 40624 | L6: 40422 | M6: 0.995
A7: RL6896 Dante | B7: CP | C7: 0 | D7: 0 | G7: RL6963 Mac8q | H7: CP | I7: RL6963 | K7: 230626 | L7: 205871 | M7: 0.8927
B8: FT1 | C8: 3374 | D8: 3366 | E8: 0.9976 | H8: FT1 | I8: RTD2851FCA_TA01 | K8: 2324 | L8: 2312 | M8: 0.9948
A9: RL6866 Mac8p | B9: CP | C9: 0 | D9: 0 | I9: RTD2841FLW_TA01 | K9: 120533 | L9: 119861 | M9: 0.9944
A10: RL6856 Merlin8 | B10: CP | C10: 114736 | D10: 96527 | E10: 0.8413 | I10: RTD2864FLV_TA01 | K10: 15712 | L10: 15412 | M10: 0.9809
B11: FT1 | C11: 59007 | D11: 58519 | E11: 0.9917 | H11: FT2 | I11: RTD2841FLW | K11: 77922 | L11: 77889 | M11: 0.9996
B12: FT2 | C12: 13950 | D12: 13946 | E12: 0.9997 | G12: RL6896 Dante | H12: CP | I12: RL6896 | K12: 0 | L12: 0
A13: RL6750 H5C2 | B13: CP | C13: 4806 | D13: 3871 | E13: 0.8055 | H13: FT1 | I13: AXD2801VPF | K13: 3374 | L13: 3366 | M13: 0.9976
A14: RL6748 Merlin7 | B14: CP | C14: 0 | D14: 0 | G14: RL6866 Mac8p | H14: CP | I14: RL6866 | K14: 0 | L14: 0
B15: FT1 | C15: 253329 | D15: 252395 | E15: 0.9963 | G15: RL6856 Merlin8 | H15: CP | I15: RL6856 | K15: 114736 | L15: 96527 | M15: 0.8413
B16: FT2 | C16: 0 | D16: 0 | H16: FT1 | I16: RTD2885PDM_FT1_TA01 | K16: 59007 | L16: 58519 | M16: 0.9917
A17: RL6746 MIO | B17: CP | C17: 314430 | D17: 312463 | E17: 0.9937 | H17: FT2 | I17: RTD2885PDM | K17: 13950 | L17: 13946 | M17: 0.9997
A18: RL6708 Bridge | B18: CP | C18: 0 | D18: 0 | G18: RL6750 H5C2 | H18: CP | I18: RL6750 | K18: 4806 | L18: 3871 | M18: 0.8055
B19: FT1 | C19: 7344 | D19: 7340 | E19: 0.9995 | G19: RL6748 Merlin7 | H19: CP | I19: RL6748 | K19: 0 | L19: 0
A20: RL6681 ATSC3 | B20: CP | C20: 0 | D20: 0 | H20: FT1 | I20: RTD2885NCK_SC | K20: 1263 | L20: 1263 | M20: 1
B21: FT1 | C21: 9016 | D21: 9000 | E21: 0.9982 | I21: RTD2875PSA_SC_TA01 | K21: 126002 | L21: 125729 | M21: 0.9978
A22: RL6672 Merlin6 | B22: CP | C22: 0 | D22: 0 | I22: RTD2885CSP_SC_TA01 | K22: 3402 | L22: 3386 | M22: 0.9953
B23: FT1 | C23: 0 | D23: 0 | I23: RTD2875PSP_SC_TA01 | K23: 115060 | L23: 114424 | M23: 0.9945
B24: FT2 | C24: 0 | D24: 0 | I24: RTD2875PNJ_SND_TA01 | K24: 7602 | L24: 7593 | M24: 0.9988
A25: RL6641 Mac7p | B25: CP | C25: 258289 | D25: 232966 | E25: 0.902 | G25: RL6746 MIO | H25: CP | I25: RL6746 | K25: 314430 | L25: 312463 | M25: 0.9937
B26: FT1 | C26: 0 | D26: 0 | G26: RL6708 Bridge | H26: CP | I26: RL6708 | K26: 0 | L26: 0
A27: RL6617 Merlin5 | B27: CP | C27: 26928 | D27: 23965 | E27: 0.89 | H27: FT1 | I27: RTD2800RR | K27: 7344 | L27: 7340 | M27: 0.9995
B28: FT1 | C28: 0 | D28: 0 | G28: RL6681 ATSC3 | H28: CP | I28: RL6681 | K28: 0 | L28: 0
B29: FT2 | C29: 0 | D29: 0 | H29: FT1 | I29: RTD2813 | K29: 9016 | L29: 9000 | M29: 0.9982
G30: RL6672 Merlin6 | H30: CP | I30: RL6672 | K30: 0 | L30: 0
G31: RL6641 Mac7p | H31: CP | I31: RL6641 | K31: 258289 | L31: 232966 | M31: 0.902
G32: RL6617 Merlin5 | H32: CP | I32: RL6617 | K32: 26928 | L32: 23965 | M32: 0.89

Sheet Top_all
A1: Project | B1: CP/FT | C1: RTD No. | E1: ECN Ver. | G1: summary | H1: Y25_W29 | J1: Top1 | K1: Top2 | L1: Top3 | M1: Top4 | N1: Top5 | O1: Top6 | P1: Top7 | Q1: Top8 | R1: Top9 | S1: Top10 | Y1: Project | Z1: CP/FT | AA1: RTD No. | AC1: ECN Ver. | AD1: Total IC | AE1: Throughput | AF1: Yield | AG1: Top1 | AH1: Top2 | AI1: Top3 | AJ1: Top4 | AK1: Top5 | AL1: Top6 | AM1: Top7 | AN1: Top8 | AO1: Top9 | AP1: Top10
A2: RL6982 Merlin9 | B2: CP | C2: RL6982 | E2: V03 | F2: Total IC | G2: 371989 | H2: 371989 | I2: Test item | J2: cp_mode2_saf_spc30_comp | K2: cp_mode3_saf_comp | L2: all_bist_wo_ETN_HV | M2: cp_mode1_saf_comp | N2: cp_mode0_saf_comp | O2: SCPU_L3_BISR_HV | P2: scpu_bist_all_1p2_HV | Q2: all_bisr_drf_mp_BISR_HV | R2: PowerShort | S2: EJTAG_GPU_BIST_HV | Y2: RL6982 Merlin9 | Z2: CP | AA2: RL6982 | AC2: V03 | AD2: 371989 | AE2: 334478 | AF2: 0.8992 | AG2: cp_mode2_saf_spc30_comp(9383ea,2.52%) | AH2: cp_mode3_saf_comp(5976ea,1.61%) | AI2: all_bist_wo_ETN_HV(5215ea,1.40%) | AJ2: cp_mode1_saf_comp(3561ea,0.96%) | AK2: cp_mode0_saf_comp(3136ea,0.84%) | AL2: SCPU_L3_BISR_HV(1467ea,0.39%) | AM2: scpu_bist_all_1p2_HV(1032ea,0.28%) | AN2: all_bisr_drf_mp_BISR_HV(850ea,0.23%) | AO2: PowerShort(776ea,0.21%) | AP2: EJTAG_GPU_BIST_HV(546ea,0.15%)
F3: Throughput | G3: 334478 | H3: 334478 | I3: q'ty | J3: 9383 | K3: 5976 | L3: 5215 | M3: 3561 | N3: 3136 | O3: 1467 | P3: 1032 | Q3: 850 | R3: 776 | S3: 546 | Z3: FT1 | AA3: RTD2875QDA_TA01 | AC3: V02 | AD3: 104745 | AE3: 104233 | AF3: 0.9951 | AG3: DDR4_2G_3000_SS_FRC_ZQp5p(123ea,0.12%) | AH3: DDR4_2G_3000_SS_single_RW_FT(110ea,0.11%) | AI3: FW_other(96ea,0.09%) | AJ3: OS_500uA(46ea,0.04%) | AK3: USB2_disconnect_mea(36ea,0.03%) | AL3: all_bisr_drf(14ea,0.01%) | AM3: PowerShort(14ea,0.01%) | AN3: HDMI20_250M_mm(10ea,0.01%) | AO3: FW_MULTI_CORE_TEST(8ea,0.01%) | AP3: scpu_bist_all_1p2_HV(6ea,0.01%)
F4: Yield | G4: 0.8992 | H4: 0.8992 | I4: % | J4: 0.0252 | K4: 0.0161 | L4: 0.014 | M4: 0.0096 | N4: 0.0084 | O4: 0.0039 | P4: 0.0028 | Q4: 0.0023 | R4: 0.0021 | S4: 0.0015 | Z4: FT1 | AA4: RTD2875QDA_HD_TA01 | AC4: V02 | AD4: 38172 | AE4: 37976 | AF4: 0.9949 | AG4: DDR4_2G_3000_SS_FRC_ZQp5p(54ea,0.14%) | AH4: DDR4_2G_3000_SS_single_RW_FT(46ea,0.12%) | AI4: FW_other(40ea,0.10%) | AJ4: OS_500uA(18ea,0.05%) | AK4: PowerShort(7ea,0.02%) | AL4: all_bisr_drf(6ea,0.02%) | AM4: Wire_Bond_Leak(4ea,0.01%) | AN4: scpu_bist_all_1p2_HV(4ea,0.01%) | AO4: IDDQ(4ea,0.01%) | AP4: FW_VE(2ea,0.01%)
B5: FT1 | C5: RTD2875QDA_TA01 | E5: V02 | F5: Total IC | G5: 104745 | H5: 104745 | I5: Test item | J5: DDR4_2G_3000_SS_FRC_ZQp5p | K5: DDR4_2G_3000_SS_single_RW_FT | L5: FW_other | M5: OS_500uA | N5: USB2_disconnect_mea | O5: all_bisr_drf | P5: PowerShort | Q5: HDMI20_250M_mm | R5: FW_MULTI_CORE_TEST | S5: scpu_bist_all_1p2_HV | Z5: FT1 | AA5: RTD2874MDA_HD_TA01 | AC5: V02 | AD5: 60589 | AE5: 60317 | AF5: 0.9955 | AG5: FW_other(75ea,0.12%) | AH5: DDR4_2G_3000_SS_FRC_ZQp5p(64ea,0.11%) | AI5: DDR4_2G_3000_SS_single_RW_FT(50ea,0.08%) | AJ5: all_bisr_drf(8ea,0.01%) | AK5: Wire_Bond_Leak(8ea,0.01%) | AL5: FW_MULTI_CORE_TEST(7ea,0.01%) | AM5: OS_500uA(5ea,0.01%) | AN5: PowerShort(5ea,0.01%) | AO5: scpu_bist_all_1p2_HV(5ea,0.01%) | AP5: scpu_bisr_bist_drf(4ea,0.01%)
F6: Throughput | G6: 104233 | H6: 104233 | I6: q'ty | J6: 123 | K6: 110 | L6: 96 | M6: 46 | N6: 36 | O6: 14 | P6: 14 | Q6: 10 | R6: 8 | S6: 6 | Z6: FT1 | AA6: RTD2874MDA_TA01 | AC6: V02 | AD6: 40624 | AE6: 40422 | AF6: 0.995 | AG6: FW_other(59ea,0.15%) | AH6: DDR4_2G_3000_SS_single_RW_FT(45ea,0.11%) | AI6: DDR4_2G_3000_SS_FRC_ZQp5p(40ea,0.10%) | AJ6: USB2_disconnect_mea(14ea,0.03%) | AK6: all_bisr_drf(5ea,0.01%) | AL6: FW_VE(5ea,0.01%) | AM6: FW_MULTI_CORE_TEST(4ea,0.01%) | AN6: OS_500uA(3ea,0.01%) | AO6: EFUSE_ReadAll_CRC(3ea,0.01%) | AP6: Wire_Bond_Leak(2ea,0.00%)
F7: Yield | G7: 0.9951 | H7: 0.9951 | I7: % | J7: 0.0012 | K7: 0.0011 | L7: 0.0009 | M7: 0.0004 | N7: 0.0003 | O7: 0.0001 | P7: 0.0001 | Q7: 0.0001 | R7: 0.0001 | S7: 0.0001 | Y7: RL6963 Mac8q | Z7: CP | AA7: RL6963 | AC7: V07 | AD7: 230626 | AE7: 205871 | AF7: 0.8927 | AG7: cp_mode1_saf_comp_B(5354ea,2.32%) | AH7: IDD(5138ea,2.23%) | AI7: cp_mode0_saf_comp(3165ea,1.37%) | AJ7: cp_mode2_saf_comp_B(2620ea,1.14%) | AK7: all_bist_m_0217_p1_BIST_LDOoff_OC700_HV(1995ea,0.87%) | AL7: Core<=180mA&SCPU<120mA(877ea,0.38%) | AM7: cp_mode1_tdf_cov70_comp_HV(697ea,0.30%) | AN7: PowerShort(515ea,0.22%) | AO7: os(430ea,0.19%) | AP7: Core 160~180&scpu 100~120(337ea,0.15%)
B8: FT1 | C8: RTD2875QDA_HD_TA01 | E8: V02 | F8: Total IC | G8: 38172 | H8: 38172 | I8: Test item | J8: DDR4_2G_3000_SS_FRC_ZQp5p | K8: DDR4_2G_3000_SS_single_RW_FT | L8: FW_other | M8: OS_500uA | N8: PowerShort | O8: all_bisr_drf | P8: Wire_Bond_Leak | Q8: scpu_bist_all_1p2_HV | R8: IDDQ | S8: FW_VE | Z8: FT1 | AA8: RTD2851FCA_TA01 | AC8: V10 | AD8: 2324 | AE8: 2312 | AF8: 0.9948 | AG8: PIF_LVDS_FT(10ea,0.43%) | AH8: FW_other(1ea,0.04%) | AI8: FW_HDMI_4K60(1ea,0.04%)
F9: Throughput | G9: 37976 | H9: 37976 | I9: q'ty | J9: 54 | K9: 46 | L9: 40 | M9: 18 | N9: 7 | O9: 6 | P9: 4 | Q9: 4 | R9: 4 | S9: 2 | Z9: FT1 | AA9: RTD2841FLW_TA01 | AC9: V10 | AD9: 120533 | AE9: 119861 | AF9: 0.9944 | AG9: FW_other(223ea,0.19%) | AH9: os(94ea,0.08%) | AI9: D4_2666M_FRC_4K60_uhd_LB_FT(73ea,0.06%) | AJ9: FW_HDMI_4K60(63ea,0.05%) | AK9: all_bist_m_0217_p1_BIST_LDOon_HV(49ea,0.04%) | AL9: power_short_EOT(35ea,0.03%) | AM9: power_short(22ea,0.02%) | AN9: FW_HDMI_480P(16ea,0.01%) | AO9: all_bist_m_0217_p5_scpu_bist_LDOon_HV(12ea,0.01%) | AP9: PIF_LVDS_FT(8ea,0.01%)
F10: Yield | G10: 0.9949 | H10: 0.9949 | I10: % | J10: 0.0014 | K10: 0.0012 | L10: 0.001 | M10: 0.0005 | N10: 0.0002 | O10: 0.0002 | P10: 0.0001 | Q10: 0.0001 | R10: 0.0001 | S10: 0.0001 | Z10: FT1 | AA10: RTD2864FLV_TA01 | AC10: V09 | AD10: 15712 | AE10: 15412 | AF10: 0.9809 | AG10: FW_other(242ea,1.54%) | AH10: FW_EMMC(16ea,0.10%) | AI10: FW_HDMI_4K60(15ea,0.10%) | AJ10: D4_2666M_FRC_4K60_uhd_LB_FT(4ea,0.03%) | AK10: OS(4ea,0.03%) | AL10: FW_Multi_core_test_1(2ea,0.01%) | AM10: all_bist_m_0217_p1_BIST_LDOon_HV(2ea,0.01%) | AN10: IFD_FT01(2ea,0.01%) | AO10: FW_SPI_NAND(2ea,0.01%) | AP10: FW_USB(1ea,0.01%)
B11: FT1 | C11: RTD2874MDA_HD_TA01 | E11: V02 | F11: Total IC | G11: 60589 | H11: 60589 | I11: Test item | J11: FW_other | K11: DDR4_2G_3000_SS_FRC_ZQp5p | L11: DDR4_2G_3000_SS_single_RW_FT | M11: all_bisr_drf | N11: Wire_Bond_Leak | O11: FW_MULTI_CORE_TEST | P11: OS_500uA | Q11: PowerShort | R11: scpu_bist_all_1p2_HV | S11: scpu_bisr_bist_drf | Z11: FT2 | AA11: RTD2841FLW | AC11: V01 | AD11: 77922 | AE11: 77889 | AF11: 0.9996 | AG11: USB2_Swing(13ea,0.02%) | AH11: Wire_bond_leak(11ea,0.01%) | AI11: IDDQ(7ea,0.01%) | AJ11: Chip_ID_B(1ea,0.00%) | AK11: por(1ea,0.00%)
F12: Throughput | G12: 60317 | H12: 60317 | I12: q'ty | J12: 75 | K12: 64 | L12: 50 | M12: 8 | N12: 8 | O12: 7 | P12: 5 | Q12: 5 | R12: 5 | S12: 4 | Y12: RL6896 Dante | Z12: FT1 | AA12: AXD2801VPF | AC12: V08 | AD12: 3374 | AE12: 3366 | AF12: 0.9976 | AG12: HDMI2p1_12g_TX_check_Done_Result(7ea,0.21%) | AH12: HDMI2p0_6G_RX(1ea,0.03%)
F13: Yield | G13: 0.9955 | H13: 0.9955 | I13: % | J13: 0.0012 | K13: 0.0011 | L13: 0.0008 | M13: 0.0001 | N13: 0.0001 | O13: 0.0001 | P13: 0.0001 | Q13: 0.0001 | R13: 0.0001 | S13: 0.0001 | Y13: RL6856 Merlin8 | Z13: CP | AA13: RL6856 | AC13: V10 | AD13: 114736 | AE13: 96527 | AF13: 0.8413 | AG13: cp_mode2_saf_comp_24ns(3504ea,3.05%) | AH13: all_bist_mp_gpu_HV(2739ea,2.39%) | AI13: cp_mode3_saf_comp_VT(2707ea,2.36%) | AJ13: cp_mode1_saf_comp(1430ea,1.25%) | AK13: cp_mode0_saf_comp(1170ea,1.02%) | AL13: all_bist_mp_gpu_LV(1091ea,0.95%) | AM13: IDD(680ea,0.59%) | AN13: power_short(487ea,0.42%) | AO13: os(436ea,0.38%) | AP13: core_scpu_power_IDD_spec(427ea,0.37%)
B14: FT1 | C14: RTD2874MDA_TA01 | E14: V02 | F14: Total IC | G14: 40624 | H14: 40624 | I14: Test item | J14: FW_other | K14: DDR4_2G_3000_SS_single_RW_FT | L14: DDR4_2G_3000_SS_FRC_ZQp5p | M14: USB2_disconnect_mea | N14: all_bisr_drf | O14: FW_VE | P14: FW_MULTI_CORE_TEST | Q14: OS_500uA | R14: EFUSE_ReadAll_CRC | S14: Wire_Bond_Leak | Z14: FT1 | AA14: RTD2885PDM_FT1_TA01 | AC14: V06 | AD14: 59007 | AE14: 58519 | AF14: 0.9917 | AG14: FW_M8(196ea,0.33%) | AH14: HDMI_12G(100ea,0.17%) | AI14: DDR_single_RW_D4(49ea,0.08%) | AJ14: DDR_ZQ_P(37ea,0.06%) | AK14: VDC01_FT01_SNR(21ea,0.04%) | AL14: Power_Short(20ea,0.03%) | AM14: IFD_FT01(18ea,0.03%) | AN14: set-error-bin(12ea,0.02%) | AO14: IFD_FT02(8ea,0.01%) | AP14: OS_500uA(7ea,0.01%)
F15: Throughput | G15: 40422 | H15: 40422 | I15: q'ty | J15: 59 | K15: 45 | L15: 40 | M15: 14 | N15: 5 | O15: 5 | P15: 4 | Q15: 3 | R15: 3 | S15: 2 | Z15: FT2 | AA15: RTD2885PDM | AC15: V04 | AD15: 13950 | AE15: 13946 | AF15: 0.9997 | AG15: OS(4ea,0.03%)
F16: Yield | G16: 0.995 | H16: 0.995 | I16: % | J16: 0.0015 | K16: 0.0011 | L16: 0.001 | M16: 0.0003 | N16: 0.0001 | O16: 0.0001 | P16: 0.0001 | Q16: 0.0001 | R16: 0.0001 | S16: 0 | Y16: RL6750 H5C2 | Z16: CP | AA16: RL6750 | AC16: V03 | AD16: 4806 | AE16: 3871 | AF16: 0.8055 | AG16: SAF_mode0_spc20_comp_211220165909_HV(153ea,3.18%) | AH16: SAF_mode1_comp_211080048_HV(147ea,3.06%) | AI16: all_bist_HV(142ea,2.95%) | AJ16: IDDQ(87ea,1.81%) | AK16: OS_500uA(72ea,1.50%) | AL16: SAF_mode2_comp_2111080208_HV(71ea,1.48%) | AM16: Power_Short(64ea,1.33%) | AN16: PIF_PP(63ea,1.31%) | AO16: all_bisr_drf(27ea,0.56%) | AP16: TDF_mode1_wo_vby1_occ_dnr_lp25_stage1_25_g5_spc20_comp_220110132151_LV(17ea,0.35%)
A17: RL6963 Mac8q | B17: CP | C17: RL6963 | E17: V07 | F17: Total IC | G17: 230626 | H17: 230626 | I17: Test item | J17: cp_mode1_saf_comp_B | K17: IDD | L17: cp_mode0_saf_comp | M17: cp_mode2_saf_comp_B | N17: all_bist_m_0217_p1_BIST_LDOoff_OC700_HV | O17: Core<=180mA&SCPU<120mA | P17: cp_mode1_tdf_cov70_comp_HV | Q17: PowerShort | R17: os | S17: Core 160~180&scpu 100~120 | Y17: RL6748 Merlin7 | Z17: FT1 | AA17: RTD2885NCK_SC | AC17: V16 | AD17: 1263 | AE17: 1263 | AF17: 1
F18: Throughput | G18: 205871 | H18: 205871 | I18: q'ty | J18: 5354 | K18: 5138 | L18: 3165 | M18: 2620 | N18: 1995 | O18: 877 | P18: 697 | Q18: 515 | R18: 430 | S18: 337 | Z18: FT1 | AA18: RTD2875PSA_SC_TA01 | AC18: V12 | AD18: 126002 | AE18: 125729 | AF18: 0.9978 | AG18: FW_other(136ea,0.11%) | AH18: OS_500uA(41ea,0.03%) | AI18: HDMI20_1p5G(17ea,0.01%) | AJ18: HDMI20_6G_VB(13ea,0.01%) | AK18: USB_squelch_trim(7ea,0.01%) | AL18: FW_VDC_PQ(6ea,0.00%) | AM18: FW_MTEST(5ea,0.00%) | AN18: FW_ETN(5ea,0.00%) | AO18: OS_2mA(5ea,0.00%) | AP18: FW_MD_Domain(5ea,0.00%)
F19: Yield | G19: 0.8927 | H19: 0.8927 | I19: % | J19: 0.0232 | K19: 0.0223 | L19: 0.0137 | M19: 0.0114 | N19: 0.0087 | O19: 0.0038 | P19: 0.003 | Q19: 0.0022 | R19: 0.0019 | S19: 0.0015 | Z19: FT1 | AA19: RTD2885CSP_SC_TA01 | AC19: V12 | AD19: 3402 | AE19: 3386 | AF19: 0.9953 | AG19: (3386ea,99.53%) | AH19: (7ea,0.21%) | AI19: (6ea,0.18%) | AJ19: (2ea,0.06%) | AK19: (1ea,0.03%) | AM19: (3402ea,100.00%)
B20: FT1 | C20: RTD2851FCA_TA01 | E20: V10 | F20: Total IC | G20: 2324 | H20: 2324 | I20: Test item | J20: PIF_LVDS_FT | K20: FW_other | L20: FW_HDMI_4K60 | Z20: FT1 | AA20: RTD2875PSP_SC_TA01 | AC20: V12 | AD20: 115060 | AE20: 114424 | AF20: 0.9945 | AG20: FW_other(380ea,0.33%) | AH20: OS_500uA(72ea,0.06%) | AI20: FW_MD_Domain(62ea,0.05%) | AJ20: HDMI20_6G_VB(34ea,0.03%) | AK20: Power_Short(13ea,0.01%) | AL20: OS_2mA(13ea,0.01%) | AM20: FW_VDC_PQ(12ea,0.01%) | AN20: FW_ETN(9ea,0.01%) | AO20: USB_squelch_trim(7ea,0.01%) | AP20: FW_MTEST(4ea,0.00%)
F21: Throughput | G21: 2312 | H21: 2312 | I21: q'ty | J21: 10 | K21: 1 | L21: 1 | Z21: FT1 | AA21: RTD2875PNJ_SND_TA01 | AC21: V12 | AD21: 7602 | AE21: 7593 | AF21: 0.9988 | AG21: (7593ea,99.88%) | AH21: (5ea,0.07%) | AI21: (1ea,0.01%) | AJ21: (1ea,0.01%) | AK21: (1ea,0.01%) | AL21: (1ea,0.01%) | AN21: (7602ea,100.00%)
F22: Yield | G22: 0.9948 | H22: 0.9948 | I22: % | J22: 0.0043 | K22: 0.0004 | L22: 0.0004 | Y22: RL6746 MIO | Z22: CP | AA22: RL6746 | AC22: V02 | AD22: 314430 | AE22: 312463 | AF22: 0.9937 | AG22: scan_saf_intl_NV_mode0(1104ea,0.35%) | AH22: chip_id_20201231(344ea,0.11%) | AI22: svad_bist_mp_LV_20210126(327ea,0.10%) | AJ22: open_short_500ua_20210205(56ea,0.02%) | AK22: idd_100_20210225(40ea,0.01%) | AL22: mio_iso_spi_sync_sd_regrw_27M(35ea,0.01%) | AM22: scan_tdf_comp_HV_mode0(12ea,0.00%) | AN22: gpio_03_gpi_read_gpo_20210202(10ea,0.00%) | AO22: scan_bf_comp_NV_mode0(9ea,0.00%) | AP22: gpio_05_gpi_l_leakage_20210202(7ea,0.00%)
B23: FT1 | C23: RTD2841FLW_TA01 | E23: V10 | F23: Total IC | G23: 120533 | H23: 120533 | I23: Test item | J23: FW_other | K23: os | L23: D4_2666M_FRC_4K60_uhd_LB_FT | M23: FW_HDMI_4K60 | N23: all_bist_m_0217_p1_BIST_LDOon_HV | O23: power_short_EOT | P23: power_short | Q23: FW_HDMI_480P | R23: all_bist_m_0217_p5_scpu_bist_LDOon_HV | S23: PIF_LVDS_FT | Y23: RL6708 Bridge | Z23: FT1 | AA23: RTD2800RR | AC23: V07 | AD23: 7344 | AE23: 7340 | AF23: 0.9995 | AG23: os_RX_vb(2ea,0.03%) | AH23: power_short_rx(1ea,0.01%) | AI23: iRealOne_12G_RX(1ea,0.01%)
F24: Throughput | G24: 119861 | H24: 119861 | I24: q'ty | J24: 223 | K24: 94 | L24: 73 | M24: 63 | N24: 49 | O24: 35 | P24: 22 | Q24: 16 | R24: 12 | S24: 8 | Y24: RL6681 ATSC3 | Z24: FT1 | AA24: RTD2813 | AC24: V01 | AD24: 9016 | AE24: 9000 | AF24: 0.9982 | AG24: open_short_2ma_220121(7ea,0.08%) | AH24: open_short_500ua_220121(5ea,0.06%) | AI24: atsc_IFD_FT02_ramp_12b(2ea,0.02%) | AJ24: wire_bond_leakage(1ea,0.01%) | AK24: atsc_IFD_FT01_12b(1ea,0.01%)
F25: Yield | G25: 0.9944 | H25: 0.9944 | I25: % | J25: 0.0019 | K25: 0.0008 | L25: 0.0006 | M25: 0.0005 | N25: 0.0004 | O25: 0.0003 | P25: 0.0002 | Q25: 0.0001 | R25: 0.0001 | S25: 0.0001 | Y25: RL6641 Mac7p | Z25: CP | AA25: RL6641 | AC25: V16 | AD25: 258289 | AE25: 232966 | AF25: 0.902 | AG25: all_bist_etn_HV(5125ea,1.98%) | AH25: cp_saf_mode2_comp_30_dummy_pattern_s2(4648ea,1.80%) | AI25: cp_saf_mode0_comp_tmax2_B_cut_s2(3029ea,1.17%) | AJ25: cp_saf_mode1_comp_tmax2_B_cut_s2(2606ea,1.01%) | AK25: IDD(2448ea,0.95%) | AL25: cp_saf_mode6_comp_tmax2_B_cut_s2(2068ea,0.80%) | AM25: PowerShort(1184ea,0.46%) | AN25: cp_tdf_mode2_comp_30_dummy_pattern_LV_s2(542ea,0.21%) | AO25: scpu_bist_all_mode_shr_delay2_SCPU1150_HV(457ea,0.18%) | AP25: GPU_DEC_OPEN_HV(396ea,0.15%)
B26: FT1 | C26: RTD2864FLV_TA01 | E26: V09 | F26: Total IC | G26: 15712 | H26: 15712 | I26: Test item | J26: FW_other | K26: FW_EMMC | L26: FW_HDMI_4K60 | M26: D4_2666M_FRC_4K60_uhd_LB_FT | N26: OS | O26: FW_Multi_core_test_1 | P26: all_bist_m_0217_p1_BIST_LDOon_HV | Q26: IFD_FT01 | R26: FW_SPI_NAND | S26: FW_USB | Y26: RL6617 Merlin5 | Z26: CP | AA26: RL6617 | AC26: V42 | AD26: 26928 | AE26: 23965 | AF26: 0.89 | AG26: cp_saf_mode0_comp_period_slow_HV(571ea,2.12%) | AH26: cp_saf_mode2_comp_period_slow_HV(562ea,2.09%) | AI26: all_bist_mp_HV(555ea,2.06%) | AJ26: cp_saf_mode1_comp_period_slow_HV(395ea,1.47%) | AK26: cp_tdf_mode0_1_comp_period_slow_LV(121ea,0.45%) | AL26: cp_tdf_mode0_0_mask_MBFF_1bit_0_comp_period_slow_LV(108ea,0.40%) | AM26: power_short(108ea,0.40%) | AN26: cp_tdf_mode2_comp_period_slow_LV(63ea,0.23%) | AO26: mln5_all_bisr_drf_mp_HV_LV(41ea,0.15%) | AP26: cp_saf_mode3_comp_period_slow_HV(39ea,0.14%)
F27: Throughput | G27: 15412 | H27: 15412 | I27: q'ty | J27: 242 | K27: 16 | L27: 15 | M27: 4 | N27: 4 | O27: 2 | P27: 2 | Q27: 2 | R27: 2 | S27: 1
F28: Yield | G28: 0.9809 | H28: 0.9809 | I28: % | J28: 0.0154 | K28: 0.001 | L28: 0.001 | M28: 0.0003 | N28: 0.0003 | O28: 0.0001 | P28: 0.0001 | Q28: 0.0001 | R28: 0.0001 | S28: 0.0001
B29: FT2 | C29: RTD2841FLW | E29: V01 | F29: Total IC | G29: 77922 | H29: 77922 | I29: Test item | J29: USB2_Swing | K29: Wire_bond_leak | L29: IDDQ | M29: Chip_ID_B | N29: por
F30: Throughput | G30: 77889 | H30: 77889 | I30: q'ty | J30: 13 | K30: 11 | L30: 7 | M30: 1 | N30: 1
F31: Yield | G31: 0.9996 | H31: 0.9996 | I31: % | J31: 0.0002 | K31: 0.0001 | L31: 0.0001 | M31: 0 | N31: 0
A32: RL6896 Dante | B32: FT1 | C32: AXD2801VPF | E32: V08 | F32: Total IC | G32: 3374 | H32: 3374 | I32: Test item | J32: HDMI2p1_12g_TX_check_Done_Result | K32: HDMI2p0_6G_RX
F33: Throughput | G33: 3366 | H33: 3366 | I33: q'ty | J33: 7 | K33: 1
F34: Yield | G34: 0.9976 | H34: 0.9976 | I34: % | J34: 0.0021 | K34: 0.0003
A35: RL6856 Merlin8 | B35: CP | C35: RL6856 | E35: V10 | F35: Total IC | G35: 114736 | H35: 114736 | I35: Test item | J35: cp_mode2_saf_comp_24ns | K35: all_bist_mp_gpu_HV | L35: cp_mode3_saf_comp_VT | M35: cp_mode1_saf_comp | N35: cp_mode0_saf_comp | O35: all_bist_mp_gpu_LV | P35: IDD | Q35: power_short | R35: os | S35: core_scpu_power_IDD_spec
F36: Throughput | G36: 96527 | H36: 96527 | I36: q'ty | J36: 3504 | K36: 2739 | L36: 2707 | M36: 1430 | N36: 1170 | O36: 1091 | P36: 680 | Q36: 487 | R36: 436 | S36: 427
F37: Yield | G37: 0.8413 | H37: 0.8413 | I37: % | J37: 0.0305 | K37: 0.0239 | L37: 0.0236 | M37: 0.0125 | N37: 0.0102 | O37: 0.0095 | P37: 0.0059 | Q37: 0.0042 | R37: 0.0038 | S37: 0.0037
B38: FT1 | C38: RTD2885PDM_FT1_TA01 | E38: V06 | F38: Total IC | G38: 59007 | H38: 59007 | I38: Test item | J38: FW_M8 | K38: HDMI_12G | L38: DDR_single_RW_D4 | M38: DDR_ZQ_P | N38: VDC01_FT01_SNR | O38: Power_Short | P38: IFD_FT01 | Q38: set-error-bin | R38: IFD_FT02 | S38: OS_500uA
F39: Throughput | G39: 58519 | H39: 58519 | I39: q'ty | J39: 196 | K39: 100 | L39: 49 | M39: 37 | N39: 21 | O39: 20 | P39: 18 | Q39: 12 | R39: 8 | S39: 7
F40: Yield | G40: 0.9917 | H40: 0.9917 | I40: % | J40: 0.0033 | K40: 0.0017 | L40: 0.0008 | M40: 0.0006 | N40: 0.0004 | O40: 0.0003 | P40: 0.0003 | Q40: 0.0002 | R40: 0.0001 | S40: 0.0001
...

Sheet RL6982_HD_TA01_V03_summary_raw
A1: 1 | B1: PASS BIN | C1: 334478 | D1: 0.8992 | N1: Project | O1: RL6982 | P1: RL6982 | Q1: RL6982 | R1: RL6982 | S1: RL6982 | T1: RL6982 | U1: RL6982 | V1: RL6982 | W1: RL6982 | X1: RL6982 | Y1: RL6982 | Z1: RL6982 | AA1: RL6982 | AB1: RL6982 | AC1: RL6982 | AD1: RL6982 | AE1: RL6982 | AF1: RL6982 | AG1: RL6982 | AH1: RL6982 | AI1: RL6982 | AJ1: RL6982 | AK1: RL6982 | AL1: RL6982 | AM1: RL6982 | AN1: RL6982 | AO1: RL6982 | AP1: RL6982 | AQ1: RL6982 | AR1: RL6982 | AS1: RL6982 | AT1: RL6982 | AU1: RL6982 | AV1: RL6982 | AW1: RL6982 | AX1: RL6982 | AY1: RL6982 | AZ1: RL6982 | BA1: RL6982 | BB1: RL6982 | BC1: RL6982 | BD1: RL6982 | BE1: RL6982 | BF1: RL6982 | BG1: RL6982 | BH1: RL6982 | BI1: RL6982 | BJ1: RL6982 | BK1: RL6982 | BL1: RL6982 | BM1: RL6982 | BN1: RL6982 | BO1: RL6982 | BP1: RL6982 | BQ1: RL6982 | BR1: RL6982 | BS1: RL6982 | BT1: RL6982 | BU1: RL6982 | BV1: RL6982 | BW1: RL6982 | BX1: RL6982 | BY1: RL6982 | BZ1: RL6982 | CA1: RL6982 | CB1: RL6982 | CC1: RL6982 | CD1: RL6982 | CE1: RL6982 | CF1: RL6982 | CG1: RL6982 | CH1: RL6982 | CI1: RL6982 | CJ1: RL6982 | CK1: RL6982 | CL1: RL6982 | CM1: RL6982 | CN1: RL6982 | CO1: RL6982 | CP1: RL6982 | CQ1: RL6982 | CR1: RL6982 | CS1: RL6982 | CT1: RL6982 | CU1: RL6982 | CV1: RL6982 | CW1: RL6982 | CX1: RL6982 | CY1: RL6982 | CZ1: RL6982 | DA1: RL6982 | DB1: RL6982 | DC1: RL6982 | DD1: RL6982 | DE1: RL6982 | DF1: RL6982 | DG1: RL6982 | DH1: RL6982 | DI1: RL6982 | DJ1: RL6982 | DK1: RL6982 | DL1: RL6982 | DM1: RL6982 | DN1: RL6982 | DO1: RL6982 | DP1: RL6982 | DQ1: RL6982 | DR1: RL6982 | DS1: RL6982 | DT1: RL6982 | DU1: RL6982 | DV1: RL6982 | DW1: RL6982 | DX1: RL6982 | DY1: RL6982 | DZ1: RL6982 | EA1: RL6982 | EB1: RL6982 | EC1: RL6982 | ED1: RL6982 | EE1: RL6982 | EF1: RL6982 | EG1: RL6982 | EH1: RL6982 | EI1: RL6982 | EJ1: RL6982 | EK1: RL6982 | EL1: RL6982 | EM1: RL6982 | EN1: RL6982 | EO1: RL6982 | EP1: RL6982 | EQ1: RL6982 | ER1: RL6982 | ES1: RL6982 | ET1: RL6982 | EU1: RL6982 | EV1: RL6982 | EW1: RL6982 | EX1: RL6982 | EY1: RL6982 | EZ1: RL6982 | FA1: RL6982 | FB1: RL6982 | FC1: RL6982 | FD1: RL6982 | FE1: RL6982 | FF1: RL6982 | FG1: RL6982 | FH1: RL6982 | FI1: RL6982 | FJ1: RL6982 | FK1: RL6982 | FL1: RL6982 | FM1: RL6982 | FN1: RL6982 | FO1: RL6982 | FP1: RL6982 | FQ1: RL6982 | FR1: RL6982 | FS1: RL6982 | FT1: RL6982 | FU1: RL6982 | FV1: RL6982 | FW1: RL6982 | FX1: RL6982 | FY1: RL6982 | FZ1: RL6982 | GA1: RL6982 | GB1: RL6982 | GC1: RL6982 | GD1: RL6982 | GE1: RL6982 | GF1: RL6982 | GG1: RL6982 | GH1: RL6982 | GI1: RL6982 | GJ1: RL6982 | GK1: RL6982 | GL1: RL6982 | GM1: RL6982 | GN1: RL6982 | GO1: RL6982 | GP1: RL6982 | GQ1: RL6982 | GR1: RL6982 | GS1: RL6982 | GT1: RL6982 | GU1: RL6982 | GV1: RL6982 | GW1: RL6982 | GX1: RL6982 | GY1: RL6982 | GZ1: RL6982 | HA1: RL6982 | HB1: RL6982 | HC1: RL6982 | HD1: RL6982 | HE1: RL6982 | HF1: RL6982 | HG1: RL6982 | HH1: RL6982 | HI1: RL6982 | HJ1: RL6982 | HK1: RL6982 | HL1: RL6982 | HM1: RL6982 | HN1: RL6982 | HO1: RL6982 | HP1: RL6982 | HQ1: RL6982 | HR1: RL6982 | HS1: RL6982 | HT1: RL6982 | HU1: RL6982 | HV1: RL6982 | HW1: RL6982 | HX1: RL6982 | HY1: RL6982 | HZ1: RL6982 | IA1: RL6982 | IB1: RL6982 | IC1: RL6982 | ID1: RL6982 | IE1: RL6982 | IF1: RL6982 | IG1: RL6982 | IH1: RL6982 | II1: RL6982 | IJ1: RL6982 | IK1: RL6982 | IL1: RL6982 | IM1: RL6982 | IN1: RL6982 | IO1: RL6982 | IP1: RL6982 | IQ1: RL6982 | IR1: RL6982 | IS1: RL6982 | IT1: RL6982 | IU1: RL6982 | IV1: RL6982 | IW1: RL6982 | IX1: RL6982 | IY1: RL6982 | IZ1: RL6982 | JA1: RL6982 | JB1: RL6982 | JC1: RL6982 | JD1: RL6982 | JE1: RL6982 | JF1: RL6982 | JG1: RL6982 | JH1: RL6982 | JI1: RL6982 | JJ1: RL6982 | JK1: RL6982 | JL1: RL6982 | JM1: RL6982 | JN1: RL6982 | JO1: RL6982 | JP1: RL6982 | JQ1: RL6982 | JR1: RL6982 | JS1: RL6982 | JT1: RL6982 | JU1: RL6982 | JV1: RL6982 | JW1: RL6982 | JX1: RL6982 | JY1: RL6982 | JZ1: RL6982 | KA1: RL6982 | KB1: RL6982 | KC1: RL6982 | KD1: RL6982 | KE1: RL6982 | KF1: RL6982 | KG1: RL6982 | KH1: RL6982 | KI1: RL6982 | KJ1: RL6982 | KK1: RL6982 | KL1: RL6982 | KM1: RL6982 | KN1: RL6982 | KO1: RL6982 | KP1: RL6982 | KQ1: RL6982 | KR1: RL6982 | KS1: RL6982 | KT1: RL6982 | KU1: RL6982 | KV1: RL6982 | KW1: RL6982 | KX1: RL6982 | KY1: RL6982 | KZ1: RL6982 | LA1: RL6982 | LB1: RL6982 | LC1: RL6982 | LD1: RL6982 | LE1: RL6982 | LF1: RL6982 | LG1: RL6982 | LH1: RL6982 | LI1: RL6982 | LJ1: RL6982 | LK1: RL6982 | LL1: RL6982 | LM1: RL6982 | LN1: RL6982 | LO1: RL6982 | LP1: RL6982 | LQ1: RL6982 | LR1: RL6982 | LS1: RL6982 | LT1: RL6982 | LU1: RL6982 | LV1: RL6982 | LW1: RL6982 | LX1: RL6982 | LY1: RL6982 | LZ1: RL6982 | MA1: RL6982 | MB1: RL6982 | MC1: RL6982 | MD1: RL6982 | ME1: RL6982 | MF1: RL6982 | MG1: RL6982 | MH1: RL6982 | MI1: RL6982 | MJ1: RL6982 | MK1: RL6982 | ML1: RL6982 | MM1: RL6982 | MN1: RL6982 | MO1: RL6982 | MP1: RL6982 | MQ1: RL6982 | MR1: RL6982
A2: Top_all | B2: BIN1 | C2: 334478 | D2: 0.8992 | N2: Product | O2: RL6982 | P2: RL6982 | Q2: RL6982 | R2: RL6982 | S2: RL6982 | T2: RL6982 | U2: RL6982 | V2: RL6982 | W2: RL6982 | X2: RL6982 | Y2: RL6982 | Z2: RL6982 | AA2: RL6982 | AB2: RL6982 | AC2: RL6982 | AD2: RL6982 | AE2: RL6982 | AF2: RL6982 | AG2: RL6982 | AH2: RL6982 | AI2: RL6982 | AJ2: RL6982 | AK2: RL6982 | AL2: RL6982 | AM2: RL6982 | AN2: RL6982 | AO2: RL6982 | AP2: RL6982 | AQ2: RL6982 | AR2: RL6982 | AS2: RL6982 | AT2: RL6982 | AU2: RL6982 | AV2: RL6982 | AW2: RL6982 | AX2: RL6982 | AY2: RL6982 | AZ2: RL6982 | BA2: RL6982 | BB2: RL6982 | BC2: RL6982 | BD2: RL6982 | BE2: RL6982 | BF2: RL6982 | BG2: RL6982 | BH2: RL6982 | BI2: RL6982 | BJ2: RL6982 | BK2: RL6982 | BL2: RL6982 | BM2: RL6982 | BN2: RL6982 | BO2: RL6982 | BP2: RL6982 | BQ2: RL6982 | BR2: RL6982 | BS2: RL6982 | BT2: RL6982 | BU2: RL6982 | BV2: RL6982 | BW2: RL6982 | BX2: RL6982 | BY2: RL6982 | BZ2: RL6982 | CA2: RL6982 | CB2: RL6982 | CC2: RL6982 | CD2: RL6982 | CE2: RL6982 | CF2: RL6982 | CG2: RL6982 | CH2: RL6982 | CI2: RL6982 | CJ2: RL6982 | CK2: RL6982 | CL2: RL6982 | CM2: RL6982 | CN2: RL6982 | CO2: RL6982 | CP2: RL6982 | CQ2: RL6982 | CR2: RL6982 | CS2: RL6982 | CT2: RL6982 | CU2: RL6982 | CV2: RL6982 | CW2: RL6982 | CX2: RL6982 | CY2: RL6982 | CZ2: RL6982 | DA2: RL6982 | DB2: RL6982 | DC2: RL6982 | DD2: RL6982 | DE2: RL6982 | DF2: RL6982 | DG2: RL6982 | DH2: RL6982 | DI2: RL6982 | DJ2: RL6982 | DK2: RL6982 | DL2: RL6982 | DM2: RL6982 | DN2: RL6982 | DO2: RL6982 | DP2: RL6982 | DQ2: RL6982 | DR2: RL6982 | DS2: RL6982 | DT2: RL6982 | DU2: RL6982 | DV2: RL6982 | DW2: RL6982 | DX2: RL6982 | DY2: RL6982 | DZ2: RL6982 | EA2: RL6982 | EB2: RL6982 | EC2: RL6982 | ED2: RL6982 | EE2: RL6982 | EF2: RL6982 | EG2: RL6982 | EH2: RL6982 | EI2: RL6982 | EJ2: RL6982 | EK2: RL6982 | EL2: RL6982 | EM2: RL6982 | EN2: RL6982 | EO2: RL6982 | EP2: RL6982 | EQ2: RL6982 | ER2: RL6982 | ES2: RL6982 | ET2: RL6982 | EU2: RL6982 | EV2: RL6982 | EW2: RL6982 | EX2: RL6982 | EY2: RL6982 | EZ2: RL6982 | FA2: RL6982 | FB2: RL6982 | FC2: RL6982 | FD2: RL6982 | FE2: RL6982 | FF2: RL6982 | FG2: RL6982 | FH2: RL6982 | FI2: RL6982 | FJ2: RL6982 | FK2: RL6982 | FL2: RL6982 | FM2: RL6982 | FN2: RL6982 | FO2: RL6982 | FP2: RL6982 | FQ2: RL6982 | FR2: RL6982 | FS2: RL6982 | FT2: RL6982 | FU2: RL6982 | FV2: RL6982 | FW2: RL6982 | FX2: RL6982 | FY2: RL6982 | FZ2: RL6982 | GA2: RL6982 | GB2: RL6982 | GC2: RL6982 | GD2: RL6982 | GE2: RL6982 | GF2: RL6982 | GG2: RL6982 | GH2: RL6982 | GI2: RL6982 | GJ2: RL6982 | GK2: RL6982 | GL2: RL6982 | GM2: RL6982 | GN2: RL6982 | GO2: RL6982 | GP2: RL6982 | GQ2: RL6982 | GR2: RL6982 | GS2: RL6982 | GT2: RL6982 | GU2: RL6982 | GV2: RL6982 | GW2: RL6982 | GX2: RL6982 | GY2: RL6982 | GZ2: RL6982 | HA2: RL6982 | HB2: RL6982 | HC2: RL6982 | HD2: RL6982 | HE2: RL6982 | HF2: RL6982 | HG2: RL6982 | HH2: RL6982 | HI2: RL6982 | HJ2: RL6982 | HK2: RL6982 | HL2: RL6982 | HM2: RL6982 | HN2: RL6982 | HO2: RL6982 | HP2: RL6982 | HQ2: RL6982 | HR2: RL6982 | HS2: RL6982 | HT2: RL6982 | HU2: RL6982 | HV2: RL6982 | HW2: RL6982 | HX2: RL6982 | HY2: RL6982 | HZ2: RL6982 | IA2: RL6982 | IB2: RL6982 | IC2: RL6982 | ID2: RL6982 | IE2: RL6982 | IF2: RL6982 | IG2: RL6982 | IH2: RL6982 | II2: RL6982 | IJ2: RL6982 | IK2: RL6982 | IL2: RL6982 | IM2: RL6982 | IN2: RL6982 | IO2: RL6982 | IP2: RL6982 | IQ2: RL6982 | IR2: RL6982 | IS2: RL6982 | IT2: RL6982 | IU2: RL6982 | IV2: RL6982 | IW2: RL6982 | IX2: RL6982 | IY2: RL6982 | IZ2: RL6982 | JA2: RL6982 | JB2: RL6982 | JC2: RL6982 | JD2: RL6982 | JE2: RL6982 | JF2: RL6982 | JG2: RL6982 | JH2: RL6982 | JI2: RL6982 | JJ2: RL6982 | JK2: RL6982 | JL2: RL6982 | JM2: RL6982 | JN2: RL6982 | JO2: RL6982 | JP2: RL6982 | JQ2: RL6982 | JR2: RL6982 | JS2: RL6982 | JT2: RL6982 | JU2: RL6982 | JV2: RL6982 | JW2: RL6982 | JX2: RL6982 | JY2: RL6982 | JZ2: RL6982 | KA2: RL6982 | KB2: RL6982 | KC2: RL6982 | KD2: RL6982 | KE2: RL6982 | KF2: RL6982 | KG2: RL6982 | KH2: RL6982 | KI2: RL6982 | KJ2: RL6982 | KK2: RL6982 | KL2: RL6982 | KM2: RL6982 | KN2: RL6982 | KO2: RL6982 | KP2: RL6982 | KQ2: RL6982 | KR2: RL6982 | KS2: RL6982 | KT2: RL6982 | KU2: RL6982 | KV2: RL6982 | KW2: RL6982 | KX2: RL6982 | KY2: RL6982 | KZ2: RL6982 | LA2: RL6982 | LB2: RL6982 | LC2: RL6982 | LD2: RL6982 | LE2: RL6982 | LF2: RL6982 | LG2: RL6982 | LH2: RL6982 | LI2: RL6982 | LJ2: RL6982 | LK2: RL6982 | LL2: RL6982 | LM2: RL6982 | LN2: RL6982 | LO2: RL6982 | LP2: RL6982 | LQ2: RL6982 | LR2: RL6982 | LS2: RL6982 | LT2: RL6982 | LU2: RL6982 | LV2: RL6982 | LW2: RL6982 | LX2: RL6982 | LY2: RL6982 | LZ2: RL6982 | MA2: RL6982 | MB2: RL6982 | MC2: RL6982 | MD2: RL6982 | ME2: RL6982 | MF2: RL6982 | MG2: RL6982 | MH2: RL6982 | MI2: RL6982 | MJ2: RL6982 | MK2: RL6982 | ML2: RL6982 | MM2: RL6982 | MN2: RL6982 | MO2: RL6982 | MP2: RL6982 | MQ2: RL6982 | MR2: RL6982
B3: OTHER | C3: 418 | D3: 0.0011 | N3: Short Lot ID | O3: P7A34 | P3: P7A20 | Q3: P7CC9 | R3: P7A30 | S3: P7A29 | T3: P7AQ4 | U3: P7A29 | V3: P7A64 | W3: P7A46 | X3: P7A68 | Y3: P7A34 | Z3: P7A64 | AA3: P7A57 | AB3: P7A64 | AC3: P7AQ4 | AD3: P7A32 | AE3: P7AQ5 | AF3: P7A64 | AG3: P7A46 | AH3: P7A29 | AI3: P7A29 | AJ3: P7A68 | AK3: P7A64 | AL3: P7A66 | AM3: P7A34 | AN3: P7A68 | AO3: P7A46 | AP3: P7CM6 | AQ3: P7AQ5 | AR3: P7A50 | AS3: P7A53 | AT3: P7AQ6 | AU3: P7A27 | AV3: P7AQ5 | AW3: P7A68 | AX3: P7A29 | AY3: P7A53 | AZ3: P7A50 | BA3: P7A50 | BB3: P7A27 | BC3: P7A57 | BD3: P7A64 | BE3: P7A64 | BF3: P7A34 | BG3: P7A68 | BH3: P7A64 | BI3: P7A57 | BJ3: P7A41 | BK3: P7A57 | BL3: P7A41 | BM3: P7A50 | BN3: P7A29 | BO3: P7AQ5 | BP3: P7A29 | BQ3: P7A30 | BR3: P7A68 | BS3: P7A57 | BT3: P7A27 | BU3: P7A41 | BV3: P7A50 | BW3: P7A46 | BX3: P7A68 | BY3: P7A32 | BZ3: P7A57 | CA3: P7A64 | CB3: P7A35 | CC3: P7A35 | CD3: P7A41 | CE3: P7A57 | CF3: P7A41 | CG3: P7A41 | CH3: P7A57 | CI3: P7A27 | CJ3: P7A68 | CK3: P7A29 | CL3: P7A27 | CM3: P7A50 | CN3: P7A57 | CO3: P7A20 | CP3: P7A68 | CQ3: P7A57 | CR3: P7A57 | CS3: P7A57 | CT3: P7A30 | CU3: P7A35 | CV3: P7A46 | CW3: P7A68 | CX3: P7A53 | CY3: P7A46 | CZ3: P7A68 | DA3: P7A29 | DB3: P7A53 | DC3: P7A29 | DD3: P7A57 | DE3: P7A27 | DF3: P7A46 | DG3: P7A57 | DH3: P7A50 | DI3: P7A57 | DJ3: P7A30 | DK3: P7A30 | DL3: P7A68 | DM3: P7A30 | DN3: P7A64 | DO3: P7A41 | DP3: P7A35 | DQ3: P7A50 | DR3: P7CC9 | DS3: P7A34 | DT3: P7A57 | DU3: P7A53 | DV3: P7A34 | DW3: P7A68 | DX3: P7A53 | DY3: P7A41 | DZ3: P7A46 | EA3: P7A64 | EB3: P7AQ5 | EC3: P7AQ4 | ED3: P7A68 | EE3: P7AQ6 | EF3: P7A64 | EG3: P7A29 | EH3: P7A61 | EI3: P7A46 | EJ3: P7A64 | EK3: P7A50 | EL3: P7A57 | EM3: P7A53 | EN3: P7A53 | EO3: P7AQ6 | EP3: P7A34 | EQ3: P7A29 | ER3: P7A64 | ES3: P7A53 | ET3: P7A68 | EU3: P7A68 | EV3: P7A34 | EW3: P7AQ5 | EX3: P7A46 | EY3: P7A57 | EZ3: P7A46 | FA3: P7A29 | FB3: P7A68 | FC3: P7A34 | FD3: P7A46 | FE3: P7A29 | FF3: P7A30 | FG3: P7A30 | FH3: P7A53 | FI3: P7A57 | FJ3: P7A29 | FK3: P7A34 | FL3: P7A41 | FM3: P7A53 | FN3: P7A34 | FO3: P7AQ5 | FP3: P7A46 | FQ3: P7A50 | FR3: P7A35 | FS3: P7A46 | FT3: P7A41 | FU3: P7A46 | FV3: P7A29 | FW3: P7A46 | FX3: P7AQ6 | FY3: P7A53 | FZ3: P7A68 | GA3: P7A53 | GB3: P7A50 | GC3: P7AQ4 | GD3: P7A35 | GE3: P7A64 | GF3: P7A27 | GG3: P7A69 | GH3: P7A64 | GI3: P7A46 | GJ3: P7A50 | GK3: P7A53 | GL3: P7A41 | GM3: P7A53 | GN3: P7A34 | GO3: P7A35 | GP3: P7A34 | GQ3: P7A64 | GR3: P7A35 | GS3: P7A34 | GT3: P7A58 | GU3: P7AQ6 | GV3: P7A41 | GW3: P7A34 | GX3: P7A46 | GY3: P7A46 | GZ3: P7A53 | HA3: P7A53 | HB3: P7A20 | HC3: P7A64 | HD3: P7A30 | HE3: P7AQ5 | HF3: P7AQ5 | HG3: P7A46 | HH3: P7A64 | HI3: P7A53 | HJ3: P7AQ6 | HK3: P7AQ4 | HL3: P7A41 | HM3: P7A57 | HN3: P7A50 | HO3: P7A29 | HP3: P7A50 | HQ3: P7A34 | HR3: P7A50 | HS3: P7AQ6 | HT3: P7A41 | HU3: P7A34 | HV3: P7A68 | HW3: P7A64 | HX3: P7A57 | HY3: P7A68 | HZ3: P7A35 | IA3: P7AQ6 | IB3: P7A50 | IC3: P7A27 | ID3: P7A30 | IE3: P7AQ4 | IF3: P7A35 | IG3: P7A68 | IH3: P7A46 | II3: P7A53 | IJ3: P7AQ4 | IK3: P7A20 | IL3: P7A53 | IM3: P7A46 | IN3: P7A29 | IO3: P7A41 | IP3: P7A68 | IQ3: P7A57 | IR3: P7A35 | IS3: P7AQ5 | IT3: P7A35 | IU3: P7A35 | IV3: P7AQ5 | IW3: P7A29 | IX3: P7A41 | IY3: P7A30 | IZ3: P7A29 | JA3: P7A64 | JB3: P7A57 | JC3: P7A41 | JD3: P7A34 | JE3: P7A20 | JF3: P7CC9 | JG3: P7AQ6 | JH3: P7A46 | JI3: P7A70 | JJ3: P7A53 | JK3: P7A50 | JL3: P7A50 | JM3: P7A53 | JN3: P7AQ4 | JO3: P7A61 | JP3: P7A34 | JQ3: P7A53 | JR3: P7A41 | JS3: P7A34 | JT3: P7A46 | JU3: P7A57 | JV3: P7AQ6 | JW3: P7CC9 | JX3: P7A68 | JY3: P7A29 | JZ3: P7CC9 | KA3: P7A27 | KB3: P7A29 | KC3: P7A35 | KD3: P7A25 | KE3: P7CC9 | KF3: P7A35 | KG3: P7AQ5 | KH3: P7AQ4 | KI3: P7A35 | KJ3: P7A30 | KK3: P7A68 | KL3: P7A50 | KM3: P7A50 | KN3: P7A34 | KO3: P7AQ6 | KP3: P7A35 | KQ3: P7A35 | KR3: P7A53 | KS3: P7AQ4 | KT3: P7A30 | KU3: P7A27 | KV3: P7A50 | KW3: P7AQ5 | KX3: P7A68 | KY3: P7AQ6 | KZ3: P7AQ4 | LA3: P7A50 | LB3: P7A27 | LC3: P7CC9 | LD3: P7AQ4 | LE3: P7AQ4 | LF3: P7A27 | LG3: P7AQ4 | LH3: P7A50 | LI3: P7A53 | LJ3: P7A34 | LK3: P7A29 | LL3: P7AQ4 | LM3: P7A34 | LN3: P7A35 | LO3: P7A57 | LP3: P7A27 | LQ3: P7A34 | LR3: P7A27 | LS3: P7A64 | LT3: P7A41 | LU3: P7AQ4 | LV3: P7A35 | LW3: P7A27 | LX3: P7A46 | LY3: P7AQ4 | LZ3: P7AQ4 | MA3: P7AQ4 | MB3: P7A27 | MC3: P7AQ4 | MD3: P7A27 | ME3: P7AQ5 | MF3: P7A50 | MG3: P7A50 | MH3: P7A30 | MI3: P7A27 | MJ3: P7A65 | MK3: P7AQ6 | ML3: P7A27 | MM3: P7AQ4 | MN3: P7AQ4 | MO3: P7A27 | MP3: P7A20 | MQ3: P7A27 | MR3: P7A27
B4: OS | C4: 1289 | D4: 0.0035 | N4: Lot ID | O4: P7A34 | P4: P7A20 | Q4: P7CC9 | R4: P7A30 | S4: P7A29 | T4: P7AQ4 | U4: P7A29 | V4: P7A64 | W4: P7A46 | X4: P7A68 | Y4: P7A34 | Z4: P7A64 | AA4: P7A57 | AB4: P7A64 | AC4: P7AQ4 | AD4: P7A32 | AE4: P7AQ5 | AF4: P7A64 | AG4: P7A46 | AH4: P7A29 | AI4: P7A29 | AJ4: P7A68 | AK4: P7A64 | AL4: P7A66 | AM4: P7A34 | AN4: P7A68 | AO4: P7A46 | AP4: P7CM6 | AQ4: P7AQ5 | AR4: P7A50 | AS4: P7A53 | AT4: P7AQ6 | AU4: P7A27 | AV4: P7AQ5 | AW4: P7A68 | AX4: P7A29 | AY4: P7A53 | AZ4: P7A50 | BA4: P7A50 | BB4: P7A27 | BC4: P7A57 | BD4: P7A64 | BE4: P7A64 | BF4: P7A34 | BG4: P7A68 | BH4: P7A64 | BI4: P7A57 | BJ4: P7A41 | BK4: P7A57 | BL4: P7A41 | BM4: P7A50 | BN4: P7A29 | BO4: P7AQ5 | BP4: P7A29 | BQ4: P7A30 | BR4: P7A68 | BS4: P7A57 | BT4: P7A27 | BU4: P7A41 | BV4: P7A50 | BW4: P7A46 | BX4: P7A68 | BY4: P7A32 | BZ4: P7A57 | CA4: P7A64 | CB4: P7A35 | CC4: P7A35 | CD4: P7A41 | CE4: P7A57 | CF4: P7A41 | CG4: P7A41 | CH4: P7A57 | CI4: P7A27 | CJ4: P7A68 | CK4: P7A29 | CL4: P7A27 | CM4: P7A50 | CN4: P7A57 | CO4: P7A20 | CP4: P7A68 | CQ4: P7A57 | CR4: P7A57 | CS4: P7A57 | CT4: P7A30 | CU4: P7A35 | CV4: P7A46 | CW4: P7A68 | CX4: P7A53 | CY4: P7A46 | CZ4: P7A68 | DA4: P7A29 | DB4: P7A53 | DC4: P7A29 | DD4: P7A57 | DE4: P7A27 | DF4: P7A46 | DG4: P7A57 | DH4: P7A50 | DI4: P7A57 | DJ4: P7A30 | DK4: P7A30 | DL4: P7A68 | DM4: P7A30 | DN4: P7A64 | DO4: P7A41 | DP4: P7A35 | DQ4: P7A50 | DR4: P7CC9 | DS4: P7A34 | DT4: P7A57 | DU4: P7A53 | DV4: P7A34 | DW4: P7A68 | DX4: P7A53 | DY4: P7A41 | DZ4: P7A46 | EA4: P7A64 | EB4: P7AQ5 | EC4: P7AQ4 | ED4: P7A68 | EE4: P7AQ6 | EF4: P7A64 | EG4: P7A29 | EH4: P7A61 | EI4: P7A46 | EJ4: P7A64 | EK4: P7A50 | EL4: P7A57 | EM4: P7A53 | EN4: P7A53 | EO4: P7AQ6 | EP4: P7A34 | EQ4: P7A29 | ER4: P7A64 | ES4: P7A53 | ET4: P7A68 | EU4: P7A68 | EV4: P7A34 | EW4: P7AQ5 | EX4: P7A46 | EY4: P7A57 | EZ4: P7A46 | FA4: P7A29 | FB4: P7A68 | FC4: P7A34 | FD4: P7A46 | FE4: P7A29 | FF4: P7A30 | FG4: P7A30 | FH4: P7A53 | FI4: P7A57 | FJ4: P7A29 | FK4: P7A34 | FL4: P7A41 | FM4: P7A53 | FN4: P7A34 | FO4: P7AQ5 | FP4: P7A46 | FQ4: P7A50 | FR4: P7A35 | FS4: P7A46 | FT4: P7A41 | FU4: P7A46 | FV4: P7A29 | FW4: P7A46 | FX4: P7AQ6 | FY4: P7A53 | FZ4: P7A68 | GA4: P7A53 | GB4: P7A50 | GC4: P7AQ4 | GD4: P7A35 | GE4: P7A64 | GF4: P7A27 | GG4: P7A69 | GH4: P7A64 | GI4: P7A46 | GJ4: P7A50 | GK4: P7A53 | GL4: P7A41 | GM4: P7A53 | GN4: P7A34 | GO4: P7A35 | GP4: P7A34 | GQ4: P7A64 | GR4: P7A35 | GS4: P7A34 | GT4: P7A58 | GU4: P7AQ6 | GV4: P7A41 | GW4: P7A34 | GX4: P7A46 | GY4: P7A46 | GZ4: P7A53 | HA4: P7A53 | HB4: P7A20 | HC4: P7A64 | HD4: P7A30 | HE4: P7AQ5 | HF4: P7AQ5 | HG4: P7A46 | HH4: P7A64 | HI4: P7A53 | HJ4: P7AQ6 | HK4: P7AQ4 | HL4: P7A41 | HM4: P7A57 | HN4: P7A50 | HO4: P7A29 | HP4: P7A50 | HQ4: P7A34 | HR4: P7A50 | HS4: P7AQ6 | HT4: P7A41 | HU4: P7A34 | HV4: P7A68 | HW4: P7A64 | HX4: P7A57 | HY4: P7A68 | HZ4: P7A35 | IA4: P7AQ6 | IB4: P7A50 | IC4: P7A27 | ID4: P7A30 | IE4: P7AQ4 | IF4: P7A35 | IG4: P7A68 | IH4: P7A46 | II4: P7A53 | IJ4: P7AQ4 | IK4: P7A20 | IL4: P7A53 | IM4: P7A46 | IN4: P7A29 | IO4: P7A41 | IP4: P7A68 | IQ4: P7A57 | IR4: P7A35 | IS4: P7AQ5 | IT4: P7A35 | IU4: P7A35 | IV4: P7AQ5 | IW4: P7A29 | IX4: P7A41 | IY4: P7A30 | IZ4: P7A29 | JA4: P7A64 | JB4: P7A57 | JC4: P7A41 | JD4: P7A34 | JE4: P7A20 | JF4: P7CC9 | JG4: P7AQ6 | JH4: P7A46 | JI4: P7A70 | JJ4: P7A53 | JK4: P7A50 | JL4: P7A50 | JM4: P7A53 | JN4: P7AQ4 | JO4: P7A61 | JP4: P7A34 | JQ4: P7A53 | JR4: P7A41 | JS4: P7A34 | JT4: P7A46 | JU4: P7A57 | JV4: P7AQ6 | JW4: P7CC9 | JX4: P7A68 | JY4: P7A29 | JZ4: P7CC9 | KA4: P7A27 | KB4: P7A29 | KC4: P7A35 | KD4: P7A25 | KE4: P7CC9 | KF4: P7A35 | KG4: P7AQ5 | KH4: P7AQ4 | KI4: P7A35 | KJ4: P7A30 | KK4: P7A68 | KL4: P7A50 | KM4: P7A50 | KN4: P7A34 | KO4: P7AQ6 | KP4: P7A35 | KQ4: P7A35 | KR4: P7A53 | KS4: P7AQ4 | KT4: P7A30 | KU4: P7A27 | KV4: P7A50 | KW4: P7AQ5 | KX4: P7A68 | KY4: P7AQ6 | KZ4: P7AQ4 | LA4: P7A50 | LB4: P7A27 | LC4: P7CC9 | LD4: P7AQ4 | LE4: P7AQ4 | LF4: P7A27 | LG4: P7AQ4 | LH4: P7A50 | LI4: P7A53 | LJ4: P7A34 | LK4: P7A29 | LL4: P7AQ4 | LM4: P7A34 | LN4: P7A35 | LO4: P7A57 | LP4: P7A27 | LQ4: P7A34 | LR4: P7A27 | LS4: P7A64 | LT4: P7A41 | LU4: P7AQ4 | LV4: P7A35 | LW4: P7A27 | LX4: P7A46 | LY4: P7AQ4 | LZ4: P7AQ4 | MA4: P7AQ4 | MB4: P7A27 | MC4: P7AQ4 | MD4: P7A27 | ME4: P7AQ5 | MF4: P7A50 | MG4: P7A50 | MH4: P7A30 | MI4: P7A27 | MJ4: P7A65 | MK4: P7AQ6 | ML4: P7A27 | MM4: P7AQ4 | MN4: P7AQ4 | MO4: P7A27 | MP4: P7A20 | MQ4: P7A27 | MR4: P7A27
B5: SD | C5: 896 | D5: 0.0024 | N5: Wafer ID | O5: MAR870-11C1 | P5: MAS247-22B7 | Q5: MAR887-17G7 | R5: MAR868-13A7 | S5: MAR757-11F4 | T5: MAR875-02G7 | U5: MAR757-04B2 | V5: MAR892-18F0 | W5: MAR874-20B0 | X5: MAR896-11F2 | Y5: MAR870-14A2 | Z5: MAR892-20F0 | AA5: MAR884-25E3 | AB5: MAR892-04F1 | AC5: MAR875-23D5 | AD5: MAR869-25G4 | AE5: MAR886-09G1 | AF5: MAR892-05E4 | AG5: MAR874-19A3 | AH5: MAR757-25F3 | AI5: MAR757-01D1 | AJ5: MAR896-16C1 | AK5: MAR892-13A6 | AL5: MAR894-16A4 | AM5: MAR870-02G4 | AN5: MAR896-10F7 | AO5: MAR874-17B5 | AP5: MAS255-08F5 | AQ5: MAR886-06A5 | AR5: MAR878-10B7 | AS5: MAR881-06A2 | AT5: MAR891-01C4 | AU5: MAR756-02F3 | AV5: MAR886-12F4 | AW5: MAR896-14D3 | AX5: MAR757-22H2 | AY5: MAR881-14D7 | AZ5: MAR878-03F0 | BA5: MAR878-16F4 | BB5: MAR756-24B4 | BC5: MAR884-15C0 | BD5: MAR892-22D6 | BE5: MAR892-17F5 | BF5: MAR870-20F1 | BG5: MAR896-18A7 | BH5: MAR892-09C0 | BI5: MAR884-24F0 | BJ5: MAR872-19G1 | BK5: MAR884-16B3 | BL5: MAR872-23E7 | BM5: MAR878-25B1 | BN5: MAR757-07G6 | BO5: MAR886-18B6 | BP5: MAR757-08G1 | BQ5: MAR868-14A2 | BR5: MAR896-08F7 | BS5: MAR884-02B4 | BT5: MAR756-11B0 | BU5: MAR872-15B2 | BV5: MAR878-02F5 | BW5: MAR874-13E1 | BX5: MAR896-12E5 | BY5: MAR869-22B0 | BZ5: MAR884-01C1 | CA5: MAR892-15G7 | CB5: MAR871-24H1 | CC5: MAR871-06B1 | CD5: MAR872-16A5 | CE5: MAR884-07F6 | CF5: MAR872-22F4 | CG5: MAR872-07F0 | CH5: MAR884-20A1 | CI5: MAR756-25A7 | CJ5: MAR896-05A3 | CK5: MAR757-12E7 | CL5: MAR756-06C7 | CM5: MAR878-24B6 | CN5: MAR884-18A1 | CO5: MAS247-24A5 | CP5: MAR896-23G3 | CQ5: MAR884-08F1 | CR5: MAR884-06G3 | CS5: MAR884-23F5 | CT5: MAR868-22D7 | CU5: MAR871-05B6 | CV5: MAR874-06H2 | CW5: MAR896-17B4 | CX5: MAR881-23G7 | CY5: MAR874-04B1 | CZ5: MAR896-22H0 | DA5: MAR757-09F4 | DB5: MAR881-11F6 | DC5: MAR757-05A5 | DD5: MAR884-21G7 | DE5: MAR756-22C6 | DF5: MAR874-03B6 | DG5: MAR884-09E4 | DH5: MAR878-01G2 | DI5: MAR884-11E4 | DJ5: MAR868-21E4 | DK5: MAR868-06E0 | DL5: MAR896-03B5 | DM5: MAR868-23D2 | DN5: MAR892-10C5 | DO5: MAR872-25D5 | DP5: MAR871-21B5 | DQ5: MAR878-20E2 | DR5: MAR887-18G2 | DS5: MAR870-01H1 | DT5: MAR884-10F1 | DU5: MAR881-03C1 | DV5: MAR870-18F1 | DW5: MAR896-02C2 | DX5: MAR881-15D2 | DY5: MAR872-04G7 | DZ5: MAR874-07G5 | EA5: MAR892-03F6 | EB5: MAR886-05B2 | EC5: MAR875-07D6 | ED5: MAR896-21A2 | EE5: MAR891-04A5 | EF5: MAR892-25B7 | EG5: MAR757-19A4 | EH5: MAR890-24A7 | EI5: MAR874-16C2 | EJ5: MAR892-14A1 | EK5: MAR878-09B2 | EL5: MAR884-04A2 | EM5: MAR881-21A6 | EN5: MAR881-09F6 | EO5: MAR891-13D5 | EP5: MAR870-15H0 | EQ5: MAR757-14D5 | ER5: MAR892-19E3 | ES5: MAR881-04B4 | ET5: MAR896-06H1 | EU5: MAR896-24F6 | EV5: MAR870-16G3 | EW5: MAR886-19B1 | EX5: MAR874-21A3 | EY5: MAR884-03A7 | EZ5: MAR874-12E6 | FA5: MAR757-20B1 | FB5: MAR896-20A7 | FC5: MAR870-08C6 | FD5: MAR874-01D0 | FE5: MAR757-16C3 | FF5: MAR868-05E5 | FG5: MAR868-07D3 | FH5: MAR881-22A1 | FI5: MAR884-14C5 | FJ5: MAR757-06A0 | FK5: MAR870-09C1 | FL5: MAR872-05G2 | FM5: MAR881-25F5 | FN5: MAR870-21E4 | FO5: MAR886-21B1 | FP5: MAR874-22H1 | FQ5: MAR878-05D6 | FR5: MAR871-17C7 | FS5: MAR874-10G0 | FT5: MAR872-08E3 | FU5: MAR874-18B0 | FV5: MAR757-15D0 | FW5: MAR874-14D4 | FX5: MAR891-19H2 | FY5: MAR881-16C5 | FZ5: MAR896-07G4 | GA5: MAR881-01D3 | GB5: MAR878-21D5 | GC5: MAR875-21E7 | GD5: MAR871-20C2 | GE5: MAR892-24C4 | GF5: MAR756-13H1 | GG5: MAR897-25C2 | GH5: MAR892-21E3 | GI5: MAR874-15C7 | GJ5: MAR878-19D5 | GK5: MAR881-20B3 | GL5: MAR872-21G1 | GM5: MAR881-02C6 | GN5: MAR870-10C6 | GO5: MAR871-11G5 | GP5: MAR870-25C0 | GQ5: MAR892-08C5 | GR5: MAR871-08H2 | GS5: MAR870-12B4 | GT5: MAR885-22D3 | GU5: MAR891-18A4 | GV5: MAR872-20G6 | GW5: MAR870-03F7 | GX5: MAR874-23G4 | GY5: MAR874-09F3 | GZ5: MAR881-13E4 | HA5: MAR881-18B3 | HB5: MAS247-16E3 | HC5: MAR892-12B3 | HD5: MAR868-08C6 | HE5: MAR886-01D6 | HF5: MAR886-17C3 | HG5: MAR874-25F2 | HH5: MAR892-06D7 | HI5: MAR881-24G2 | HJ5: MAR891-17B1 | HK5: MAR875-19E7 | HL5: MAR872-12D1 | HM5: MAR884-19G7 | HN5: MAR878-12A5 | HO5: MAR757-18B1 | HP5: MAR878-23C3 | HQ5: MAR870-06E0 | HR5: MAR878-13A0 | HS5: MAR891-11E7 | HT5: MAR872-11D6 | HU5: MAR870-22D7 | HV5: MAR896-09F2 | HW5: MAR892-02G3 | HX5: MAR884-12D7 | HY5: MAR896-13E0 | HZ5: MAR871-25G4 | IA5: MAR891-02B7 | IB5: MAR878-15G1 | IC5: MAR756-21D3 | ID5: MAR868-24C5 | IE5: MAR875-18F4 | IF5: MAR871-23A3 | IG5: MAR896-25F1 | IH5: MAR874-02C3 | II5: MAR881-10G3 | IJ5: MAR875-10D1 | IK5: MAS247-25A0 | IL5: MAR881-08G3 | IM5: MAR874-08G0 | IN5: MAR757-24G0 | IO5: MAR872-18G6 | IP5: MAR896-15C6 | IQ5: MAR884-22G2 | IR5: MAR871-10H2 | IS5: MAR886-03C4 | IT5: MAR871-02D5 | IU5: MAR871-04C3 | IV5: MAR886-02D1 | IW5: MAR757-10G1 | IX5: MAR872-13C4 | IY5: MAR868-16G3 | IZ5: MAR757-21A4 | JA5: MAR892-11C0 | JB5: MAR884-17A6 | JC5: MAR872-24E2 | JD5: MAR870-23D2 | JE5: MAS247-01F1 | JF5: MAR887-10D7 | JG5: MAR891-20A4 | JH5: MAR874-11F3 | JI5: MAS256-16G3 | JJ5: MAR881-19A6 | JK5: MAR878-06D1 | JL5: MAR878-18E2 | JM5: MAR881-05A7 | JN5: MAR875-22E2 | JO5: MAR890-08B0 | JP5: MAR870-19E4 | JQ5: MAR881-07H0 | JR5: MAR872-14B7 | JS5: MAR870-17F6 | JT5: MAR874-24F7 | JU5: MAR884-05H0 | JV5: MAR891-12E2 | JW5: MAR887-02A2 | JX5: MAR896-01C7 | JY5: MAR757-23G5 | JZ5: MAR887-01A7 | KA5: MAR756-20E0 | KB5: MAR757-13E2 | KC5: MAR871-03D0 | KD5: MAR754-13F4 | KE5: MAR887-03H0 | KF5: MAR871-01E2 | KG5: MAR886-20B6 | KH5: MAR875-03G2 | KI5: MAR871-07A4 | KJ5: MAR868-25C0 | KK5: MAR896-19A2 | KL5: MAR878-04E3 | KM5: MAR878-17E7 | KN5: MAR870-04F2 | KO5: MAR891-09E7 | KP5: MAR871-22B0 | KQ5: MAR871-19B5 | KR5: MAR881-17C0 | KS5: MAR875-01A1 | KT5: MAR868-15H0 | KU5: MAR756-16F2 | KV5: MAR878-22D0 | KW5: MAR886-04B7 | KX5: MAR896-04B0 | KY5: MAR891-10F4 | KZ5: MAR875-24D0 | LA5: MAR878-07C4 | LB5: MAR756-03E6 | LC5: MAR887-09D2 | LD5: MAR875-05F0 | LE5: MAR875-20F4 | LF5: MAR756-08B5 | LG5: MAR875-04F5 | LH5: MAR878-11B2 | LI5: MAR881-12F1 | LJ5: MAR870-24C5 | LK5: MAR757-17B6 | LL5: MAR875-11C4 | LM5: MAR870-07D3 | LN5: MAR871-18C2 | LO5: MAR884-13D2 | LP5: MAR756-23C1 | LQ5: MAR870-05E5 | LR5: MAR756-18E0 | LS5: MAR892-01H0 | LT5: MAR872-06F5 | LU5: MAR875-06E3 | LV5: MAR871-09G5 | LW5: MAR756-14G4 | LX5: MAR874-05A4 | LY5: MAR875-15A0 | LZ5: MAR875-13B2 | MA5: MAR875-17G1 | MB5: MAR756-19D3 | MC5: MAR875-09C4 | MD5: MAR756-10B5 | ME5: MAR886-22A4 | MF5: MAR878-14G6 | MG5: MAR878-08B7 | MH5: MAR868-19E4 | MI5: MAR756-12A3 | MJ5: MAR893-24H0 | MK5: MAR891-03B2 | ML5: MAR756-07C2 | MM5: MAR875-12B7 | MN5: MAR875-08D1 | MO5: MAR756-15F7 | MP5: MAS247-23B2 | MQ5: MAR756-05D4 | MR5: MAR756-04E1
B6: POR | C6: 35 | D6: 0.0001 | N6: Wafer NO. | O6: 11 | P6: 22 | Q6: 17 | R6: 13 | S6: 11 | T6: 2 | U6: 4 | V6: 18 | W6: 20 | X6: 11 | Y6: 14 | Z6: 20 | AA6: 25 | AB6: 4 | AC6: 23 | AD6: 25 | AE6: 9 | AF6: 5 | AG6: 19 | AH6: 25 | AI6: 1 | AJ6: 16 | AK6: 13 | AL6: 16 | AM6: 2 | AN6: 10 | AO6: 17 | AP6: 8 | AQ6: 6 | AR6: 10 | AS6: 6 | AT6: 1 | AU6: 2 | AV6: 12 | AW6: 14 | AX6: 22 | AY6: 14 | AZ6: 3 | BA6: 16 | BB6: 24 | BC6: 15 | BD6: 22 | BE6: 17 | BF6: 20 | BG6: 18 | BH6: 9 | BI6: 24 | BJ6: 19 | BK6: 16 | BL6: 23 | BM6: 25 | BN6: 7 | BO6: 18 | BP6: 8 | BQ6: 14 | BR6: 8 | BS6: 2 | BT6: 11 | BU6: 15 | BV6: 2 | BW6: 13 | BX6: 12 | BY6: 22 | BZ6: 1 | CA6: 15 | CB6: 24 | CC6: 6 | CD6: 16 | CE6: 7 | CF6: 22 | CG6: 7 | CH6: 20 | CI6: 25 | CJ6: 5 | CK6: 12 | CL6: 6 | CM6: 24 | CN6: 18 | CO6: 24 | CP6: 23 | CQ6: 8 | CR6: 6 | CS6: 23 | CT6: 22 | CU6: 5 | CV6: 6 | CW6: 17 | CX6: 23 | CY6: 4 | CZ6: 22 | DA6: 9 | DB6: 11 | DC6: 5 | DD6: 21 | DE6: 22 | DF6: 3 | DG6: 9 | DH6: 1 | DI6: 11 | DJ6: 21 | DK6: 6 | DL6: 3 | DM6: 23 | DN6: 10 | DO6: 25 | DP6: 21 | DQ6: 20 | DR6: 18 | DS6: 1 | DT6: 10 | DU6: 3 | DV6: 18 | DW6: 2 | DX6: 15 | DY6: 4 | DZ6: 7 | EA6: 3 | EB6: 5 | EC6: 7 | ED6: 21 | EE6: 4 | EF6: 25 | EG6: 19 | EH6: 24 | EI6: 16 | EJ6: 14 | EK6: 9 | EL6: 4 | EM6: 21 | EN6: 9 | EO6: 13 | EP6: 15 | EQ6: 14 | ER6: 19 | ES6: 4 | ET6: 6 | EU6: 24 | EV6: 16 | EW6: 19 | EX6: 21 | EY6: 3 | EZ6: 12 | FA6: 20 | FB6: 20 | FC6: 8 | FD6: 1 | FE6: 16 | FF6: 5 | FG6: 7 | FH6: 22 | FI6: 14 | FJ6: 6 | FK6: 9 | FL6: 5 | FM6: 25 | FN6: 21 | FO6: 21 | FP6: 22 | FQ6: 5 | FR6: 17 | FS6: 10 | FT6: 8 | FU6: 18 | FV6: 15 | FW6: 14 | FX6: 19 | FY6: 16 | FZ6: 7 | GA6: 1 | GB6: 21 | GC6: 21 | GD6: 20 | GE6: 24 | GF6: 13 | GG6: 25 | GH6: 21 | GI6: 15 | GJ6: 19 | GK6: 20 | GL6: 21 | GM6: 2 | GN6: 10 | GO6: 11 | GP6: 25 | GQ6: 8 | GR6: 8 | GS6: 12 | GT6: 22 | GU6: 18 | GV6: 20 | GW6: 3 | GX6: 23 | GY6: 9 | GZ6: 13 | HA6: 18 | HB6: 16 | HC6: 12 | HD6: 8 | HE6: 1 | HF6: 17 | HG6: 25 | HH6: 6 | HI6: 24 | HJ6: 17 | HK6: 19 | HL6: 12 | HM6: 19 | HN6: 12 | HO6: 18 | HP6: 23 | HQ6: 6 | HR6: 13 | HS6: 11 | HT6: 11 | HU6: 22 | HV6: 9 | HW6: 2 | HX6: 12 | HY6: 13 | HZ6: 25 | IA6: 2 | IB6: 15 | IC6: 21 | ID6: 24 | IE6: 18 | IF6: 23 | IG6: 25 | IH6: 2 | II6: 10 | IJ6: 10 | IK6: 25 | IL6: 8 | IM6: 8 | IN6: 24 | IO6: 18 | IP6: 15 | IQ6: 22 | IR6: 10 | IS6: 3 | IT6: 2 | IU6: 4 | IV6: 2 | IW6: 10 | IX6: 13 | IY6: 16 | IZ6: 21 | JA6: 11 | JB6: 17 | JC6: 24 | JD6: 23 | JE6: 1 | JF6: 10 | JG6: 20 | JH6: 11 | JI6: 16 | JJ6: 19 | JK6: 6 | JL6: 18 | JM6: 5 | JN6: 22 | JO6: 8 | JP6: 19 | JQ6: 7 | JR6: 14 | JS6: 17 | JT6: 24 | JU6: 5 | JV6: 12 | JW6: 2 | JX6: 1 | JY6: 23 | JZ6: 1 | KA6: 20 | KB6: 13 | KC6: 3 | KD6: 13 | KE6: 3 | KF6: 1 | KG6: 20 | KH6: 3 | KI6: 7 | KJ6: 25 | KK6: 19 | KL6: 4 | KM6: 17 | KN6: 4 | KO6: 9 | KP6: 22 | KQ6: 19 | KR6: 17 | KS6: 1 | KT6: 15 | KU6: 16 | KV6: 22 | KW6: 4 | KX6: 4 | KY6: 10 | KZ6: 24 | LA6: 7 | LB6: 3 | LC6: 9 | LD6: 5 | LE6: 20 | LF6: 8 | LG6: 4 | LH6: 11 | LI6: 12 | LJ6: 24 | LK6: 17 | LL6: 11 | LM6: 7 | LN6: 18 | LO6: 13 | LP6: 23 | LQ6: 5 | LR6: 18 | LS6: 1 | LT6: 6 | LU6: 6 | LV6: 9 | LW6: 14 | LX6: 5 | LY6: 15 | LZ6: 13 | MA6: 17 | MB6: 19 | MC6: 9 | MD6: 10 | ME6: 22 | MF6: 14 | MG6: 8 | MH6: 19 | MI6: 12 | MJ6: 24 | MK6: 3 | ML6: 7 | MM6: 12 | MN6: 8 | MO6: 15 | MP6: 23 | MQ6: 5 | MR6: 4
B7: IDD | C7: 256 | D7: 0.0007 | N7: Re-Test | O7: 6 | P7: 3 | Q7: 1 | R7: 2 | S7: 2 | T7: 4 | U7: 1 | V7: 1 | W7: 2 | X7: 1 | Y7: 6 | Z7: 1 | AA7: 1 | AB7: 1 | AC7: 1 | AD7: 2 | AE7: 1 | AF7: 1 | AG7: 2 | AH7: 1 | AI7: 1 | AJ7: 1 | AK7: 2 | AL7: 7 | AM7: 1 | AN7: 1 | AO7: 1 | AP7: 1 | AQ7: 2 | AR7: 1 | AS7: 1 | AT7: 1 | AU7: 6 | AV7: 3 | AW7: 2 | AX7: 1 | AY7: 1 | AZ7: 1 | BA7: 3 | BB7: 1 | BC7: 1 | BD7: 1 | BE7: 2 | BF7: 1 | BG7: 1 | BH7: 1 | BI7: 1 | BJ7: 1 | BK7: 1 | BL7: 1 | BM7: 2 | BN7: 1 | BO7: 2 | BP7: 1 | BQ7: 1 | BR7: 1 | BS7: 1 | BT7: 1 | BU7: 1 | BV7: 1 | BW7: 1 | BX7: 3 | BY7: 4 | BZ7: 1 | CA7: 1 | CB7: 1 | CC7: 1 | CD7: 1 | CE7: 1 | CF7: 1 | CG7: 1 | CH7: 8 | CI7: 1 | CJ7: 1 | CK7: 1 | CL7: 1 | CM7: 1 | CN7: 5 | CO7: 1 | CP7: 2 | CQ7: 8 | CR7: 1 | CS7: 1 | CT7: 1 | CU7: 1 | CV7: 1 | CW7: 1 | CX7: 1 | CY7: 1 | CZ7: 1 | DA7: 1 | DB7: 2 | DC7: 1 | DD7: 1 | DE7: 2 | DF7: 3 | DG7: 2 | DH7: 3 | DI7: 4 | DJ7: 1 | DK7: 1 | DL7: 1 | DM7: 3 | DN7: 1 | DO7: 1 | DP7: 1 | DQ7: 1 | DR7: 1 | DS7: 1 | DT7: 1 | DU7: 1 | DV7: 1 | DW7: 3 | DX7: 1 | DY7: 1 | DZ7: 1 | EA7: 1 | EB7: 1 | EC7: 1 | ED7: 1 | EE7: 1 | EF7: 1 | EG7: 1 | EH7: 2 | EI7: 1 | EJ7: 1 | EK7: 2 | EL7: 1 | EM7: 1 | EN7: 1 | EO7: 1 | EP7: 1 | EQ7: 1 | ER7: 1 | ES7: 1 | ET7: 1 | EU7: 1 | EV7: 1 | EW7: 1 | EX7: 1 | EY7: 1 | EZ7: 2 | FA7: 1 | FB7: 3 | FC7: 1 | FD7: 1 | FE7: 2 | FF7: 1 | FG7: 1 | FH7: 1 | FI7: 1 | FJ7: 1 | FK7: 1 | FL7: 1 | FM7: 1 | FN7: 1 | FO7: 1 | FP7: 1 | FQ7: 4 | FR7: 1 | FS7: 3 | FT7: 1 | FU7: 8 | FV7: 4 | FW7: 3 | FX7: 2 | FY7: 1 | FZ7: 1 | GA7: 1 | GB7: 2 | GC7: 1 | GD7: 1 | GE7: 1 | GF7: 1 | GG7: 2 | GH7: 1 | GI7: 1 | GJ7: 1 | GK7: 1 | GL7: 1 | GM7: 4 | GN7: 1 | GO7: 4 | GP7: 1 | GQ7: 1 | GR7: 1 | GS7: 1 | GT7: 5 | GU7: 1 | GV7: 6 | GW7: 3 | GX7: 1 | GY7: 1 | GZ7: 1 | HA7: 1 | HB7: 1 | HC7: 1 | HD7: 1 | HE7: 1 | HF7: 1 | HG7: 1 | HH7: 1 | HI7: 1 | HJ7: 1 | HK7: 2 | HL7: 2 | HM7: 1 | HN7: 2 | HO7: 1 | HP7: 1 | HQ7: 1 | HR7: 1 | HS7: 1 | HT7: 1 | HU7: 1 | HV7: 1 | HW7: 1 | HX7: 2 | HY7: 1 | HZ7: 3 | IA7: 1 | IB7: 1 | IC7: 1 | ID7: 1 | IE7: 1 | IF7: 1 | IG7: 1 | IH7: 1 | II7: 1 | IJ7: 3 | IK7: 2 | IL7: 1 | IM7: 1 | IN7: 1 | IO7: 1 | IP7: 2 | IQ7: 1 | IR7: 1 | IS7: 1 | IT7: 1 | IU7: 1 | IV7: 1 | IW7: 1 | IX7: 1 | IY7: 1 | IZ7: 1 | JA7: 1 | JB7: 1 | JC7: 1 | JD7: 1 | JE7: 1 | JF7: 1 | JG7: 1 | JH7: 1 | JI7: 5 | JJ7: 1 | JK7: 1 | JL7: 1 | JM7: 1 | JN7: 1 | JO7: 1 | JP7: 1 | JQ7: 1 | JR7: 1 | JS7: 1 | JT7: 3 | JU7: 5 | JV7: 1 | JW7: 1 | JX7: 1 | JY7: 1 | JZ7: 1 | KA7: 1 | KB7: 1 | KC7: 1 | KD7: 9 | KE7: 1 | KF7: 1 | KG7: 1 | KH7: 1 | KI7: 1 | KJ7: 1 | KK7: 1 | KL7: 1 | KM7: 1 | KN7: 1 | KO7: 1 | KP7: 1 | KQ7: 1 | KR7: 1 | KS7: 1 | KT7: 1 | KU7: 4 | KV7: 1 | KW7: 1 | KX7: 1 | KY7: 1 | KZ7: 1 | LA7: 1 | LB7: 1 | LC7: 1 | LD7: 1 | LE7: 2 | LF7: 1 | LG7: 2 | LH7: 1 | LI7: 1 | LJ7: 1 | LK7: 1 | LL7: 4 | LM7: 1 | LN7: 1 | LO7: 1 | LP7: 1 | LQ7: 1 | LR7: 1 | LS7: 1 | LT7: 2 | LU7: 1 | LV7: 1 | LW7: 2 | LX7: 1 | LY7: 1 | LZ7: 3 | MA7: 1 | MB7: 1 | MC7: 1 | MD7: 1 | ME7: 1 | MF7: 2 | MG7: 1 | MH7: 5 | MI7: 1 | MJ7: 2 | MK7: 1 | ML7: 1 | MM7: 1 | MN7: 3 | MO7: 1 | MP7: 1 | MQ7: 1 | MR7: 1
B8: OTP | C8: 19 | D8: 0.0001 | N8: ProbeCard | O8: RL6982-PC-22 | P8: RL6982-PC-11 | Q8: RL6982-PC-09 | R8: RL6982-PC-01 | S8: RL6982-PC-18 | T8: RL6982-PC-08 | U8: RL6982-PC-18 | V8: RL6982-PC-07 | W8: RL6982-PC-16 | X8: RL6982-PC-01 | Y8: RL6982-PC-22 | Z8: RL6982-PC-07 | AA8: RL6982-PC-08 | AB8: RL6982-PC-20 | AC8: RL6982-PC-11 | AD8: RL6982-PC-11 | AE8: RL6982-PC-23 | AF8: RL6982-PC-20 | AG8: RL6982-PC-11 | AH8: RL6982-PC-20 | AI8: RL6982-PC-18 | AJ8: RL6982-PC-01 | AK8: RL6982-PC-01 | AL8: RL6982-PC-07 | AM8: RL6982-PC-09 | AN8: RL6982-PC-01 | AO8: RL6982-PC-16 | AP8: RL6982-PC-17 | AQ8: RL6982-PC-20 | AR8: RL6982-PC-08 | AS8: RL6982-PC-14 | AT8: RL6982-PC-19 | AU8: RL6982-PC-09 | AV8: RL6982-PC-23 | AW8: RL6982-PC-01 | AX8: RL6982-PC-20 | AY8: RL6982-PC-19 | AZ8: RL6982-PC-11 | BA8: RL6982-PC-08 | BB8: RL6982-PC-17 | BC8: RL6982-PC-02 | BD8: RL6982-PC-07 | BE8: RL6982-PC-01 | BF8: RL6982-PC-23 | BG8: RL6982-PC-14 | BH8: RL6982-PC-01 | BI8: RL6982-PC-08 | BJ8: RL6982-PC-12 | BK8: RL6982-PC-02 | BL8: RL6982-PC-11 | BM8: RL6982-PC-17 | BN8: RL6982-PC-18 | BO8: RL6982-PC-07 | BP8: RL6982-PC-18 | BQ8: RL6982-PC-01 | BR8: RL6982-PC-07 | BS8: RL6982-PC-18 | BT8: RL6982-PC-08 | BU8: RL6982-PC-22 | BV8: RL6982-PC-11 | BW8: RL6982-PC-19 | BX8: RL6982-PC-01 | BY8: RL6982-PC-17 | BZ8: RL6982-PC-18 | CA8: RL6982-PC-01 | CB8: RL6982-PC-09 | CC8: RL6982-PC-23 | CD8: RL6982-PC-22 | CE8: RL6982-PC-18 | CF8: RL6982-PC-11 | CG8: RL6982-PC-19 | CH8: RL6982-PC-08 | CI8: RL6982-PC-17 | CJ8: RL6982-PC-07 | CK8: RL6982-PC-02 | CL8: RL6982-PC-09 | CM8: RL6982-PC-17 | CN8: RL6982-PC-08 | CO8: RL6982-PC-20 | CP8: RL6982-PC-14 | CQ8: RL6982-PC-18 | CR8: RL6982-PC-18 | CS8: RL6982-PC-08 | CT8: RL6982-PC-23 | CU8: RL6982-PC-23 | CV8: RL6982-PC-18 | CW8: RL6982-PC-14 | CX8: RL6982-PC-06 | CY8: RL6982-PC-18 | CZ8: RL6982-PC-14 | DA8: RL6982-PC-06 | DB8: RL6982-PC-19 | DC8: RL6982-PC-18 | DD8: RL6982-PC-08 | DE8: RL6982-PC-06 | DF8: RL6982-PC-18 | DG8: RL6982-PC-02 | DH8: RL6982-PC-11 | DI8: RL6982-PC-02 | DJ8: RL6982-PC-23 | DK8: RL6982-PC-14 | DL8: RL6982-PC-07 | DM8: RL6982-PC-23 | DN8: RL6982-PC-01 | DO8: RL6982-PC-11 | DP8: RL6982-PC-09 | DQ8: RL6982-PC-17 | DR8: RL6982-PC-09 | DS8: RL6982-PC-09 | DT8: RL6982-PC-02 | DU8: RL6982-PC-14 | DV8: RL6982-PC-23 | DW8: RL6982-PC-07 | DX8: RL6982-PC-19 | DY8: RL6982-PC-19 | DZ8: RL6982-PC-18 | EA8: RL6982-PC-20 | EB8: RL6982-PC-20 | EC8: RL6982-PC-17 | ED8: RL6982-PC-14 | EE8: RL6982-PC-19 | EF8: RL6982-PC-07 | EG8: RL6982-PC-20 | EH8: RL6982-PC-02 | EI8: RL6982-PC-19 | EJ8: RL6982-PC-01 | EK8: RL6982-PC-08 | EL8: RL6982-PC-18 | EM8: RL6982-PC-06 | EN8: RL6982-PC-19 | EO8: RL6982-PC-01 | EP8: RL6982-PC-22 | EQ8: RL6982-PC-02 | ER8: RL6982-PC-07 | ES8: RL6982-PC-14 | ET8: RL6982-PC-07 | EU8: RL6982-PC-14 | EV8: RL6982-PC-22 | EW8: RL6982-PC-07 | EX8: RL6982-PC-16 | EY8: RL6982-PC-18 | EZ8: RL6982-PC-19 | FA8: RL6982-PC-20 | FB8: RL6982-PC-14 | FC8: RL6982-PC-09 | FD8: RL6982-PC-18 | FE8: RL6982-PC-06 | FF8: RL6982-PC-14 | FG8: RL6982-PC-14 | FH8: RL6982-PC-06 | FI8: RL6982-PC-02 | FJ8: RL6982-PC-18 | FK8: RL6982-PC-22 | FL8: RL6982-PC-19 | FM8: RL6982-PC-06 | FN8: RL6982-PC-23 | FO8: RL6982-PC-07 | FP8: RL6982-PC-16 | FQ8: RL6982-PC-11 | FR8: RL6982-PC-09 | FS8: RL6982-PC-19 | FT8: RL6982-PC-19 | FU8: RL6982-PC-16 | FV8: RL6982-PC-06 | FW8: RL6982-PC-19 | FX8: RL6982-PC-14 | FY8: RL6982-PC-19 | FZ8: RL6982-PC-07 | GA8: RL6982-PC-14 | GB8: RL6982-PC-17 | GC8: RL6982-PC-11 | GD8: RL6982-PC-09 | GE8: RL6982-PC-07 | GF8: RL6982-PC-08 | GG8: RL6982-PC-06 | GH8: RL6982-PC-07 | GI8: RL6982-PC-19 | GJ8: RL6982-PC-17 | GK8: RL6982-PC-06 | GL8: RL6982-PC-11 | GM8: RL6982-PC-14 | GN8: RL6982-PC-22 | GO8: RL6982-PC-22 | GP8: RL6982-PC-23 | GQ8: RL6982-PC-20 | GR8: RL6982-PC-23 | GS8: RL6982-PC-22 | GT8: RL6982-PC-07 | GU8: RL6982-PC-14 | GV8: RL6982-PC-11 | GW8: RL6982-PC-09 | GX8: RL6982-PC-16 | GY8: RL6982-PC-19 | GZ8: RL6982-PC-19 | HA8: RL6982-PC-06 | HB8: RL6982-PC-07 | HC8: RL6982-PC-01 | HD8: RL6982-PC-14 | HE8: RL6982-PC-20 | HF8: RL6982-PC-07 | HG8: RL6982-PC-16 | HH8: RL6982-PC-20 | HI8: RL6982-PC-06 | HJ8: RL6982-PC-14 | HK8: RL6982-PC-11 | HL8: RL6982-PC-22 | HM8: RL6982-PC-08 | HN8: RL6982-PC-08 | HO8: RL6982-PC-20 | HP8: RL6982-PC-17 | HQ8: RL6982-PC-09 | HR8: RL6982-PC-08 | HS8: RL6982-PC-01 | HT8: RL6982-PC-22 | HU8: RL6982-PC-23 | HV8: RL6982-PC-01 | HW8: RL6982-PC-20 | HX8: RL6982-PC-02 | HY8: RL6982-PC-01 | HZ8: RL6982-PC-09 | IA8: RL6982-PC-19 | IB8: RL6982-PC-08 | IC8: RL6982-PC-17 | ID8: RL6982-PC-23 | IE8: RL6982-PC-11 | IF8: RL6982-PC-09 | IG8: RL6982-PC-14 | IH8: RL6982-PC-18 | II8: RL6982-PC-19 | IJ8: RL6982-PC-16 | IK8: RL6982-PC-20 | IL8: RL6982-PC-14 | IM8: RL6982-PC-18 | IN8: RL6982-PC-20 | IO8: RL6982-PC-12 | IP8: RL6982-PC-01 | IQ8: RL6982-PC-08 | IR8: RL6982-PC-22 | IS8: RL6982-PC-20 | IT8: RL6982-PC-23 | IU8: RL6982-PC-23 | IV8: RL6982-PC-20 | IW8: RL6982-PC-02 | IX8: RL6982-PC-22 | IY8: RL6982-PC-01 | IZ8: RL6982-PC-20 | JA8: RL6982-PC-01 | JB8: RL6982-PC-08 | JC8: RL6982-PC-11 | JD8: RL6982-PC-23 | JE8: RL6982-PC-15 | JF8: RL6982-PC-18 | JG8: RL6982-PC-14 | JH8: RL6982-PC-19 | JI8: RL6982-PC-07 | JJ8: RL6982-PC-06 | JK8: RL6982-PC-11 | JL8: RL6982-PC-17 | JM8: RL6982-PC-14 | JN8: RL6982-PC-11 | JO8: RL6982-PC-18 | JP8: RL6982-PC-23 | JQ8: RL6982-PC-14 | JR8: RL6982-PC-22 | JS8: RL6982-PC-23 | JT8: RL6982-PC-16 | JU8: RL6982-PC-18 | JV8: RL6982-PC-01 | JW8: RL6982-PC-06 | JX8: RL6982-PC-07 | JY8: RL6982-PC-20 | JZ8: RL6982-PC-06 | KA8: RL6982-PC-17 | KB8: RL6982-PC-02 | KC8: RL6982-PC-23 | KD8: RL6982-PC-07 | KE8: RL6982-PC-06 | KF8: RL6982-PC-23 | KG8: RL6982-PC-07 | KH8: RL6982-PC-17 | KI8: RL6982-PC-23 | KJ8: RL6982-PC-23 | KK8: RL6982-PC-14 | KL8: RL6982-PC-11 | KM8: RL6982-PC-17 | KN8: RL6982-PC-09 | KO8: RL6982-PC-01 | KP8: RL6982-PC-09 | KQ8: RL6982-PC-09 | KR8: RL6982-PC-06 | KS8: RL6982-PC-17 | KT8: RL6982-PC-01 | KU8: RL6982-PC-07 | KV8: RL6982-PC-17 | KW8: RL6982-PC-20 | KX8: RL6982-PC-07 | KY8: RL6982-PC-01 | KZ8: RL6982-PC-11 | LA8: RL6982-PC-11 | LB8: RL6982-PC-09 | LC8: RL6982-PC-18 | LD8: RL6982-PC-17 | LE8: RL6982-PC-11 | LF8: RL6982-PC-09 | LG8: RL6982-PC-17 | LH8: RL6982-PC-08 | LI8: RL6982-PC-19 | LJ8: RL6982-PC-23 | LK8: RL6982-PC-20 | LL8: RL6982-PC-16 | LM8: RL6982-PC-09 | LN8: RL6982-PC-09 | LO8: RL6982-PC-02 | LP8: RL6982-PC-17 | LQ8: RL6982-PC-09 | LR8: RL6982-PC-17 | LS8: RL6982-PC-20 | LT8: RL6982-PC-19 | LU8: RL6982-PC-17 | LV8: RL6982-PC-22 | LW8: RL6982-PC-08 | LX8: RL6982-PC-18 | LY8: RL6982-PC-16 | LZ8: RL6982-PC-16 | MA8: RL6982-PC-11 | MB8: RL6982-PC-17 | MC8: RL6982-PC-16 | MD8: RL6982-PC-08 | ME8: RL6982-PC-07 | MF8: RL6982-PC-08 | MG8: RL6982-PC-11 | MH8: RL6982-PC-23 | MI8: RL6982-PC-08 | MJ8: RL6982-PC-11 | MK8: RL6982-PC-19 | ML8: RL6982-PC-09 | MM8: RL6982-PC-16 | MN8: RL6982-PC-16 | MO8: RL6982-PC-08 | MP8: RL6982-PC-20 | MQ8: RL6982-PC-09 | MR8: RL6982-PC-09
