Workbook

Sheet Summary_RTD
A1: 20260216~20260222 | B1: CP/FT | C1: Total IC | D1: Throughput | E1: Yield | G1: 20260216~20260222 | H1: CP/FT | I1: RTD No. | K1: Total IC | L1: Throughput | M1: Yield
A2: RL7047 | B2: CP | C2: 20790 | D2: 15996 | E2: 0.7694 | G2: RL7047 | H2: CP | I2: RL7047 | K2: 20790 | L2: 15996 | M2: 0.7694
A3: RL7032 Merlin8p | B3: CP | C3: 27196 | D3: 23242 | E3: 0.8546 | G3: RL7032 Merlin8p | H3: CP | I3: RL7032 | K3: 27196 | L3: 23242 | M3: 0.8546
B4: FT1 | C4: 9556 | D4: 9462 | E4: 0.9902 | H4: FT1 | I4: RTD2885QDM_SA_CN_TA01 | K4: 9556 | L4: 9462 | M4: 0.9902
B5: FT2 | C5: 0 | D5: 0 | G5: RL7002 Mac9q | H5: CP | I5: RL7002 | K5: 0 | L5: 0
A6: RL7002 Mac9q | B6: CP | C6: 0 | D6: 0 | G6: RL6990 Dora | H6: CP | I6: RL6990 | K6: 0 | L6: 0
A7: RL6990 Dora | B7: CP | C7: 0 | D7: 0 | G7: RL6982 Merlin9 | H7: CP | I7: RL6982 | K7: 474516 | L7: 426336 | M7: 0.8985
B8: FT1 | C8: 0 | D8: 0 | H8: FT1 | I8: RTD2875QDA_TA01 | K8: 96906 | L8: 96563 | M8: 0.9965
A9: RL6982 Merlin9 | B9: CP | C9: 474516 | D9: 426336 | E9: 0.8985 | I9: RTD2865PCJ_SA_TA01 | K9: 22527 | L9: 22432 | M9: 0.9958
B10: FT1 | C10: 351834 | D10: 350493 | E10: 0.9962 | I10: RTD2875QDB_TA01 | K10: 97211 | L10: 96800 | M10: 0.9958
A11: RL6963 Mac8q | B11: CP | C11: 139138 | D11: 123762 | E11: 0.8895 | I11: RTD2875QDA_HD_TA01 | K11: 73866 | L11: 73590 | M11: 0.9963
B12: FT1 | C12: 77833 | D12: 77157 | E12: 0.9913 | I12: RTD2875QDB_HD_TA01 | K12: 61324 | L12: 61108 | M12: 0.9965
B13: FT2 | C13: 44719 | D13: 44711 | E13: 0.9998 | G13: RL6963 Mac8q | H13: CP | I13: RL6963 | K13: 139138 | L13: 123762 | M13: 0.8895
A14: RL6896 Dante | B14: CP | C14: 0 | D14: 0 | H14: FT1 | I14: RTD2864FLV_TA01 | K14: 70847 | L14: 70190 | M14: 0.9907
B15: FT1 | C15: 0 | D15: 0 | I15: RTD2874FLF_TA01 | K15: 3386 | L15: 3380 | M15: 0.9982
A16: RL6866 Mac8p | B16: CP | C16: 0 | D16: 0 | I16: RTD2841FLW_TA01 | K16: 3600 | L16: 3587 | M16: 0.9964
A17: RL6856 Merlin8 | B17: CP | C17: 0 | D17: 0 | H17: FT2 | I17: RTD2841FLW_TA01 | K17: 44719 | L17: 44711 | M17: 0.9998
B18: FT1 | C18: 69825 | D18: 69533 | E18: 0.9958 | G18: RL6896 Dante | H18: CP | I18: RL6896 | K18: 0 | L18: 0
B19: FT2 | C19: 69532 | D19: 69475 | E19: 0.9992 | G19: RL6866 Mac8p | H19: CP | I19: RL6866 | K19: 0 | L19: 0
A20: RL6750 H5C2 | B20: CP | C20: 0 | D20: 0 | G20: RL6856 Merlin8 | H20: CP | I20: RL6856 | K20: 0 | L20: 0
B21: FT1 | C21: 6262 | D21: 6047 | E21: 0.9657 | H21: FT1 | I21: RTD2885PDM_FT1_TA01 | K21: 43002 | L21: 42785 | M21: 0.995
A22: RL6748 Merlin7 | B22: CP | C22: 21873 | D22: 19458 | E22: 0.8896 | I22: RTD2886NSS_SC_FT1_TA01 | K22: 23956 | L22: 23901 | M22: 0.9977
B23: FT1 | C23: 179064 | D23: 178399 | E23: 0.9963 | I23: RTD2885PGK_SC_FT1_TA01 | K23: 2867 | L23: 2847 | M23: 0.993
B24: FT2 | C24: 819 | D24: 818 | E24: 0.9988 | H24: FT2 | I24: RTD2885PDM_FT2_TA01 | K24: 42785 | L24: 42757 | M24: 0.9993
A25: RL6746 MIO | B25: CP | C25: 0 | D25: 0 | I25: RTD2886NSP_SC_FT2_TA01 | K25: 26747 | L25: 26718 | M25: 0.9989
B26: FT1 | C26: 0 | D26: 0 | G26: RL6750 H5C2 | H26: CP | I26: RL6750 | K26: 0 | L26: 0
A27: RL6708 Bridge | B27: CP | C27: 0 | D27: 0 | H27: FT1 | I27: RTD2890_B19_TA01 | K27: 6262 | L27: 6047 | M27: 0.9657
B28: FT1 | C28: 0 | D28: 0 | G28: RL6748 Merlin7 | H28: CP | I28: RL6748 | K28: 21873 | L28: 19458 | M28: 0.8896
A29: RL6681 ATSC3 | B29: CP | C29: 0 | D29: 0 | H29: FT1 | I29: RTD2881PSP_SDY_TA01 | K29: 17943 | L29: 17912 | M29: 0.9983
B30: FT1 | C30: 0 | D30: 0 | I30: RTD2875NDB_LC_TA01 | K30: 4952 | L30: 4936 | M30: 0.9968
A31: RL6672 Merlin6 | B31: CP | C31: 104448 | D31: 87872 | E31: 0.8413 | I31: RTD2875NDA_LC_TA01 | K31: 820 | L31: 819 | M31: 0.9988
B32: FT1 | C32: 0 | D32: 0 | I32: RTD2875PSP_SC_TA01 | K32: 130618 | L32: 130301 | M32: 0.9976
B33: FT2 | C33: 0 | D33: 0 | I33: RTD2881PSD_WDC_TA01 | K33: 22300 | L33: 22012 | M33: 0.9871
A34: RL6641 Mac7p | B34: CP | C34: 0 | D34: 0 | I34: RTD2885NDP_HSC | J34: 4K120 without ATSC C版 | K34: 2431 | L34: 2419 | M34: 0.9951
B35: FT1 | C35: 40314 | D35: 39980 | E35: 0.9917 | H35: FT2 | I35: RTD2875_C_FT2 | K35: 819 | L35: 818 | M35: 0.9988
A36: RL6617 Merlin5 | B36: CP | C36: 0 | D36: 0 | G36: RL6746 MIO | H36: CP | I36: RL6746 | K36: 0 | L36: 0
B37: FT1 | C37: 0 | D37: 0 | G37: RL6708 Bridge | H37: CP | I37: RL6708 | K37: 0 | L37: 0
B38: FT2 | C38: 0 | D38: 0 | G38: RL6681 ATSC3 | H38: CP | I38: RL6681 | K38: 0 | L38: 0
G39: RL6672 Merlin6 | H39: CP | I39: RL6672 | K39: 104448 | L39: 87872 | M39: 0.8413
G40: RL6641 Mac7p | H40: CP | I40: RL6641 | K40: 0 | L40: 0
...

Sheet Top_all
A1: Project | B1: CP/FT | C1: RTD No. | E1: ECN Ver. | G1: summary | H1: Y26_W08 | J1: Top1 | K1: Top2 | L1: Top3 | M1: Top4 | N1: Top5 | O1: Top6 | P1: Top7 | Q1: Top8 | R1: Top9 | S1: Top10 | Y1: Project | Z1: CP/FT | AA1: RTD No. | AC1: ECN Ver. | AD1: Total IC | AE1: Throughput | AF1: Yield | AG1: Top1 | AH1: Top2 | AI1: Top3 | AJ1: Top4 | AK1: Top5 | AL1: Top6 | AM1: Top7 | AN1: Top8 | AO1: Top9 | AP1: Top10
A2: RL7047 | B2: CP | C2: RL7047 | E2: V01 | F2: Total IC | G2: 20790 | H2: 20790 | I2: Test item | J2: cp_mode1_saf_comp | K2: cp_mode2_saf_comp | L2: cp_mode0_tdf_cov94_gpu_c5_comp | M2: cp_mode5_tdf_sync_comp | N2: cp_mode0_saf_comp | O2: MD_PLLUSB2_CP | P2: CP_PCIe_REFCLK | Q2: cp_mode2_tdf_sync_comp_lv | R2: cp_mode5_saf_comp | S2: cp_mode3_saf_comp | Y2: RL7047 | Z2: CP | AA2: RL7047 | AC2: V01 | AD2: 20790 | AE2: 15996 | AF2: 0.7694 | AG2: cp_mode1_saf_comp(1251ea,6.02%) | AH2: cp_mode2_saf_comp(678ea,3.26%) | AI2: cp_mode0_tdf_cov94_gpu_c5_comp(641ea,3.08%) | AJ2: cp_mode5_tdf_sync_comp(387ea,1.86%) | AK2: cp_mode0_saf_comp(367ea,1.77%) | AL2: MD_PLLUSB2_CP(236ea,1.14%) | AM2: CP_PCIe_REFCLK(192ea,0.92%) | AN2: cp_mode2_tdf_sync_comp_lv(138ea,0.66%) | AO2: cp_mode5_saf_comp(127ea,0.61%) | AP2: cp_mode3_saf_comp(118ea,0.57%)
F3: Throughput | G3: 15996 | H3: 15996 | I3: q'ty | J3: 1251 | K3: 678 | L3: 641 | M3: 387 | N3: 367 | O3: 236 | P3: 192 | Q3: 138 | R3: 127 | S3: 118 | Y3: RL7032 Merlin8p | Z3: CP | AA3: RL7032 | AC3: V02 | AD3: 27196 | AE3: 23242 | AF3: 0.8546 | AG3: cp_mode3_saf_comp_retest(957ea,3.52%) | AH3: cp_mode2_saf_spc25_comp_retest(763ea,2.81%) | AI3: all_bist_mp_HV(481ea,1.77%) | AJ3: cp_mode0_saf_comp(277ea,1.02%) | AK3: cp_mode1_saf_comp(227ea,0.83%) | AL3: scpu_bisr_bist_drf_vddr_mp_X1(179ea,0.66%) | AM3: cp_mode3_tdf_comp_HV_retest(138ea,0.51%) | AN3: IDD(105ea,0.39%) | AO3: OTP_iddq_rtk(84ea,0.31%) | AP3: OpenShort(82ea,0.30%)
F4: Yield | G4: 0.7694 | H4: 0.7694 | I4: % | J4: 0.0602 | K4: 0.0326 | L4: 0.0308 | M4: 0.0186 | N4: 0.0177 | O4: 0.0114 | P4: 0.0092 | Q4: 0.0066 | R4: 0.0061 | S4: 0.0057 | Z4: FT1 | AA4: RTD2885QDM_SA_CN_TA01 | AC4: V02 | AD4: 9556 | AE4: 9462 | AF4: 0.9902 | AG4: IDDQ_m8p_new(36ea,0.38%) | AH4: FW_MD_Domain(27ea,0.28%) | AI4: DDR_single_RW_DC1_debug(10ea,0.10%) | AJ4: FW_other(8ea,0.08%) | AK4: DDR_single_RW_DC2_debug(3ea,0.03%) | AL4: all_bist_mp(3ea,0.03%) | AM4: scpu_bist_all_mp(2ea,0.02%) | AN4: scpu_bisr_bist_drf_vddr(2ea,0.02%) | AO4: PIF_PP_SWING_LV43(1ea,0.01%) | AP4: POR(1ea,0.01%)
A5: RL7032 Merlin8p | B5: CP | C5: RL7032 | E5: V02 | F5: Total IC | G5: 27196 | H5: 27196 | I5: Test item | J5: cp_mode3_saf_comp_retest | K5: cp_mode2_saf_spc25_comp_retest | L5: all_bist_mp_HV | M5: cp_mode0_saf_comp | N5: cp_mode1_saf_comp | O5: scpu_bisr_bist_drf_vddr_mp_X1 | P5: cp_mode3_tdf_comp_HV_retest | Q5: IDD | R5: OTP_iddq_rtk | S5: OpenShort | Y5: RL6982 Merlin9 | Z5: CP | AA5: RL6982 | AC5: V05 | AD5: 460472 | AE5: 414394 | AF5: 0.8999 | AG5: cp_mode2_saf_spc30_comp(11324ea,2.46%) | AH5: cp_mode3_saf_comp(7147ea,1.55%) | AI5: all_bist_mp_3_HV(6652ea,1.44%) | AJ5: cp_mode1_saf_comp(4439ea,0.96%) | AK5: cp_mode0_saf_comp(3662ea,0.80%) | AL5: scpu_bisr_bist_drf_vddr_mp_1(1974ea,0.43%) | AM5: scpu_bist_all_1p2_HV(1278ea,0.28%) | AN5: all_bisr_drf_mp_1(1028ea,0.22%) | AO5: PowerShort(939ea,0.20%) | AP5: cp_mode3_tdf_c5_cov92_comp_HV(779ea,0.17%)
F6: Throughput | G6: 23242 | H6: 23242 | I6: q'ty | J6: 957 | K6: 763 | L6: 481 | M6: 277 | N6: 227 | O6: 179 | P6: 138 | Q6: 105 | R6: 84 | S6: 82 | Z6: CP | AA6: RL6982 | AC6: V05 | AD6: 14044 | AE6: 11942 | AF6: 0.8503 | AG6: cp_mode4_saf_comp_retest(489ea,3.48%) | AH6: cp_mode2_saf_spc30_comp(403ea,2.87%) | AI6: cp_mode3_saf_comp(259ea,1.84%) | AJ6: all_bist_mp_3_HV(195ea,1.39%) | AK6: cp_mode1_saf_comp(155ea,1.10%) | AL6: cp_mode0_saf_comp(135ea,0.96%) | AM6: PowerShort(57ea,0.41%) | AN6: scpu_bisr_bist_drf_vddr_mp_1(49ea,0.35%) | AO6: cp_mode3_tdf_c5_cov92_comp_HV(45ea,0.32%) | AP6: cp_mode0_sdd_c10_plp9_icgC100_1_cov0to96_comp_LV(34ea,0.24%)
F7: Yield | G7: 0.8546 | H7: 0.8546 | I7: % | J7: 0.0352 | K7: 0.0281 | L7: 0.0177 | M7: 0.0102 | N7: 0.0083 | O7: 0.0066 | P7: 0.0051 | Q7: 0.0039 | R7: 0.0031 | S7: 0.003 | Z7: FT1 | AA7: RTD2875QDA_TA01 | AC7: V05 | AD7: 74606 | AE7: 74342 | AF7: 0.9965 | AG7: FW_other(102ea,0.14%) | AH7: DDR4_2G_3000_SS_single_RW_FT(88ea,0.12%) | AI7: OS_500uA(21ea,0.03%) | AJ7: PIF_LVDS_FT(11ea,0.01%) | AK7: PowerShort(7ea,0.01%) | AL7: all_bisr_drf(6ea,0.01%) | AM7: USB2_disconnect_mea(3ea,0.00%) | AN7: EFUSE_ReadAll_CRC(3ea,0.00%) | AO7: chip_id_HRAM(2ea,0.00%) | AP7: scpu_bisr_bist_drf(2ea,0.00%)
B8: FT1 | C8: RTD2885QDM_SA_CN_TA01 | E8: V02 | F8: Total IC | G8: 9556 | H8: 9556 | I8: Test item | J8: IDDQ_m8p_new | K8: FW_MD_Domain | L8: DDR_single_RW_DC1_debug | M8: FW_other | N8: DDR_single_RW_DC2_debug | O8: all_bist_mp | P8: scpu_bist_all_mp | Q8: scpu_bisr_bist_drf_vddr | R8: PIF_PP_SWING_LV43 | S8: POR | Z8: FT1 | AA8: RTD2865PCJ_SA_TA01 | AC8: V03 | AD8: 22527 | AE8: 22432 | AF8: 0.9958 | AG8: USB2_FT_Z0(50ea,0.22%) | AH8: (13ea,0.06%) | AI8: DDR4_1p5G_3200_SS_single_RW_FT(12ea,0.05%) | AJ8: (7ea,0.03%) | AK8: OS_500uA(4ea,0.02%) | AL8: (2ea,0.01%) | AM8: USB2_swing_mea(2ea,0.01%) | AN8: BB_FT01(1ea,0.00%) | AO8: HDMI20_250M_VB(1ea,0.00%) | AP8: IFD_FT01_SNR(1ea,0.00%)
F9: Throughput | G9: 9462 | H9: 9462 | I9: q'ty | J9: 36 | K9: 27 | L9: 10 | M9: 8 | N9: 3 | O9: 3 | P9: 2 | Q9: 2 | R9: 1 | S9: 1 | Z9: FT1 | AA9: RTD2875QDA_TA01 | AC9: V03 | AD9: 22300 | AE9: 22221 | AF9: 0.9965 | AG9: DDR4_2G_3000_SS_FRC_ZQp5p(19ea,0.09%) | AH9: DDR4_2G_3000_SS_single_RW_FT(18ea,0.08%) | AI9: FW_other(14ea,0.06%) | AJ9: PowerShort(8ea,0.04%) | AK9: OS_500uA(4ea,0.02%) | AL9: scpu_bist_all_1p2_HV(3ea,0.01%) | AM9: scpu_bisr_bist_drf(2ea,0.01%) | AN9: chip_id_HRAM(1ea,0.00%) | AO9: EFUSE_ReadAll_CRC(1ea,0.00%) | AP9: scpu_bist_all_1p2_LV(1ea,0.00%)
F10: Yield | G10: 0.9902 | H10: 0.9902 | I10: % | J10: 0.0038 | K10: 0.0028 | L10: 0.001 | M10: 0.0008 | N10: 0.0003 | O10: 0.0003 | P10: 0.0002 | Q10: 0.0002 | R10: 0.0001 | S10: 0.0001 | Z10: FT1 | AA10: RTD2875QDB_TA01 | AC10: V04 | AD10: 24973 | AE10: 24888 | AF10: 0.9966 | AG10: DDR4_2G_3000_SS_FRC_ZQp5p(20ea,0.08%) | AH10: DDR4_2G_3000_SS_single_RW_FT(19ea,0.08%) | AI10: FW_other(18ea,0.07%) | AJ10: OS_500uA(11ea,0.04%) | AK10: FW_MULTI_CORE_TEST(3ea,0.01%) | AL10: SIF_FT01(2ea,0.01%) | AM10: FW_VE(2ea,0.01%) | AN10: USB2_disconnect_trim_RT(1ea,0.00%) | AO10: USB2_FT_Z0(1ea,0.00%) | AP10: IDDQ(1ea,0.00%)
A11: RL6982 Merlin9 | B11: CP | C11: RL6982 | E11: V05 | F11: Total IC | G11: 460472 | H11: 460472 | I11: Test item | J11: cp_mode2_saf_spc30_comp | K11: cp_mode3_saf_comp | L11: all_bist_mp_3_HV | M11: cp_mode1_saf_comp | N11: cp_mode0_saf_comp | O11: scpu_bisr_bist_drf_vddr_mp_1 | P11: scpu_bist_all_1p2_HV | Q11: all_bisr_drf_mp_1 | R11: PowerShort | S11: cp_mode3_tdf_c5_cov92_comp_HV | Z11: FT1 | AA11: RTD2875QDA_HD_TA01 | AC11: V03 | AD11: 73866 | AE11: 73590 | AF11: 0.9963 | AG11: DDR4_2G_3000_SS_FRC_ZQp5p(52ea,0.07%) | AH11: DDR4_2G_3000_SS_single_RW_FT(50ea,0.07%) | AI11: FW_other(47ea,0.06%) | AJ11: USB2_disconnect_mea(29ea,0.04%) | AK11: OS_500uA(28ea,0.04%) | AL11: PowerShort(17ea,0.02%) | AM11: all_bisr_drf(10ea,0.01%) | AN11: Wire_Bond_Leak(8ea,0.01%) | AO11: FW_VE(5ea,0.01%) | AP11: scpu_bist_all_1p2_HV(4ea,0.01%)
F12: Throughput | G12: 414394 | H12: 414394 | I12: q'ty | J12: 11324 | K12: 7147 | L12: 6652 | M12: 4439 | N12: 3662 | O12: 1974 | P12: 1278 | Q12: 1028 | R12: 939 | S12: 779 | Z12: FT1 | AA12: RTD2875QDB_TA01 | AC12: V05 | AD12: 72238 | AE12: 71912 | AF12: 0.9955 | AG12: FW_other(140ea,0.19%) | AH12: DDR4_2G_3000_SS_single_RW_FT(88ea,0.12%) | AI12: POR(19ea,0.03%) | AJ12: USB2_disconnect_mea(11ea,0.02%) | AK12: OS_500uA(10ea,0.01%) | AL12: all_bisr_drf(9ea,0.01%) | AM12: USB2_disconnect_trim_RT(6ea,0.01%) | AN12: IDDQ(5ea,0.01%) | AO12: PIF_LVDS_FT(5ea,0.01%) | AP12: scpu_bisr_bist_drf(4ea,0.01%)
F13: Yield | G13: 0.8999 | H13: 0.8999 | I13: % | J13: 0.0246 | K13: 0.0155 | L13: 0.0144 | M13: 0.0096 | N13: 0.008 | O13: 0.0043 | P13: 0.0028 | Q13: 0.0022 | R13: 0.002 | S13: 0.0017 | Z13: FT1 | AA13: RTD2875QDB_HD_TA01 | AC13: V04 | AD13: 61324 | AE13: 61108 | AF13: 0.9965 | AG13: DDR4_2G_3000_SS_single_RW_FT(54ea,0.09%) | AH13: DDR4_2G_3000_SS_FRC_ZQp5p(40ea,0.07%) | AI13: FW_other(37ea,0.06%) | AJ13: OS_500uA(20ea,0.03%) | AK13: PowerShort(9ea,0.01%) | AL13: FW_MULTI_CORE_TEST(7ea,0.01%) | AM13: USB2_disconnect_mea(6ea,0.01%) | AN13: FW_VE(6ea,0.01%) | AO13: scpu_bist_all_1p2_HV(5ea,0.01%) | AP13: all_bisr_drf(5ea,0.01%)
B14: CP | C14: RL6982 | E14: V05 | F14: Total IC | G14: 14044 | H14: 14044 | I14: Test item | J14: cp_mode4_saf_comp_retest | K14: cp_mode2_saf_spc30_comp | L14: cp_mode3_saf_comp | M14: all_bist_mp_3_HV | N14: cp_mode1_saf_comp | O14: cp_mode0_saf_comp | P14: PowerShort | Q14: scpu_bisr_bist_drf_vddr_mp_1 | R14: cp_mode3_tdf_c5_cov92_comp_HV | S14: cp_mode0_sdd_c10_plp9_icgC100_1_cov0to96_comp_LV | Y14: RL6963 Mac8q | Z14: CP | AA14: RL6963 | AC14: V07 | AD14: 139138 | AE14: 123762 | AF14: 0.8895 | AG14: cp_mode1_saf_comp_B(3414ea,2.45%) | AH14: cp_mode0_saf_comp(1894ea,1.36%) | AI14: mac8p_scpu_bisr_bist_drf_etn_phy_LV_only_drf_0214(1693ea,1.22%) | AJ14: cp_mode2_saf_comp_B(1575ea,1.13%) | AK14: IDD(1381ea,0.99%) | AL14: all_bist_m_0217_p1_BIST_LDOoff_OC700_HV(1247ea,0.90%) | AM14: PowerShort(389ea,0.28%) | AN14: mac8p_scpu_vddr_part1_0p9v(338ea,0.24%) | AO14: cp_mode1_tdf_cov70_comp_HV(310ea,0.22%) | AP14: PLLSCPUA_CP05_APP(288ea,0.21%)
F15: Throughput | G15: 11942 | H15: 11942 | I15: q'ty | J15: 489 | K15: 403 | L15: 259 | M15: 195 | N15: 155 | O15: 135 | P15: 57 | Q15: 49 | R15: 45 | S15: 34 | Z15: FT1 | AA15: RTD2864FLV_TA01 | AC15: V10 | AD15: 70847 | AE15: 70190 | AF15: 0.9907 | AG15: FW_HDMI_4K60(216ea,0.30%) | AH15: FW_other(152ea,0.21%) | AI15: os(38ea,0.05%) | AJ15: D4_2666M_FRC_4K60_uhd_LB_FT(30ea,0.04%) | AK15: VDC02_FT_ADC_SNR(29ea,0.04%) | AL15: Wire_bond_leak(25ea,0.04%) | AM15: IFD_FT02(19ea,0.03%) | AN15: FW_NAND(14ea,0.02%) | AO15: FW_HDMI_480P(13ea,0.02%) | AP15: IFD_FT01(9ea,0.01%)
F16: Yield | G16: 0.8503 | H16: 0.8503 | I16: % | J16: 0.0348 | K16: 0.0287 | L16: 0.0184 | M16: 0.0139 | N16: 0.011 | O16: 0.0096 | P16: 0.0041 | Q16: 0.0035 | R16: 0.0032 | S16: 0.0024 | Z16: FT1 | AA16: RTD2874FLF_TA01 | AC16: V10 | AD16: 3386 | AE16: 3380 | AF16: 0.9982 | AG16: D4_2666M_FRC_4K60_uhd_LB_FT(4ea,0.12%) | AH16: SCPU_BISR_HV(1ea,0.03%) | AI16: FW_other(1ea,0.03%)
B17: FT1 | C17: RTD2875QDA_TA01 | E17: V05 | F17: Total IC | G17: 74606 | H17: 74606 | I17: Test item | J17: FW_other | K17: DDR4_2G_3000_SS_single_RW_FT | L17: OS_500uA | M17: PIF_LVDS_FT | N17: PowerShort | O17: all_bisr_drf | P17: USB2_disconnect_mea | Q17: EFUSE_ReadAll_CRC | R17: chip_id_HRAM | S17: scpu_bisr_bist_drf | Z17: FT1 | AA17: RTD2841FLW_TA01 | AC17: V10 | AD17: 3600 | AE17: 3587 | AF17: 0.9964 | AG17: FW_other(5ea,0.14%) | AH17: D4_2666M_FRC_4K60_uhd_LB_FT(1ea,0.03%) | AI17: FW_MD_Domain(1ea,0.03%) | AJ17: ETN_MLT3(1ea,0.03%) | AK17: FW_HDMI_4K60(1ea,0.03%) | AL17: FW_CP(1ea,0.03%) | AM17: all_bist_m_0217_p5_scpu_bist_LDOon_HV(1ea,0.03%) | AN17: all_bist_m_0217_p1_BIST_LDOon_LV(1ea,0.03%) | AO17: all_bist_m_0217_p1_BIST_LDOon_HV(1ea,0.03%)
F18: Throughput | G18: 74342 | H18: 74342 | I18: q'ty | J18: 102 | K18: 88 | L18: 21 | M18: 11 | N18: 7 | O18: 6 | P18: 3 | Q18: 3 | R18: 2 | S18: 2 | Z18: FT2 | AA18: RTD2841FLW_TA01 | AC18: V02 | AD18: 44719 | AE18: 44711 | AF18: 0.9998 | AG18: USB2_Swing(6ea,0.01%) | AH18: Wire_bond_leak(2ea,0.00%)
F19: Yield | G19: 0.9965 | H19: 0.9965 | I19: % | J19: 0.0014 | K19: 0.0012 | L19: 0.0003 | M19: 0.0001 | N19: 0.0001 | O19: 0.0001 | P19: 0 | Q19: 0 | R19: 0 | S19: 0 | Y19: RL6856 Merlin8 | Z19: FT1 | AA19: RTD2885PDM_FT1_TA01 | AC19: V08 | AD19: 43002 | AE19: 42785 | AF19: 0.995 | AG19: FW_M8(99ea,0.23%) | AH19: DDR_single_RW_D4(29ea,0.07%) | AI19: DDR_ZQ_P(26ea,0.06%) | AJ19: VDC01_FT01_SNR(13ea,0.03%) | AK19: IDDQ(12ea,0.03%) | AL19: HDMI_12G(11ea,0.03%) | AM19: Power_Short(9ea,0.02%) | AN19: set-error-bin(6ea,0.01%) | AO19: OS_500uA(5ea,0.01%) | AP19: ETN_TX_FT0(2ea,0.00%)
B20: FT1 | C20: RTD2865PCJ_SA_TA01 | E20: V03 | F20: Total IC | G20: 22527 | H20: 22527 | I20: Test item | J20: USB2_FT_Z0 | L20: DDR4_1p5G_3200_SS_single_RW_FT | N20: OS_500uA | P20: USB2_swing_mea | Q20: BB_FT01 | R20: HDMI20_250M_VB | S20: IFD_FT01_SNR | Z20: FT1 | AA20: RTD2886NSS_SC_FT1_TA01 | AC20: V09 | AD20: 23956 | AE20: 23901 | AF20: 0.9977 | AG20: FW_M8(33ea,0.14%) | AH20: PIF_PP_FT_tt(4ea,0.02%) | AI20: HDMI_12G_ALL_Port(4ea,0.02%) | AJ20: set-error-bin(4ea,0.02%) | AK20: ddr_single_rw(3ea,0.01%) | AL20: Power_Short(1ea,0.00%) | AM20: Thermal_IDD_comp_4K(1ea,0.00%) | AN20: ddr_FRC_CN_n5percent(1ea,0.00%) | AO20: POR(1ea,0.00%) | AP20: VDC01_SNR_FT01(1ea,0.00%)
F21: Throughput | G21: 22432 | H21: 22432 | I21: q'ty | J21: 50 | K21: 13 | L21: 12 | M21: 7 | N21: 4 | O21: 2 | P21: 2 | Q21: 1 | R21: 1 | S21: 1 | Z21: FT1 | AA21: RTD2885PGK_SC_FT1_TA01 | AC21: V10 | AD21: 2867 | AE21: 2847 | AF21: 0.993 | AG21: Power_Short(20ea,0.70%)
F22: Yield | G22: 0.9958 | H22: 0.9958 | I22: % | J22: 0.0022 | K22: 0.0006 | L22: 0.0005 | M22: 0.0003 | N22: 0.0002 | O22: 0.0001 | P22: 0.0001 | Q22: 0 | R22: 0 | S22: 0 | Z22: FT2 | AA22: RTD2885PDM_FT2_TA01 | AC22: V05 | AD22: 42785 | AE22: 42757 | AF22: 0.9993 | AG22: USB2_disconnect_mea(27ea,0.06%) | AH22: OS(1ea,0.00%)
B23: FT1 | C23: RTD2875QDA_TA01 | E23: V03 | F23: Total IC | G23: 22300 | H23: 22300 | I23: Test item | J23: DDR4_2G_3000_SS_FRC_ZQp5p | K23: DDR4_2G_3000_SS_single_RW_FT | L23: FW_other | M23: PowerShort | N23: OS_500uA | O23: scpu_bist_all_1p2_HV | P23: scpu_bisr_bist_drf | Q23: chip_id_HRAM | R23: EFUSE_ReadAll_CRC | S23: scpu_bist_all_1p2_LV | Z23: FT2 | AA23: RTD2886NSP_SC_FT2_TA01 | AC23: V04 | AD23: 26747 | AE23: 26718 | AF23: 0.9989 | AG23: USB2_Disconnect_trim(29ea,0.11%)
F24: Throughput | G24: 22221 | H24: 22221 | I24: q'ty | J24: 19 | K24: 18 | L24: 14 | M24: 8 | N24: 4 | O24: 3 | P24: 2 | Q24: 1 | R24: 1 | S24: 1 | Y24: RL6750 H5C2 | Z24: FT1 | AA24: RTD2890_B19_TA01 | AC24: V03 | AD24: 6262 | AE24: 6047 | AF24: 0.9657 | AG24: D3_WB_0p25G_single_RW(143ea,2.28%) | AH24: OS_2mA(31ea,0.50%) | AI24: OS_check_switch_B19(29ea,0.46%) | AJ24: FW_Other(4ea,0.06%) | AK24: OS_500uA(3ea,0.05%) | AL24: FW_SCPU_QC(2ea,0.03%) | AM24: OTP_RSA_HASH_VALUE_check_NV(2ea,0.03%) | AN24: Power_Short(1ea,0.02%)
F25: Yield | G25: 0.9965 | H25: 0.9965 | I25: % | J25: 0.0009 | K25: 0.0008 | L25: 0.0006 | M25: 0.0004 | N25: 0.0002 | O25: 0.0001 | P25: 0.0001 | Q25: 0 | R25: 0 | S25: 0 | Y25: RL6748 Merlin7 | Z25: CP | AA25: RL6748 | AC25: V25 | AD25: 21873 | AE25: 19458 | AF25: 0.8896 | AG25: cp_mode0_saf_0to90_comp_C(625ea,2.86%) | AH25: all_bist_mp_scpu_all_bist_1106_CLK144_GPU_ETN_HV(510ea,2.33%) | AI25: cp_mode2_saf_0to90_comp_C_slow(400ea,1.83%) | AJ25: cp_mode1_saf_0to90_comp_C(281ea,1.28%) | AK25: IDD(82ea,0.37%) | AL25: PowerShort(77ea,0.35%) | AM25: cp_mode0_2_sdd_se0_a75_lp14_dsu_lp28_cat_cs1013_comp_LV(66ea,0.30%) | AN25: cp_mode0_0_tdf_lp8_cat_comp_C_LV(48ea,0.22%) | AO25: cp_mode0_tdf_se0_l3mcp_ttr_cov70_comp_HV(43ea,0.20%) | AP25: GPIO_04_GPIReadH_normal(24ea,0.11%)
B26: FT1 | C26: RTD2875QDB_TA01 | E26: V04 | F26: Total IC | G26: 24973 | H26: 24973 | I26: Test item | J26: DDR4_2G_3000_SS_FRC_ZQp5p | K26: DDR4_2G_3000_SS_single_RW_FT | L26: FW_other | M26: OS_500uA | N26: FW_MULTI_CORE_TEST | O26: SIF_FT01 | P26: FW_VE | Q26: USB2_disconnect_trim_RT | R26: USB2_FT_Z0 | S26: IDDQ | Z26: FT1 | AA26: RTD2881PSP_SDY_TA01 | AC26: V03 | AD26: 17943 | AE26: 17912 | AF26: 0.9983 | AG26: FW_M7(12ea,0.07%) | AH26: HDMI20_1p5G(5ea,0.03%) | AI26: HDMI21_12G_144hz(3ea,0.02%) | AJ26: Power_Short(3ea,0.02%) | AK26: USB_squelch_trim(2ea,0.01%) | AL26: IDDQ(1ea,0.01%) | AM26: HDMI20_6G(1ea,0.01%) | AN26: ETN_TX_FT0(1ea,0.01%) | AO26: CEC_FT01(1ea,0.01%) | AP26: OS_500uA(1ea,0.01%)
F27: Throughput | G27: 24888 | H27: 24888 | I27: q'ty | J27: 20 | K27: 19 | L27: 18 | M27: 11 | N27: 3 | O27: 2 | P27: 2 | Q27: 1 | R27: 1 | S27: 1 | Z27: FT1 | AA27: RTD2875NDB_LC_TA01 | AC27: V27 | AD27: 4952 | AE27: 4936 | AF27: 0.9968 | AG27: DDR_1p5GB_FRC_HV_1st(5ea,0.10%) | AH27: HDMI20_1p5G(2ea,0.04%) | AI27: BB_FT01(2ea,0.04%) | AJ27: FW_M7(2ea,0.04%) | AK27: Power_Short(1ea,0.02%) | AL27: IFD_FT03_QADC_ramp(1ea,0.02%) | AM27: ETN_TX_FT0(1ea,0.02%) | AN27: HDMI20_6G_VB(1ea,0.02%) | AO27: OS_500uA(1ea,0.02%)
F28: Yield | G28: 0.9966 | H28: 0.9966 | I28: % | J28: 0.0008 | K28: 0.0008 | L28: 0.0007 | M28: 0.0004 | N28: 0.0001 | O28: 0.0001 | P28: 0.0001 | Q28: 0 | R28: 0 | S28: 0 | Z28: FT1 | AA28: RTD2875NDA_LC_TA01 | AC28: V27 | AD28: 820 | AE28: 819 | AF28: 0.9988 | AG28: HDMI20_1p5G(1ea,0.12%)
B29: FT1 | C29: RTD2875QDA_HD_TA01 | E29: V03 | F29: Total IC | G29: 73866 | H29: 73866 | I29: Test item | J29: DDR4_2G_3000_SS_FRC_ZQp5p | K29: DDR4_2G_3000_SS_single_RW_FT | L29: FW_other | M29: USB2_disconnect_mea | N29: OS_500uA | O29: PowerShort | P29: all_bisr_drf | Q29: Wire_Bond_Leak | R29: FW_VE | S29: scpu_bist_all_1p2_HV | Z29: FT1 | AA29: RTD2875PSP_SC_TA01 | AC29: V12 | AD29: 130618 | AE29: 130301 | AF29: 0.9976 | AG29: FW_other(140ea,0.11%) | AH29: OS_500uA(56ea,0.04%) | AI29: HDMI20_6G_VB(29ea,0.02%) | AJ29: Power_Short(17ea,0.01%) | AK29: OS_2mA(11ea,0.01%) | AL29: HDMI20_1p5G(10ea,0.01%) | AM29: FW_MD_Domain(6ea,0.00%) | AN29: FW_ETN(6ea,0.00%) | AO29: FW_MTEST(5ea,0.00%) | AP29: FW_VDE(3ea,0.00%)
F30: Throughput | G30: 73590 | H30: 73590 | I30: q'ty | J30: 52 | K30: 50 | L30: 47 | M30: 29 | N30: 28 | O30: 17 | P30: 10 | Q30: 8 | R30: 5 | S30: 4 | Z30: FT1 | AA30: RTD2881PSD_WDC_TA01 | AC30: V23 | AD30: 22300 | AE30: 22012 | AF30: 0.9871 | AG30: DDR4_3GB_single_RW(103ea,0.46%) | AH30: FW_other(70ea,0.31%) | AI30: Power_Short(29ea,0.13%) | AJ30: FW_MD_Domain(28ea,0.13%) | AK30: IDDQ(23ea,0.10%) | AL30: os_500uA_s(12ea,0.05%) | AM30: USB_disconnect_trim(9ea,0.04%) | AN30: HDMI20_6G(4ea,0.02%) | AO30: HDMI21_3G(3ea,0.01%) | AP30: HDMI_5VDET_HPD(1ea,0.00%)
F31: Yield | G31: 0.9963 | H31: 0.9963 | I31: % | J31: 0.0007 | K31: 0.0007 | L31: 0.0006 | M31: 0.0004 | N31: 0.0004 | O31: 0.0002 | P31: 0.0001 | Q31: 0.0001 | R31: 0.0001 | S31: 0.0001 | Z31: FT1 | AA31: RTD2885NDP_HSC | AB31: 4K120 without ATSC C版 | AC31: V19 | AD31: 2431 | AE31: 2419 | AF31: 0.9951 | AG31: DDR_FRC_HV_1st(7ea,0.29%) | AH31: VDC01_FT01_SNR(2ea,0.08%) | AI31: USB_xZ0_MNT(1ea,0.04%) | AJ31: HDMI20_6G_VB(1ea,0.04%) | AK31: EARC_FT4_CM_swing_cm7(1ea,0.04%)
B32: FT1 | C32: RTD2875QDB_TA01 | E32: V05 | F32: Total IC | G32: 72238 | H32: 72238 | I32: Test item | J32: FW_other | K32: DDR4_2G_3000_SS_single_RW_FT | L32: POR | M32: USB2_disconnect_mea | N32: OS_500uA | O32: all_bisr_drf | P32: USB2_disconnect_trim_RT | Q32: IDDQ | R32: PIF_LVDS_FT | S32: scpu_bisr_bist_drf | Z32: FT2 | AA32: RTD2875_C_FT2 | AC32: V07 | AD32: 819 | AE32: 818 | AF32: 0.9988 | AG32: PIF_CML_SWING_CAL(1ea,0.12%)
F33: Throughput | G33: 71912 | H33: 71912 | I33: q'ty | J33: 140 | K33: 88 | L33: 19 | M33: 11 | N33: 10 | O33: 9 | P33: 6 | Q33: 5 | R33: 5 | S33: 4 | Y33: RL6672 Merlin6 | Z33: CP | AA33: RL6672 | AC33: V19 | AD33: 104448 | AE33: 87872 | AF33: 0.8413 | AG33: all_bist_mp_etn_HV(3506ea,3.36%) | AH33: IDDQ_final_check_mln6(2788ea,2.67%) | AI33: E_cp_saf_mode2_comp(2419ea,2.32%) | AJ33: cp_saf_mode0_comp(2407ea,2.30%) | AK33: C_cp_saf_mode1_comp(1638ea,1.57%) | AL33: Power_short(672ea,0.64%) | AM33: scpu_bist_all_mode_HV(318ea,0.30%) | AN33: cp_sdd_mode0_2_con_94to95_comp_lv(248ea,0.24%) | AO33: OS(238ea,0.23%) | AP33: E_cp_tdf_mode2_TiEx_tmax2_MaskHidden_lp_5_comp_lv(225ea,0.22%)
F34: Yield | G34: 0.9955 | H34: 0.9955 | I34: % | J34: 0.0019 | K34: 0.0012 | L34: 0.0003 | M34: 0.0002 | N34: 0.0001 | O34: 0.0001 | P34: 0.0001 | Q34: 0.0001 | R34: 0.0001 | S34: 0.0001 | Y34: RL6641 Mac7p | Z34: FT1 | AA34: RTD2841ACM_PS_TA01 | AC34: V26 | AD34: 31409 | AE34: 31172 | AF34: 0.9925 | AG34: FW_other(131ea,0.42%) | AH34: DDR4_FRC_1G_8G(25ea,0.08%) | AI34: FW_VE (16ea,0.05%) | AJ34: HDMI_6G(14ea,0.04%) | AK34: os_DDR4_8G1G(12ea,0.04%) | AL34: FW_ACPU (10ea,0.03%) | AM34: chip_id(7ea,0.02%) | AN34: PowerShort(5ea,0.02%) | AO34: FW_MD_DOMAIN (4ea,0.01%) | AP34: HDMI_250M(4ea,0.01%)
B35: FT1 | C35: RTD2875QDB_HD_TA01 | E35: V04 | F35: Total IC | G35: 61324 | H35: 61324 | I35: Test item | J35: DDR4_2G_3000_SS_single_RW_FT | K35: DDR4_2G_3000_SS_FRC_ZQp5p | L35: FW_other | M35: OS_500uA | N35: PowerShort | O35: FW_MULTI_CORE_TEST | P35: USB2_disconnect_mea | Q35: FW_VE | R35: scpu_bist_all_1p2_HV | S35: all_bisr_drf | Z35: FT1 | AA35: RTD2841ASM_PS_TA01 | AC35: V26 | AD35: 8905 | AE35: 8808 | AF35: 0.9891 | AG35: FW_other(54ea,0.61%) | AH35: os_DDR4_8G1G(21ea,0.24%) | AI35: DDR4_FRC_1G_8G(5ea,0.06%) | AJ35: FW_VE (3ea,0.03%) | AK35: HDMI_6G(2ea,0.02%) | AL35: chip_id(2ea,0.02%) | AM35: ETN_TX_FT0(2ea,0.02%) | AN35: FW_ACPU (1ea,0.01%) | AO35: FW_MD_DOMAIN (1ea,0.01%) | AP35: PIF_CML_FT(1ea,0.01%)
F36: Throughput | G36: 61108 | H36: 61108 | I36: q'ty | J36: 54 | K36: 40 | L36: 37 | M36: 20 | N36: 9 | O36: 7 | P36: 6 | Q36: 6 | R36: 5 | S36: 5
F37: Yield | G37: 0.9965 | H37: 0.9965 | I37: % | J37: 0.0009 | K37: 0.0007 | L37: 0.0006 | M37: 0.0003 | N37: 0.0001 | O37: 0.0001 | P37: 0.0001 | Q37: 0.0001 | R37: 0.0001 | S37: 0.0001
A38: RL6963 Mac8q | B38: CP | C38: RL6963 | E38: V07 | F38: Total IC | G38: 139138 | H38: 139138 | I38: Test item | J38: cp_mode1_saf_comp_B | K38: cp_mode0_saf_comp | L38: mac8p_scpu_bisr_bist_drf_etn_phy_LV_only_drf_0214 | M38: cp_mode2_saf_comp_B | N38: IDD | O38: all_bist_m_0217_p1_BIST_LDOoff_OC700_HV | P38: PowerShort | Q38: mac8p_scpu_vddr_part1_0p9v | R38: cp_mode1_tdf_cov70_comp_HV | S38: PLLSCPUA_CP05_APP
F39: Throughput | G39: 123762 | H39: 123762 | I39: q'ty | J39: 3414 | K39: 1894 | L39: 1693 | M39: 1575 | N39: 1381 | O39: 1247 | P39: 389 | Q39: 338 | R39: 310 | S39: 288
F40: Yield | G40: 0.8895 | H40: 0.8895 | I40: % | J40: 0.0245 | K40: 0.0136 | L40: 0.0122 | M40: 0.0113 | N40: 0.0099 | O40: 0.009 | P40: 0.0028 | Q40: 0.0024 | R40: 0.0022 | S40: 0.0021
...

Sheet RL7047_TA01_V01_summary_raw_da
A1: 0.9888 | B1: PASS BIN | C1: 15996 | D1: 0.7694 | N1: Project | O1: RL7047 | P1: RL7047 | Q1: RL7047 | R1: RL7047 | S1: RL7047 | T1: RL7047 | U1: RL7047 | V1: RL7047 | W1: RL7047 | X1: RL7047 | Y1: RL7047 | Z1: RL7047 | AA1: RL7047 | AB1: RL7047 | AC1: RL7047 | AD1: RL7047 | AE1: RL7047 | AF1: RL7047 | AG1: RL7047 | AH1: RL7047 | AI1: RL7047 | AJ1: RL7047 | AK1: RL7047 | AL1: RL7047 | AM1: RL7047 | AN1: RL7047 | AO1: RL7047
A2: Top_all | B2: BIN1 | C2: 15996 | D2: 0.7694 | N2: Product | O2: RL7047_CA | P2: RL7047_CA | Q2: RL7047_CA | R2: RL7047_CA | S2: RL7047_CA | T2: RL7047_CA | U2: RL7047_CA | V2: RL7047_CA | W2: RL7047_CA | X2: RL7047_CA | Y2: RL7047_CA | Z2: RL7047_CA | AA2: RL7047_CA | AB2: RL7047_CA | AC2: RL7047_CA | AD2: RL7047_CA | AE2: RL7047_CA | AF2: RL7047_CA | AG2: RL7047_CA | AH2: RL7047_CA | AI2: RL7047_CA | AJ2: RL7047_CA | AK2: RL7047_CA | AL2: RL7047_CA | AM2: RL7047_CA | AN2: RL7047_CA | AO2: RL7047_CA
B3: OTHER | C3: 14 | D3: 0.0007 | N3: Short Lot ID | O3: Q1G74 | P3: Q1H21 | Q3: Q1G74 | R3: Q1HP5 | S3: Q1HP5 | T3: Q1G74 | U3: Q1H21 | V3: Q1HP5 | W3: Q1H21 | X3: Q1H21 | Y3: Q1H21 | Z3: Q1H21 | AA3: Q1H21 | AB3: Q1H21 | AC3: Q1H21 | AD3: Q1H21 | AE3: Q1H21 | AF3: Q1H21 | AG3: Q1H21 | AH3: Q1H21 | AI3: Q1H21 | AJ3: Q1H21 | AK3: Q1H21 | AL3: Q1H21 | AM3: Q1H21 | AN3: Q1H21 | AO3: Q1H21
B4: OS | C4: 125 | D4: 0.006 | N4: Lot ID | O4: Q1G74 | P4: Q1H21 | Q4: Q1G74 | R4: Q1HP5 | S4: Q1HP5 | T4: Q1G74 | U4: Q1H21 | V4: Q1HP5 | W4: Q1H21 | X4: Q1H21 | Y4: Q1H21 | Z4: Q1H21 | AA4: Q1H21 | AB4: Q1H21 | AC4: Q1H21 | AD4: Q1H21 | AE4: Q1H21 | AF4: Q1H21 | AG4: Q1H21 | AH4: Q1H21 | AI4: Q1H21 | AJ4: Q1H21 | AK4: Q1H21 | AL4: Q1H21 | AM4: Q1H21 | AN4: Q1H21 | AO4: Q1H21
B5: IDD | C5: 0 | D5: 0 | N5: Wafer ID | O5: P6FV25-17C6 | P5: PF8L96-24E3 | Q5: P6FV25-18C1 | R5: P6FV25-15E0 | S5: P6FV25-14E5 | T5: P6FV25-19B4 | U5: PF8L96-16A6 | V5: P6FV25-16D3 | W5: PF8L96-20G7 | X5: PF8L96-07F1 | Y5: PF8L96-13C5 | Z5: PF8L96-21G2 | AA5: PF8L96-17A1 | AB5: PF8L96-12D2 | AC5: PF8L96-19G2 | AD5: PF8L96-25D6 | AE5: PF8L96-22F5 | AF5: PF8L96-09D7 | AG5: PF8L96-05G3 | AH5: PF8L96-11D7 | AI5: PF8L96-10E4 | AJ5: PF8L96-08E4 | AK5: PF8L96-06F6 | AL5: PF8L96-15B3 | AM5: PF8L96-18G7 | AN5: PF8L96-14C0 | AO5: PF8L96-23F0
B6: SD | C6: 475 | D6: 0.0228 | N6: Wafer NO. | O6: 17 | P6: 24 | Q6: 18 | R6: 15 | S6: 14 | T6: 19 | U6: 16 | V6: 16 | W6: 20 | X6: 7 | Y6: 13 | Z6: 21 | AA6: 17 | AB6: 12 | AC6: 19 | AD6: 25 | AE6: 22 | AF6: 9 | AG6: 5 | AH6: 11 | AI6: 10 | AJ6: 8 | AK6: 6 | AL6: 15 | AM6: 18 | AN6: 14 | AO6: 23
B7: OTP | C7: 0 | D7: 0 | N7: Re-Test | O7: 1 | P7: 1 | Q7: 1 | R7: 2 | S7: 2 | T7: 1 | U7: 1 | V7: 2 | W7: 1 | X7: 1 | Y7: 1 | Z7: 1 | AA7: 1 | AB7: 1 | AC7: 1 | AD7: 1 | AE7: 1 | AF7: 1 | AG7: 1 | AH7: 1 | AI7: 1 | AJ7: 1 | AK7: 1 | AL7: 1 | AM7: 1 | AN7: 1 | AO7: 1
B8: SCAN | C8: 3912 | D8: 0.1882 | N8: ProbeCard | O8: JP10902 | P8: JP10902 | Q8: JP10902 | R8: JP10902 | S8: JP10902 | T8: JP10902 | U8: JP10902 | V8: JP10902 | W8: JP10902 | X8: JP10902 | Y8: JP10902 | Z8: JP10902 | AA8: JP10902 | AB8: JP10902 | AC8: JP10902 | AD8: JP10902 | AE8: JP10902 | AF8: JP10902 | AG8: JP10902 | AH8: JP10902 | AI8: JP10902 | AJ8: JP10902 | AK8: JP10902 | AL8: JP10902 | AM8: JP10902 | AN8: JP10902 | AO8: JP10902
B9: BIST | C9: 35 | D9: 0.0017 | N9: Yield | O9: 0.6338 | P9: 0.6831 | Q9: 0.7039 | R9: 0.7078 | S9: 0.7351 | T9: 0.7364 | U9: 0.7364 | V9: 0.7506 | W9: 0.7545 | X9: 0.7675 | Y9: 0.7701 | Z9: 0.7818 | AA9: 0.7818 | AB9: 0.7818 | AC9: 0.7818 | AD9: 0.7844 | AE9: 0.7857 | AF9: 0.7961 | AG9: 0.8013 | AH9: 0.8013 | AI9: 0.8026 | AJ9: 0.8078 | AK9: 0.8091 | AL9: 0.813 | AM9: 0.8169 | AN9: 0.8247 | AO9: 0.8247
B10: DIC | C10: 1 | D10: 0 | N10: CP | O10: CP1 | P10: CP1 | Q10: CP1 | R10: CP1 | S10: CP1 | T10: CP1 | U10: CP1 | V10: CP1 | W10: CP1 | X10: CP1 | Y10: CP1 | Z10: CP1 | AA10: CP1 | AB10: CP1 | AC10: CP1 | AD10: CP1 | AE10: CP1 | AF10: CP1 | AG10: CP1 | AH10: CP1 | AI10: CP1 | AJ10: CP1 | AK10: CP1 | AL10: CP1 | AM10: CP1 | AN10: CP1 | AO10: CP1
C11: 0 | D11: 0 | N11: Starttime | O11: 2026-02-21 23:19:26 | P11: 2026-02-21 08:53:02 | Q11: 2026-02-22 05:40:01 | R11: 2026-02-20 22:00:19 | S11: 2026-02-20 21:19:02 | T11: 2026-02-22 11:59:45 | U11: 2026-02-18 21:58:30 | V11: 2026-02-20 23:03:02 | W11: 2026-02-20 00:52:08 | X11: 2026-02-16 08:01:23 | Y11: 2026-02-18 01:09:36 | Z11: 2026-02-20 07:22:24 | AA11: 2026-02-19 04:43:44 | AB11: 2026-02-17 18:28:10 | AC11: 2026-02-19 18:06:43 | AD11: 2026-02-21 14:59:45 | AE11: 2026-02-20 14:01:27 | AF11: 2026-02-16 22:10:23 | AG11: 2026-02-15 18:07:32 | AH11: 2026-02-17 11:47:25 | AI11: 2026-02-17 04:56:49 | AJ11: 2026-02-16 14:39:07 | AK11: 2026-02-16 00:58:00 | AL11: 2026-02-18 15:02:45 | AM11: 2026-02-19 11:21:07 | AN11: 2026-02-18 08:07:38 | AO11: 2026-02-21 01:36:04
A12: 0.9888 | B12: PASS BIN | C12: 15996 | D12: 0.7694 | E12: PASS BIN | N12: Endtime | O12: 2026-02-22 05:38:09 | P12: 2026-02-21 14:57:50 | Q12: 2026-02-22 11:57:52 | R12: 2026-02-20 23:01:11 | S12: 2026-02-20 21:58:30 | T12: 2026-02-22 18:21:23 | U12: 2026-02-19 04:41:51 | V12: 2026-02-20 23:53:48 | W12: 2026-02-20 07:20:31 | X12: 2026-02-16 14:36:50 | Y12: 2026-02-18 08:05:45 | Z12: 2026-02-20 13:59:34 | AA12: 2026-02-19 11:19:15 | AB12: 2026-02-18 01:07:44 | AC12: 2026-02-20 00:50:16 | AD12: 2026-02-21 21:41:39 | AE12: 2026-02-20 20:49:08 | AF12: 2026-02-17 04:54:57 | AG12: 2026-02-16 00:55:41 | AH12: 2026-02-17 18:26:17 | AI12: 2026-02-17 11:45:33 | AJ12: 2026-02-16 22:08:32 | AK12: 2026-02-16 07:59:05 | AL12: 2026-02-18 21:56:37 | AM12: 2026-02-19 18:04:52 | AN12: 2026-02-18 15:00:52 | AO12: 2026-02-21 08:51:11
B13: BIN1 | C13: 15996 | D13: 0.7694 | E13: PASS BIN | N13: Week | O13: 202608 | P13: 202608 | Q13: 202608 | R13: 202608 | S13: 202608 | T13: 202608 | U13: 202608 | V13: 202608 | W13: 202608 | X13: 202608 | Y13: 202608 | Z13: 202608 | AA13: 202608 | AB13: 202608 | AC13: 202608 | AD13: 202608 | AE13: 202608 | AF13: 202608 | AG13: 202608 | AH13: 202608 | AI13: 202608 | AJ13: 202608 | AK13: 202608 | AL13: 202608 | AM13: 202608 | AN13: 202608 | AO13: 202608
B14: OTHER | C14: 14 | D14: 0.0007 | E14: OTHER | N14: Month | O14: 2026-02 | P14: 2026-02 | Q14: 2026-02 | R14: 2026-02 | S14: 2026-02 | T14: 2026-02 | U14: 2026-02 | V14: 2026-02 | W14: 2026-02 | X14: 2026-02 | Y14: 2026-02 | Z14: 2026-02 | AA14: 2026-02 | AB14: 2026-02 | AC14: 2026-02 | AD14: 2026-02 | AE14: 2026-02 | AF14: 2026-02 | AG14: 2026-02 | AH14: 2026-02 | AI14: 2026-02 | AJ14: 2026-02 | AK14: 2026-02 | AL14: 2026-02 | AM14: 2026-02 | AN14: 2026-02 | AO14: 2026-02
B15: OS | C15: 125 | D15: 0.006 | E15: OS | N15: Program | O15: RL7047_TA01 | P15: RL7047_TA01 | Q15: RL7047_TA01 | R15: RL7047_TA01 | S15: RL7047_TA01 | T15: RL7047_TA01 | U15: RL7047_TA01 | V15: RL7047_TA01 | W15: RL7047_TA01 | X15: RL7047_TA01 | Y15: RL7047_TA01 | Z15: RL7047_TA01 | AA15: RL7047_TA01 | AB15: RL7047_TA01 | AC15: RL7047_TA01 | AD15: RL7047_TA01 | AE15: RL7047_TA01 | AF15: RL7047_TA01 | AG15: RL7047_TA01 | AH15: RL7047_TA01 | AI15: RL7047_TA01 | AJ15: RL7047_TA01 | AK15: RL7047_TA01 | AL15: RL7047_TA01 | AM15: RL7047_TA01 | AN15: RL7047_TA01 | AO15: RL7047_TA01
B16: IDD | C16: 0 | D16: 0 | E16: IDD | N16: Version(ECN) | O16: RL7047_TA01_V01 | P16: RL7047_TA01_V01 | Q16: RL7047_TA01_V01 | R16: RL7047_TA01_V01 | S16: RL7047_TA01_V01 | T16: RL7047_TA01_V01 | U16: RL7047_TA01_V01 | V16: RL7047_TA01_V01 | W16: RL7047_TA01_V01 | X16: RL7047_TA01_V01 | Y16: RL7047_TA01_V01 | Z16: RL7047_TA01_V01 | AA16: RL7047_TA01_V01 | AB16: RL7047_TA01_V01 | AC16: RL7047_TA01_V01 | AD16: RL7047_TA01_V01 | AE16: RL7047_TA01_V01 | AF16: RL7047_TA01_V01 | AG16: RL7047_TA01_V01 | AH16: RL7047_TA01_V01 | AI16: RL7047_TA01_V01 | AJ16: RL7047_TA01_V01 | AK16: RL7047_TA01_V01 | AL16: RL7047_TA01_V01 | AM16: RL7047_TA01_V01 | AN16: RL7047_TA01_V01 | AO16: RL7047_TA01_V01
B17: SD_OTHER | C17: 8 | D17: 0.0004 | E17: SD | N17: Pass Die | O17: 488 | P17: 526 | Q17: 542 | R17: 545 | S17: 566 | T17: 567 | U17: 567 | V17: 578 | W17: 581 | X17: 591 | Y17: 593 | Z17: 602 | AA17: 602 | AB17: 602 | AC17: 602 | AD17: 604 | AE17: 605 | AF17: 613 | AG17: 617 | AH17: 617 | AI17: 618 | AJ17: 622 | AK17: 623 | AL17: 626 | AM17: 629 | AN17: 635 | AO17: 635
B18: PLL | C18: 251 | D18: 0.0121 | E18: SD | N18: Total Die | O18: 770 | P18: 770 | Q18: 770 | R18: 770 | S18: 770 | T18: 770 | U18: 770 | V18: 770 | W18: 770 | X18: 770 | Y18: 770 | Z18: 770 | AA18: 770 | AB18: 770 | AC18: 770 | AD18: 770 | AE18: 770 | AF18: 770 | AG18: 770 | AH18: 770 | AI18: 770 | AJ18: 770 | AK18: 770 | AL18: 770 | AM18: 770 | AN18: 770 | AO18: 770
B19: BB | C19: 0 | D19: 0 | E19: SD | I19: PASS BIN | M19: 0.7483353 | N19: 1.4966706 | O19: 0.63376623 | P19: 0.68311688 | Q19: 0.7038961 | R19: 0.70779221 | S19: 0.73506494 | T19: 0.73636364 | U19: 0.73636364 | V19: 0.75064935 | W19: 0.75454545 | X19: 0.76753247 | Y19: 0.77012987 | Z19: 0.78181818 | AA19: 0.78181818 | AB19: 0.78181818 | AC19: 0.78181818 | AD19: 0.78441558 | AE19: 0.78571429 | AF19: 0.7961039 | AG19: 0.8012987 | AH19: 0.8012987 | AI19: 0.8025974 | AJ19: 0.80779221 | AK19: 0.80909091 | AL19: 0.81298701 | AM19: 0.81688312 | AN19: 0.82467532 | AO19: 0.82467532
B20: GPIO | C20: 0 | D20: 0 | E20: SD | I20: OTHER | M20: 0.00049587 | N20: 0.00099174 | O20: 0.0012987 | P20: 0 | Q20: 0 | R20: 0 | S20: 0.0025974 | T20: 0.0012987 | U20: 0.0012987 | V20: 0 | W20: 0 | X20: 0.0012987 | Y20: 0 | Z20: 0.0012987 | AA20: 0 | AB20: 0 | AC20: 0.0012987 | AD20: 0.0025974 | AE20: 0.0012987 | AF20: 0 | AG20: 0 | AH20: 0 | AI20: 0 | AJ20: 0.0012987 | AK20: 0 | AL20: 0 | AM20: 0.0012987 | AN20: 0 | AO20: 0.0012987
B21: LSADC | C21: 0 | D21: 0 | E21: SD | I21: OS | M21: 0.00798111 | N21: 0.01596222 | O21: 0.00519481 | P21: 0.0038961 | Q21: 0.00649351 | R21: 0.00519481 | S21: 0.00909091 | T21: 0.01428571 | U21: 0 | V21: 0.01558442 | W21: 0.00649351 | X21: 0.00909091 | Y21: 0.00909091 | Z21: 0.0025974 | AA21: 0.0038961 | AB21: 0.0038961 | AC21: 0.01038961 | AD21: 0.00519481 | AE21: 0.0012987 | AF21: 0.00649351 | AG21: 0.00779221 | AH21: 0.0038961 | AI21: 0.0038961 | AJ21: 0.0025974 | AK21: 0.0025974 | AL21: 0.00649351 | AM21: 0.0038961 | AN21: 0.00909091 | AO21: 0.0038961
B22: PIF | C22: 21 | D22: 0.001 | E22: SD | I22: IDD | M22: 0.00186541 | N22: 0.00373082 | O22: 0 | P22: 0 | Q22: 0 | R22: 0 | S22: 0 | T22: 0 | U22: 0 | V22: 0 | W22: 0 | X22: 0 | Y22: 0 | Z22: 0 | AA22: 0 | AB22: 0 | AC22: 0 | AD22: 0 | AE22: 0 | AF22: 0 | AG22: 0 | AH22: 0 | AI22: 0 | AJ22: 0 | AK22: 0 | AL22: 0 | AM22: 0 | AN22: 0 | AO22: 0
B23: SFM | C23: 0 | D23: 0 | E23: SD | I23: SD_OTHER | M23: 0.0003778 | N23: 0.0007556 | O23: 0 | P23: 0.0025974 | Q23: 0 | R23: 0 | S23: 0 | T23: 0 | U23: 0 | V23: 0 | W23: 0.0012987 | X23: 0.0012987 | Y23: 0 | Z23: 0 | AA23: 0 | AB23: 0 | AC23: 0 | AD23: 0 | AE23: 0.0012987 | AF23: 0 | AG23: 0 | AH23: 0 | AI23: 0.0025974 | AJ23: 0 | AK23: 0 | AL23: 0.0012987 | AM23: 0 | AN23: 0 | AO23: 0
B24: TCON | C24: 3 | D24: 0.0001 | E24: SD | I24: PLL | M24: 0.01286895 | N24: 0.0257379 | O24: 0.02857143 | P24: 0.00779221 | Q24: 0.01688312 | R24: 0.00649351 | S24: 0.05324675 | T24: 0.02337662 | U24: 0.00779221 | V24: 0.01818182 | W24: 0.00909091 | X24: 0.00909091 | Y24: 0.01298701 | Z24: 0.01168831 | AA24: 0.00649351 | AB24: 0.00909091 | AC24: 0.00649351 | AD24: 0.01298701 | AE24: 0.00519481 | AF24: 0.00649351 | AG24: 0.00909091 | AH24: 0.01428571 | AI24: 0.01168831 | AJ24: 0.00779221 | AK24: 0.00649351 | AL24: 0.00649351 | AM24: 0.00519481 | AN24: 0.00649351 | AO24: 0.00649351
B25: PCIE | C25: 192 | D25: 0.0092 | E25: SD | I25: BB | M25: 0.00016529 | N25: 0.00033058 | O25: 0 | P25: 0 | Q25: 0 | R25: 0 | S25: 0 | T25: 0 | U25: 0 | V25: 0 | W25: 0 | X25: 0 | Y25: 0 | Z25: 0 | AA25: 0 | AB25: 0 | AC25: 0 | AD25: 0 | AE25: 0 | AF25: 0 | AG25: 0 | AH25: 0 | AI25: 0 | AJ25: 0 | AK25: 0 | AL25: 0 | AM25: 0 | AN25: 0 | AO25: 0
B26: USB2 | C26: 0 | D26: 0 | E26: SD | I26: GPIO | M26: 2.361e-05 | N26: 4.722e-05 | O26: 0 | P26: 0 | Q26: 0 | R26: 0 | S26: 0 | T26: 0 | U26: 0 | V26: 0 | W26: 0 | X26: 0 | Y26: 0 | Z26: 0 | AA26: 0 | AB26: 0 | AC26: 0 | AD26: 0 | AE26: 0 | AF26: 0 | AG26: 0 | AH26: 0 | AI26: 0 | AJ26: 0 | AK26: 0 | AL26: 0 | AM26: 0 | AN26: 0 | AO26: 0
B27: ETN | C27: 0 | D27: 0 | E27: SD | I27: LSADC | M27: 0.00011806 | N27: 0.00023612 | O27: 0 | P27: 0 | Q27: 0 | R27: 0 | S27: 0 | T27: 0 | U27: 0 | V27: 0 | W27: 0 | X27: 0 | Y27: 0 | Z27: 0 | AA27: 0 | AB27: 0 | AC27: 0 | AD27: 0 | AE27: 0 | AF27: 0 | AG27: 0 | AH27: 0 | AI27: 0 | AJ27: 0 | AK27: 0 | AL27: 0 | AM27: 0 | AN27: 0 | AO27: 0
B28: SNR | C28: 0 | D28: 0 | E28: SD | I28: PIF | M28: 0.0011098 | N28: 0.0022196 | O28: 0 | P28: 0.0012987 | Q28: 0.0012987 | R28: 0 | S28: 0 | T28: 0 | U28: 0.0012987 | V28: 0 | W28: 0.0025974 | X28: 0 | Y28: 0.0012987 | Z28: 0.0012987 | AA28: 0 | AB28: 0.0038961 | AC28: 0.0038961 | AD28: 0 | AE28: 0.0012987 | AF28: 0.0025974 | AG28: 0.0012987 | AH28: 0 | AI28: 0 | AJ28: 0 | AK28: 0.0012987 | AL28: 0.0012987 | AM28: 0.0012987 | AN28: 0 | AO28: 0.0012987
B29: DPRX | C29: 0 | D29: 0 | E29: SD | I29: SFM | M29: 0 | N29: 0 | O29: 0 | P29: 0 | Q29: 0 | R29: 0 | S29: 0 | T29: 0 | U29: 0 | V29: 0 | W29: 0 | X29: 0 | Y29: 0 | Z29: 0 | AA29: 0 | AB29: 0 | AC29: 0 | AD29: 0 | AE29: 0 | AF29: 0 | AG29: 0 | AH29: 0 | AI29: 0 | AJ29: 0 | AK29: 0 | AL29: 0 | AM29: 0 | AN29: 0 | AO29: 0
B30: USB3 | C30: 0 | D30: 0 | E30: SD | I30: TCON | M30: 0.00047226 | N30: 0.00094452 | O30: 0 | P30: 0 | Q30: 0 | R30: 0 | S30: 0 | T30: 0 | U30: 0 | V30: 0 | W30: 0 | X30: 0 | Y30: 0 | Z30: 0 | AA30: 0 | AB30: 0 | AC30: 0 | AD30: 0.0012987 | AE30: 0 | AF30: 0 | AG30: 0 | AH30: 0 | AI30: 0 | AJ30: 0 | AK30: 0 | AL30: 0.0012987 | AM30: 0.0012987 | AN30: 0 | AO30: 0
... B41: DIC | C41: 1 | D41: 0 | E41: DIC | I41: SDD_HV | M41: 0.00016529 | N41: 0.00033058 | O41: 0 | P41: 0 | Q41: 0 | R41: 0 | S41: 0 | T41: 0.0012987 | U41: 0 | V41: 0.0012987 | W41: 0 | X41: 0 | Y41: 0 | Z41: 0 | AA41: 0 | AB41: 0 | AC41: 0 | AD41: 0 | AE41: 0 | AF41: 0 | AG41: 0 | AH41: 0 | AI41: 0 | AJ41: 0 | AK41: 0 | AL41: 0 | AM41: 0 | AN41: 0 | AO41: 0
C42: 0 | D42: 0 | I42: TDF_HV | M42: 0.0638961 | N42: 0.1277922 | O42: 0.16103896 | P42: 0.02467532 | Q42: 0.11428571 | R42: 0.12597403 | S42: 0.04025974 | T42: 0.09090909 | U42: 0.02727273 | V42: 0.09220779 | W42: 0.07922078 | X42: 0.06753247 | Y42: 0.03896104 | Z42: 0.02207792 | AA42: 0.05714286 | AB42: 0.02597403 | AC42: 0.05194805 | AD42: 0.01818182 | AE42: 0.01948052 | AF42: 0.04935065 | AG42: 0.03246753 | AH42: 0.05324675 | AI42: 0.03636364 | AJ42: 0.04415584 | AK42: 0.03506494 | AL42: 0.05194805 | AM42: 0.01688312 | AN42: 0.02467532 | AO42: 0.03896104
I43: SDD_LV | M43: 0.00059032 | N43: 0.00118064 | O43: 0.0012987 | P43: 0.0012987 | Q43: 0.0012987 | R43: 0.0012987 | S43: 0 | T43: 0 | U43: 0 | V43: 0 | W43: 0 | X43: 0 | Y43: 0.0012987 | Z43: 0 | AA43: 0 | AB43: 0.0012987 | AC43: 0 | AD43: 0 | AE43: 0 | AF43: 0 | AG43: 0.0012987 | AH43: 0 | AI43: 0 | AJ43: 0 | AK43: 0.0012987 | AL43: 0.0012987 | AM43: 0 | AN43: 0 | AO43: 0
I44: TDF_LV | M44: 0.00892562 | N44: 0.01785124 | O44: 0.00649351 | P44: 0.01038961 | Q44: 0.00779221 | R44: 0.01428571 | S44: 0.01038961 | T44: 0.01428571 | U44: 0.00649351 | V44: 0.01298701 | W44: 0.00519481 | X44: 0.00519481 | Y44: 0.01038961 | Z44: 0.01168831 | AA44: 0.01038961 | AB44: 0.01558442 | AC44: 0.00779221 | AD44: 0.01298701 | AE44: 0.0038961 | AF44: 0.00779221 | AG44: 0.01558442 | AH44: 0.0038961 | AI44: 0.01298701 | AJ44: 0.00779221 | AK44: 0.00909091 | AL44: 0.0038961 | AM44: 0.00779221 | AN44: 0.00649351 | AO44: 0.00779221
I45: BIST_HV | M45: 0.0022196 | N45: 0.0044392 | O45: 0 | P45: 0.0025974 | Q45: 0 | R45: 0 | S45: 0 | T45: 0.0012987 | U45: 0.0025974 | V45: 0.0012987 | W45: 0 | X45: 0.0025974 | Y45: 0.0012987 | Z45: 0.0025974 | AA45: 0 | AB45: 0.0012987 | AC45: 0.0025974 | AD45: 0.0012987 | AE45: 0.0012987 | AF45: 0.0038961 | AG45: 0.0025974 | AH45: 0.0038961 | AI45: 0.0012987 | AJ45: 0.0025974 | AK45: 0.0012987 | AL45: 0 | AM45: 0 | AN45: 0.0012987 | AO45: 0.0012987
I46: BIST_LV | M46: 0.00035419 | N46: 0.00070838 | O46: 0 | P46: 0.0012987 | Q46: 0 | R46: 0 | S46: 0.0012987 | T46: 0 | U46: 0 | V46: 0 | W46: 0 | X46: 0 | Y46: 0 | Z46: 0.0012987 | AA46: 0 | AB46: 0 | AC46: 0 | AD46: 0 | AE46: 0.0025974 | AF46: 0 | AG46: 0 | AH46: 0 | AI46: 0 | AJ46: 0 | AK46: 0 | AL46: 0 | AM46: 0 | AN46: 0 | AO46: 0
I47: DIC | M47: 0.00153483 | N47: 0.00306966 | O47: 0 | P47: 0 | Q47: 0 | R47: 0 | S47: 0 | T47: 0 | U47: 0 | V47: 0 | W47: 0 | X47: 0 | Y47: 0.0012987 | Z47: 0 | AA47: 0 | AB47: 0 | AC47: 0 | AD47: 0 | AE47: 0 | AF47: 0 | AG47: 0 | AH47: 0 | AI47: 0 | AJ47: 0 | AK47: 0 | AL47: 0 | AM47: 0 | AN47: 0 | AO47: 0
M48: 0 | N48: 0 | O48: 0 | P48: 0 | Q48: 0 | R48: 0 | S48: 0 | T48: 0 | U48: 0 | V48: 0 | W48: 0 | X48: 0 | Y48: 0 | Z48: 0 | AA48: 0 | AB48: 0 | AC48: 0 | AD48: 0 | AE48: 0 | AF48: 0 | AG48: 0 | AH48: 0 | AI48: 0 | AJ48: 0 | AK48: 0 | AL48: 0 | AM48: 0 | AN48: 0 | AO48: 0
A49: 2026-02-16-2026-02-22 | J49: 27
A50: Order | B50: Item | C50: Bin | D50: Test program | E50: Test voltage | F50: Fail Type | G50: Fail Type | H50: q'ty | I50: % | J50: >10% | K50: >avg*2 | L50: Max | M50: Avg % | N50: Highlight %
...

Sheet RL7032_TA01_V02_summary_raw_da
A1: 1 | B1: PASS BIN | C1: 23242 | D1: 0.8546 | N1: Project | O1: RL7032 | P1: RL7032 | Q1: RL7032 | R1: RL7032 | S1: RL7032 | T1: RL7032 | U1: RL7032 | V1: RL7032 | W1: RL7032 | X1: RL7032 | Y1: RL7032 | Z1: RL7032 | AA1: RL7032 | AB1: RL7032 | AC1: RL7032 | AD1: RL7032 | AE1: RL7032 | AF1: RL7032 | AG1: RL7032 | AH1: RL7032 | AI1: RL7032 | AJ1: RL7032 | AK1: RL7032 | AL1: RL7032 | AM1: RL7032 | AN1: RL7032
A2: Top_all | B2: BIN1 | C2: 23242 | D2: 0.8546 | N2: Product | O2: RL7032 | P2: RL7032 | Q2: RL7032 | R2: RL7032 | S2: RL7032 | T2: RL7032 | U2: RL7032 | V2: RL7032 | W2: RL7032 | X2: RL7032 | Y2: RL7032 | Z2: RL7032 | AA2: RL7032 | AB2: RL7032 | AC2: RL7032 | AD2: RL7032 | AE2: RL7032 | AF2: RL7032 | AG2: RL7032 | AH2: RL7032 | AI2: RL7032 | AJ2: RL7032 | AK2: RL7032 | AL2: RL7032 | AM2: RL7032 | AN2: RL7032
B3: IDD | C3: 105 | D3: 0.0039 | N3: Short Lot ID | O3: Q2FF2 | P3: Q2FF2 | Q3: Q2FF2 | R3: Q2FF2 | S3: Q2FF2 | T3: Q2FF2 | U3: Q2FF2 | V3: Q2FF2 | W3: Q2C99 | X3: Q2FF2 | Y3: Q2FF2 | Z3: Q2FF2 | AA3: Q2C99 | AB3: Q2C99 | AC3: Q2C99 | AD3: Q2FF2 | AE3: Q2C99 | AF3: Q2FF2 | AG3: Q2C99 | AH3: Q2FF2 | AI3: Q2FF2 | AJ3: Q2FF2 | AK3: Q2C99 | AL3: Q2C99 | AM3: Q2C99 | AN3: Q2C99
B4: OS | C4: 157 | D4: 0.0058 | N4: Lot ID | O4: Q2FF2 | P4: Q2FF2 | Q4: Q2FF2 | R4: Q2FF2 | S4: Q2FF2 | T4: Q2FF2 | U4: Q2FF2 | V4: Q2FF2 | W4: Q2C99 | X4: Q2FF2 | Y4: Q2FF2 | Z4: Q2FF2 | AA4: Q2C99 | AB4: Q2C99 | AC4: Q2C99 | AD4: Q2FF2 | AE4: Q2C99 | AF4: Q2FF2 | AG4: Q2C99 | AH4: Q2FF2 | AI4: Q2FF2 | AJ4: Q2FF2 | AK4: Q2C99 | AL4: Q2C99 | AM4: Q2C99 | AN4: Q2C99
B5: OTP | C5: 92 | D5: 0.0034 | N5: Wafer ID | O5: PFHN77-13G0 | P5: PFHN77-01E7 | Q5: PFHN77-21C2 | R5: PFHN77-23B0 | S5: PFHN77-15E6 | T5: PFHN77-04D0 | U5: PFHN77-18C7 | V5: PFHN77-19C2 | W5: PFEQ54-06E2 | X5: PFHN77-17D4 | Y5: PFHN77-03D5 | Z5: PFHN77-02E2 | AA5: PFEQ54-04F4 | AB5: PFEQ54-12B6 | AC5: PFEQ54-10D0 | AD5: PFHN77-16E1 | AE5: PFEQ54-08D0 | AF5: PFHN77-24A3 | AG5: PFEQ54-07D5 | AH5: PFHN77-20C7 | AI5: PFHN77-22B5 | AJ5: PFHN77-14F3 | AK5: PFEQ54-13B1 | AL5: PFEQ54-11C3 | AM5: PFEQ54-05E7 | AN5: PFEQ54-09C3
B6: SD | C6: 28 | D6: 0.001 | N6: Wafer NO. | O6: 13 | P6: 1 | Q6: 21 | R6: 23 | S6: 15 | T6: 4 | U6: 18 | V6: 19 | W6: 6 | X6: 17 | Y6: 3 | Z6: 2 | AA6: 4 | AB6: 12 | AC6: 10 | AD6: 16 | AE6: 8 | AF6: 24 | AG6: 7 | AH6: 20 | AI6: 22 | AJ6: 14 | AK6: 13 | AL6: 11 | AM6: 5 | AN6: 9
B7: OC | C7: 3 | D7: 0.0001 | N7: Re-Test | O7: 1 | P7: 1 | Q7: 1 | R7: 1 | S7: 1 | T7: 1 | U7: 1 | V7: 1 | W7: 1 | X7: 1 | Y7: 1 | Z7: 1 | AA7: 1 | AB7: 1 | AC7: 1 | AD7: 1 | AE7: 1 | AF7: 1 | AG7: 1 | AH7: 1 | AI7: 1 | AJ7: 1 | AK7: 1 | AL7: 1 | AM7: 1 | AN7: 1
B8: DIC | C8: 2 | D8: 0.0001 | N8: ProbeCard | O8: JP10646 | P8: JP10791 | Q8: JP10646 | R8: JP10646 | S8: JP10646 | T8: JP10791 | U8: JP10646 | V8: JP10646 | W8: JP10646 | X8: JP10646 | Y8: JP10791 | Z8: JP10791 | AA8: JP10646 | AB8: JP10646 | AC8: JP10646 | AD8: JP10646 | AE8: JP10646 | AF8: JP10646 | AG8: JP10646 | AH8: JP10646 | AI8: JP10646 | AJ8: JP10646 | AK8: JP10646 | AL8: JP10646 | AM8: JP10646 | AN8: JP10646
B9: BIST | C9: 822 | D9: 0.0302 | N9: Yield | O9: 0.7887 | P9: 0.8231 | Q9: 0.825 | R9: 0.826 | S9: 0.8279 | T9: 0.8308 | U9: 0.8394 | V9: 0.8442 | W9: 0.8547 | X9: 0.8547 | Y9: 0.8576 | Z9: 0.8585 | AA9: 0.8595 | AB9: 0.8604 | AC9: 0.8623 | AD9: 0.8623 | AE9: 0.8662 | AF9: 0.8671 | AG9: 0.8681 | AH9: 0.8681 | AI9: 0.8719 | AJ9: 0.8728 | AK9: 0.8767 | AL9: 0.8795 | AM9: 0.8862 | AN9: 0.8881
B10: SCAN | C10: 2724 | D10: 0.1002 | N10: CP | O10: CP1 | P10: CP1 | Q10: CP1 | R10: CP1 | S10: CP1 | T10: CP1 | U10: CP1 | V10: CP1 | W10: CP1 | X10: CP1 | Y10: CP1 | Z10: CP1 | AA10: CP1 | AB10: CP1 | AC10: CP1 | AD10: CP1 | AE10: CP1 | AF10: CP1 | AG10: CP1 | AH10: CP1 | AI10: CP1 | AJ10: CP1 | AK10: CP1 | AL10: CP1 | AM10: CP1 | AN10: CP1
B11: OTHER | C11: 20 | D11: 0.0007 | N11: Starttime | O11: 2026-02-18 10:35:22 | P11: 2026-02-21 17:34:41 | Q11: 2026-02-20 09:28:11 | R11: 2026-02-20 21:03:29 | S11: 2026-02-18 22:20:38 | T11: 2026-02-22 13:07:43 | U11: 2026-02-19 15:50:31 | V11: 2026-02-19 21:35:02 | W11: 2026-02-16 11:43:59 | X11: 2026-02-19 09:57:47 | Y11: 2026-02-22 07:20:27 | Z11: 2026-02-22 01:29:01 | AA11: 2026-02-15 23:52:50 | AB11: 2026-02-17 22:43:10 | AC11: 2026-02-17 11:05:12 | AD11: 2026-02-19 04:10:08 | AE11: 2026-02-16 23:22:55 | AF11: 2026-02-21 02:52:34 | AG11: 2026-02-16 17:29:38 | AH11: 2026-02-20 03:32:36 | AI11: 2026-02-20 15:13:21 | AJ11: 2026-02-18 16:24:44 | AK11: 2026-02-18 04:34:02 | AL11: 2026-02-17 16:52:32 | AM11: 2026-02-16 05:43:38 | AN11: 2026-02-17 05:12:23
B12: POR | C12: 1 | D12: 0 | N12: Endtime | O12: 2026-02-18 16:22:16 | P12: 2026-02-22 01:26:34 | Q12: 2026-02-20 15:10:53 | R12: 2026-02-21 02:50:05 | S12: 2026-02-19 04:07:39 | T12: 2026-02-22 19:06:44 | U12: 2026-02-19 21:32:36 | V12: 2026-02-20 03:30:09 | W12: 2026-02-16 17:27:07 | X12: 2026-02-19 15:48:04 | Y12: 2026-02-22 13:05:16 | Z12: 2026-02-22 07:17:51 | AA12: 2026-02-16 05:41:07 | AB12: 2026-02-18 04:31:38 | AC12: 2026-02-17 16:50:06 | AD12: 2026-02-19 09:55:18 | AE12: 2026-02-17 05:09:55 | AF12: 2026-02-21 08:40:21 | AG12: 2026-02-16 23:20:27 | AH12: 2026-02-20 09:25:41 | AI12: 2026-02-20 21:01:02 | AJ12: 2026-02-18 22:18:03 | AK12: 2026-02-18 10:24:08 | AL12: 2026-02-17 22:40:40 | AM12: 2026-02-16 11:41:30 | AN12: 2026-02-17 11:02:42
A13: 1 | B13: PASS BIN | C13: 23242 | D13: 0.8546 | E13: PASS BIN | N13: Week | O13: 202608 | P13: 202608 | Q13: 202608 | R13: 202608 | S13: 202608 | T13: 202608 | U13: 202608 | V13: 202608 | W13: 202608 | X13: 202608 | Y13: 202608 | Z13: 202608 | AA13: 202608 | AB13: 202608 | AC13: 202608 | AD13: 202608 | AE13: 202608 | AF13: 202608 | AG13: 202608 | AH13: 202608 | AI13: 202608 | AJ13: 202608 | AK13: 202608 | AL13: 202608 | AM13: 202608 | AN13: 202608
B14: BIN1 | C14: 23242 | D14: 0.8546 | E14: PASS BIN | N14: Month | O14: 2026-02 | P14: 2026-02 | Q14: 2026-02 | R14: 2026-02 | S14: 2026-02 | T14: 2026-02 | U14: 2026-02 | V14: 2026-02 | W14: 2026-02 | X14: 2026-02 | Y14: 2026-02 | Z14: 2026-02 | AA14: 2026-02 | AB14: 2026-02 | AC14: 2026-02 | AD14: 2026-02 | AE14: 2026-02 | AF14: 2026-02 | AG14: 2026-02 | AH14: 2026-02 | AI14: 2026-02 | AJ14: 2026-02 | AK14: 2026-02 | AL14: 2026-02 | AM14: 2026-02 | AN14: 2026-02
B15: IDD | C15: 105 | D15: 0.0039 | E15: IDD | N15: Program | O15: RL7032_TA01 | P15: RL7032_TA01 | Q15: RL7032_TA01 | R15: RL7032_TA01 | S15: RL7032_TA01 | T15: RL7032_TA01 | U15: RL7032_TA01 | V15: RL7032_TA01 | W15: RL7032_TA01 | X15: RL7032_TA01 | Y15: RL7032_TA01 | Z15: RL7032_TA01 | AA15: RL7032_TA01 | AB15: RL7032_TA01 | AC15: RL7032_TA01 | AD15: RL7032_TA01 | AE15: RL7032_TA01 | AF15: RL7032_TA01 | AG15: RL7032_TA01 | AH15: RL7032_TA01 | AI15: RL7032_TA01 | AJ15: RL7032_TA01 | AK15: RL7032_TA01 | AL15: RL7032_TA01 | AM15: RL7032_TA01 | AN15: RL7032_TA01
B16: OS | C16: 157 | D16: 0.0058 | E16: OS | N16: Version(ECN) | O16: RL7032_TA01_V02 | P16: RL7032_TA01_V02 | Q16: RL7032_TA01_V02 | R16: RL7032_TA01_V02 | S16: RL7032_TA01_V02 | T16: RL7032_TA01_V02 | U16: RL7032_TA01_V02 | V16: RL7032_TA01_V02 | W16: RL7032_TA01_V02 | X16: RL7032_TA01_V02 | Y16: RL7032_TA01_V02 | Z16: RL7032_TA01_V02 | AA16: RL7032_TA01_V02 | AB16: RL7032_TA01_V02 | AC16: RL7032_TA01_V02 | AD16: RL7032_TA01_V02 | AE16: RL7032_TA01_V02 | AF16: RL7032_TA01_V02 | AG16: RL7032_TA01_V02 | AH16: RL7032_TA01_V02 | AI16: RL7032_TA01_V02 | AJ16: RL7032_TA01_V02 | AK16: RL7032_TA01_V02 | AL16: RL7032_TA01_V02 | AM16: RL7032_TA01_V02 | AN16: RL7032_TA01_V02
B17: OTP | C17: 92 | D17: 0.0034 | E17: OTP | N17: Pass Die | O17: 825 | P17: 861 | Q17: 863 | R17: 864 | S17: 866 | T17: 869 | U17: 878 | V17: 883 | W17: 894 | X17: 894 | Y17: 897 | Z17: 898 | AA17: 899 | AB17: 900 | AC17: 902 | AD17: 902 | AE17: 906 | AF17: 907 | AG17: 908 | AH17: 908 | AI17: 912 | AJ17: 913 | AK17: 917 | AL17: 920 | AM17: 927 | AN17: 929
B18: HDMI | C18: 20 | D18: 0.0007 | E18: SD | N18: Total Die | O18: 1046 | P18: 1046 | Q18: 1046 | R18: 1046 | S18: 1046 | T18: 1046 | U18: 1046 | V18: 1046 | W18: 1046 | X18: 1046 | Y18: 1046 | Z18: 1046 | AA18: 1046 | AB18: 1046 | AC18: 1046 | AD18: 1046 | AE18: 1046 | AF18: 1046 | AG18: 1046 | AH18: 1046 | AI18: 1046 | AJ18: 1046 | AK18: 1046 | AL18: 1046 | AM18: 1046 | AN18: 1046
B19: PLL | C19: 2 | D19: 0.0001 | E19: SD | I19: PASS BIN | M19: 0.84970347 | N19: 1.6994069 | O19: 0.78871893 | P19: 0.82313576 | Q19: 0.8250478 | R19: 0.82600382 | S19: 0.82791587 | T19: 0.83078394 | U19: 0.83938815 | V19: 0.84416826 | W19: 0.85468451 | X19: 0.85468451 | Y19: 0.85755258 | Z19: 0.8585086 | AA19: 0.85946463 | AB19: 0.86042065 | AC19: 0.8623327 | AD19: 0.8623327 | AE19: 0.86615679 | AF19: 0.86711281 | AG19: 0.86806883 | AH19: 0.86806883 | AI19: 0.87189293 | AJ19: 0.87284895 | AK19: 0.87667304 | AL19: 0.87954111 | AM19: 0.88623327 | AN19: 0.88814532
B20: VDC | C20: 0 | D20: 0 | E20: SD | I20: IDD | M20: 0.00458703 | N20: 0.00917406 | O20: 0.00764818 | P20: 0.00764818 | Q20: 0.00382409 | R20: 0.00573614 | S20: 0.00478011 | T20: 0.00573614 | U20: 0.00573614 | V20: 0.00382409 | W20: 0 | X20: 0.00669216 | Y20: 0.00095602 | Z20: 0.00669216 | AA20: 0.00286807 | AB20: 0.00669216 | AC20: 0.00191205 | AD20: 0.00286807 | AE20: 0 | AF20: 0.00095602 | AG20: 0.00191205 | AH20: 0.00095602 | AI20: 0.00191205 | AJ20: 0.00478011 | AK20: 0.00573614 | AL20: 0.00478011 | AM20: 0.00095602 | AN20: 0.00478011
B21: USB | C21: 0 | D21: 0 | E21: SD | I21: OS | M21: 0.00802021 | N21: 0.01604042 | O21: 0.00573614 | P21: 0.00764818 | Q21: 0.00573614 | R21: 0.01051625 | S21: 0.00669216 | T21: 0.00478011 | U21: 0.00382409 | V21: 0.00764818 | W21: 0.00764818 | X21: 0.00478011 | Y21: 0.00382409 | Z21: 0.00095602 | AA21: 0.00573614 | AB21: 0.00764818 | AC21: 0.00764818 | AD21: 0.00382409 | AE21: 0.00382409 | AF21: 0.00669216 | AG21: 0.00669216 | AH21: 0.00669216 | AI21: 0.00478011 | AJ21: 0.00764818 | AK21: 0.00286807 | AL21: 0.00191205 | AM21: 0.00573614 | AN21: 0.00860421
B22: ADC | C22: 0 | D22: 0 | E22: SD | I22: OTP | M22: 0.00435582 | N22: 0.00871164 | O22: 0.01051625 | P22: 0.0124283 | Q22: 0.01147228 | R22: 0.00669216 | S22: 0.00669216 | T22: 0.00191205 | U22: 0.00191205 | V22: 0.02007648 | W22: 0 | X22: 0.00382409 | Y22: 0 | Z22: 0.00286807 | AA22: 0 | AB22: 0.00191205 | AC22: 0 | AD22: 0 | AE22: 0 | AF22: 0.00191205 | AG22: 0.00095602 | AH22: 0 | AI22: 0 | AJ22: 0.00095602 | AK22: 0 | AL22: 0.00095602 | AM22: 0.00095602 | AN22: 0.00191205
B23: PIF | C23: 3 | D23: 0.0001 | E23: SD | I23: HDMI | M23: 0.00088992 | N23: 0.00177984 | O23: 0.00191205 | P23: 0 | Q23: 0 | R23: 0.00191205 | S23: 0.00382409 | T23: 0.00095602 | U23: 0 | V23: 0.00478011 | W23: 0 | X23: 0.00191205 | Y23: 0 | Z23: 0.00095602 | AA23: 0 | AB23: 0.00095602 | AC23: 0 | AD23: 0 | AE23: 0 | AF23: 0 | AG23: 0 | AH23: 0 | AI23: 0 | AJ23: 0.00095602 | AK23: 0.00095602 | AL23: 0 | AM23: 0 | AN23: 0
B24: TCON | C24: 0 | D24: 0 | E24: SD | I24: PLL | M24: 5.017e-05 | N24: 0.00010034 | O24: 0 | P24: 0 | Q24: 0 | R24: 0 | S24: 0 | T24: 0 | U24: 0 | V24: 0 | W24: 0 | X24: 0 | Y24: 0 | Z24: 0 | AA24: 0 | AB24: 0.00095602 | AC24: 0 | AD24: 0 | AE24: 0 | AF24: 0 | AG24: 0 | AH24: 0 | AI24: 0 | AJ24: 0 | AK24: 0 | AL24: 0 | AM24: 0 | AN24: 0.00095602
B25: LDO | C25: 0 | D25: 0 | E25: SD | I25: VDC | M25: 3.054e-05 | N25: 6.108e-05 | O25: 0 | P25: 0 | Q25: 0 | R25: 0 | S25: 0 | T25: 0 | U25: 0 | V25: 0 | W25: 0 | X25: 0 | Y25: 0 | Z25: 0 | AA25: 0 | AB25: 0 | AC25: 0 | AD25: 0 | AE25: 0 | AF25: 0 | AG25: 0 | AH25: 0 | AI25: 0 | AJ25: 0 | AK25: 0 | AL25: 0 | AM25: 0 | AN25: 0
B26: SARADC | C26: 0 | D26: 0 | E26: SD | I26: USB | M26: 2.181e-05 | N26: 4.362e-05 | O26: 0 | P26: 0 | Q26: 0 | R26: 0 | S26: 0 | T26: 0 | U26: 0 | V26: 0 | W26: 0 | X26: 0 | Y26: 0 | Z26: 0 | AA26: 0 | AB26: 0 | AC26: 0 | AD26: 0 | AE26: 0 | AF26: 0 | AG26: 0 | AH26: 0 | AI26: 0 | AJ26: 0 | AK26: 0 | AL26: 0 | AM26: 0 | AN26: 0
B27: SD_OTHER | C27: 2 | D27: 0.0001 | E27: SD | I27: ADC | M27: 2.18e-06 | N27: 4.36e-06 | O27: 0 | P27: 0 | Q27: 0 | R27: 0 | S27: 0 | T27: 0 | U27: 0 | V27: 0 | W27: 0 | X27: 0 | Y27: 0 | Z27: 0 | AA27: 0 | AB27: 0 | AC27: 0 | AD27: 0 | AE27: 0 | AF27: 0 | AG27: 0 | AH27: 0 | AI27: 0 | AJ27: 0 | AK27: 0 | AL27: 0 | AM27: 0 | AN27: 0
B28: GPIO | C28: 1 | D28: 0 | E28: SD | I28: PIF | M28: 6.544e-05 | N28: 0.00013088 | O28: 0.00095602 | P28: 0 | Q28: 0 | R28: 0 | S28: 0 | T28: 0 | U28: 0 | V28: 0 | W28: 0 | X28: 0 | Y28: 0 | Z28: 0.00191205 | AA28: 0 | AB28: 0 | AC28: 0 | AD28: 0 | AE28: 0 | AF28: 0 | AG28: 0 | AH28: 0 | AI28: 0 | AJ28: 0 | AK28: 0 | AL28: 0 | AM28: 0 | AN28: 0
B29: ETN | C29: 0 | D29: 0 | E29: SD | I29: TCON | M29: 2.18e-06 | N29: 4.36e-06 | O29: 0 | P29: 0 | Q29: 0 | R29: 0 | S29: 0 | T29: 0 | U29: 0 | V29: 0 | W29: 0 | X29: 0 | Y29: 0 | Z29: 0 | AA29: 0 | AB29: 0 | AC29: 0 | AD29: 0 | AE29: 0 | AF29: 0 | AG29: 0 | AH29: 0 | AI29: 0 | AJ29: 0 | AK29: 0 | AL29: 0 | AM29: 0 | AN29: 0
B30: EARC | C30: 0 | D30: 0 | E30: SD | I30: LDO | M30: 8.72e-06 | N30: 1.744e-05 | O30: 0 | P30: 0 | Q30: 0 | R30: 0 | S30: 0 | T30: 0 | U30: 0 | V30: 0 | W30: 0 | X30: 0 | Y30: 0 | Z30: 0 | AA30: 0 | AB30: 0 | AC30: 0 | AD30: 0 | AE30: 0 | AF30: 0 | AG30: 0 | AH30: 0 | AI30: 0 | AJ30: 0 | AK30: 0 | AL30: 0 | AM30: 0 | AN30: 0
... B44: POR | C44: 1 | D44: 0 | E44: POR | I44: SAF | M44: 0.08249231 | N44: 0.16498462 | O44: 0.1166348 | P44: 0.09560229 | Q44: 0.09751434 | R44: 0.07743786 | S44: 0.10133843 | T44: 0.10038241 | U44: 0.09655832 | V44: 0.07170172 | W44: 0.09560229 | X44: 0.06022945 | Y44: 0.08413002 | Z44: 0.07361377 | AA44: 0.09369025 | AB44: 0.07552581 | AC44: 0.08508604 | AD44: 0.08699809 | AE44: 0.09369025 | AF44: 0.0793499 | AG44: 0.08413002 | AH44: 0.07839388 | AI44: 0.07265774 | AJ44: 0.06118547 | AK44: 0.08221797 | AL44: 0.07839388 | AM44: 0.07456979 | AN44: 0.06118547
I45: SDD_LV | M45: 0.0022488 | N45: 0.0044976 | O45: 0.00191205 | P45: 0.00095602 | Q45: 0.00095602 | R45: 0.00095602 | S45: 0.00191205 | T45: 0.00286807 | U45: 0.00191205 | V45: 0.00191205 | W45: 0.00095602 | X45: 0.00095602 | Y45: 0.00382409 | Z45: 0.00191205 | AA45: 0 | AB45: 0.00095602 | AC45: 0.00095602 | AD45: 0.00382409 | AE45: 0.00191205 | AF45: 0.00286807 | AG45: 0 | AH45: 0.00191205 | AI45: 0.00095602 | AJ45: 0.00095602 | AK45: 0.00286807 | AL45: 0.00095602 | AM45: 0 | AN45: 0.00286807
I46: TDF_HV | M46: 0.00791987 | N46: 0.01583974 | O46: 0.00956023 | P46: 0.01434034 | Q46: 0.00573614 | R46: 0.02963671 | S46: 0.01338432 | T46: 0.01434034 | U46: 0.00669216 | V46: 0.01816444 | W46: 0.00669216 | X46: 0.01051625 | Y46: 0.01051625 | Z46: 0.00956023 | AA46: 0.00095602 | AB46: 0.00382409 | AC46: 0.00956023 | AD46: 0.01147228 | AE46: 0.00286807 | AF46: 0.00764818 | AG46: 0.00382409 | AH46: 0.01051625 | AI46: 0.00956023 | AJ46: 0.00860421 | AK46: 0.00669216 | AL46: 0.00286807 | AM46: 0.00191205 | AN46: 0.00382409
I47: BF | M47: 0.0015072 | N47: 0.0030144 | O47: 0.00095602 | P47: 0.00286807 | Q47: 0.00095602 | R47: 0 | S47: 0 | T47: 0 | U47: 0.00095602 | V47: 0.00286807 | W47: 0.00095602 | X47: 0.00095602 | Y47: 0 | Z47: 0.00286807 | AA47: 0 | AB47: 0 | AC47: 0.00286807 | AD47: 0.00191205 | AE47: 0.00191205 | AF47: 0 | AG47: 0 | AH47: 0 | AI47: 0.00095602 | AJ47: 0 | AK47: 0.00095602 | AL47: 0 | AM47: 0.00095602 | AN47: 0
I48: OTHER | M48: 0.00066308 | N48: 0.00132616 | O48: 0.00191205 | P48: 0.00095602 | Q48: 0 | R48: 0 | S48: 0.00095602 | T48: 0 | U48: 0.00095602 | V48: 0 | W48: 0 | X48: 0.00095602 | Y48: 0.00191205 | Z48: 0.00191205 | AA48: 0.00095602 | AB48: 0 | AC48: 0.00095602 | AD48: 0.00286807 | AE48: 0.00095602 | AF48: 0.00095602 | AG48: 0 | AH48: 0 | AI48: 0 | AJ48: 0 | AK48: 0.00095602 | AL48: 0.00191205 | AM48: 0 | AN48: 0
I49: POR | M49: 8.507e-05 | N49: 0.00017014 | O49: 0 | P49: 0 | Q49: 0 | R49: 0 | S49: 0 | T49: 0 | U49: 0 | V49: 0 | W49: 0 | X49: 0 | Y49: 0.00095602 | Z49: 0 | AA49: 0 | AB49: 0 | AC49: 0 | AD49: 0 | AE49: 0 | AF49: 0 | AG49: 0 | AH49: 0 | AI49: 0 | AJ49: 0 | AK49: 0 | AL49: 0 | AM49: 0 | AN49: 0
A50: 2026-02-16-2026-02-22 | J50: 26
