Workbook

Sheet Summary_RTD
A1: 20250922~20250928 | B1: CP/FT | C1: Total IC | D1: Throughput | E1: Yield | G1: 20250922~20250928 | H1: CP/FT | I1: RTD No. | K1: Total IC | L1: Throughput | M1: Yield
A2: RL7032 Merlin8p | B2: CP | C2: 0 | D2: 0 | G2: RL7032 Merlin8p | H2: CP | I2: RL7032 | K2: 0 | L2: 0
A3: RL6982 Merlin9 | B3: CP | C3: 295935 | D3: 267118 | E3: 0.9026 | G3: RL6982 Merlin9 | H3: CP | I3: RL6982 | K3: 295935 | L3: 267118 | M3: 0.9026
B4: FT1 | C4: 193597 | D4: 192750 | E4: 0.9956 | H4: FT1 | I4: RTD2875QPA_TA01 | K4: 2661 | L4: 2632 | M4: 0.9891
A5: RL6963 Mac8q | B5: CP | C5: 125796 | D5: 114328 | E5: 0.9088 | I5: RTD2874MDA_TA01 | K5: 9643 | L5: 9600 | M5: 0.9955
B6: FT1 | C6: 101850 | D6: 101079 | E6: 0.9924 | I6: RTD2875QDA_HD_TA01 | K6: 95777 | L6: 95359 | M6: 0.9956
B7: FT2 | C7: 42266 | D7: 42257 | E7: 0.9998 | I7: RTD2875QDA_TA01 | K7: 83613 | L7: 83264 | M7: 0.9958
A8: RL6896 Dante | B8: CP | C8: 0 | D8: 0 | I8: RTD2875QPA_HD_TA01 | K8: 1903 | L8: 1895 | M8: 0.9958
B9: FT1 | C9: 5164 | D9: 5121 | E9: 0.9917 | G9: RL6963 Mac8q | H9: CP | I9: RL6963 | K9: 125796 | L9: 114328 | M9: 0.9088
A10: RL6866 Mac8p | B10: CP | C10: 0 | D10: 0 | H10: FT1 | I10: RTD2864FLV_TA01 | K10: 32765 | L10: 32510 | M10: 0.9922
A11: RL6856 Merlin8 | B11: CP | C11: 64752 | D11: 55618 | E11: 0.8589 | I11: RTD2851FCA_TA01 | K11: 8716 | L11: 8695 | M11: 0.9976
B12: FT1 | C12: 114820 | D12: 114308 | E12: 0.9955 | I12: RTD2841FLW_TA01 | K12: 60369 | L12: 59874 | M12: 0.9918
B13: FT2 | C13: 70225 | D13: 70122 | E13: 0.9985 | H13: FT2 | I13: RTD2841FLW_TA01 | K13: 36262 | L13: 36260 | M13: 0.9999
A14: RL6750 H5C2 | B14: CP | C14: 40050 | D14: 31586 | E14: 0.7887 | I14: RTD2816AWA_TA01 | K14: 6004 | L14: 5997 | M14: 0.9988
A15: RL6748 Merlin7 | B15: CP | C15: 69422 | D15: 60832 | E15: 0.8763 | G15: RL6896 Dante | H15: CP | I15: RL6896 | K15: 0 | L15: 0
B16: FT1 | C16: 155992 | D16: 155532 | E16: 0.9971 | H16: FT1 | I16: AXD2801VPF | K16: 1735 | L16: 1696 | M16: 0.9775
B17: FT2 | C17: 0 | D17: 0 | I17: AXD2801SPH | K17: 3429 | L17: 3425 | M17: 0.9988
A18: RL6746 MIO | B18: CP | C18: 0 | D18: 0 | G18: RL6866 Mac8p | H18: CP | I18: RL6866 | K18: 0 | L18: 0
A19: RL6708 Bridge | B19: CP | C19: 0 | D19: 0 | G19: RL6856 Merlin8 | H19: CP | I19: RL6856 | K19: 64752 | L19: 55618 | M19: 0.8589
B20: FT1 | C20: 0 | D20: 0 | H20: FT1 | I20: RTD2885PDM_FT1_TA01 | K20: 69291 | L20: 68928 | M20: 0.9948
A21: RL6681 ATSC3 | B21: CP | C21: 0 | D21: 0 | I21: RTD2886NSS_SC_FT1_TA01 | K21: 45529 | L21: 45380 | M21: 0.9967
B22: FT1 | C22: 0 | D22: 0 | H22: FT2 | I22: RTD2885PDM | K22: 12907 | L22: 12905 | M22: 0.9998
A23: RL6672 Merlin6 | B23: CP | C23: 0 | D23: 0 | I23: RTD2886NSP_SC_FT2_TA01 | K23: 57318 | L23: 57217 | M23: 0.9982
B24: FT1 | C24: 0 | D24: 0 | G24: RL6750 H5C2 | H24: CP | I24: RL6750 | K24: 40050 | L24: 31586 | M24: 0.7887
B25: FT2 | C25: 0 | D25: 0 | G25: RL6748 Merlin7 | H25: CP | I25: RL6748 | K25: 69422 | L25: 60832 | M25: 0.8763
A26: RL6641 Mac7p | B26: CP | C26: 140342 | D26: 124456 | E26: 0.8868 | H26: FT1 | I26: RTD2875PNJ_SND_TA01 | K26: 40904 | L26: 40892 | M26: 0.9997
B27: FT1 | C27: 0 | D27: 0 | I27: RTD2875NAA_SC_TA01 | K27: 8544 | L27: 8524 | M27: 0.9977
A28: RL6617 Merlin5 | B28: CP | C28: 0 | D28: 0 | I28: RTD2881PSP_SDY_TA01 | K28: 14259 | L28: 14085 | M28: 0.9878
B29: FT1 | C29: 0 | D29: 0 | I29: RTD2875NDB_LC_TA01 | K29: 774 | L29: 771 | M29: 0.9961
B30: FT2 | C30: 0 | D30: 0 | I30: RTD2885NDM_HLC | J30: 4K120 without ATSC C版（OTP燒錄與RTD2885NDM-HSB-CC同 | K30: 1657 | L30: 1639 | M30: 0.9891
I31: RTD2875PSP_SC_TA01 | K31: 89038 | L31: 88821 | M31: 0.9976
I32: RTD2885NCH_WC_TA01 | K32: 816 | L32: 800 | M32: 0.9804
G33: RL6746 MIO | H33: CP | I33: RL6746 | K33: 0 | L33: 0
G34: RL6708 Bridge | H34: CP | I34: RL6708 | K34: 0 | L34: 0
G35: RL6681 ATSC3 | H35: CP | I35: RL6681 | K35: 0 | L35: 0
G36: RL6672 Merlin6 | H36: CP | I36: RL6672 | K36: 0 | L36: 0
G37: RL6641 Mac7p | H37: CP | I37: RL6641 | K37: 140342 | L37: 124456 | M37: 0.8868
G38: RL6617 Merlin5 | H38: CP | I38: RL6617 | K38: 0 | L38: 0

Sheet Top_all
A1: Project | B1: CP/FT | C1: RTD No. | E1: ECN Ver. | G1: summary | H1: Y25_W39 | J1: Top1 | K1: Top2 | L1: Top3 | M1: Top4 | N1: Top5 | O1: Top6 | P1: Top7 | Q1: Top8 | R1: Top9 | S1: Top10 | Y1: Project | Z1: CP/FT | AA1: RTD No. | AC1: ECN Ver. | AD1: Total IC | AE1: Throughput | AF1: Yield | AG1: Top1 | AH1: Top2 | AI1: Top3 | AJ1: Top4 | AK1: Top5 | AL1: Top6 | AM1: Top7 | AN1: Top8 | AO1: Top9 | AP1: Top10
A2: RL6982 Merlin9 | B2: CP | C2: RL6982 | E2: V03 | F2: Total IC | G2: 295935 | H2: 295935 | I2: Test item | J2: cp_mode2_saf_spc30_comp | K2: cp_mode3_saf_comp | L2: all_bist_wo_ETN_HV | M2: cp_mode1_saf_comp | N2: cp_mode0_saf_comp | O2: SCPU_L3_BISR_HV | P2: scpu_bist_all_1p2_HV | Q2: all_bisr_drf_mp_BISR_HV | R2: PowerShort | S2: cp_mode3_tdf_c5_cov92_comp_HV | Y2: RL6982 Merlin9 | Z2: CP | AA2: RL6982 | AC2: V03 | AD2: 295935 | AE2: 267118 | AF2: 0.9026 | AG2: cp_mode2_saf_spc30_comp(7191ea,2.43%) | AH2: cp_mode3_saf_comp(4610ea,1.56%) | AI2: all_bist_wo_ETN_HV(4130ea,1.40%) | AJ2: cp_mode1_saf_comp(2568ea,0.87%) | AK2: cp_mode0_saf_comp(2349ea,0.79%) | AL2: SCPU_L3_BISR_HV(1145ea,0.39%) | AM2: scpu_bist_all_1p2_HV(790ea,0.27%) | AN2: all_bisr_drf_mp_BISR_HV(647ea,0.22%) | AO2: PowerShort(604ea,0.20%) | AP2: cp_mode3_tdf_c5_cov92_comp_HV(432ea,0.15%)
F3: Throughput | G3: 267118 | H3: 267118 | I3: q'ty | J3: 7191 | K3: 4610 | L3: 4130 | M3: 2568 | N3: 2349 | O3: 1145 | P3: 790 | Q3: 647 | R3: 604 | S3: 432 | Z3: FT1 | AA3: RTD2875QPA_TA01 | AC3: V03 | AD3: 2661 | AE3: 2632 | AF3: 0.9891 | AG3: DDR4_2G_3000_SS_FRC_ZQp5p(26ea,0.98%) | AH3: USB2_disconnect_trim_RT(1ea,0.04%) | AI3: FW_other(1ea,0.04%) | AJ3: USB2_FT_Z0(1ea,0.04%)
F4: Yield | G4: 0.9026 | H4: 0.9026 | I4: % | J4: 0.0243 | K4: 0.0156 | L4: 0.014 | M4: 0.0087 | N4: 0.0079 | O4: 0.0039 | P4: 0.0027 | Q4: 0.0022 | R4: 0.002 | S4: 0.0015 | Z4: FT1 | AA4: RTD2874MDA_TA01 | AC4: V03 | AD4: 9643 | AE4: 9600 | AF4: 0.9955 | AG4: DDR4_2G_3000_SS_single_RW_FT(13ea,0.13%) | AH4: FW_other(10ea,0.10%) | AI4: DDR4_2G_3000_SS_FRC_ZQp5p(6ea,0.06%) | AJ4: HDMI20_5p94G_mm(2ea,0.02%) | AK4: OS_500uA(2ea,0.02%) | AL4: FW_MULTI_CORE_TEST(1ea,0.01%) | AM4: FW_VE(1ea,0.01%) | AN4: all_bisr_drf(1ea,0.01%) | AO4: PowerShort(1ea,0.01%) | AP4: FW_SCPU(1ea,0.01%)
B5: FT1 | C5: RTD2875QPA_TA01 | E5: V03 | F5: Total IC | G5: 2661 | H5: 2661 | I5: Test item | J5: DDR4_2G_3000_SS_FRC_ZQp5p | K5: USB2_disconnect_trim_RT | L5: FW_other | M5: USB2_FT_Z0 | Z5: FT1 | AA5: RTD2875QDA_HD_TA01 | AC5: V03 | AD5: 95777 | AE5: 95359 | AF5: 0.9956 | AG5: DDR4_2G_3000_SS_FRC_ZQp5p(83ea,0.09%) | AH5: FW_other(76ea,0.08%) | AI5: OS_500uA(70ea,0.07%) | AJ5: DDR4_2G_3000_SS_single_RW_FT(67ea,0.07%) | AK5: PowerShort(28ea,0.03%) | AL5: Wire_Bond_Leak(21ea,0.02%) | AM5: IDDQ(13ea,0.01%) | AN5: FW_MULTI_CORE_TEST(7ea,0.01%) | AO5: FW_VE(7ea,0.01%) | AP5: scpu_bisr_bist_drf(5ea,0.01%)
F6: Throughput | G6: 2632 | H6: 2632 | I6: q'ty | J6: 26 | K6: 1 | L6: 1 | M6: 1 | Z6: FT1 | AA6: RTD2875QDA_TA01 | AC6: V03 | AD6: 83613 | AE6: 83264 | AF6: 0.9958 | AG6: DDR4_2G_3000_SS_single_RW_FT(69ea,0.08%) | AH6: DDR4_2G_3000_SS_FRC_ZQp5p(67ea,0.08%) | AI6: FW_other(64ea,0.08%) | AJ6: OS_500uA(34ea,0.04%) | AK6: USB2_disconnect_mea(30ea,0.04%) | AL6: PowerShort(13ea,0.02%) | AM6: Wire_Bond_Leak(12ea,0.01%) | AN6: chip_id_HRAM(5ea,0.01%) | AO6: scpu_bist_all_1p2_HV(5ea,0.01%) | AP6: ETN_TX_MDI(4ea,0.00%)
F7: Yield | G7: 0.9891 | H7: 0.9891 | I7: % | J7: 0.0098 | K7: 0.0004 | L7: 0.0004 | M7: 0.0004 | Z7: FT1 | AA7: RTD2875QPA_HD_TA01 | AC7: V03 | AD7: 1903 | AE7: 1895 | AF7: 0.9958 | AG7: DDR4_2G_3000_SS_FRC_ZQp5p(3ea,0.16%) | AH7: DDR4_2G_3000_SS_single_RW_FT(2ea,0.11%) | AI7: FW_other(2ea,0.11%) | AJ7: OS_500uA(1ea,0.05%)
B8: FT1 | C8: RTD2874MDA_TA01 | E8: V03 | F8: Total IC | G8: 9643 | H8: 9643 | I8: Test item | J8: DDR4_2G_3000_SS_single_RW_FT | K8: FW_other | L8: DDR4_2G_3000_SS_FRC_ZQp5p | M8: HDMI20_5p94G_mm | N8: OS_500uA | O8: FW_MULTI_CORE_TEST | P8: FW_VE | Q8: all_bisr_drf | R8: PowerShort | S8: FW_SCPU | Y8: RL6963 Mac8q | Z8: CP | AA8: RL6963 | AC8: V07 | AD8: 125796 | AE8: 114328 | AF8: 0.9088 | AG8: cp_mode1_saf_comp_B(2924ea,2.32%) | AH8: cp_mode0_saf_comp(1501ea,1.19%) | AI8: cp_mode2_saf_comp_B(1418ea,1.13%) | AJ8: all_bist_m_0217_p1_BIST_LDOoff_OC700_HV(1206ea,0.96%) | AK8: IDD(924ea,0.73%) | AL8: PowerShort(386ea,0.31%) | AM8: os(379ea,0.30%) | AN8: cp_mode1_tdf_cov70_comp_HV(344ea,0.27%) | AO8: GPIO_01_GPOH(201ea,0.16%) | AP8: all_bist_m_0217_p2_GPU_BIST_LDOoff_HV(142ea,0.11%)
F9: Throughput | G9: 9600 | H9: 9600 | I9: q'ty | J9: 13 | K9: 10 | L9: 6 | M9: 2 | N9: 2 | O9: 1 | P9: 1 | Q9: 1 | R9: 1 | S9: 1 | Z9: FT1 | AA9: RTD2864FLV_TA01 | AC9: V10 | AD9: 32765 | AE9: 32510 | AF9: 0.9922 | AG9: FW_other(104ea,0.32%) | AH9: D4_2666M_FRC_4K60_uhd_LB_FT(41ea,0.13%) | AI9: os(38ea,0.12%) | AJ9: FW_HDMI_4K60(22ea,0.07%) | AK9: ETN_MLT3(7ea,0.02%) | AL9: OTP_cust_PD_and_BMC_burn(6ea,0.02%) | AM9: all_bist_m_0217_p1_BIST_LDOon_HV(5ea,0.02%) | AN9: all_bist_m_0217_p5_scpu_bist_LDOon_HV(4ea,0.01%) | AO9: PIF_LVDS_FT(3ea,0.01%) | AP9: OTP_Apple_Mfi_key_Demeter(3ea,0.01%)
F10: Yield | G10: 0.9955 | H10: 0.9955 | I10: % | J10: 0.0013 | K10: 0.001 | L10: 0.0006 | M10: 0.0002 | N10: 0.0002 | O10: 0.0001 | P10: 0.0001 | Q10: 0.0001 | R10: 0.0001 | S10: 0.0001 | Z10: FT1 | AA10: RTD2851FCA_TA01 | AC10: V10 | AD10: 8716 | AE10: 8695 | AF10: 0.9976 | AG10: os(6ea,0.07%) | AH10: FW_HDMI_4K60(4ea,0.05%) | AI10: FW_other(3ea,0.03%) | AJ10: power_short(2ea,0.02%) | AK10: D4_2666M_FRC_4K60_uhd_LB_FT(2ea,0.02%) | AL10: FW_Multi_core_test_1(1ea,0.01%) | AM10: all_bist_m_0217_p5_scpu_bist_LDOon_HV(1ea,0.01%) | AN10: EARC_FT_03_CPFT(1ea,0.01%) | AO10: all_bist_m_0217_p1_BIST_LDOon_HV(1ea,0.01%)
B11: FT1 | C11: RTD2875QDA_HD_TA01 | E11: V03 | F11: Total IC | G11: 95777 | H11: 95777 | I11: Test item | J11: DDR4_2G_3000_SS_FRC_ZQp5p | K11: FW_other | L11: OS_500uA | M11: DDR4_2G_3000_SS_single_RW_FT | N11: PowerShort | O11: Wire_Bond_Leak | P11: IDDQ | Q11: FW_MULTI_CORE_TEST | R11: FW_VE | S11: scpu_bisr_bist_drf | Z11: FT1 | AA11: RTD2841FLW_TA01 | AC11: V10 | AD11: 60369 | AE11: 59874 | AF11: 0.9918 | AG11: FW_other(267ea,0.44%) | AH11: FW_HDMI_480P(62ea,0.10%) | AI11: FW_HDMI_4K60(52ea,0.09%) | AJ11: all_bist_m_0217_p1_BIST_LDOon_HV(24ea,0.04%) | AK11: PIF_LVDS_FT(19ea,0.03%) | AL11: D4_2666M_FRC_4K60_uhd_LB_FT(17ea,0.03%) | AM11: FW_Multi_core_test_1(7ea,0.01%) | AN11: power_short(7ea,0.01%) | AO11: all_bist_m_0217_p5_scpu_bist_LDOon_HV(4ea,0.01%) | AP11: FW_Multi_core_test_2(4ea,0.01%)
F12: Throughput | G12: 95359 | H12: 95359 | I12: q'ty | J12: 83 | K12: 76 | L12: 70 | M12: 67 | N12: 28 | O12: 21 | P12: 13 | Q12: 7 | R12: 7 | S12: 5 | Z12: FT2 | AA12: RTD2841FLW_TA01 | AC12: V02 | AD12: 36262 | AE12: 36260 | AF12: 0.9999 | AG12: USB2_Swing(1ea,0.00%) | AH12: Wire_bond_leak(1ea,0.00%)
F13: Yield | G13: 0.9956 | H13: 0.9956 | I13: % | J13: 0.0009 | K13: 0.0008 | L13: 0.0007 | M13: 0.0007 | N13: 0.0003 | O13: 0.0002 | P13: 0.0001 | Q13: 0.0001 | R13: 0.0001 | S13: 0.0001 | Z13: FT2 | AA13: RTD2816AWA_TA01 | AC13: V02 | AD13: 6004 | AE13: 5997 | AF13: 0.9988 | AG13: PIF_eDP_FT(7ea,0.12%)
B14: FT1 | C14: RTD2875QDA_TA01 | E14: V03 | F14: Total IC | G14: 83613 | H14: 83613 | I14: Test item | J14: DDR4_2G_3000_SS_single_RW_FT | K14: DDR4_2G_3000_SS_FRC_ZQp5p | L14: FW_other | M14: OS_500uA | N14: USB2_disconnect_mea | O14: PowerShort | P14: Wire_Bond_Leak | Q14: chip_id_HRAM | R14: scpu_bist_all_1p2_HV | S14: ETN_TX_MDI | Y14: RL6896 Dante | Z14: FT1 | AA14: AXD2801VPF | AC14: V08 | AD14: 1735 | AE14: 1696 | AF14: 0.9775 | AG14: OS_500uA(20ea,1.15%) | AH14: HDMI2p1_12g_TX_check_Done_Result(17ea,0.98%) | AI14: DDR3_FRC_CA_n6PI(2ea,0.12%)
F15: Throughput | G15: 83264 | H15: 83264 | I15: q'ty | J15: 69 | K15: 67 | L15: 64 | M15: 34 | N15: 30 | O15: 13 | P15: 12 | Q15: 5 | R15: 5 | S15: 4 | Z15: FT1 | AA15: AXD2801SPH | AC15: V08 | AD15: 3429 | AE15: 3425 | AF15: 0.9988 | AG15: DDR3_FRC_CA_n6PI(2ea,0.06%) | AH15: FW(1ea,0.03%) | AI15: SARADC_FuncTest(1ea,0.03%)
F16: Yield | G16: 0.9958 | H16: 0.9958 | I16: % | J16: 0.0008 | K16: 0.0008 | L16: 0.0008 | M16: 0.0004 | N16: 0.0004 | O16: 0.0002 | P16: 0.0001 | Q16: 0.0001 | R16: 0.0001 | S16: 0 | Y16: RL6856 Merlin8 | Z16: CP | AA16: RL6856 | AC16: V11 | AD16: 64752 | AE16: 55618 | AF16: 0.8589 | AG16: cp_mode2_saf_comp_24ns(1695ea,2.62%) | AH16: cp_mode3_saf_comp_VT(1523ea,2.35%) | AI16: all_bist_mp_gpu_HV(1470ea,2.27%) | AJ16: cp_mode1_saf_comp(739ea,1.14%) | AK16: cp_mode0_saf_comp(547ea,0.84%) | AL16: core_scpu_power_IDD_spec(416ea,0.64%) | AM16: IDD(322ea,0.50%) | AN16: all_bist_mp_gpu_LV(306ea,0.47%) | AO16: eARC_PLL_CLK_CP1_44p1K(286ea,0.44%) | AP16: os(208ea,0.32%)
B17: FT1 | C17: RTD2875QPA_HD_TA01 | E17: V03 | F17: Total IC | G17: 1903 | H17: 1903 | I17: Test item | J17: DDR4_2G_3000_SS_FRC_ZQp5p | K17: DDR4_2G_3000_SS_single_RW_FT | L17: FW_other | M17: OS_500uA | Z17: FT1 | AA17: RTD2885PDM_FT1_TA01 | AC17: V07 | AD17: 69291 | AE17: 68928 | AF17: 0.9948 | AG17: FW_M8(174ea,0.25%) | AH17: DDR_single_RW_D4(58ea,0.08%) | AI17: DDR_ZQ_P(31ea,0.04%) | AJ17: HDMI_12G(26ea,0.04%) | AK17: Power_Short(23ea,0.03%) | AL17: VDC01_FT01_SNR(16ea,0.02%) | AM17: set-error-bin(11ea,0.02%) | AN17: ETN_TX_FT0(9ea,0.01%) | AO17: IFD_FT01(3ea,0.00%) | AP17: IFD_FT03_QADC_ramp_adc(2ea,0.00%)
F18: Throughput | G18: 1895 | H18: 1895 | I18: q'ty | J18: 3 | K18: 2 | L18: 2 | M18: 1 | Z18: FT1 | AA18: RTD2886NSS_SC_FT1_TA01 | AC18: V08 | AD18: 45529 | AE18: 45380 | AF18: 0.9967 | AG18: FW_USB(48ea,0.11%) | AH18: FW_MEMC(20ea,0.04%) | AI18: FW_VE(19ea,0.04%) | AJ18: set-error-bin(11ea,0.02%) | AK18: FW_other(8ea,0.02%) | AL18: Thermal_IDD_comp_4K(8ea,0.02%) | AM18: ddr_single_rw(8ea,0.02%) | AN18: OS_500uA(5ea,0.01%) | AO18: HDMI_12G_ALL_Port(4ea,0.01%) | AP18: ddr_FRC_CN_n5percent(3ea,0.01%)
F19: Yield | G19: 0.9958 | H19: 0.9958 | I19: % | J19: 0.0016 | K19: 0.0011 | L19: 0.0011 | M19: 0.0005 | Z19: FT2 | AA19: RTD2885PDM | AC19: V04 | AD19: 12907 | AE19: 12905 | AF19: 0.9998 | AG19: SARADC_RES2K(1ea,0.01%) | AH19: OS(1ea,0.01%)
A20: RL6963 Mac8q | B20: CP | C20: RL6963 | E20: V07 | F20: Total IC | G20: 125796 | H20: 125796 | I20: Test item | J20: cp_mode1_saf_comp_B | K20: cp_mode0_saf_comp | L20: cp_mode2_saf_comp_B | M20: all_bist_m_0217_p1_BIST_LDOoff_OC700_HV | N20: IDD | O20: PowerShort | P20: os | Q20: cp_mode1_tdf_cov70_comp_HV | R20: GPIO_01_GPOH | S20: all_bist_m_0217_p2_GPU_BIST_LDOoff_HV | Z20: FT2 | AA20: RTD2886NSP_SC_FT2_TA01 | AC20: V04 | AD20: 57318 | AE20: 57217 | AF20: 0.9982 | AG20: USB2_Disconnect_trim(100ea,0.17%) | AH20: wafer_info(1ea,0.00%)
F21: Throughput | G21: 114328 | H21: 114328 | I21: q'ty | J21: 2924 | K21: 1501 | L21: 1418 | M21: 1206 | N21: 924 | O21: 386 | P21: 379 | Q21: 344 | R21: 201 | S21: 142 | Y21: RL6750 H5C2 | Z21: CP | AA21: RL6750 | AC21: V04 | AD21: 40050 | AE21: 31586 | AF21: 0.7887 | AG21: Chip_ID(1796ea,4.48%) | AH21: IDDQ(1568ea,3.92%) | AI21: SAF_mode0_spc20_comp_211220165909_HV(1027ea,2.56%) | AJ21: all_bist_HV(1005ea,2.51%) | AK21: SAF_mode1_comp_211080048_HV(975ea,2.43%) | AL21: SAF_mode2_comp_2111080208_HV(447ea,1.12%) | AM21: TDF_mode1_wo_vby1_occ_dnr_lp25_stage1_25_g5_spc20_comp_220110132151_LV(301ea,0.75%) | AN21: Read_OTP_HVS(296ea,0.74%) | AO21: all_bisr_drf(186ea,0.46%) | AP21: Power_Short(179ea,0.45%)
F22: Yield | G22: 0.9088 | H22: 0.9088 | I22: % | J22: 0.0232 | K22: 0.0119 | L22: 0.0113 | M22: 0.0096 | N22: 0.0073 | O22: 0.0031 | P22: 0.003 | Q22: 0.0027 | R22: 0.0016 | S22: 0.0011 | Y22: RL6748 Merlin7 | Z22: CP | AA22: RL6748 | AC22: V25 | AD22: 51354 | AE22: 45135 | AF22: 0.8789 | AG22: cp_mode0_saf_0to90_comp_C(1582ea,3.08%) | AH22: all_bist_mp_scpu_all_bist_1106_CLK144_GPU_ETN_HV(1174ea,2.29%) | AI22: cp_mode2_saf_0to90_comp_C_slow(1096ea,2.13%) | AJ22: cp_mode1_saf_0to90_comp_C(751ea,1.46%) | AK22: cp_mode0_0_tdf_lp8_cat_comp_C_LV(236ea,0.46%) | AL22: cp_mode0_2_sdd_se0_a75_lp14_dsu_lp28_cat_cs1013_comp_LV(146ea,0.28%) | AM22: IDD(145ea,0.28%) | AN22: cp_mode0_tdf_se0_l3mcp_ttr_cov70_comp_HV(137ea,0.27%) | AO22: PowerShort(115ea,0.22%) | AP22: PIF_PP_DIFF_HI_CP(96ea,0.19%)
B23: FT1 | C23: RTD2864FLV_TA01 | E23: V10 | F23: Total IC | G23: 32765 | H23: 32765 | I23: Test item | J23: FW_other | K23: D4_2666M_FRC_4K60_uhd_LB_FT | L23: os | M23: FW_HDMI_4K60 | N23: ETN_MLT3 | O23: OTP_cust_PD_and_BMC_burn | P23: all_bist_m_0217_p1_BIST_LDOon_HV | Q23: all_bist_m_0217_p5_scpu_bist_LDOon_HV | R23: PIF_LVDS_FT | S23: OTP_Apple_Mfi_key_Demeter | Z23: CP | AA23: RL6748 | AC23: V25 | AD23: 18068 | AE23: 15697 | AF23: 0.8688 | AG23: cp_mode0_saf_0to90_comp_C(624ea,3.45%) | AH23: cp_mode2_saf_0to90_comp_C_slow(389ea,2.15%) | AI23: all_bist_mp_scpu_all_bist_1106_CLK144_GPU_ETN_HV(359ea,1.99%) | AJ23: cp_mode1_saf_0to90_comp_C(268ea,1.48%) | AK23: cp_mode3_tdf_comp_B_HL_3p63v_ttr(172ea,0.95%) | AL23: cp_mode0_0_tdf_lp8_cat_comp_C_LV(120ea,0.66%) | AM23: cp_mode0_tdf_se0_l3mcp_ttr_cov70_comp_HV(51ea,0.28%) | AN23: cp_mode0_2_sdd_se0_a75_lp14_dsu_lp28_cat_cs1013_comp_LV(42ea,0.23%) | AO23: IDD(34ea,0.19%) | AP23: os(33ea,0.18%)
F24: Throughput | G24: 32510 | H24: 32510 | I24: q'ty | J24: 104 | K24: 41 | L24: 38 | M24: 22 | N24: 7 | O24: 6 | P24: 5 | Q24: 4 | R24: 3 | S24: 3 | Z24: FT1 | AA24: RTD2875PNJ_SND_TA01 | AC24: V12 | AD24: 40904 | AE24: 40892 | AF24: 0.9997 | AG24: HDMI20_1p5G(4ea,0.01%) | AH24: FW_other(3ea,0.01%) | AI24: HDMI20_6G_VB(2ea,0.00%) | AJ24: FW_MD_Domain(1ea,0.00%) | AK24: FW_MTEST(1ea,0.00%) | AL24: FW_SCPU_VDDR(1ea,0.00%)
F25: Yield | G25: 0.9922 | H25: 0.9922 | I25: % | J25: 0.0032 | K25: 0.0013 | L25: 0.0012 | M25: 0.0007 | N25: 0.0002 | O25: 0.0002 | P25: 0.0002 | Q25: 0.0001 | R25: 0.0001 | S25: 0.0001 | Z25: FT1 | AA25: RTD2875NAA_SC_TA01 | AC25: V26 | AD25: 8544 | AE25: 8524 | AF25: 0.9977 | AG25: DDR_1p5GB_FRC_HV_1st(10ea,0.12%) | AH25: DDR_1p5GB_FRC_LV(2ea,0.02%) | AI25: atsc_IFD_FT02_ramp_12b(1ea,0.01%) | AJ25: PIF_CML_FT(1ea,0.01%) | AK25: DDR_1p5GB_MD(1ea,0.01%) | AL25: FW_MEMC(1ea,0.01%) | AM25: BB_FT01(1ea,0.01%) | AN25: OS_500uA(1ea,0.01%) | AO25: FW_M7(1ea,0.01%) | AP25: ETN_TX_FT0(1ea,0.01%)
B26: FT1 | C26: RTD2851FCA_TA01 | E26: V10 | F26: Total IC | G26: 8716 | H26: 8716 | I26: Test item | J26: os | K26: FW_HDMI_4K60 | L26: FW_other | M26: power_short | N26: D4_2666M_FRC_4K60_uhd_LB_FT | O26: FW_Multi_core_test_1 | P26: all_bist_m_0217_p5_scpu_bist_LDOon_HV | Q26: EARC_FT_03_CPFT | R26: all_bist_m_0217_p1_BIST_LDOon_HV | Z26: FT1 | AA26: RTD2881PSP_SDY_TA01 | AC26: V02 | AD26: 14259 | AE26: 14085 | AF26: 0.9878 | AG26: HDMI_5VDET_HPD(162ea,1.14%) | AH26: HDMI21_12G_144hz(3ea,0.02%) | AI26: FW_M7(3ea,0.02%) | AJ26: BB_FT01(3ea,0.02%) | AK26: FW_MEMC(1ea,0.01%) | AL26: PIF_LVDS_FT(1ea,0.01%) | AM26: OS_500uA(1ea,0.01%)
F27: Throughput | G27: 8695 | H27: 8695 | I27: q'ty | J27: 6 | K27: 4 | L27: 3 | M27: 2 | N27: 2 | O27: 1 | P27: 1 | Q27: 1 | R27: 1 | Z27: FT1 | AA27: RTD2875NDB_LC_TA01 | AC27: V26 | AD27: 774 | AE27: 771 | AF27: 0.9961 | AG27: DDR_1p5GB_FRC_HV_1st(1ea,0.13%) | AH27: Power_Short(1ea,0.13%) | AI27: IDDQ(1ea,0.13%)
F28: Yield | G28: 0.9976 | H28: 0.9976 | I28: % | J28: 0.0007 | K28: 0.0005 | L28: 0.0003 | M28: 0.0002 | N28: 0.0002 | O28: 0.0001 | P28: 0.0001 | Q28: 0.0001 | R28: 0.0001 | Z28: FT1 | AA28: RTD2885NDM_HLC | AB28: 4K120 without ATSC C版（OTP燒錄與RTD2885NDM-HSB-CC同 | AC28: V19 | AD28: 1657 | AE28: 1639 | AF28: 0.9891 | AG28: DDR_FRC_HV_1st(15ea,0.91%) | AH28: HDMI20_1p5G(1ea,0.06%) | AI28: BB_FT01(1ea,0.06%) | AJ28: HDMI20_6G_VB(1ea,0.06%)
B29: FT1 | C29: RTD2841FLW_TA01 | E29: V10 | F29: Total IC | G29: 60369 | H29: 60369 | I29: Test item | J29: FW_other | K29: FW_HDMI_480P | L29: FW_HDMI_4K60 | M29: all_bist_m_0217_p1_BIST_LDOon_HV | N29: PIF_LVDS_FT | O29: D4_2666M_FRC_4K60_uhd_LB_FT | P29: FW_Multi_core_test_1 | Q29: power_short | R29: all_bist_m_0217_p5_scpu_bist_LDOon_HV | S29: FW_Multi_core_test_2 | Z29: FT1 | AA29: RTD2875PSP_SC_TA01 | AC29: V12 | AD29: 89038 | AE29: 88821 | AF29: 0.9976 | AG29: FW_other(71ea,0.08%) | AH29: OS_500uA(70ea,0.08%) | AI29: HDMI20_1p5G(15ea,0.02%) | AJ29: HDMI20_6G_VB(10ea,0.01%) | AK29: Power_Short(9ea,0.01%) | AL29: OS_2mA(5ea,0.01%) | AM29: FW_ETN(3ea,0.00%) | AN29: FW_MTEST(3ea,0.00%) | AO29: VDC03_FT02_INL_DNL(3ea,0.00%) | AP29: IDDQ(3ea,0.00%)
F30: Throughput | G30: 59874 | H30: 59874 | I30: q'ty | J30: 267 | K30: 62 | L30: 52 | M30: 24 | N30: 19 | O30: 17 | P30: 7 | Q30: 7 | R30: 4 | S30: 4 | Z30: FT1 | AA30: RTD2885NCH_WC_TA01 | AC30: V20 | AD30: 816 | AE30: 800 | AF30: 0.9804 | AG30: DDR4_3GB_single_RW(8ea,0.98%) | AH30: FW_other(2ea,0.25%) | AI30: IDDQ(2ea,0.25%) | AJ30: DDR4_3GB_FRC_HV(1ea,0.12%) | AK30: FW_MD_Domain(1ea,0.12%) | AL30: os_500uA_s(1ea,0.12%) | AM30: Power_Short(1ea,0.12%)
F31: Yield | G31: 0.9918 | H31: 0.9918 | I31: % | J31: 0.0044 | K31: 0.001 | L31: 0.0009 | M31: 0.0004 | N31: 0.0003 | O31: 0.0003 | P31: 0.0001 | Q31: 0.0001 | R31: 0.0001 | S31: 0.0001 | Y31: RL6641 Mac7p | Z31: CP | AA31: RL6641 | AC31: V16 | AD31: 140342 | AE31: 124456 | AF31: 0.8868 | AG31: all_bist_etn_HV(2740ea,1.95%) | AH31: cp_saf_mode2_comp_30_dummy_pattern_s2(2569ea,1.83%) | AI31: IDD(2413ea,1.72%) | AJ31: cp_saf_mode0_comp_tmax2_B_cut_s2(1696ea,1.21%) | AK31: cp_saf_mode1_comp_tmax2_B_cut_s2(1456ea,1.04%) | AL31: PowerShort(1098ea,0.78%) | AM31: cp_saf_mode6_comp_tmax2_B_cut_s2(1085ea,0.77%) | AN31: cp_tdf_mode2_comp_30_dummy_pattern_LV_s2(437ea,0.31%) | AO31: scpu_bist_all_mode_shr_delay2_SCPU1150_HV(261ea,0.19%) | AP31: GPU_DEC_OPEN_HV(218ea,0.16%)
B32: FT2 | C32: RTD2841FLW_TA01 | E32: V02 | F32: Total IC | G32: 36262 | H32: 36262 | I32: Test item | J32: USB2_Swing | K32: Wire_bond_leak
F33: Throughput | G33: 36260 | H33: 36260 | I33: q'ty | J33: 1 | K33: 1
F34: Yield | G34: 0.9999 | H34: 0.9999 | I34: % | J34: 0 | K34: 0
B35: FT2 | C35: RTD2816AWA_TA01 | E35: V02 | F35: Total IC | G35: 6004 | H35: 6004 | I35: Test item | J35: PIF_eDP_FT
F36: Throughput | G36: 5997 | H36: 5997 | I36: q'ty | J36: 7
F37: Yield | G37: 0.9988 | H37: 0.9988 | I37: % | J37: 0.0012
A38: RL6896 Dante | B38: FT1 | C38: AXD2801VPF | E38: V08 | F38: Total IC | G38: 1735 | H38: 1735 | I38: Test item | J38: OS_500uA | K38: HDMI2p1_12g_TX_check_Done_Result | L38: DDR3_FRC_CA_n6PI
F39: Throughput | G39: 1696 | H39: 1696 | I39: q'ty | J39: 20 | K39: 17 | L39: 2
F40: Yield | G40: 0.9775 | H40: 0.9775 | I40: % | J40: 0.0115 | K40: 0.0098 | L40: 0.0012
...

Sheet RL6982_HD_TA01_V03_summary_raw
A1: 1 | B1: PASS BIN | C1: 267118 | D1: 0.9026 | N1: Project | O1: RL6982 | P1: RL6982 | Q1: RL6982 | R1: RL6982 | S1: RL6982 | T1: RL6982 | U1: RL6982 | V1: RL6982 | W1: RL6982 | X1: RL6982 | Y1: RL6982 | Z1: RL6982 | AA1: RL6982 | AB1: RL6982 | AC1: RL6982 | AD1: RL6982 | AE1: RL6982 | AF1: RL6982 | AG1: RL6982 | AH1: RL6982 | AI1: RL6982 | AJ1: RL6982 | AK1: RL6982 | AL1: RL6982 | AM1: RL6982 | AN1: RL6982 | AO1: RL6982 | AP1: RL6982 | AQ1: RL6982 | AR1: RL6982 | AS1: RL6982 | AT1: RL6982 | AU1: RL6982 | AV1: RL6982 | AW1: RL6982 | AX1: RL6982 | AY1: RL6982 | AZ1: RL6982 | BA1: RL6982 | BB1: RL6982 | BC1: RL6982 | BD1: RL6982 | BE1: RL6982 | BF1: RL6982 | BG1: RL6982 | BH1: RL6982 | BI1: RL6982 | BJ1: RL6982 | BK1: RL6982 | BL1: RL6982 | BM1: RL6982 | BN1: RL6982 | BO1: RL6982 | BP1: RL6982 | BQ1: RL6982 | BR1: RL6982 | BS1: RL6982 | BT1: RL6982 | BU1: RL6982 | BV1: RL6982 | BW1: RL6982 | BX1: RL6982 | BY1: RL6982 | BZ1: RL6982 | CA1: RL6982 | CB1: RL6982 | CC1: RL6982 | CD1: RL6982 | CE1: RL6982 | CF1: RL6982 | CG1: RL6982 | CH1: RL6982 | CI1: RL6982 | CJ1: RL6982 | CK1: RL6982 | CL1: RL6982 | CM1: RL6982 | CN1: RL6982 | CO1: RL6982 | CP1: RL6982 | CQ1: RL6982 | CR1: RL6982 | CS1: RL6982 | CT1: RL6982 | CU1: RL6982 | CV1: RL6982 | CW1: RL6982 | CX1: RL6982 | CY1: RL6982 | CZ1: RL6982 | DA1: RL6982 | DB1: RL6982 | DC1: RL6982 | DD1: RL6982 | DE1: RL6982 | DF1: RL6982 | DG1: RL6982 | DH1: RL6982 | DI1: RL6982 | DJ1: RL6982 | DK1: RL6982 | DL1: RL6982 | DM1: RL6982 | DN1: RL6982 | DO1: RL6982 | DP1: RL6982 | DQ1: RL6982 | DR1: RL6982 | DS1: RL6982 | DT1: RL6982 | DU1: RL6982 | DV1: RL6982 | DW1: RL6982 | DX1: RL6982 | DY1: RL6982 | DZ1: RL6982 | EA1: RL6982 | EB1: RL6982 | EC1: RL6982 | ED1: RL6982 | EE1: RL6982 | EF1: RL6982 | EG1: RL6982 | EH1: RL6982 | EI1: RL6982 | EJ1: RL6982 | EK1: RL6982 | EL1: RL6982 | EM1: RL6982 | EN1: RL6982 | EO1: RL6982 | EP1: RL6982 | EQ1: RL6982 | ER1: RL6982 | ES1: RL6982 | ET1: RL6982 | EU1: RL6982 | EV1: RL6982 | EW1: RL6982 | EX1: RL6982 | EY1: RL6982 | EZ1: RL6982 | FA1: RL6982 | FB1: RL6982 | FC1: RL6982 | FD1: RL6982 | FE1: RL6982 | FF1: RL6982 | FG1: RL6982 | FH1: RL6982 | FI1: RL6982 | FJ1: RL6982 | FK1: RL6982 | FL1: RL6982 | FM1: RL6982 | FN1: RL6982 | FO1: RL6982 | FP1: RL6982 | FQ1: RL6982 | FR1: RL6982 | FS1: RL6982 | FT1: RL6982 | FU1: RL6982 | FV1: RL6982 | FW1: RL6982 | FX1: RL6982 | FY1: RL6982 | FZ1: RL6982 | GA1: RL6982 | GB1: RL6982 | GC1: RL6982 | GD1: RL6982 | GE1: RL6982 | GF1: RL6982 | GG1: RL6982 | GH1: RL6982 | GI1: RL6982 | GJ1: RL6982 | GK1: RL6982 | GL1: RL6982 | GM1: RL6982 | GN1: RL6982 | GO1: RL6982 | GP1: RL6982 | GQ1: RL6982 | GR1: RL6982 | GS1: RL6982 | GT1: RL6982 | GU1: RL6982 | GV1: RL6982 | GW1: RL6982 | GX1: RL6982 | GY1: RL6982 | GZ1: RL6982 | HA1: RL6982 | HB1: RL6982 | HC1: RL6982 | HD1: RL6982 | HE1: RL6982 | HF1: RL6982 | HG1: RL6982 | HH1: RL6982 | HI1: RL6982 | HJ1: RL6982 | HK1: RL6982 | HL1: RL6982 | HM1: RL6982 | HN1: RL6982 | HO1: RL6982 | HP1: RL6982 | HQ1: RL6982 | HR1: RL6982 | HS1: RL6982 | HT1: RL6982 | HU1: RL6982 | HV1: RL6982 | HW1: RL6982 | HX1: RL6982 | HY1: RL6982 | HZ1: RL6982 | IA1: RL6982 | IB1: RL6982 | IC1: RL6982 | ID1: RL6982 | IE1: RL6982 | IF1: RL6982 | IG1: RL6982 | IH1: RL6982 | II1: RL6982 | IJ1: RL6982 | IK1: RL6982 | IL1: RL6982 | IM1: RL6982 | IN1: RL6982 | IO1: RL6982 | IP1: RL6982 | IQ1: RL6982 | IR1: RL6982 | IS1: RL6982 | IT1: RL6982 | IU1: RL6982 | IV1: RL6982 | IW1: RL6982 | IX1: RL6982 | IY1: RL6982 | IZ1: RL6982 | JA1: RL6982 | JB1: RL6982 | JC1: RL6982 | JD1: RL6982 | JE1: RL6982 | JF1: RL6982 | JG1: RL6982 | JH1: RL6982 | JI1: RL6982 | JJ1: RL6982 | JK1: RL6982 | JL1: RL6982 | JM1: RL6982 | JN1: RL6982 | JO1: RL6982 | JP1: RL6982 | JQ1: RL6982 | JR1: RL6982 | JS1: RL6982 | JT1: RL6982 | JU1: RL6982 | JV1: RL6982 | JW1: RL6982 | JX1: RL6982 | JY1: RL6982 | JZ1: RL6982
A2: Top_all | B2: BIN1 | C2: 267118 | D2: 0.9026 | N2: Product | O2: RL6982 | P2: RL6982 | Q2: RL6982 | R2: RL6982 | S2: RL6982 | T2: RL6982 | U2: RL6982 | V2: RL6982 | W2: RL6982 | X2: RL6982 | Y2: RL6982 | Z2: RL6982 | AA2: RL6982 | AB2: RL6982 | AC2: RL6982 | AD2: RL6982 | AE2: RL6982 | AF2: RL6982 | AG2: RL6982 | AH2: RL6982 | AI2: RL6982 | AJ2: RL6982 | AK2: RL6982 | AL2: RL6982 | AM2: RL6982 | AN2: RL6982 | AO2: RL6982 | AP2: RL6982 | AQ2: RL6982 | AR2: RL6982 | AS2: RL6982 | AT2: RL6982 | AU2: RL6982 | AV2: RL6982 | AW2: RL6982 | AX2: RL6982 | AY2: RL6982 | AZ2: RL6982 | BA2: RL6982 | BB2: RL6982 | BC2: RL6982 | BD2: RL6982 | BE2: RL6982 | BF2: RL6982 | BG2: RL6982 | BH2: RL6982 | BI2: RL6982 | BJ2: RL6982 | BK2: RL6982 | BL2: RL6982 | BM2: RL6982 | BN2: RL6982 | BO2: RL6982 | BP2: RL6982 | BQ2: RL6982 | BR2: RL6982 | BS2: RL6982 | BT2: RL6982 | BU2: RL6982 | BV2: RL6982 | BW2: RL6982 | BX2: RL6982 | BY2: RL6982 | BZ2: RL6982 | CA2: RL6982 | CB2: RL6982 | CC2: RL6982 | CD2: RL6982 | CE2: RL6982 | CF2: RL6982 | CG2: RL6982 | CH2: RL6982 | CI2: RL6982 | CJ2: RL6982 | CK2: RL6982 | CL2: RL6982 | CM2: RL6982 | CN2: RL6982 | CO2: RL6982 | CP2: RL6982 | CQ2: RL6982 | CR2: RL6982 | CS2: RL6982 | CT2: RL6982 | CU2: RL6982 | CV2: RL6982 | CW2: RL6982 | CX2: RL6982 | CY2: RL6982 | CZ2: RL6982 | DA2: RL6982 | DB2: RL6982 | DC2: RL6982 | DD2: RL6982 | DE2: RL6982 | DF2: RL6982 | DG2: RL6982 | DH2: RL6982 | DI2: RL6982 | DJ2: RL6982 | DK2: RL6982 | DL2: RL6982 | DM2: RL6982 | DN2: RL6982 | DO2: RL6982 | DP2: RL6982 | DQ2: RL6982 | DR2: RL6982 | DS2: RL6982 | DT2: RL6982 | DU2: RL6982 | DV2: RL6982 | DW2: RL6982 | DX2: RL6982 | DY2: RL6982 | DZ2: RL6982 | EA2: RL6982 | EB2: RL6982 | EC2: RL6982 | ED2: RL6982 | EE2: RL6982 | EF2: RL6982 | EG2: RL6982 | EH2: RL6982 | EI2: RL6982 | EJ2: RL6982 | EK2: RL6982 | EL2: RL6982 | EM2: RL6982 | EN2: RL6982 | EO2: RL6982 | EP2: RL6982 | EQ2: RL6982 | ER2: RL6982 | ES2: RL6982 | ET2: RL6982 | EU2: RL6982 | EV2: RL6982 | EW2: RL6982 | EX2: RL6982 | EY2: RL6982 | EZ2: RL6982 | FA2: RL6982 | FB2: RL6982 | FC2: RL6982 | FD2: RL6982 | FE2: RL6982 | FF2: RL6982 | FG2: RL6982 | FH2: RL6982 | FI2: RL6982 | FJ2: RL6982 | FK2: RL6982 | FL2: RL6982 | FM2: RL6982 | FN2: RL6982 | FO2: RL6982 | FP2: RL6982 | FQ2: RL6982 | FR2: RL6982 | FS2: RL6982 | FT2: RL6982 | FU2: RL6982 | FV2: RL6982 | FW2: RL6982 | FX2: RL6982 | FY2: RL6982 | FZ2: RL6982 | GA2: RL6982 | GB2: RL6982 | GC2: RL6982 | GD2: RL6982 | GE2: RL6982 | GF2: RL6982 | GG2: RL6982 | GH2: RL6982 | GI2: RL6982 | GJ2: RL6982 | GK2: RL6982 | GL2: RL6982 | GM2: RL6982 | GN2: RL6982 | GO2: RL6982 | GP2: RL6982 | GQ2: RL6982 | GR2: RL6982 | GS2: RL6982 | GT2: RL6982 | GU2: RL6982 | GV2: RL6982 | GW2: RL6982 | GX2: RL6982 | GY2: RL6982 | GZ2: RL6982 | HA2: RL6982 | HB2: RL6982 | HC2: RL6982 | HD2: RL6982 | HE2: RL6982 | HF2: RL6982 | HG2: RL6982 | HH2: RL6982 | HI2: RL6982 | HJ2: RL6982 | HK2: RL6982 | HL2: RL6982 | HM2: RL6982 | HN2: RL6982 | HO2: RL6982 | HP2: RL6982 | HQ2: RL6982 | HR2: RL6982 | HS2: RL6982 | HT2: RL6982 | HU2: RL6982 | HV2: RL6982 | HW2: RL6982 | HX2: RL6982 | HY2: RL6982 | HZ2: RL6982 | IA2: RL6982 | IB2: RL6982 | IC2: RL6982 | ID2: RL6982 | IE2: RL6982 | IF2: RL6982 | IG2: RL6982 | IH2: RL6982 | II2: RL6982 | IJ2: RL6982 | IK2: RL6982 | IL2: RL6982 | IM2: RL6982 | IN2: RL6982 | IO2: RL6982 | IP2: RL6982 | IQ2: RL6982 | IR2: RL6982 | IS2: RL6982 | IT2: RL6982 | IU2: RL6982 | IV2: RL6982 | IW2: RL6982 | IX2: RL6982 | IY2: RL6982 | IZ2: RL6982 | JA2: RL6982 | JB2: RL6982 | JC2: RL6982 | JD2: RL6982 | JE2: RL6982 | JF2: RL6982 | JG2: RL6982 | JH2: RL6982 | JI2: RL6982 | JJ2: RL6982 | JK2: RL6982 | JL2: RL6982 | JM2: RL6982 | JN2: RL6982 | JO2: RL6982 | JP2: RL6982 | JQ2: RL6982 | JR2: RL6982 | JS2: RL6982 | JT2: RL6982 | JU2: RL6982 | JV2: RL6982 | JW2: RL6982 | JX2: RL6982 | JY2: RL6982 | JZ2: RL6982
B3: OTHER | C3: 242 | D3: 0.0008 | N3: Short Lot ID | O3: P9CN5 | P3: P9AT6 | Q3: P9CS3 | R3: P9CL7 | S3: P9CS4 | T3: P9CS3 | U3: P9CM6 | V3: P9CS3 | W3: P9CC4 | X3: P9CM6 | Y3: P9CS4 | Z3: P9CC4 | AA3: P9CS5 | AB3: P9CL7 | AC3: P9CM6 | AD3: P9CS4 | AE3: P9CC4 | AF3: P9CS5 | AG3: P9CL7 | AH3: P9AT9 | AI3: P9CS5 | AJ3: P9CN5 | AK3: P9CS4 | AL3: P9AT6 | AM3: P9CL7 | AN3: P9CS3 | AO3: P9CS2 | AP3: P9CC4 | AQ3: P9CS4 | AR3: P9CS4 | AS3: P9CS4 | AT3: P9CS5 | AU3: P9AU3 | AV3: P9CS3 | AW3: P9CS3 | AX3: P9CS2 | AY3: P9CS3 | AZ3: P9CL7 | BA3: P9AT9 | BB3: P9CL7 | BC3: P9CC6 | BD3: P9CS5 | BE3: P9CS2 | BF3: P9CL7 | BG3: P9CM1 | BH3: P9CM1 | BI3: P9CC4 | BJ3: P9CS3 | BK3: P9CM6 | BL3: P9CL7 | BM3: P9CS4 | BN3: P9CS4 | BO3: P9CS5 | BP3: P9CC4 | BQ3: P9CM6 | BR3: P9AT9 | BS3: P9CS3 | BT3: P9CS2 | BU3: P9AT9 | BV3: P9CC3 | BW3: P9CS2 | BX3: P9CC4 | BY3: P9CS5 | BZ3: P9CL7 | CA3: P9CS4 | CB3: P9CS5 | CC3: P9CL7 | CD3: P9CS4 | CE3: P9CS2 | CF3: P9CS3 | CG3: P9AT9 | CH3: P9CL7 | CI3: P9CM1 | CJ3: P9CC6 | CK3: P9CS2 | CL3: P9AT9 | CM3: P9AT9 | CN3: P9CL6 | CO3: P9AT9 | CP3: P9CS4 | CQ3: P9CM0 | CR3: P9CS3 | CS3: P9CC6 | CT3: P9CS2 | CU3: P9CS2 | CV3: P9CM0 | CW3: P9CC6 | CX3: P9CC6 | CY3: P9CC4 | CZ3: P9CS5 | DA3: P9AU3 | DB3: P9CC6 | DC3: P9CN5 | DD3: P9CM6 | DE3: P9CS4 | DF3: P9CC4 | DG3: P9CS3 | DH3: P9CS4 | DI3: P9CS4 | DJ3: P9CC6 | DK3: P9CM6 | DL3: P9CS3 | DM3: P9CS5 | DN3: P9CS4 | DO3: P9CS3 | DP3: P9CM6 | DQ3: P9CS3 | DR3: P9CS3 | DS3: P9CM1 | DT3: P9CS4 | DU3: P9CM1 | DV3: P9CL7 | DW3: P9CL6 | DX3: P9CC6 | DY3: P9CM0 | DZ3: P9CS5 | EA3: P9CS4 | EB3: P9CL7 | EC3: P9CC4 | ED3: P9CS3 | EE3: P9AT6 | EF3: P9CS5 | EG3: P9CS2 | EH3: P9CS4 | EI3: P9CM1 | EJ3: P9CM0 | EK3: P9CM1 | EL3: P9AU3 | EM3: P9CS2 | EN3: P9CS5 | EO3: P9CM1 | EP3: P9CC3 | EQ3: P9CS2 | ER3: P9AU3 | ES3: P9CM0 | ET3: P9AT9 | EU3: P9CC6 | EV3: P9CS4 | EW3: P9CM0 | EX3: P9CM0 | EY3: P9CM1 | EZ3: P9CS2 | FA3: P9CC3 | FB3: P9CM0 | FC3: P9CS4 | FD3: P9CS3 | FE3: P9CN3 | FF3: P9AT6 | FG3: P9CC6 | FH3: P9CL7 | FI3: P9CM0 | FJ3: P9CS5 | FK3: P9CC4 | FL3: P9AT9 | FM3: P9CM0 | FN3: P9CM0 | FO3: P9CC3 | FP3: P9CC4 | FQ3: P9CC6 | FR3: P9CS2 | FS3: P9CS5 | FT3: P9CL6 | FU3: P9CM1 | FV3: P9CC6 | FW3: P9AT9 | FX3: P9CS3 | FY3: P9CC6 | FZ3: P9CL7 | GA3: P9CL7 | GB3: P9CM6 | GC3: P9CC3 | GD3: P9AU3 | GE3: P9CM0 | GF3: P9CC4 | GG3: P9CC3 | GH3: P9CC6 | GI3: P9CS4 | GJ3: P9CC3 | GK3: P9CC6 | GL3: P9CC4 | GM3: P9CL7 | GN3: P9AT6 | GO3: P9CL7 | GP3: P9CM1 | GQ3: P9CS3 | GR3: P9CM0 | GS3: P9CM0 | GT3: P9CS5 | GU3: P9CC4 | GV3: P9CS5 | GW3: P9CL6 | GX3: P9CC3 | GY3: P9CS3 | GZ3: P9AT9 | HA3: P9CS3 | HB3: P9AT9 | HC3: P9CS5 | HD3: P9CS2 | HE3: P9CC6 | HF3: P9CL7 | HG3: P9CM0 | HH3: P9CC4 | HI3: P9CC3 | HJ3: P9CL7 | HK3: P9CS3 | HL3: P9CM1 | HM3: P9CC6 | HN3: P9CL7 | HO3: P9CS4 | HP3: P9CS3 | HQ3: P9CS4 | HR3: P9CL6 | HS3: P9CC3 | HT3: P9CS2 | HU3: P9CL6 | HV3: P9CC3 | HW3: P9AT6 | HX3: P9CC4 | HY3: P9AT9 | HZ3: P9CM0 | IA3: P9CS2 | IB3: P9CC3 | IC3: P9CM1 | ID3: P9CL7 | IE3: P9AT9 | IF3: P9CM0 | IG3: P9CC3 | IH3: P9CC6 | II3: P9CC3 | IJ3: P9CC6 | IK3: P9CM6 | IL3: P9CC3 | IM3: P9CC3 | IN3: P9CM0 | IO3: P9CS4 | IP3: P9CM0 | IQ3: P9CM0 | IR3: P9CC6 | IS3: P9CC6 | IT3: P9CM6 | IU3: P9CL6 | IV3: P9CM6 | IW3: P9CM0 | IX3: P9CC3 | IY3: P9CM0 | IZ3: P9CC5 | JA3: P9CM0 | JB3: P9CM6 | JC3: P9CC6 | JD3: P9AU3 | JE3: P9CL7 | JF3: P9CC3 | JG3: P9CC3 | JH3: P9CC3 | JI3: P9CL7 | JJ3: P9AT9 | JK3: P9CC3 | JL3: P9CC3 | JM3: P9CC6 | JN3: P9CS5 | JO3: P9AT9 | JP3: P9CC6 | JQ3: P9CS2 | JR3: P9CC3 | JS3: P9CM0 | JT3: P9CC3 | JU3: P9CM0 | JV3: P9CC6 | JW3: P9CL7 | JX3: P9CC3 | JY3: P9AT9 | JZ3: P9AT9
B4: OS | C4: 866 | D4: 0.0029 | N4: Lot ID | O4: P9CN5 | P4: P9AT6 | Q4: P9CS3 | R4: P9CL7 | S4: P9CS4 | T4: P9CS3 | U4: P9CM6 | V4: P9CS3 | W4: P9CC4 | X4: P9CM6 | Y4: P9CS4 | Z4: P9CC4 | AA4: P9CS5 | AB4: P9CL7 | AC4: P9CM6 | AD4: P9CS4 | AE4: P9CC4 | AF4: P9CS5 | AG4: P9CL7 | AH4: P9AT9 | AI4: P9CS5 | AJ4: P9CN5 | AK4: P9CS4 | AL4: P9AT6 | AM4: P9CL7 | AN4: P9CS3 | AO4: P9CS2 | AP4: P9CC4 | AQ4: P9CS4 | AR4: P9CS4 | AS4: P9CS4 | AT4: P9CS5 | AU4: P9AU3 | AV4: P9CS3 | AW4: P9CS3 | AX4: P9CS2 | AY4: P9CS3 | AZ4: P9CL7 | BA4: P9AT9 | BB4: P9CL7 | BC4: P9CC6 | BD4: P9CS5 | BE4: P9CS2 | BF4: P9CL7 | BG4: P9CM1 | BH4: P9CM1 | BI4: P9CC4 | BJ4: P9CS3 | BK4: P9CM6 | BL4: P9CL7 | BM4: P9CS4 | BN4: P9CS4 | BO4: P9CS5 | BP4: P9CC4 | BQ4: P9CM6 | BR4: P9AT9 | BS4: P9CS3 | BT4: P9CS2 | BU4: P9AT9 | BV4: P9CC3 | BW4: P9CS2 | BX4: P9CC4 | BY4: P9CS5 | BZ4: P9CL7 | CA4: P9CS4 | CB4: P9CS5 | CC4: P9CL7 | CD4: P9CS4 | CE4: P9CS2 | CF4: P9CS3 | CG4: P9AT9 | CH4: P9CL7 | CI4: P9CM1 | CJ4: P9CC6 | CK4: P9CS2 | CL4: P9AT9 | CM4: P9AT9 | CN4: P9CL6 | CO4: P9AT9 | CP4: P9CS4 | CQ4: P9CM0 | CR4: P9CS3 | CS4: P9CC6 | CT4: P9CS2 | CU4: P9CS2 | CV4: P9CM0 | CW4: P9CC6 | CX4: P9CC6 | CY4: P9CC4 | CZ4: P9CS5 | DA4: P9AU3 | DB4: P9CC6 | DC4: P9CN5 | DD4: P9CM6 | DE4: P9CS4 | DF4: P9CC4 | DG4: P9CS3 | DH4: P9CS4 | DI4: P9CS4 | DJ4: P9CC6 | DK4: P9CM6 | DL4: P9CS3 | DM4: P9CS5 | DN4: P9CS4 | DO4: P9CS3 | DP4: P9CM6 | DQ4: P9CS3 | DR4: P9CS3 | DS4: P9CM1 | DT4: P9CS4 | DU4: P9CM1 | DV4: P9CL7 | DW4: P9CL6 | DX4: P9CC6 | DY4: P9CM0 | DZ4: P9CS5 | EA4: P9CS4 | EB4: P9CL7 | EC4: P9CC4 | ED4: P9CS3 | EE4: P9AT6 | EF4: P9CS5 | EG4: P9CS2 | EH4: P9CS4 | EI4: P9CM1 | EJ4: P9CM0 | EK4: P9CM1 | EL4: P9AU3 | EM4: P9CS2 | EN4: P9CS5 | EO4: P9CM1 | EP4: P9CC3 | EQ4: P9CS2 | ER4: P9AU3 | ES4: P9CM0 | ET4: P9AT9 | EU4: P9CC6 | EV4: P9CS4 | EW4: P9CM0 | EX4: P9CM0 | EY4: P9CM1 | EZ4: P9CS2 | FA4: P9CC3 | FB4: P9CM0 | FC4: P9CS4 | FD4: P9CS3 | FE4: P9CN3 | FF4: P9AT6 | FG4: P9CC6 | FH4: P9CL7 | FI4: P9CM0 | FJ4: P9CS5 | FK4: P9CC4 | FL4: P9AT9 | FM4: P9CM0 | FN4: P9CM0 | FO4: P9CC3 | FP4: P9CC4 | FQ4: P9CC6 | FR4: P9CS2 | FS4: P9CS5 | FT4: P9CL6 | FU4: P9CM1 | FV4: P9CC6 | FW4: P9AT9 | FX4: P9CS3 | FY4: P9CC6 | FZ4: P9CL7 | GA4: P9CL7 | GB4: P9CM6 | GC4: P9CC3 | GD4: P9AU3 | GE4: P9CM0 | GF4: P9CC4 | GG4: P9CC3 | GH4: P9CC6 | GI4: P9CS4 | GJ4: P9CC3 | GK4: P9CC6 | GL4: P9CC4 | GM4: P9CL7 | GN4: P9AT6 | GO4: P9CL7 | GP4: P9CM1 | GQ4: P9CS3 | GR4: P9CM0 | GS4: P9CM0 | GT4: P9CS5 | GU4: P9CC4 | GV4: P9CS5 | GW4: P9CL6 | GX4: P9CC3 | GY4: P9CS3 | GZ4: P9AT9 | HA4: P9CS3 | HB4: P9AT9 | HC4: P9CS5 | HD4: P9CS2 | HE4: P9CC6 | HF4: P9CL7 | HG4: P9CM0 | HH4: P9CC4 | HI4: P9CC3 | HJ4: P9CL7 | HK4: P9CS3 | HL4: P9CM1 | HM4: P9CC6 | HN4: P9CL7 | HO4: P9CS4 | HP4: P9CS3 | HQ4: P9CS4 | HR4: P9CL6 | HS4: P9CC3 | HT4: P9CS2 | HU4: P9CL6 | HV4: P9CC3 | HW4: P9AT6 | HX4: P9CC4 | HY4: P9AT9 | HZ4: P9CM0 | IA4: P9CS2 | IB4: P9CC3 | IC4: P9CM1 | ID4: P9CL7 | IE4: P9AT9 | IF4: P9CM0 | IG4: P9CC3 | IH4: P9CC6 | II4: P9CC3 | IJ4: P9CC6 | IK4: P9CM6 | IL4: P9CC3 | IM4: P9CC3 | IN4: P9CM0 | IO4: P9CS4 | IP4: P9CM0 | IQ4: P9CM0 | IR4: P9CC6 | IS4: P9CC6 | IT4: P9CM6 | IU4: P9CL6 | IV4: P9CM6 | IW4: P9CM0 | IX4: P9CC3 | IY4: P9CM0 | IZ4: P9CC5 | JA4: P9CM0 | JB4: P9CM6 | JC4: P9CC6 | JD4: P9AU3 | JE4: P9CL7 | JF4: P9CC3 | JG4: P9CC3 | JH4: P9CC3 | JI4: P9CL7 | JJ4: P9AT9 | JK4: P9CC3 | JL4: P9CC3 | JM4: P9CC6 | JN4: P9CS5 | JO4: P9AT9 | JP4: P9CC6 | JQ4: P9CS2 | JR4: P9CC3 | JS4: P9CM0 | JT4: P9CC3 | JU4: P9CM0 | JV4: P9CC6 | JW4: P9CL7 | JX4: P9CC3 | JY4: P9AT9 | JZ4: P9AT9
B5: SD | C5: 728 | D5: 0.0025 | N5: Wafer ID | O5: MAX518-15G1 | P5: MAX055-18A1 | Q5: MAX507-18A5 | R5: MAX053-17G4 | S5: MAX510-12B4 | T5: MAX507-21A0 | U5: MAX513-09A7 | V5: MAX507-16B7 | W5: MAX514-09F3 | X5: MAX513-06C6 | Y5: MAX510-23D2 | Z5: MAX514-06H2 | AA5: MAX521-07H0 | AB5: MAX053-05F3 | AC5: MAX513-07C1 | AD5: MAX510-10C6 | AE5: MAX514-11F3 | AF5: MAX521-06A2 | AG5: MAX053-04G0 | AH5: MAX059-18D3 | AI5: MAX521-03C1 | AJ5: MAX518-11B2 | AK5: MAX510-24C5 | AL5: MAX055-03A7 | AM5: MAX053-16H1 | AN5: MAX507-15C4 | AO5: MAX069-14F0 | AP5: MAX514-18B0 | AQ5: MAX510-07D3 | AR5: MAX510-05E5 | AS5: MAX510-25C0 | AT5: MAX521-23G7 | AU5: MAX072-02B0 | AV5: MAX507-17B2 | AW5: MAX507-20A5 | AX5: MAX069-25G6 | AY5: MAX507-25E7 | AZ5: MAX053-07E1 | BA5: MAX059-22C1 | BB5: MAX053-13B5 | BC5: MAX524-10F1 | BD5: MAX521-25F5 | BE5: MAX069-02D7 | BF5: MAX053-14B0 | BG5: MAX508-21E4 | BH5: MAX508-25C0 | BI5: MAX514-01D0 | BJ5: MAX507-13D6 | BK5: MAX513-13H0 | BL5: MAX053-10D4 | BM5: MAX510-06E0 | BN5: MAX510-04F2 | BO5: MAX521-04B4 | BP5: MAX514-02C3 | BQ5: MAX513-25A6 | BR5: MAX059-02E6 | BS5: MAX507-22G6 | BT5: MAX069-15E3 | BU5: MAX059-21C6 | BV5: MAX512-14B7 | BW5: MAX069-05C0 | BX5: MAX514-24F7 | BY5: MAX521-11F6 | BZ5: MAX053-06E6 | CA5: MAX510-08C6 | CB5: MAX521-15D2 | CC5: MAX053-01A4 | CD5: MAX510-02G4 | CE5: MAX069-10A1 | CF5: MAX507-19A0 | CG5: MAX059-19C6 | CH5: MAX053-08D4 | CI5: MAX508-06E0 | CJ5: MAX524-03A7 | CK5: MAX069-20C4 | CL5: MAX059-01F3 | CM5: MAX059-24A7 | CN5: MAX052-10G3 | CO5: MAX059-14F7 | CP5: MAX510-19E4 | CQ5: MAX505-17H0 | CR5: MAX507-12E3 | CS5: MAX524-07F6 | CT5: MAX069-23A5 | CU5: MAX069-24A0 | CV5: MAX505-18G3 | CW5: MAX524-16B3 | CX5: MAX524-13D2 | CY5: MAX514-03B6 | CZ5: MAX521-05A7 | DA5: MAX072-19G3 | DB5: MAX524-22G2 | DC5: MAX518-16F4 | DD5: MAX513-24B3 | DE5: MAX510-22D7 | DF5: MAX514-05A4 | DG5: MAX507-07G2 | DH5: MAX510-03F7 | DI5: MAX510-15H0 | DJ5: MAX524-09E4 | DK5: MAX513-23C0 | DL5: MAX507-24F4 | DM5: MAX521-13E4 | DN5: MAX510-13A7 | DO5: MAX507-06G7 | DP5: MAX513-17E4 | DQ5: MAX507-03B3 | DR5: MAX507-14D1 | DS5: MAX508-20F1 | DT5: MAX510-14A2 | DU5: MAX508-22D7 | DV5: MAX053-02H2 | DW5: MAX052-24G2 | DX5: MAX524-08F1 | DY5: MAX505-21F6 | DZ5: MAX521-14D7 | EA5: MAX510-16G3 | EB5: MAX053-22E5 | EC5: MAX514-10G0 | ED5: MAX507-23G1 | EE5: MAX055-02B4 | EF5: MAX521-18B3 | EG5: MAX069-17D1 | EH5: MAX510-01H1 | EI5: MAX508-16G3 | EJ5: MAX505-07E5 | EK5: MAX508-08C6 | EL5: MAX072-18H0 | EM5: MAX069-16D6 | EN5: MAX521-24G2 | EO5: MAX508-14A2 | EP5: MAX512-20G6 | EQ5: MAX069-18C4 | ER5: MAX072-10E5 | ES5: MAX505-20G3 | ET5: MAX059-10B0 | EU5: MAX524-06G3 | EV5: MAX510-20F1 | EW5: MAX505-04G4 | EX5: MAX505-19F6 | EY5: MAX508-15H0 | EZ5: MAX069-21B7 | FA5: MAX512-09D6 | FB5: MAX505-22F1 | FC5: MAX510-17F6 | FD5: MAX507-09F0 | FE5: MAX515-23D5 | FF5: MAX055-01C1 | FG5: MAX524-20A1 | FH5: MAX053-20F7 | FI5: MAX505-12C6 | FJ5: MAX521-20B3 | FK5: MAX514-08G0 | FL5: MAX059-04D4 | FM5: MAX505-03H1 | FN5: MAX505-09D3 | FO5: MAX512-19G1 | FP5: MAX514-07G5 | FQ5: MAX524-01C1 | FR5: MAX069-13F5 | FS5: MAX521-21A6 | FT5: MAX052-25F5 | FU5: MAX508-24C5 | FV5: MAX524-14C5 | FW5: MAX059-16E5 | FX5: MAX507-08F5 | FY5: MAX524-19G7 | FZ5: MAX053-18F7 | GA5: MAX053-09C7 | GB5: MAX513-08B4 | GC5: MAX512-03A1 | GD5: MAX072-01B5 | GE5: MAX505-15A7 | GF5: MAX514-23G4 | GG5: MAX512-06F5 | GH5: MAX524-21G7 | GI5: MAX510-21E4 | GJ5: MAX512-08E3 | GK5: MAX524-15C0 | GL5: MAX514-19A3 | GM5: MAX053-19F2 | GN5: MAX055-20A1 | GO5: MAX053-23E0 | GP5: MAX508-23D2 | GQ5: MAX507-02C0 | GR5: MAX505-01B0 | GS5: MAX505-13C1 | GT5: MAX521-12F1 | GU5: MAX514-04B1 | GV5: MAX521-16C5 | GW5: MAX052-15D2 | GX5: MAX512-17A0 | GY5: MAX507-05A1 | GZ5: MAX059-20D3 | HA5: MAX507-11F0 | HB5: MAX059-03E1 | HC5: MAX521-22A1 | HD5: MAX069-19B7 | HE5: MAX524-05H0 | HF5: MAX053-21F2 | HG5: MAX505-14B4 | HH5: MAX514-22H1 | HI5: MAX512-22F4 | HJ5: MAX053-25C6 | HK5: MAX507-10F5 | HL5: MAX508-07D3 | HM5: MAX524-04A2 | HN5: MAX053-24D3 | HO5: MAX510-09C1 | HP5: MAX507-04A6 | HQ5: MAX510-11C1 | HR5: MAX052-14D7 | HS5: MAX512-04G7 | HT5: MAX069-22B2 | HU5: MAX052-11F6 | HV5: MAX512-11D6 | HW5: MAX055-17A6 | HX5: MAX514-21A3 | HY5: MAX059-12H1 | HZ5: MAX505-08E0 | IA5: MAX069-12G2 | IB5: MAX512-21G1 | IC5: MAX508-13A7 | ID5: MAX053-12C2 | IE5: MAX059-13G4 | IF5: MAX505-06F2 | IG5: MAX512-05G2 | IH5: MAX524-18A1 | II5: MAX512-25D5 | IJ5: MAX524-12D7 | IK5: MAX513-14G3 | IL5: MAX512-12D1 | IM5: MAX512-01B3 | IN5: MAX505-10E0 | IO5: MAX510-18F1 | IP5: MAX505-23E4 | IQ5: MAX505-24D7 | IR5: MAX524-24F0 | IS5: MAX524-02B4 | IT5: MAX513-16F1 | IU5: MAX052-16C5 | IV5: MAX513-22C5 | IW5: MAX505-25D2 | IX5: MAX512-16A5 | IY5: MAX505-16A2 | IZ5: MAX516-18C5 | JA5: MAX505-05F7 | JB5: MAX513-15F6 | JC5: MAX524-25E3 | JD5: MAX072-20H0 | JE5: MAX053-03G5 | JF5: MAX512-13C4 | JG5: MAX512-15B2 | JH5: MAX512-07F0 | JI5: MAX053-15A3 | JJ5: MAX059-11A3 | JK5: MAX512-18G6 | JL5: MAX512-23E7 | JM5: MAX524-17A6 | JN5: MAX521-08G3 | JO5: MAX059-23B4 | JP5: MAX524-11E4 | JQ5: MAX069-11G7 | JR5: MAX512-24E2 | JS5: MAX505-02A3 | JT5: MAX512-10E3 | JU5: MAX505-11D3 | JV5: MAX524-23F5 | JW5: MAX053-11C7 | JX5: MAX512-02A6 | JY5: MAX059-15F2 | JZ5: MAX059-17E0
B6: POR | C6: 40 | D6: 0.0001 | N6: Wafer NO. | O6: 15 | P6: 18 | Q6: 18 | R6: 17 | S6: 12 | T6: 21 | U6: 9 | V6: 16 | W6: 9 | X6: 6 | Y6: 23 | Z6: 6 | AA6: 7 | AB6: 5 | AC6: 7 | AD6: 10 | AE6: 11 | AF6: 6 | AG6: 4 | AH6: 18 | AI6: 3 | AJ6: 11 | AK6: 24 | AL6: 3 | AM6: 16 | AN6: 15 | AO6: 14 | AP6: 18 | AQ6: 7 | AR6: 5 | AS6: 25 | AT6: 23 | AU6: 2 | AV6: 17 | AW6: 20 | AX6: 25 | AY6: 25 | AZ6: 7 | BA6: 22 | BB6: 13 | BC6: 10 | BD6: 25 | BE6: 2 | BF6: 14 | BG6: 21 | BH6: 25 | BI6: 1 | BJ6: 13 | BK6: 13 | BL6: 10 | BM6: 6 | BN6: 4 | BO6: 4 | BP6: 2 | BQ6: 25 | BR6: 2 | BS6: 22 | BT6: 15 | BU6: 21 | BV6: 14 | BW6: 5 | BX6: 24 | BY6: 11 | BZ6: 6 | CA6: 8 | CB6: 15 | CC6: 1 | CD6: 2 | CE6: 10 | CF6: 19 | CG6: 19 | CH6: 8 | CI6: 6 | CJ6: 3 | CK6: 20 | CL6: 1 | CM6: 24 | CN6: 10 | CO6: 14 | CP6: 19 | CQ6: 17 | CR6: 12 | CS6: 7 | CT6: 23 | CU6: 24 | CV6: 18 | CW6: 16 | CX6: 13 | CY6: 3 | CZ6: 5 | DA6: 19 | DB6: 22 | DC6: 16 | DD6: 24 | DE6: 22 | DF6: 5 | DG6: 7 | DH6: 3 | DI6: 15 | DJ6: 9 | DK6: 23 | DL6: 24 | DM6: 13 | DN6: 13 | DO6: 6 | DP6: 17 | DQ6: 3 | DR6: 14 | DS6: 20 | DT6: 14 | DU6: 22 | DV6: 2 | DW6: 24 | DX6: 8 | DY6: 21 | DZ6: 14 | EA6: 16 | EB6: 22 | EC6: 10 | ED6: 23 | EE6: 2 | EF6: 18 | EG6: 17 | EH6: 1 | EI6: 16 | EJ6: 7 | EK6: 8 | EL6: 18 | EM6: 16 | EN6: 24 | EO6: 14 | EP6: 20 | EQ6: 18 | ER6: 10 | ES6: 20 | ET6: 10 | EU6: 6 | EV6: 20 | EW6: 4 | EX6: 19 | EY6: 15 | EZ6: 21 | FA6: 9 | FB6: 22 | FC6: 17 | FD6: 9 | FE6: 23 | FF6: 1 | FG6: 20 | FH6: 20 | FI6: 12 | FJ6: 20 | FK6: 8 | FL6: 4 | FM6: 3 | FN6: 9 | FO6: 19 | FP6: 7 | FQ6: 1 | FR6: 13 | FS6: 21 | FT6: 25 | FU6: 24 | FV6: 14 | FW6: 16 | FX6: 8 | FY6: 19 | FZ6: 18 | GA6: 9 | GB6: 8 | GC6: 3 | GD6: 1 | GE6: 15 | GF6: 23 | GG6: 6 | GH6: 21 | GI6: 21 | GJ6: 8 | GK6: 15 | GL6: 19 | GM6: 19 | GN6: 20 | GO6: 23 | GP6: 23 | GQ6: 2 | GR6: 1 | GS6: 13 | GT6: 12 | GU6: 4 | GV6: 16 | GW6: 15 | GX6: 17 | GY6: 5 | GZ6: 20 | HA6: 11 | HB6: 3 | HC6: 22 | HD6: 19 | HE6: 5 | HF6: 21 | HG6: 14 | HH6: 22 | HI6: 22 | HJ6: 25 | HK6: 10 | HL6: 7 | HM6: 4 | HN6: 24 | HO6: 9 | HP6: 4 | HQ6: 11 | HR6: 14 | HS6: 4 | HT6: 22 | HU6: 11 | HV6: 11 | HW6: 17 | HX6: 21 | HY6: 12 | HZ6: 8 | IA6: 12 | IB6: 21 | IC6: 13 | ID6: 12 | IE6: 13 | IF6: 6 | IG6: 5 | IH6: 18 | II6: 25 | IJ6: 12 | IK6: 14 | IL6: 12 | IM6: 1 | IN6: 10 | IO6: 18 | IP6: 23 | IQ6: 24 | IR6: 24 | IS6: 2 | IT6: 16 | IU6: 16 | IV6: 22 | IW6: 25 | IX6: 16 | IY6: 16 | IZ6: 18 | JA6: 5 | JB6: 15 | JC6: 25 | JD6: 20 | JE6: 3 | JF6: 13 | JG6: 15 | JH6: 7 | JI6: 15 | JJ6: 11 | JK6: 18 | JL6: 23 | JM6: 17 | JN6: 8 | JO6: 23 | JP6: 11 | JQ6: 11 | JR6: 24 | JS6: 2 | JT6: 10 | JU6: 11 | JV6: 23 | JW6: 11 | JX6: 2 | JY6: 15 | JZ6: 17
B7: IDD | C7: 163 | D7: 0.0006 | N7: Re-Test | O7: 2 | P7: 1 | Q7: 6 | R7: 1 | S7: 1 | T7: 16 | U7: 1 | V7: 2 | W7: 1 | X7: 1 | Y7: 3 | Z7: 1 | AA7: 1 | AB7: 1 | AC7: 1 | AD7: 1 | AE7: 1 | AF7: 1 | AG7: 1 | AH7: 1 | AI7: 1 | AJ7: 2 | AK7: 2 | AL7: 8 | AM7: 2 | AN7: 1 | AO7: 1 | AP7: 5 | AQ7: 1 | AR7: 1 | AS7: 1 | AT7: 1 | AU7: 1 | AV7: 1 | AW7: 2 | AX7: 1 | AY7: 1 | AZ7: 1 | BA7: 1 | BB7: 1 | BC7: 1 | BD7: 1 | BE7: 1 | BF7: 1 | BG7: 1 | BH7: 1 | BI7: 1 | BJ7: 1 | BK7: 3 | BL7: 1 | BM7: 1 | BN7: 1 | BO7: 1 | BP7: 1 | BQ7: 1 | BR7: 1 | BS7: 1 | BT7: 1 | BU7: 1 | BV7: 1 | BW7: 2 | BX7: 1 | BY7: 2 | BZ7: 1 | CA7: 3 | CB7: 2 | CC7: 1 | CD7: 2 | CE7: 1 | CF7: 1 | CG7: 1 | CH7: 2 | CI7: 1 | CJ7: 1 | CK7: 1 | CL7: 1 | CM7: 1 | CN7: 11 | CO7: 2 | CP7: 1 | CQ7: 1 | CR7: 1 | CS7: 1 | CT7: 1 | CU7: 5 | CV7: 1 | CW7: 4 | CX7: 1 | CY7: 1 | CZ7: 1 | DA7: 1 | DB7: 1 | DC7: 1 | DD7: 1 | DE7: 2 | DF7: 1 | DG7: 1 | DH7: 1 | DI7: 1 | DJ7: 1 | DK7: 1 | DL7: 3 | DM7: 1 | DN7: 1 | DO7: 1 | DP7: 1 | DQ7: 1 | DR7: 4 | DS7: 1 | DT7: 1 | DU7: 1 | DV7: 1 | DW7: 1 | DX7: 1 | DY7: 1 | DZ7: 1 | EA7: 1 | EB7: 2 | EC7: 1 | ED7: 1 | EE7: 1 | EF7: 3 | EG7: 2 | EH7: 1 | EI7: 2 | EJ7: 1 | EK7: 2 | EL7: 1 | EM7: 2 | EN7: 1 | EO7: 1 | EP7: 1 | EQ7: 1 | ER7: 1 | ES7: 3 | ET7: 2 | EU7: 1 | EV7: 1 | EW7: 1 | EX7: 1 | EY7: 1 | EZ7: 2 | FA7: 1 | FB7: 1 | FC7: 1 | FD7: 1 | FE7: 6 | FF7: 1 | FG7: 1 | FH7: 1 | FI7: 1 | FJ7: 1 | FK7: 1 | FL7: 1 | FM7: 3 | FN7: 2 | FO7: 2 | FP7: 1 | FQ7: 1 | FR7: 1 | FS7: 1 | FT7: 1 | FU7: 1 | FV7: 2 | FW7: 1 | FX7: 3 | FY7: 1 | FZ7: 1 | GA7: 1 | GB7: 1 | GC7: 2 | GD7: 1 | GE7: 1 | GF7: 1 | GG7: 1 | GH7: 1 | GI7: 1 | GJ7: 1 | GK7: 3 | GL7: 1 | GM7: 1 | GN7: 1 | GO7: 1 | GP7: 1 | GQ7: 1 | GR7: 1 | GS7: 1 | GT7: 1 | GU7: 1 | GV7: 1 | GW7: 1 | GX7: 1 | GY7: 5 | GZ7: 1 | HA7: 1 | HB7: 1 | HC7: 1 | HD7: 1 | HE7: 1 | HF7: 1 | HG7: 1 | HH7: 1 | HI7: 1 | HJ7: 1 | HK7: 1 | HL7: 1 | HM7: 1 | HN7: 1 | HO7: 3 | HP7: 1 | HQ7: 1 | HR7: 1 | HS7: 1 | HT7: 3 | HU7: 2 | HV7: 1 | HW7: 1 | HX7: 1 | HY7: 1 | HZ7: 3 | IA7: 1 | IB7: 1 | IC7: 1 | ID7: 2 | IE7: 1 | IF7: 1 | IG7: 1 | IH7: 1 | II7: 1 | IJ7: 1 | IK7: 1 | IL7: 1 | IM7: 1 | IN7: 2 | IO7: 1 | IP7: 1 | IQ7: 1 | IR7: 1 | IS7: 1 | IT7: 1 | IU7: 1 | IV7: 2 | IW7: 1 | IX7: 1 | IY7: 1 | IZ7: 3 | JA7: 5 | JB7: 1 | JC7: 1 | JD7: 1 | JE7: 1 | JF7: 1 | JG7: 1 | JH7: 1 | JI7: 1 | JJ7: 1 | JK7: 1 | JL7: 5 | JM7: 1 | JN7: 1 | JO7: 1 | JP7: 1 | JQ7: 1 | JR7: 1 | JS7: 1 | JT7: 1 | JU7: 1 | JV7: 1 | JW7: 1 | JX7: 1 | JY7: 1 | JZ7: 3
B8: OTP | C8: 19 | D8: 0.0001 | N8: ProbeCard | O8: RL6982-PC-15 | P8: RL6982-PC-17 | Q8: RL6982-PC-25 | R8: RL6982-PC-25 | S8: RL6982-PC-01 | T8: RL6982-PC-25 | U8: RL6982-PC-23 | V8: RL6982-PC-03 | W8: RL6982-PC-11 | X8: RL6982-PC-23 | Y8: RL6982-PC-06 | Z8: RL6982-PC-11 | AA8: RL6982-PC-06 | AB8: RL6982-PC-09 | AC8: RL6982-PC-23 | AD8: RL6982-PC-01 | AE8: RL6982-PC-03 | AF8: RL6982-PC-06 | AG8: RL6982-PC-09 | AH8: RL6982-PC-23 | AI8: RL6982-PC-06 | AJ8: RL6982-PC-15 | AK8: RL6982-PC-06 | AL8: RL6982-PC-25 | AM8: RL6982-PC-18 | AN8: RL6982-PC-03 | AO8: RL6982-PC-11 | AP8: RL6982-PC-17 | AQ8: RL6982-PC-18 | AR8: RL6982-PC-18 | AS8: RL6982-PC-06 | AT8: RL6982-PC-01 | AU8: RL6982-PC-06 | AV8: RL6982-PC-25 | AW8: RL6982-PC-25 | AX8: RL6982-PC-02 | AY8: RL6982-PC-25 | AZ8: RL6982-PC-09 | BA8: RL6982-PC-23 | BB8: RL6982-PC-17 | BC8: RL6982-PC-17 | BD8: RL6982-PC-01 | BE8: RL6982-PC-02 | BF8: RL6982-PC-17 | BG8: RL6982-PC-15 | BH8: RL6982-PC-15 | BI8: RL6982-PC-11 | BJ8: RL6982-PC-03 | BK8: RL6982-PC-18 | BL8: RL6982-PC-17 | BM8: RL6982-PC-18 | BN8: RL6982-PC-18 | BO8: RL6982-PC-06 | BP8: RL6982-PC-11 | BQ8: RL6982-PC-17 | BR8: RL6982-PC-11 | BS8: RL6982-PC-25 | BT8: RL6982-PC-11 | BU8: RL6982-PC-23 | BV8: RL6982-PC-23 | BW8: RL6982-PC-02 | BX8: RL6982-PC-09 | BY8: RL6982-PC-18 | BZ8: RL6982-PC-09 | CA8: RL6982-PC-18 | CB8: RL6982-PC-18 | CC8: RL6982-PC-09 | CD8: RL6982-PC-18 | CE8: RL6982-PC-11 | CF8: RL6982-PC-25 | CG8: RL6982-PC-23 | CH8: RL6982-PC-09 | CI8: RL6982-PC-03 | CJ8: RL6982-PC-23 | CK8: RL6982-PC-02 | CL8: RL6982-PC-11 | CM8: RL6982-PC-23 | CN8: RL6982-PC-06 | CO8: RL6982-PC-18 | CP8: RL6982-PC-06 | CQ8: RL6982-PC-15 | CR8: RL6982-PC-03 | CS8: RL6982-PC-23 | CT8: RL6982-PC-02 | CU8: RL6982-PC-02 | CV8: RL6982-PC-06 | CW8: RL6982-PC-17 | CX8: RL6982-PC-17 | CY8: RL6982-PC-11 | CZ8: RL6982-PC-06 | DA8: RL6982-PC-15 | DB8: RL6982-PC-09 | DC8: RL6982-PC-15 | DD8: RL6982-PC-17 | DE8: RL6982-PC-06 | DF8: RL6982-PC-11 | DG8: RL6982-PC-07 | DH8: RL6982-PC-18 | DI8: RL6982-PC-01 | DJ8: RL6982-PC-17 | DK8: RL6982-PC-17 | DL8: RL6982-PC-25 | DM8: RL6982-PC-18 | DN8: RL6982-PC-01 | DO8: RL6982-PC-07 | DP8: RL6982-PC-09 | DQ8: RL6982-PC-07 | DR8: RL6982-PC-03 | DS8: RL6982-PC-15 | DT8: RL6982-PC-01 | DU8: RL6982-PC-15 | DV8: RL6982-PC-09 | DW8: RL6982-PC-25 | DX8: RL6982-PC-03 | DY8: RL6982-PC-06 | DZ8: RL6982-PC-18 | EA8: RL6982-PC-01 | EB8: RL6982-PC-25 | EC8: RL6982-PC-03 | ED8: RL6982-PC-25 | EE8: RL6982-PC-25 | EF8: RL6982-PC-01 | EG8: RL6982-PC-11 | EH8: RL6982-PC-18 | EI8: RL6982-PC-11 | EJ8: RL6982-PC-07 | EK8: RL6982-PC-03 | EL8: RL6982-PC-15 | EM8: RL6982-PC-11 | EN8: RL6982-PC-01 | EO8: RL6982-PC-11 | EP8: RL6982-PC-07 | EQ8: RL6982-PC-11 | ER8: RL6982-PC-18 | ES8: RL6982-PC-06 | ET8: RL6982-PC-18 | EU8: RL6982-PC-23 | EV8: RL6982-PC-06 | EW8: RL6982-PC-07 | EX8: RL6982-PC-06 | EY8: RL6982-PC-11 | EZ8: RL6982-PC-02 | FA8: RL6982-PC-23 | FB8: RL6982-PC-06 | FC8: RL6982-PC-01 | FD8: RL6982-PC-03 | FE8: RL6982-PC-25 | FF8: RL6982-PC-25 | FG8: RL6982-PC-09 | FH8: RL6982-PC-25 | FI8: RL6982-PC-15 | FJ8: RL6982-PC-01 | FK8: RL6982-PC-11 | FL8: RL6982-PC-11 | FM8: RL6982-PC-07 | FN8: RL6982-PC-07 | FO8: RL6982-PC-07 | FP8: RL6982-PC-11 | FQ8: RL6982-PC-23 | FR8: RL6982-PC-11 | FS8: RL6982-PC-01 | FT8: RL6982-PC-25 | FU8: RL6982-PC-15 | FV8: RL6982-PC-17 | FW8: RL6982-PC-18 | FX8: RL6982-PC-07 | FY8: RL6982-PC-09 | FZ8: RL6982-PC-25 | GA8: RL6982-PC-17 | GB8: RL6982-PC-23 | GC8: RL6982-PC-15 | GD8: RL6982-PC-06 | GE8: RL6982-PC-15 | GF8: RL6982-PC-09 | GG8: RL6982-PC-15 | GH8: RL6982-PC-09 | GI8: RL6982-PC-06 | GJ8: RL6982-PC-15 | GK8: RL6982-PC-17 | GL8: RL6982-PC-02 | GM8: RL6982-PC-25 | GN8: RL6982-PC-17 | GO8: RL6982-PC-25 | GP8: RL6982-PC-15 | GQ8: RL6982-PC-07 | GR8: RL6982-PC-01 | GS8: RL6982-PC-15 | GT8: RL6982-PC-18 | GU8: RL6982-PC-11 | GV8: RL6982-PC-18 | GW8: RL6982-PC-02 | GX8: RL6982-PC-07 | GY8: RL6982-PC-07 | GZ8: RL6982-PC-23 | HA8: RL6982-PC-03 | HB8: RL6982-PC-11 | HC8: RL6982-PC-01 | HD8: RL6982-PC-02 | HE8: RL6982-PC-23 | HF8: RL6982-PC-25 | HG8: RL6982-PC-15 | HH8: RL6982-PC-09 | HI8: RL6982-PC-07 | HJ8: RL6982-PC-25 | HK8: RL6982-PC-03 | HL8: RL6982-PC-03 | HM8: RL6982-PC-23 | HN8: RL6982-PC-25 | HO8: RL6982-PC-18 | HP8: RL6982-PC-07 | HQ8: RL6982-PC-01 | HR8: RL6982-PC-02 | HS8: RL6982-PC-15 | HT8: RL6982-PC-02 | HU8: RL6982-PC-02 | HV8: RL6982-PC-23 | HW8: RL6982-PC-17 | HX8: RL6982-PC-09 | HY8: RL6982-PC-18 | HZ8: RL6982-PC-07 | IA8: RL6982-PC-11 | IB8: RL6982-PC-07 | IC8: RL6982-PC-11 | ID8: RL6982-PC-17 | IE8: RL6982-PC-18 | IF8: RL6982-PC-07 | IG8: RL6982-PC-15 | IH8: RL6982-PC-09 | II8: RL6982-PC-07 | IJ8: RL6982-PC-17 | IK8: RL6982-PC-09 | IL8: RL6982-PC-23 | IM8: RL6982-PC-15 | IN8: RL6982-PC-15 | IO8: RL6982-PC-06 | IP8: RL6982-PC-06 | IQ8: RL6982-PC-06 | IR8: RL6982-PC-09 | IS8: RL6982-PC-23 | IT8: RL6982-PC-09 | IU8: RL6982-PC-02 | IV8: RL6982-PC-17 | IW8: RL6982-PC-06 | IX8: RL6982-PC-23 | IY8: RL6982-PC-15 | IZ8: RL6982-PC-23 | JA8: RL6982-PC-07 | JB8: RL6982-PC-09 | JC8: RL6982-PC-09 | JD8: RL6982-PC-15 | JE8: RL6982-PC-09 | JF8: RL6982-PC-23 | JG8: RL6982-PC-23 | JH8: RL6982-PC-15 | JI8: RL6982-PC-17 | JJ8: RL6982-PC-18 | JK8: RL6982-PC-07 | JL8: RL6982-PC-07 | JM8: RL6982-PC-09 | JN8: RL6982-PC-06 | JO8: RL6982-PC-23 | JP8: RL6982-PC-17 | JQ8: RL6982-PC-11 | JR8: RL6982-PC-07 | JS8: RL6982-PC-01 | JT8: RL6982-PC-23 | JU8: RL6982-PC-15 | JV8: RL6982-PC-09 | JW8: RL6982-PC-17 | JX8: RL6982-PC-15 | JY8: RL6982-PC-18 | JZ8: RL6982-PC-18
B9: SCAN | C9: 19194 | D9: 0.0649 | N9: Yield | O9: 0.8042 | P9: 0.8162 | Q9: 0.8438 | R9: 0.8438 | S9: 0.8465 | T9: 0.8528 | U9: 0.8539 | V9: 0.8557 | W9: 0.8575 | X9: 0.8631 | Y9: 0.8667 | Z9: 0.8667 | AA9: 0.8676 | AB9: 0.8686 | AC9: 0.8695 | AD9: 0.8713 | AE9: 0.8722 | AF9: 0.875 | AG9: 0.8759 | AH9: 0.8768 | AI9: 0.8768 | AJ9: 0.8778 | AK9: 0.8778 | AL9: 0.8796 | AM9: 0.8805 | AN9: 0.8814 | AO9: 0.8824 | AP9: 0.8833 | AQ9: 0.8833 | AR9: 0.8842 | AS9: 0.8842 | AT9: 0.8851 | AU9: 0.8851 | AV9: 0.8851 | AW9: 0.886 | AX9: 0.886 | AY9: 0.886 | AZ9: 0.886 | BA9: 0.8869 | BB9: 0.8869 | BC9: 0.8869 | BD9: 0.8869 | BE9: 0.8869 | BF9: 0.8879 | BG9: 0.8879 | BH9: 0.8879 | BI9: 0.8879 | BJ9: 0.8888 | BK9: 0.8888 | BL9: 0.8888 | BM9: 0.8897 | BN9: 0.8897 | BO9: 0.8897 | BP9: 0.8906 | BQ9: 0.8915 | BR9: 0.8915 | BS9: 0.8915 | BT9: 0.8925 | BU9: 0.8925 | BV9: 0.8925 | BW9: 0.8925 | BX9: 0.8934 | BY9: 0.8934 | BZ9: 0.8934 | CA9: 0.8943 | CB9: 0.8952 | CC9: 0.8952 | CD9: 0.8952 | CE9: 0.8952 | CF9: 0.8952 | CG9: 0.8961 | CH9: 0.8961 | CI9: 0.8961 | CJ9: 0.8961 | CK9: 0.8971 | CL9: 0.8971 | CM9: 0.8971 | CN9: 0.8971 | CO9: 0.8971 | CP9: 0.8971 | CQ9: 0.8971 | CR9: 0.898 | CS9: 0.898 | CT9: 0.898 | CU9: 0.898 | CV9: 0.898 | CW9: 0.898 | CX9: 0.8989 | CY9: 0.8989 | CZ9: 0.8989 | DA9: 0.8998 | DB9: 0.8998 | DC9: 0.8998 | DD9: 0.8998 | DE9: 0.8998 | DF9: 0.8998 | DG9: 0.9007 | DH9: 0.9007 | DI9: 0.9007 | DJ9: 0.9007 | DK9: 0.9007 | DL9: 0.9007 | DM9: 0.9007 | DN9: 0.9007 | DO9: 0.9017 | DP9: 0.9017 | DQ9: 0.9026 | DR9: 0.9026 | DS9: 0.9026 | DT9: 0.9026 | DU9: 0.9026 | DV9: 0.9026 | DW9: 0.9026 | DX9: 0.9026 | DY9: 0.9026 | DZ9: 0.9026 | EA9: 0.9026 | EB9: 0.9035 | EC9: 0.9035 | ED9: 0.9035 | EE9: 0.9035 | EF9: 0.9035 | EG9: 0.9035 | EH9: 0.9035 | EI9: 0.9044 | EJ9: 0.9044 | EK9: 0.9044 | EL9: 0.9044 | EM9: 0.9044 | EN9: 0.9044 | EO9: 0.9044 | EP9: 0.9044 | EQ9: 0.9044 | ER9: 0.9044 | ES9: 0.9044 | ET9: 0.9053 | EU9: 0.9053 | EV9: 0.9053 | EW9: 0.9053 | EX9: 0.9053 | EY9: 0.9053 | EZ9: 0.9053 | FA9: 0.9062 | FB9: 0.9062 | FC9: 0.9062 | FD9: 0.9062 | FE9: 0.9062 | FF9: 0.9062 | FG9: 0.9062 | FH9: 0.9062 | FI9: 0.9072 | FJ9: 0.9072 | FK9: 0.9072 | FL9: 0.9072 | FM9: 0.9081 | FN9: 0.9081 | FO9: 0.9081 | FP9: 0.9081 | FQ9: 0.9081 | FR9: 0.9081 | FS9: 0.9081 | FT9: 0.909 | FU9: 0.909 | FV9: 0.909 | FW9: 0.909 | FX9: 0.909 | FY9: 0.909 | FZ9: 0.9099 | GA9: 0.9099 | GB9: 0.9099 | GC9: 0.9099 | GD9: 0.9099 | GE9: 0.9099 | GF9: 0.9099 | GG9: 0.9108 | GH9: 0.9108 | GI9: 0.9108 | GJ9: 0.9108 | GK9: 0.9108 | GL9: 0.9108 | GM9: 0.9108 | GN9: 0.9108 | GO9: 0.9108 | GP9: 0.9108 | GQ9: 0.9118 | GR9: 0.9118 | GS9: 0.9118 | GT9: 0.9118 | GU9: 0.9118 | GV9: 0.9118 | GW9: 0.9118 | GX9: 0.9127 | GY9: 0.9127 | GZ9: 0.9127 | HA9: 0.9127 | HB9: 0.9127 | HC9: 0.9136 | HD9: 0.9136 | HE9: 0.9136 | HF9: 0.9136 | HG9: 0.9136 | HH9: 0.9136 | HI9: 0.9136 | HJ9: 0.9136 | HK9: 0.9136 | HL9: 0.9145 | HM9: 0.9145 | HN9: 0.9145 | HO9: 0.9145 | HP9: 0.9145 | HQ9: 0.9145 | HR9: 0.9154 | HS9: 0.9154 | HT9: 0.9154 | HU9: 0.9154 | HV9: 0.9154 | HW9: 0.9154 | HX9: 0.9164 | HY9: 0.9164 | HZ9: 0.9164 | IA9: 0.9164 | IB9: 0.9164 | IC9: 0.9164 | ID9: 0.9173 | IE9: 0.9173 | IF9: 0.9173 | IG9: 0.9173 | IH9: 0.9173 | II9: 0.9182 | IJ9: 0.9182 | IK9: 0.9182 | IL9: 0.9191 | IM9: 0.9191 | IN9: 0.9191 | IO9: 0.9191 | IP9: 0.9191 | IQ9: 0.92 | IR9: 0.92 | IS9: 0.92 | IT9: 0.92 | IU9: 0.921 | IV9: 0.921 | IW9: 0.921 | IX9: 0.921 | IY9: 0.921 | IZ9: 0.921 | JA9: 0.9219 | JB9: 0.9228 | JC9: 0.9228 | JD9: 0.9228 | JE9: 0.9237 | JF9: 0.9237 | JG9: 0.9237 | JH9: 0.9237 | JI9: 0.9246 | JJ9: 0.9246 | JK9: 0.9246 | JL9: 0.9246 | JM9: 0.9256 | JN9: 0.9265 | JO9: 0.9274 | JP9: 0.9283 | JQ9: 0.9283 | JR9: 0.9283 | JS9: 0.9301 | JT9: 0.9301 | JU9: 0.932 | JV9: 0.932 | JW9: 0.932 | JX9: 0.932 | JY9: 0.9393 | JZ9: 0.9412
