Workbook

Sheet Summary_RTD
A1: 20250728~20250803 | B1: CP/FT | C1: Total IC | D1: Throughput | E1: Yield | G1: 20250728~20250803 | H1: CP/FT | I1: RTD No. | K1: Total IC | L1: Throughput | M1: Yield
A2: RL6982 Merlin9 | B2: CP | C2: 448147 | D2: 401507 | E2: 0.8959 | G2: RL6982 Merlin9 | H2: CP | I2: RL6982 | K2: 448147 | L2: 401507 | M2: 0.8959
B3: FT1 | C3: 360336 | D3: 358677 | E3: 0.9954 | H3: FT1 | I3: RTD2875QDA_HD_TA01 | K3: 104240 | L3: 103717 | M3: 0.995
A4: RL6963 Mac8q | B4: CP | C4: 41932 | D4: 37722 | E4: 0.8996 | I4: RTD2875QDA_TA01 | K4: 256096 | L4: 254960 | M4: 0.9956
B5: FT1 | C5: 131349 | D5: 130770 | E5: 0.9956 | G5: RL6963 Mac8q | H5: CP | I5: RL6963 | K5: 41932 | L5: 37722 | M5: 0.8996
B6: FT2 | C6: 137095 | D6: 136588 | E6: 0.9963 | H6: FT1 | I6: RTD2841FLW_TA01 | K6: 37220 | L6: 37133 | M6: 0.9977
A7: RL6896 Dante | B7: CP | C7: 0 | D7: 0 | I7: RTD2864FLV_TA01 | K7: 73231 | L7: 72862 | M7: 0.995
B8: FT1 | C8: 0 | D8: 0 | I8: RTD2851FCA_TA01 | K8: 20898 | L8: 20775 | M8: 0.9941
A9: RL6866 Mac8p | B9: CP | C9: 0 | D9: 0 | H9: FT2 | I9: RTD2841FLW | K9: 137095 | L9: 136588 | M9: 0.9963
A10: RL6856 Merlin8 | B10: CP | C10: 104512 | D10: 87433 | E10: 0.8366 | G10: RL6896 Dante | H10: CP | I10: RL6896 | K10: 0 | L10: 0
B11: FT1 | C11: 49452 | D11: 49080 | E11: 0.9925 | G11: RL6866 Mac8p | H11: CP | I11: RL6866 | K11: 0 | L11: 0
B12: FT2 | C12: 42038 | D12: 41932 | E12: 0.9975 | G12: RL6856 Merlin8 | H12: CP | I12: RL6856 | K12: 104512 | L12: 87433 | M12: 0.8366
A13: RL6750 H5C2 | B13: CP | C13: 0 | D13: 0 | H13: FT1 | I13: RTD2886NSS_SC_FT1_TA01 | K13: 16631 | L13: 16565 | M13: 0.996
A14: RL6748 Merlin7 | B14: CP | C14: 100806 | D14: 86516 | E14: 0.8582 | I14: RTD2885PDM_FT1_TA01 | K14: 32821 | L14: 32515 | M14: 0.9907
B15: FT1 | C15: 240177 | D15: 239333 | E15: 0.9965 | H15: FT2 | I15: RTD2885PDM | K15: 12464 | L15: 12463 | M15: 0.9999
B16: FT2 | C16: 41864 | D16: 41813 | E16: 0.9988 | I16: RTD2818AWA_SC_FT2_TA01 | K16: 4627 | L16: 4556 | M16: 0.9847
A17: RL6746 MIO | B17: CP | C17: 0 | D17: 0 | I17: RTD2886NSP_SC_FT2_TA01 | K17: 24947 | L17: 24913 | M17: 0.9986
A18: RL6708 Bridge | B18: CP | C18: 0 | D18: 0 | G18: RL6750 H5C2 | H18: CP | I18: RL6750 | K18: 0 | L18: 0
B19: FT1 | C19: 7324 | D19: 7319 | E19: 0.9993 | G19: RL6748 Merlin7 | H19: CP | I19: RL6748 | K19: 100806 | L19: 86516 | M19: 0.8582
A20: RL6681 ATSC3 | B20: CP | C20: 0 | D20: 0 | H20: FT1 | I20: RTD2875NDB_LC_TA01 | K20: 33982 | L20: 33831 | M20: 0.9956
B21: FT1 | C21: 0 | D21: 0 | I21: RTD2875PSA_SC_TA01 | K21: 37935 | L21: 37835 | M21: 0.9974
A22: RL6672 Merlin6 | B22: CP | C22: 0 | D22: 0 | I22: RTD2874WDA_SC_TA01 | K22: 13200 | L22: 13154 | M22: 0.9965
B23: FT1 | C23: 3648 | D23: 3610 | E23: 0.9896 | I23: RTD2875PSP_SC_TA01 | K23: 65214 | L23: 64969 | M23: 0.9962
B24: FT2 | C24: 803 | D24: 803 | E24: 1 | I24: RTD2875PZK_SC_TA01 | K24: 24541 | L24: 24517 | M24: 0.999
A25: RL6641 Mac7p | B25: CP | C25: 131384 | D25: 119500 | E25: 0.9095 | I25: RTD2875NAA_SC_TA01 | K25: 9210 | L25: 9155 | M25: 0.994
B26: FT1 | C26: 47439 | D26: 47069 | E26: 0.9922 | I26: RTD2875NDA_LC_TA01 | K26: 14381 | L26: 14312 | M26: 0.9952
A27: RL6617 Merlin5 | B27: CP | C27: 0 | D27: 0 | I27: RTD2875PNJ_SND_TA01 | K27: 11906 | L27: 11850 | M27: 0.9953
B28: FT1 | C28: 13306 | D28: 13267 | E28: 0.9971 | I28: RTD2875PCK_SC_TA01 | K28: 29808 | L28: 29710 | M28: 0.9967
B29: FT2 | C29: 0 | D29: 0 | H29: FT2 | I29: RTD2875NDB_C_FT2 | K29: 5255 | L29: 5255 | M29: 1
I30: RTD2875_C_FT2 | K30: 36609 | L30: 36558 | M30: 0.9986
G31: RL6746 MIO | H31: CP | I31: RL6746 | K31: 0 | L31: 0
G32: RL6708 Bridge | H32: CP | I32: RL6708 | K32: 0 | L32: 0
H33: FT1 | I33: RTD2800TR | K33: 7324 | L33: 7319 | M33: 0.9993
G34: RL6681 ATSC3 | H34: CP | I34: RL6681 | K34: 0 | L34: 0
G35: RL6672 Merlin6 | H35: CP | I35: RL6672 | K35: 0 | L35: 0
H36: FT1 | I36: RTD2873ASR_HVC | J36: Sony DDR4(2G/三星) | K36: 811 | L36: 803 | M36: 0.9901
I37: RTD2873ASS_HVF | K37: 2837 | L37: 2807 | M37: 0.9894
H38: FT2 | I38: RTD2875SF_SONY_FT2 | J38: Sony FT2 | K38: 803 | L38: 803 | M38: 1
G39: RL6641 Mac7p | H39: CP | I39: RL6641 | K39: 131384 | L39: 119500 | M39: 0.9095
H40: FT1 | I40: RTD2851ASS_PS | K40: 763 | L40: 758 | M40: 0.9934
...

Sheet Top_all
A1: Project | B1: CP/FT | C1: RTD No. | E1: ECN Ver. | G1: summary | H1: Y25_W31 | J1: Top1 | K1: Top2 | L1: Top3 | M1: Top4 | N1: Top5 | O1: Top6 | P1: Top7 | Q1: Top8 | R1: Top9 | S1: Top10 | Y1: Project | Z1: CP/FT | AA1: RTD No. | AC1: ECN Ver. | AD1: Total IC | AE1: Throughput | AF1: Yield | AG1: Top1 | AH1: Top2 | AI1: Top3 | AJ1: Top4 | AK1: Top5 | AL1: Top6 | AM1: Top7 | AN1: Top8 | AO1: Top9 | AP1: Top10
A2: RL6982 Merlin9 | B2: CP | C2: RL6982 | E2: V03 | F2: Total IC | G2: 448147 | H2: 448147 | I2: Test item | J2: cp_mode2_saf_spc30_comp | K2: cp_mode3_saf_comp | L2: all_bist_wo_ETN_HV | M2: cp_mode1_saf_comp | N2: cp_mode0_saf_comp | O2: SCPU_L3_BISR_HV | P2: scpu_bist_all_1p2_HV | Q2: PowerShort | R2: all_bisr_drf_mp_BISR_HV | S2: EJTAG_GPU_BIST_HV | Y2: RL6982 Merlin9 | Z2: CP | AA2: RL6982 | AC2: V03 | AD2: 448147 | AE2: 401507 | AF2: 0.8959 | AG2: cp_mode2_saf_spc30_comp(12155ea,2.71%) | AH2: cp_mode3_saf_comp(7552ea,1.69%) | AI2: all_bist_wo_ETN_HV(6088ea,1.36%) | AJ2: cp_mode1_saf_comp(4526ea,1.01%) | AK2: cp_mode0_saf_comp(4160ea,0.93%) | AL2: SCPU_L3_BISR_HV(1726ea,0.39%) | AM2: scpu_bist_all_1p2_HV(1120ea,0.25%) | AN2: PowerShort(1120ea,0.25%) | AO2: all_bisr_drf_mp_BISR_HV(957ea,0.21%) | AP2: EJTAG_GPU_BIST_HV(677ea,0.15%)
F3: Throughput | G3: 401507 | H3: 401507 | I3: q'ty | J3: 12155 | K3: 7552 | L3: 6088 | M3: 4526 | N3: 4160 | O3: 1726 | P3: 1120 | Q3: 1120 | R3: 957 | S3: 677 | Z3: FT1 | AA3: RTD2875QDA_HD_TA01 | AC3: V02 | AD3: 82997 | AE3: 82572 | AF3: 0.9949 | AG3: DDR4_2G_3000_SS_single_RW_FT(121ea,0.15%) | AH3: DDR4_2G_3000_SS_FRC_ZQp5p(72ea,0.09%) | AI3: OS_500uA(50ea,0.06%) | AJ3: FW_other(50ea,0.06%) | AK3: USB2_disconnect_mea(39ea,0.05%) | AL3: PowerShort(15ea,0.02%) | AM3: IDDQ(15ea,0.02%) | AN3: FW_MULTI_CORE_TEST(10ea,0.01%) | AO3: all_bisr_drf(8ea,0.01%) | AP3: Wire_Bond_Leak(7ea,0.01%)
F4: Yield | G4: 0.8959 | H4: 0.8959 | I4: % | J4: 0.0271 | K4: 0.0169 | L4: 0.0136 | M4: 0.0101 | N4: 0.0093 | O4: 0.0039 | P4: 0.0025 | Q4: 0.0025 | R4: 0.0021 | S4: 0.0015 | Z4: FT1 | AA4: RTD2875QDA_TA01 | AC4: V03 | AD4: 155493 | AE4: 154909 | AF4: 0.9962 | AG4: DDR4_2G_3000_SS_single_RW_FT(154ea,0.10%) | AH4: FW_other(118ea,0.08%) | AI4: DDR4_2G_3000_SS_FRC_ZQp5p(98ea,0.06%) | AJ4: OS_500uA(43ea,0.03%) | AK4: VDC02_FT02_SNR(19ea,0.01%) | AL4: all_bisr_drf(17ea,0.01%) | AM4: scpu_bist_all_1p2_HV(16ea,0.01%) | AN4: IFD_FT03_IADC_ramp(13ea,0.01%) | AO4: PowerShort(10ea,0.01%) | AP4: USB2_disconnect_mea(9ea,0.01%)
B5: FT1 | C5: RTD2875QDA_HD_TA01 | E5: V02 | F5: Total IC | G5: 82997 | H5: 82997 | I5: Test item | J5: DDR4_2G_3000_SS_single_RW_FT | K5: DDR4_2G_3000_SS_FRC_ZQp5p | L5: OS_500uA | M5: FW_other | N5: USB2_disconnect_mea | O5: PowerShort | P5: IDDQ | Q5: FW_MULTI_CORE_TEST | R5: all_bisr_drf | S5: Wire_Bond_Leak | Z5: FT1 | AA5: RTD2875QDA_TA01 | AC5: V02 | AD5: 100603 | AE5: 100051 | AF5: 0.9945 | AG5: DDR4_2G_3000_SS_single_RW_FT(176ea,0.17%) | AH5: DDR4_2G_3000_SS_FRC_ZQp5p(106ea,0.11%) | AI5: FW_other(81ea,0.08%) | AJ5: OS_500uA(67ea,0.07%) | AK5: USB2_disconnect_mea(44ea,0.04%) | AL5: PowerShort(25ea,0.02%) | AM5: Wire_Bond_Leak(9ea,0.01%) | AN5: ETN_TX_MDI(6ea,0.01%) | AO5: all_bisr_drf(5ea,0.00%) | AP5: HDMI20_250M_mm(4ea,0.00%)
F6: Throughput | G6: 82572 | H6: 82572 | I6: q'ty | J6: 121 | K6: 72 | L6: 50 | M6: 50 | N6: 39 | O6: 15 | P6: 15 | Q6: 10 | R6: 8 | S6: 7 | Z6: FT1 | AA6: RTD2875QDA_HD_TA01 | AC6: V03 | AD6: 21243 | AE6: 21145 | AF6: 0.9954 | AG6: DDR4_2G_3000_SS_single_RW_FT(34ea,0.16%) | AH6: DDR4_2G_3000_SS_FRC_ZQp5p(26ea,0.12%) | AI6: FW_other(11ea,0.05%) | AJ6: USB2_disconnect_mea(6ea,0.03%) | AK6: OS_500uA(5ea,0.02%) | AL6: PowerShort(5ea,0.02%) | AM6: all_bisr_drf(3ea,0.01%) | AN6: Wire_Bond_Leak(2ea,0.01%) | AO6: FW_MULTI_CORE_TEST(1ea,0.00%) | AP6: PIF_LVDS_FT(1ea,0.00%)
F7: Yield | G7: 0.9949 | H7: 0.9949 | I7: % | J7: 0.0015 | K7: 0.0009 | L7: 0.0006 | M7: 0.0006 | N7: 0.0005 | O7: 0.0002 | P7: 0.0002 | Q7: 0.0001 | R7: 0.0001 | S7: 0.0001 | Y7: RL6963 Mac8q | Z7: CP | AA7: RL6963 | AC7: V07 | AD7: 41932 | AE7: 37722 | AF7: 0.8996 | AG7: cp_mode1_saf_comp_B(1043ea,2.49%) | AH7: cp_mode0_saf_comp(683ea,1.63%) | AI7: cp_mode2_saf_comp_B(499ea,1.19%) | AJ7: all_bist_m_0217_p1_BIST_LDOoff_OC700_HV(394ea,0.94%) | AK7: cp_mode1_tdf_cov70_comp_HV(220ea,0.52%) | AL7: mac8p_scpu_bisr_bist_drf_etn_phy_LV_only_drf_0214(178ea,0.42%) | AM7: IDD(167ea,0.40%) | AN7: os(96ea,0.23%) | AO7: PowerShort(88ea,0.21%) | AP7: cp_mode2_tdf_mask_dp14_dpll_plp25_Bcut_cov70_comp_HV(69ea,0.16%)
B8: FT1 | C8: RTD2875QDA_TA01 | E8: V03 | F8: Total IC | G8: 155493 | H8: 155493 | I8: Test item | J8: DDR4_2G_3000_SS_single_RW_FT | K8: FW_other | L8: DDR4_2G_3000_SS_FRC_ZQp5p | M8: OS_500uA | N8: VDC02_FT02_SNR | O8: all_bisr_drf | P8: scpu_bist_all_1p2_HV | Q8: IFD_FT03_IADC_ramp | R8: PowerShort | S8: USB2_disconnect_mea | Z8: FT1 | AA8: RTD2841FLW_TA01 | AC8: V10 | AD8: 37220 | AE8: 37133 | AF8: 0.9977 | AG8: FW_other(24ea,0.06%) | AH8: all_bist_m_0217_p1_BIST_LDOon_HV(19ea,0.05%) | AI8: all_bist_m_0217_p5_scpu_bist_LDOon_HV(6ea,0.02%) | AJ8: FW_HDMI_4K60(6ea,0.02%) | AK8: D4_2666M_FRC_4K60_uhd_LB_FT(4ea,0.01%) | AL8: os(3ea,0.01%) | AM8: power_short(3ea,0.01%) | AN8: FW_Multi_core_test_1(3ea,0.01%) | AO8: ETN_MLT3(3ea,0.01%) | AP8: SCPU_BISR_HV(2ea,0.01%)
F9: Throughput | G9: 154909 | H9: 154909 | I9: q'ty | J9: 154 | K9: 118 | L9: 98 | M9: 43 | N9: 19 | O9: 17 | P9: 16 | Q9: 13 | R9: 10 | S9: 9 | Z9: FT1 | AA9: RTD2864FLV_TA01 | AC9: V10 | AD9: 73231 | AE9: 72862 | AF9: 0.995 | AG9: FW_other(143ea,0.20%) | AH9: FW_HDMI_4K60(61ea,0.08%) | AI9: D4_2666M_FRC_4K60_uhd_LB_FT(38ea,0.05%) | AJ9: os(26ea,0.04%) | AK9: all_bist_m_0217_p1_BIST_LDOon_HV(22ea,0.03%) | AL9: ETN_MLT3(15ea,0.02%) | AM9: PIF_LVDS_FT(12ea,0.02%) | AN9: power_short(8ea,0.01%) | AO9: PIF_PP_FT_780M(4ea,0.01%) | AP9: IFD_FT02(4ea,0.01%)
F10: Yield | G10: 0.9962 | H10: 0.9962 | I10: % | J10: 0.001 | K10: 0.0008 | L10: 0.0006 | M10: 0.0003 | N10: 0.0001 | O10: 0.0001 | P10: 0.0001 | Q10: 0.0001 | R10: 0.0001 | S10: 0.0001 | Z10: FT1 | AA10: RTD2851FCA_TA01 | AC10: V10 | AD10: 20898 | AE10: 20775 | AF10: 0.9941 | AG10: FW_other(43ea,0.21%) | AH10: FW_HDMI_4K60(24ea,0.11%) | AI10: PIF_LVDS_FT(12ea,0.06%) | AJ10: D4_2666M_FRC_4K60_uhd_LB_FT(11ea,0.05%) | AK10: all_bist_m_0217_p1_BIST_LDOon_HV(5ea,0.02%) | AL10: FW_EMMC(3ea,0.01%) | AM10: os(3ea,0.01%) | AN10: power_short(3ea,0.01%) | AO10: IFD_FT02(2ea,0.01%) | AP10: IFD_FT03_IADC_ramp(2ea,0.01%)
B11: FT1 | C11: RTD2875QDA_TA01 | E11: V02 | F11: Total IC | G11: 100603 | H11: 100603 | I11: Test item | J11: DDR4_2G_3000_SS_single_RW_FT | K11: DDR4_2G_3000_SS_FRC_ZQp5p | L11: FW_other | M11: OS_500uA | N11: USB2_disconnect_mea | O11: PowerShort | P11: Wire_Bond_Leak | Q11: ETN_TX_MDI | R11: all_bisr_drf | S11: HDMI20_250M_mm | Z11: FT2 | AA11: RTD2841FLW | AC11: V01 | AD11: 137095 | AE11: 136588 | AF11: 0.9963 | AG11: USB2_Swing(323ea,0.24%) | AH11: IDDQ(171ea,0.12%) | AI11: USB2_Disconnect_trim(6ea,0.00%) | AJ11: Chip_ID_B(4ea,0.00%) | AK11: Wire_bond_leak(3ea,0.00%)
F12: Throughput | G12: 100051 | H12: 100051 | I12: q'ty | J12: 176 | K12: 106 | L12: 81 | M12: 67 | N12: 44 | O12: 25 | P12: 9 | Q12: 6 | R12: 5 | S12: 4 | Y12: RL6856 Merlin8 | Z12: CP | AA12: RL6856 | AC12: V10 | AD12: 104512 | AE12: 87433 | AF12: 0.8366 | AG12: cp_mode2_saf_comp_24ns(3191ea,3.05%) | AH12: cp_mode3_saf_comp_VT(2640ea,2.53%) | AI12: all_bist_mp_gpu_HV(2618ea,2.50%) | AJ12: cp_mode1_saf_comp(1249ea,1.20%) | AK12: cp_mode0_saf_comp(1143ea,1.09%) | AL12: all_bist_mp_gpu_LV(1136ea,1.09%) | AM12: IDD(754ea,0.72%) | AN12: power_short(543ea,0.52%) | AO12: core_scpu_power_IDD_spec(416ea,0.40%) | AP12: cp_mode3_tdf_c5_comp_HV_24ns(329ea,0.31%)
F13: Yield | G13: 0.9945 | H13: 0.9945 | I13: % | J13: 0.0017 | K13: 0.0011 | L13: 0.0008 | M13: 0.0007 | N13: 0.0004 | O13: 0.0002 | P13: 0.0001 | Q13: 0.0001 | R13: 0 | S13: 0 | Z13: FT1 | AA13: RTD2886NSS_SC_FT1_TA01 | AC13: V08 | AD13: 16631 | AE13: 16565 | AF13: 0.996 | AG13: FW_USB(36ea,0.22%) | AH13: ddr_single_rw(8ea,0.05%) | AI13: FW_MEMC(5ea,0.03%) | AJ13: FW_VE(4ea,0.02%) | AK13: IDDQ(3ea,0.02%) | AL13: ddr_FRC_CN_n5percent(2ea,0.01%) | AM13: Power_Short(2ea,0.01%) | AN13: FW_ETN(1ea,0.01%) | AO13: Thermal_IDD_comp_4K(1ea,0.01%) | AP13: set-error-bin(1ea,0.01%)
B14: FT1 | C14: RTD2875QDA_HD_TA01 | E14: V03 | F14: Total IC | G14: 21243 | H14: 21243 | I14: Test item | J14: DDR4_2G_3000_SS_single_RW_FT | K14: DDR4_2G_3000_SS_FRC_ZQp5p | L14: FW_other | M14: USB2_disconnect_mea | N14: OS_500uA | O14: PowerShort | P14: all_bisr_drf | Q14: Wire_Bond_Leak | R14: FW_MULTI_CORE_TEST | S14: PIF_LVDS_FT | Z14: FT1 | AA14: RTD2885PDM_FT1_TA01 | AC14: V06 | AD14: 32821 | AE14: 32515 | AF14: 0.9907 | AG14: FW_M8(164ea,0.50%) | AH14: HDMI_12G(63ea,0.19%) | AI14: DDR_single_RW_D4(30ea,0.09%) | AJ14: VDC01_FT01_SNR(14ea,0.04%) | AK14: Power_Short(10ea,0.03%) | AL14: DDR_ZQ_P(8ea,0.02%) | AM14: set-error-bin(5ea,0.02%) | AN14: IDDQ(2ea,0.01%) | AO14: HDMI_0p25G(2ea,0.01%) | AP14: OS_500uA(2ea,0.01%)
F15: Throughput | G15: 21145 | H15: 21145 | I15: q'ty | J15: 34 | K15: 26 | L15: 11 | M15: 6 | N15: 5 | O15: 5 | P15: 3 | Q15: 2 | R15: 1 | S15: 1 | Z15: FT2 | AA15: RTD2885PDM | AC15: V04 | AD15: 12464 | AE15: 12463 | AF15: 0.9999 | AG15: USB2_Swing(1ea,0.01%)
F16: Yield | G16: 0.9954 | H16: 0.9954 | I16: % | J16: 0.0016 | K16: 0.0012 | L16: 0.0005 | M16: 0.0003 | N16: 0.0002 | O16: 0.0002 | P16: 0.0001 | Q16: 0.0001 | R16: 0 | S16: 0 | Z16: FT2 | AA16: RTD2818AWA_SC_FT2_TA01 | AC16: V03 | AD16: 4627 | AE16: 4556 | AF16: 0.9847 | AG16: DPRX_AUX_TX_Z0(66ea,1.43%) | AH16: USB2_Disconnect_trim(5ea,0.11%)
A17: RL6963 Mac8q | B17: CP | C17: RL6963 | E17: V07 | F17: Total IC | G17: 41932 | H17: 41932 | I17: Test item | J17: cp_mode1_saf_comp_B | K17: cp_mode0_saf_comp | L17: cp_mode2_saf_comp_B | M17: all_bist_m_0217_p1_BIST_LDOoff_OC700_HV | N17: cp_mode1_tdf_cov70_comp_HV | O17: mac8p_scpu_bisr_bist_drf_etn_phy_LV_only_drf_0214 | P17: IDD | Q17: os | R17: PowerShort | S17: cp_mode2_tdf_mask_dp14_dpll_plp25_Bcut_cov70_comp_HV | Z17: FT2 | AA17: RTD2886NSP_SC_FT2_TA01 | AC17: V04 | AD17: 24947 | AE17: 24913 | AF17: 0.9986 | AG17: USB2_Disconnect_trim(31ea,0.12%) | AH17: Wire_bond_leak(1ea,0.00%) | AI17: OS_2mA(1ea,0.00%) | AJ17: USB2_Squelch_trim(1ea,0.00%)
F18: Throughput | G18: 37722 | H18: 37722 | I18: q'ty | J18: 1043 | K18: 683 | L18: 499 | M18: 394 | N18: 220 | O18: 178 | P18: 167 | Q18: 96 | R18: 88 | S18: 69 | Y18: RL6748 Merlin7 | Z18: CP | AA18: RL6748 | AC18: V25 | AD18: 100806 | AE18: 86516 | AF18: 0.8582 | AG18: all_bist_mp_scpu_all_bist_1106_CLK144_GPU_ETN_HV(2879ea,2.86%) | AH18: cp_mode0_saf_0to90_comp_C(2762ea,2.74%) | AI18: cp_mode2_saf_0to90_comp_C_slow(1982ea,1.97%) | AJ18: cp_mode1_saf_0to90_comp_C(1288ea,1.28%) | AK18: IDD(1214ea,1.20%) | AL18: cp_mode0_0_tdf_lp8_cat_comp_C_LV(790ea,0.78%) | AM18: cp_mode0_2_sdd_se0_a75_lp14_dsu_lp28_cat_cs1013_comp_LV(563ea,0.56%) | AN18: PowerShort(424ea,0.42%) | AO18: OTP_iddq_rtk(274ea,0.27%) | AP18: cp_mode0_tdf_se0_l3mcp_ttr_cov70_comp_HV(252ea,0.25%)
F19: Yield | G19: 0.8996 | H19: 0.8996 | I19: % | J19: 0.0249 | K19: 0.0163 | L19: 0.0119 | M19: 0.0094 | N19: 0.0052 | O19: 0.0042 | P19: 0.004 | Q19: 0.0023 | R19: 0.0021 | S19: 0.0016 | Z19: FT1 | AA19: RTD2875NDB_LC_TA01 | AC19: V25 | AD19: 33982 | AE19: 33831 | AF19: 0.9956 | AG19: DDR_1p5GB_FRC_HV_1st(84ea,0.25%) | AH19: OS_500uA(19ea,0.06%) | AI19: HDMI20_6G_VB(12ea,0.04%) | AJ19: HDMI20_1p5G(7ea,0.02%) | AK19: DDR_1p5GB_MD(3ea,0.01%) | AL19: Power_Short(3ea,0.01%) | AM19: FW_MD_Domain(3ea,0.01%) | AN19: DDR_1p5GB_FRC_LV(3ea,0.01%) | AO19: IDDQ(3ea,0.01%) | AP19: FW_M7(2ea,0.01%)
B20: FT1 | C20: RTD2841FLW_TA01 | E20: V10 | F20: Total IC | G20: 37220 | H20: 37220 | I20: Test item | J20: FW_other | K20: all_bist_m_0217_p1_BIST_LDOon_HV | L20: all_bist_m_0217_p5_scpu_bist_LDOon_HV | M20: FW_HDMI_4K60 | N20: D4_2666M_FRC_4K60_uhd_LB_FT | O20: os | P20: power_short | Q20: FW_Multi_core_test_1 | R20: ETN_MLT3 | S20: SCPU_BISR_HV | Z20: FT1 | AA20: RTD2875PSA_SC_TA01 | AC20: V12 | AD20: 37935 | AE20: 37835 | AF20: 0.9974 | AG20: FW_other(47ea,0.12%) | AH20: HDMI20_6G_VB(12ea,0.03%) | AI20: OS_500uA(9ea,0.02%) | AJ20: HDMI20_1p5G(8ea,0.02%) | AK20: FW_VDC_PQ(4ea,0.01%) | AL20: FW_ETN(4ea,0.01%) | AM20: FW_MTEST(3ea,0.01%) | AN20: BB_FT01(2ea,0.01%) | AO20: USB_disconnect_trim(2ea,0.01%) | AP20: FW_MEMC(2ea,0.01%)
F21: Throughput | G21: 37133 | H21: 37133 | I21: q'ty | J21: 24 | K21: 19 | L21: 6 | M21: 6 | N21: 4 | O21: 3 | P21: 3 | Q21: 3 | R21: 3 | S21: 2 | Z21: FT1 | AA21: RTD2874WDA_SC_TA01 | AC21: V25 | AD21: 13200 | AE21: 13154 | AF21: 0.9965 | AG21: DDR_1p5GB_FRC_HV_1st(20ea,0.15%) | AH21: OS_500uA(8ea,0.06%) | AI21: Power_Short(3ea,0.02%) | AJ21: POR(2ea,0.02%) | AK21: BB_FT01(2ea,0.02%) | AL21: HDMI20_6G_VB(2ea,0.02%) | AM21: HDMI20_1p5G(2ea,0.02%) | AN21: FW_MD_Domain(2ea,0.02%) | AO21: DDR_1p5GB_MD(1ea,0.01%) | AP21: ETN_TX_FT0(1ea,0.01%)
F22: Yield | G22: 0.9977 | H22: 0.9977 | I22: % | J22: 0.0006 | K22: 0.0005 | L22: 0.0002 | M22: 0.0002 | N22: 0.0001 | O22: 0.0001 | P22: 0.0001 | Q22: 0.0001 | R22: 0.0001 | S22: 0.0001 | Z22: FT1 | AA22: RTD2875PSP_SC_TA01 | AC22: V12 | AD22: 65214 | AE22: 64969 | AF22: 0.9962 | AG22: FW_other(94ea,0.14%) | AH22: FW_VDC_PQ(39ea,0.06%) | AI22: FW_MD_Domain(29ea,0.04%) | AJ22: OS_500uA(23ea,0.04%) | AK22: USB_squelch_trim(17ea,0.03%) | AL22: HDMI20_6G_VB(9ea,0.01%) | AM22: OS_2mA(7ea,0.01%) | AN22: Power_Short(6ea,0.01%) | AO22: FW_VE_Encode(3ea,0.00%) | AP22: BB_FT01(2ea,0.00%)
B23: FT1 | C23: RTD2864FLV_TA01 | E23: V10 | F23: Total IC | G23: 73231 | H23: 73231 | I23: Test item | J23: FW_other | K23: FW_HDMI_4K60 | L23: D4_2666M_FRC_4K60_uhd_LB_FT | M23: os | N23: all_bist_m_0217_p1_BIST_LDOon_HV | O23: ETN_MLT3 | P23: PIF_LVDS_FT | Q23: power_short | R23: PIF_PP_FT_780M | S23: IFD_FT02 | Z23: FT1 | AA23: RTD2875PZK_SC_TA01 | AC23: V12 | AD23: 24541 | AE23: 24517 | AF23: 0.999 | AG23: FW_other(7ea,0.03%) | AH23: HDMI20_6G_VB(4ea,0.02%) | AI23: OS_500uA(3ea,0.01%) | AJ23: HDMI20_1p5G(3ea,0.01%) | AK23: FW_MTEST(2ea,0.01%) | AL23: FW_VE_Encode(2ea,0.01%) | AM23: FW_USB(1ea,0.00%) | AN23: Power_Short(1ea,0.00%) | AO23: FW_VDC_PQ(1ea,0.00%)
F24: Throughput | G24: 72862 | H24: 72862 | I24: q'ty | J24: 143 | K24: 61 | L24: 38 | M24: 26 | N24: 22 | O24: 15 | P24: 12 | Q24: 8 | R24: 4 | S24: 4 | Z24: FT1 | AA24: RTD2875NAA_SC_TA01 | AC24: V25 | AD24: 9210 | AE24: 9155 | AF24: 0.994 | AG24: DDR_1p5GB_FRC_HV_1st(19ea,0.21%) | AH24: VDC03_FT02_INL_DNL(12ea,0.13%) | AI24: OS_500uA(11ea,0.12%) | AJ24: atsc_IFD_FT02_ramp_12b(3ea,0.03%) | AK24: FW_USB(2ea,0.02%) | AL24: atsc_IFD_FT01_12b(1ea,0.01%) | AM24: HDMI20_1p5G(1ea,0.01%) | AN24: HDMI20_6G_VB(1ea,0.01%) | AO24: IDDQ(1ea,0.01%) | AP24: VDC01_FT01_SNR(1ea,0.01%)
F25: Yield | G25: 0.995 | H25: 0.995 | I25: % | J25: 0.002 | K25: 0.0008 | L25: 0.0005 | M25: 0.0004 | N25: 0.0003 | O25: 0.0002 | P25: 0.0002 | Q25: 0.0001 | R25: 0.0001 | S25: 0.0001 | Z25: FT1 | AA25: RTD2875NDA_LC_TA01 | AC25: V25 | AD25: 14381 | AE25: 14312 | AF25: 0.9952 | AG25: DDR_1p5GB_FRC_HV_1st(27ea,0.19%) | AH25: FW_VDC_PQ(9ea,0.06%) | AI25: HDMI20_6G_VB(4ea,0.03%) | AJ25: OS_500uA(4ea,0.03%) | AK25: DDR_1p5GB_MD(4ea,0.03%) | AL25: FW_M7(3ea,0.02%) | AM25: Power_Short(3ea,0.02%) | AN25: USB_squelch_trim(3ea,0.02%) | AO25: wafer_info(3ea,0.02%) | AP25: FW_MD_Domain(2ea,0.01%)
B26: FT1 | C26: RTD2851FCA_TA01 | E26: V10 | F26: Total IC | G26: 20898 | H26: 20898 | I26: Test item | J26: FW_other | K26: FW_HDMI_4K60 | L26: PIF_LVDS_FT | M26: D4_2666M_FRC_4K60_uhd_LB_FT | N26: all_bist_m_0217_p1_BIST_LDOon_HV | O26: FW_EMMC | P26: os | Q26: power_short | R26: IFD_FT02 | S26: IFD_FT03_IADC_ramp | Z26: FT1 | AA26: RTD2875PNJ_SND_TA01 | AC26: V12 | AD26: 11906 | AE26: 11850 | AF26: 0.9953 | AG26: FW_other(17ea,0.14%) | AH26: OS_2mA(11ea,0.09%) | AI26: OS_500uA(8ea,0.07%) | AJ26: HDMI20_6G_VB(5ea,0.04%) | AK26: USB_squelch_trim(3ea,0.03%) | AL26: FW_USB(3ea,0.03%) | AM26: USB_disconnect_trim(3ea,0.03%) | AN26: FW_VE_Encode(2ea,0.02%) | AO26: HDMI20_1p5G(1ea,0.01%) | AP26: ETN_TX_FT0(1ea,0.01%)
F27: Throughput | G27: 20775 | H27: 20775 | I27: q'ty | J27: 43 | K27: 24 | L27: 12 | M27: 11 | N27: 5 | O27: 3 | P27: 3 | Q27: 3 | R27: 2 | S27: 2 | Z27: FT1 | AA27: RTD2875PCK_SC_TA01 | AC27: V12 | AD27: 29808 | AE27: 29710 | AF27: 0.9967 | AG27: FW_other(52ea,0.17%) | AH27: FW_MD_Domain(14ea,0.05%) | AI27: OS_500uA(8ea,0.03%) | AJ27: HDMI20_6G_VB(4ea,0.01%) | AK27: FW_VDE(3ea,0.01%) | AL27: OS_2mA(2ea,0.01%) | AM27: USB_squelch_trim(2ea,0.01%) | AN27: HDMI20_1p5G(2ea,0.01%) | AO27: Power_Short(2ea,0.01%) | AP27: BB_FT01(2ea,0.01%)
F28: Yield | G28: 0.9941 | H28: 0.9941 | I28: % | J28: 0.0021 | K28: 0.0011 | L28: 0.0006 | M28: 0.0005 | N28: 0.0002 | O28: 0.0001 | P28: 0.0001 | Q28: 0.0001 | R28: 0.0001 | S28: 0.0001 | Z28: FT2 | AA28: RTD2875NDB_C_FT2 | AC28: V06 | AD28: 5255 | AE28: 5255 | AF28: 1
B29: FT2 | C29: RTD2841FLW | E29: V01 | F29: Total IC | G29: 137095 | H29: 137095 | I29: Test item | J29: USB2_Swing | K29: IDDQ | L29: USB2_Disconnect_trim | M29: Chip_ID_B | N29: Wire_bond_leak | Z29: FT2 | AA29: RTD2875_C_FT2 | AC29: V07 | AD29: 36609 | AE29: 36558 | AF29: 0.9986 | AG29: PIF_CML_SWING_CAL(45ea,0.12%) | AH29: HDMI_Z0_N(3ea,0.01%) | AI29: por(1ea,0.00%) | AJ29: OTP_PIF_CML_cal(1ea,0.00%) | AK29: HDMI_Z0_P(1ea,0.00%)
F30: Throughput | G30: 136588 | H30: 136588 | I30: q'ty | J30: 323 | K30: 171 | L30: 6 | M30: 4 | N30: 3 | Y30: RL6708 Bridge | Z30: FT1 | AA30: RTD2800TR | AC30: V07 | AD30: 7324 | AE30: 7319 | AF30: 0.9993 | AG30: Vby1_CML_Mode_RX(2ea,0.03%) | AH30: os_TX_vb(2ea,0.03%) | AI30: OTP_IDDQ(1ea,0.01%)
F31: Yield | G31: 0.9963 | H31: 0.9963 | I31: % | J31: 0.0024 | K31: 0.0012 | L31: 0 | M31: 0 | N31: 0 | Y31: RL6672 Merlin6 | Z31: FT1 | AA31: RTD2873ASR_HVC | AB31: Sony DDR4(2G/三星) | AC31: V19 | AD31: 811 | AE31: 803 | AF31: 0.9901 | AG31: FRC_D4_2G_SS_LV(3ea,0.37%) | AH31: MC_D4_2G_SS_HV_1st(3ea,0.37%) | AI31: FW_SCPU_VDDR(1ea,0.12%) | AJ31: HDMI_RX_Z0(1ea,0.12%)
A32: RL6856 Merlin8 | B32: CP | C32: RL6856 | E32: V10 | F32: Total IC | G32: 104512 | H32: 104512 | I32: Test item | J32: cp_mode2_saf_comp_24ns | K32: cp_mode3_saf_comp_VT | L32: all_bist_mp_gpu_HV | M32: cp_mode1_saf_comp | N32: cp_mode0_saf_comp | O32: all_bist_mp_gpu_LV | P32: IDD | Q32: power_short | R32: core_scpu_power_IDD_spec | S32: cp_mode3_tdf_c5_comp_HV_24ns | Z32: FT1 | AA32: RTD2873ASS_HVF | AC32: V20 | AD32: 2837 | AE32: 2807 | AF32: 0.9894 | AG32: MC_D4_1p5G_SS_HV_1st(20ea,0.70%) | AH32: FRC_D4_1p5G_SS_HV(3ea,0.11%) | AI32: IFD_FT02(1ea,0.04%) | AJ32: VDC01_FT01_SNR(1ea,0.04%) | AK32: SIF_FT01(1ea,0.04%) | AL32: HDMI20_4k60_6G_Sony(1ea,0.04%) | AM32: Power_Short(1ea,0.04%) | AN32: FW_EMMC(1ea,0.04%) | AO32: ETN_TX_FT0(1ea,0.04%)
F33: Throughput | G33: 87433 | H33: 87433 | I33: q'ty | J33: 3191 | K33: 2640 | L33: 2618 | M33: 1249 | N33: 1143 | O33: 1136 | P33: 754 | Q33: 543 | R33: 416 | S33: 329 | Z33: FT2 | AA33: RTD2875SF_SONY_FT2 | AB33: Sony FT2 | AC33: V05 | AD33: 803 | AE33: 803 | AF33: 1
F34: Yield | G34: 0.8366 | H34: 0.8366 | I34: % | J34: 0.0305 | K34: 0.0253 | L34: 0.025 | M34: 0.012 | N34: 0.0109 | O34: 0.0109 | P34: 0.0072 | Q34: 0.0052 | R34: 0.004 | S34: 0.0031 | Y34: RL6641 Mac7p | Z34: CP | AA34: RL6641 | AC34: V16 | AD34: 131384 | AE34: 119500 | AF34: 0.9095 | AG34: cp_saf_mode2_comp_30_dummy_pattern_s2(2264ea,1.72%) | AH34: all_bist_etn_HV(2183ea,1.66%) | AI34: cp_saf_mode0_comp_tmax2_B_cut_s2(1734ea,1.32%) | AJ34: cp_saf_mode1_comp_tmax2_B_cut_s2(1308ea,1.00%) | AK34: cp_saf_mode6_comp_tmax2_B_cut_s2(1011ea,0.77%) | AL34: IDD(825ea,0.63%) | AM34: PowerShort(537ea,0.41%) | AN34: cp_tdf_mode2_comp_30_dummy_pattern_LV_s2(271ea,0.21%) | AO34: scpu_bist_all_mode_shr_delay2_SCPU1150_HV(192ea,0.15%) | AP34: GPU_DEC_OPEN_HV(173ea,0.13%)
B35: FT1 | C35: RTD2886NSS_SC_FT1_TA01 | E35: V08 | F35: Total IC | G35: 16631 | H35: 16631 | I35: Test item | J35: FW_USB | K35: ddr_single_rw | L35: FW_MEMC | M35: FW_VE | N35: IDDQ | O35: ddr_FRC_CN_n5percent | P35: Power_Short | Q35: FW_ETN | R35: Thermal_IDD_comp_4K | S35: set-error-bin | Z35: FT1 | AA35: RTD2851ASS_PS | AC35: V25 | AD35: 763 | AE35: 758 | AF35: 0.9934 | AG35: DDR4_FRC_2G_8G8G(5ea,0.66%)
F36: Throughput | G36: 16565 | H36: 16565 | I36: q'ty | J36: 36 | K36: 8 | L36: 5 | M36: 4 | N36: 3 | O36: 2 | P36: 2 | Q36: 1 | R36: 1 | S36: 1 | Z36: FT1 | AA36: RTD2841ASS_PS_TA01 | AC36: V26 | AD36: 24508 | AE36: 24291 | AF36: 0.9911 | AG36: DDR4_FRC_1p5G_8G4G(116ea,0.47%) | AH36: YPP03(19ea,0.08%) | AI36: FW_other(17ea,0.07%) | AJ36: FW_VE (16ea,0.07%) | AK36: FW_MD_DOMAIN (8ea,0.03%) | AL36: FW_ACPU (8ea,0.03%) | AM36: Wire_bond_leak(7ea,0.03%) | AN36: chip_id(4ea,0.02%) | AO36: HDMI_6G(3ea,0.01%) | AP36: VDC01_SNR(3ea,0.01%)
F37: Yield | G37: 0.996 | H37: 0.996 | I37: % | J37: 0.0022 | K37: 0.0005 | L37: 0.0003 | M37: 0.0002 | N37: 0.0002 | O37: 0.0001 | P37: 0.0001 | Q37: 0.0001 | R37: 0.0001 | S37: 0.0001 | Z37: FT1 | AA37: RTD2841ACM_PS_TA01 | AC37: V26 | AD37: 18926 | AE37: 18834 | AF37: 0.9951 | AG37: DDR4_FRC_1G_8G(50ea,0.26%) | AH37: YPP03(10ea,0.05%) | AI37: FW_VE (9ea,0.05%) | AJ37: FW_other(3ea,0.02%) | AK37: FW_ACPU (3ea,0.02%) | AL37: FW_MD_DOMAIN (2ea,0.01%) | AM37: VDC02_DAC_ramp(2ea,0.01%) | AN37: chip_id(2ea,0.01%) | AO37: VDC01_SNR(2ea,0.01%) | AP37: FW_VDE (1ea,0.01%)
B38: FT1 | C38: RTD2885PDM_FT1_TA01 | E38: V06 | F38: Total IC | G38: 32821 | H38: 32821 | I38: Test item | J38: FW_M8 | K38: HDMI_12G | L38: DDR_single_RW_D4 | M38: VDC01_FT01_SNR | N38: Power_Short | O38: DDR_ZQ_P | P38: set-error-bin | Q38: IDDQ | R38: HDMI_0p25G | S38: OS_500uA | Z38: FT1 | AA38: RTD2841ACS_PS_TA01 | AC38: V26 | AD38: 3242 | AE38: 3186 | AF38: 0.9827 | AG38: DDR4_FRC_1p5G_8G4G(31ea,0.96%) | AH38: FW_other(18ea,0.56%) | AI38: FW_ACPU (3ea,0.09%) | AJ38: FW_VE (2ea,0.06%) | AK38: VDC01_SNR(1ea,0.03%) | AL38: YPP03(1ea,0.03%)
F39: Throughput | G39: 32515 | H39: 32515 | I39: q'ty | J39: 164 | K39: 63 | L39: 30 | M39: 14 | N39: 10 | O39: 8 | P39: 5 | Q39: 2 | R39: 2 | S39: 2 | Y39: RL6617 Merlin5 | Z39: FT1 | AA39: RTD2851MCJSB | AC39: V15 | AD39: 13306 | AE39: 13267 | AF39: 0.9971 | AG39: DDR_FRC_NV_NY_part2(16ea,0.12%) | AH39: FW_other(5ea,0.04%) | AI39: HDMI_6G(4ea,0.03%) | AJ39: FW_MD_Domain (4ea,0.03%) | AK39: IDDQ(2ea,0.02%) | AL39: FW_ACPU (2ea,0.02%) | AM39: IDDQ_DDR_standby_NY(1ea,0.01%) | AN39: DDR_FRC_NV_NY_part6(1ea,0.01%) | AO39: FW_VDE (1ea,0.01%) | AP39: OTP_IDD(1ea,0.01%)
F40: Yield | G40: 0.9907 | H40: 0.9907 | I40: % | J40: 0.005 | K40: 0.0019 | L40: 0.0009 | M40: 0.0004 | N40: 0.0003 | O40: 0.0002 | P40: 0.0002 | Q40: 0.0001 | R40: 0.0001 | S40: 0.0001
...

Sheet RL6982_HD_TA01_V03_summary_raw
A1: 1 | B1: PASS BIN | C1: 401507 | D1: 0.8959 | N1: Project | O1: RL6982 | P1: RL6982 | Q1: RL6982 | R1: RL6982 | S1: RL6982 | T1: RL6982 | U1: RL6982 | V1: RL6982 | W1: RL6982 | X1: RL6982 | Y1: RL6982 | Z1: RL6982 | AA1: RL6982 | AB1: RL6982 | AC1: RL6982 | AD1: RL6982 | AE1: RL6982 | AF1: RL6982 | AG1: RL6982 | AH1: RL6982 | AI1: RL6982 | AJ1: RL6982 | AK1: RL6982 | AL1: RL6982 | AM1: RL6982 | AN1: RL6982 | AO1: RL6982 | AP1: RL6982 | AQ1: RL6982 | AR1: RL6982 | AS1: RL6982 | AT1: RL6982 | AU1: RL6982 | AV1: RL6982 | AW1: RL6982 | AX1: RL6982 | AY1: RL6982 | AZ1: RL6982 | BA1: RL6982 | BB1: RL6982 | BC1: RL6982 | BD1: RL6982 | BE1: RL6982 | BF1: RL6982 | BG1: RL6982 | BH1: RL6982 | BI1: RL6982 | BJ1: RL6982 | BK1: RL6982 | BL1: RL6982 | BM1: RL6982 | BN1: RL6982 | BO1: RL6982 | BP1: RL6982 | BQ1: RL6982 | BR1: RL6982 | BS1: RL6982 | BT1: RL6982 | BU1: RL6982 | BV1: RL6982 | BW1: RL6982 | BX1: RL6982 | BY1: RL6982 | BZ1: RL6982 | CA1: RL6982 | CB1: RL6982 | CC1: RL6982 | CD1: RL6982 | CE1: RL6982 | CF1: RL6982 | CG1: RL6982 | CH1: RL6982 | CI1: RL6982 | CJ1: RL6982 | CK1: RL6982 | CL1: RL6982 | CM1: RL6982 | CN1: RL6982 | CO1: RL6982 | CP1: RL6982 | CQ1: RL6982 | CR1: RL6982 | CS1: RL6982 | CT1: RL6982 | CU1: RL6982 | CV1: RL6982 | CW1: RL6982 | CX1: RL6982 | CY1: RL6982 | CZ1: RL6982 | DA1: RL6982 | DB1: RL6982 | DC1: RL6982 | DD1: RL6982 | DE1: RL6982 | DF1: RL6982 | DG1: RL6982 | DH1: RL6982 | DI1: RL6982 | DJ1: RL6982 | DK1: RL6982 | DL1: RL6982 | DM1: RL6982 | DN1: RL6982 | DO1: RL6982 | DP1: RL6982 | DQ1: RL6982 | DR1: RL6982 | DS1: RL6982 | DT1: RL6982 | DU1: RL6982 | DV1: RL6982 | DW1: RL6982 | DX1: RL6982 | DY1: RL6982 | DZ1: RL6982 | EA1: RL6982 | EB1: RL6982 | EC1: RL6982 | ED1: RL6982 | EE1: RL6982 | EF1: RL6982 | EG1: RL6982 | EH1: RL6982 | EI1: RL6982 | EJ1: RL6982 | EK1: RL6982 | EL1: RL6982 | EM1: RL6982 | EN1: RL6982 | EO1: RL6982 | EP1: RL6982 | EQ1: RL6982 | ER1: RL6982 | ES1: RL6982 | ET1: RL6982 | EU1: RL6982 | EV1: RL6982 | EW1: RL6982 | EX1: RL6982 | EY1: RL6982 | EZ1: RL6982 | FA1: RL6982 | FB1: RL6982 | FC1: RL6982 | FD1: RL6982 | FE1: RL6982 | FF1: RL6982 | FG1: RL6982 | FH1: RL6982 | FI1: RL6982 | FJ1: RL6982 | FK1: RL6982 | FL1: RL6982 | FM1: RL6982 | FN1: RL6982 | FO1: RL6982 | FP1: RL6982 | FQ1: RL6982 | FR1: RL6982 | FS1: RL6982 | FT1: RL6982 | FU1: RL6982 | FV1: RL6982 | FW1: RL6982 | FX1: RL6982 | FY1: RL6982 | FZ1: RL6982 | GA1: RL6982 | GB1: RL6982 | GC1: RL6982 | GD1: RL6982 | GE1: RL6982 | GF1: RL6982 | GG1: RL6982 | GH1: RL6982 | GI1: RL6982 | GJ1: RL6982 | GK1: RL6982 | GL1: RL6982 | GM1: RL6982 | GN1: RL6982 | GO1: RL6982 | GP1: RL6982 | GQ1: RL6982 | GR1: RL6982 | GS1: RL6982 | GT1: RL6982 | GU1: RL6982 | GV1: RL6982 | GW1: RL6982 | GX1: RL6982 | GY1: RL6982 | GZ1: RL6982 | HA1: RL6982 | HB1: RL6982 | HC1: RL6982 | HD1: RL6982 | HE1: RL6982 | HF1: RL6982 | HG1: RL6982 | HH1: RL6982 | HI1: RL6982 | HJ1: RL6982 | HK1: RL6982 | HL1: RL6982 | HM1: RL6982 | HN1: RL6982 | HO1: RL6982 | HP1: RL6982 | HQ1: RL6982 | HR1: RL6982 | HS1: RL6982 | HT1: RL6982 | HU1: RL6982 | HV1: RL6982 | HW1: RL6982 | HX1: RL6982 | HY1: RL6982 | HZ1: RL6982 | IA1: RL6982 | IB1: RL6982 | IC1: RL6982 | ID1: RL6982 | IE1: RL6982 | IF1: RL6982 | IG1: RL6982 | IH1: RL6982 | II1: RL6982 | IJ1: RL6982 | IK1: RL6982 | IL1: RL6982 | IM1: RL6982 | IN1: RL6982 | IO1: RL6982 | IP1: RL6982 | IQ1: RL6982 | IR1: RL6982 | IS1: RL6982 | IT1: RL6982 | IU1: RL6982 | IV1: RL6982 | IW1: RL6982 | IX1: RL6982 | IY1: RL6982 | IZ1: RL6982 | JA1: RL6982 | JB1: RL6982 | JC1: RL6982 | JD1: RL6982 | JE1: RL6982 | JF1: RL6982 | JG1: RL6982 | JH1: RL6982 | JI1: RL6982 | JJ1: RL6982 | JK1: RL6982 | JL1: RL6982 | JM1: RL6982 | JN1: RL6982 | JO1: RL6982 | JP1: RL6982 | JQ1: RL6982 | JR1: RL6982 | JS1: RL6982 | JT1: RL6982 | JU1: RL6982 | JV1: RL6982 | JW1: RL6982 | JX1: RL6982 | JY1: RL6982 | JZ1: RL6982 | KA1: RL6982 | KB1: RL6982 | KC1: RL6982 | KD1: RL6982 | KE1: RL6982 | KF1: RL6982 | KG1: RL6982 | KH1: RL6982 | KI1: RL6982 | KJ1: RL6982 | KK1: RL6982 | KL1: RL6982 | KM1: RL6982 | KN1: RL6982 | KO1: RL6982 | KP1: RL6982 | KQ1: RL6982 | KR1: RL6982 | KS1: RL6982 | KT1: RL6982 | KU1: RL6982 | KV1: RL6982 | KW1: RL6982 | KX1: RL6982 | KY1: RL6982 | KZ1: RL6982 | LA1: RL6982 | LB1: RL6982 | LC1: RL6982 | LD1: RL6982 | LE1: RL6982 | LF1: RL6982 | LG1: RL6982 | LH1: RL6982 | LI1: RL6982 | LJ1: RL6982 | LK1: RL6982 | LL1: RL6982 | LM1: RL6982 | LN1: RL6982 | LO1: RL6982 | LP1: RL6982 | LQ1: RL6982 | LR1: RL6982 | LS1: RL6982 | LT1: RL6982 | LU1: RL6982 | LV1: RL6982 | LW1: RL6982 | LX1: RL6982 | LY1: RL6982 | LZ1: RL6982 | MA1: RL6982 | MB1: RL6982 | MC1: RL6982 | MD1: RL6982 | ME1: RL6982 | MF1: RL6982 | MG1: RL6982 | MH1: RL6982 | MI1: RL6982 | MJ1: RL6982 | MK1: RL6982 | ML1: RL6982 | MM1: RL6982 | MN1: RL6982 | MO1: RL6982 | MP1: RL6982 | MQ1: RL6982 | MR1: RL6982 | MS1: RL6982 | MT1: RL6982 | MU1: RL6982 | MV1: RL6982 | MW1: RL6982 | MX1: RL6982 | MY1: RL6982 | MZ1: RL6982 | NA1: RL6982 | NB1: RL6982 | NC1: RL6982 | ND1: RL6982 | NE1: RL6982 | NF1: RL6982 | NG1: RL6982 | NH1: RL6982 | NI1: RL6982 | NJ1: RL6982 | NK1: RL6982 | NL1: RL6982 | NM1: RL6982 | NN1: RL6982 | NO1: RL6982 | NP1: RL6982 | NQ1: RL6982 | NR1: RL6982 | NS1: RL6982 | NT1: RL6982 | NU1: RL6982 | NV1: RL6982 | NW1: RL6982 | NX1: RL6982 | NY1: RL6982 | NZ1: RL6982 | OA1: RL6982 | OB1: RL6982 | OC1: RL6982 | OD1: RL6982 | OE1: RL6982 | OF1: RL6982 | OG1: RL6982 | OH1: RL6982 | OI1: RL6982 | OJ1: RL6982 | OK1: RL6982 | OL1: RL6982 | OM1: RL6982 | ON1: RL6982 | OO1: RL6982 | OP1: RL6982 | OQ1: RL6982 | OR1: RL6982 | OS1: RL6982 | OT1: RL6982 | OU1: RL6982 | OV1: RL6982 | OW1: RL6982 | OX1: RL6982 | OY1: RL6982 | OZ1: RL6982 | PA1: RL6982 | PB1: RL6982 | PC1: RL6982 | PD1: RL6982 | PE1: RL6982 | PF1: RL6982 | PG1: RL6982 | PH1: RL6982 | PI1: RL6982 | PJ1: RL6982
A2: Top_all | B2: BIN1 | C2: 401507 | D2: 0.8959 | N2: Product | O2: RL6982 | P2: RL6982 | Q2: RL6982 | R2: RL6982 | S2: RL6982 | T2: RL6982 | U2: RL6982 | V2: RL6982 | W2: RL6982 | X2: RL6982 | Y2: RL6982 | Z2: RL6982 | AA2: RL6982 | AB2: RL6982 | AC2: RL6982 | AD2: RL6982 | AE2: RL6982 | AF2: RL6982 | AG2: RL6982 | AH2: RL6982 | AI2: RL6982 | AJ2: RL6982 | AK2: RL6982 | AL2: RL6982 | AM2: RL6982 | AN2: RL6982 | AO2: RL6982 | AP2: RL6982 | AQ2: RL6982 | AR2: RL6982 | AS2: RL6982 | AT2: RL6982 | AU2: RL6982 | AV2: RL6982 | AW2: RL6982 | AX2: RL6982 | AY2: RL6982 | AZ2: RL6982 | BA2: RL6982 | BB2: RL6982 | BC2: RL6982 | BD2: RL6982 | BE2: RL6982 | BF2: RL6982 | BG2: RL6982 | BH2: RL6982 | BI2: RL6982 | BJ2: RL6982 | BK2: RL6982 | BL2: RL6982 | BM2: RL6982 | BN2: RL6982 | BO2: RL6982 | BP2: RL6982 | BQ2: RL6982 | BR2: RL6982 | BS2: RL6982 | BT2: RL6982 | BU2: RL6982 | BV2: RL6982 | BW2: RL6982 | BX2: RL6982 | BY2: RL6982 | BZ2: RL6982 | CA2: RL6982 | CB2: RL6982 | CC2: RL6982 | CD2: RL6982 | CE2: RL6982 | CF2: RL6982 | CG2: RL6982 | CH2: RL6982 | CI2: RL6982 | CJ2: RL6982 | CK2: RL6982 | CL2: RL6982 | CM2: RL6982 | CN2: RL6982 | CO2: RL6982 | CP2: RL6982 | CQ2: RL6982 | CR2: RL6982 | CS2: RL6982 | CT2: RL6982 | CU2: RL6982 | CV2: RL6982 | CW2: RL6982 | CX2: RL6982 | CY2: RL6982 | CZ2: RL6982 | DA2: RL6982 | DB2: RL6982 | DC2: RL6982 | DD2: RL6982 | DE2: RL6982 | DF2: RL6982 | DG2: RL6982 | DH2: RL6982 | DI2: RL6982 | DJ2: RL6982 | DK2: RL6982 | DL2: RL6982 | DM2: RL6982 | DN2: RL6982 | DO2: RL6982 | DP2: RL6982 | DQ2: RL6982 | DR2: RL6982 | DS2: RL6982 | DT2: RL6982 | DU2: RL6982 | DV2: RL6982 | DW2: RL6982 | DX2: RL6982 | DY2: RL6982 | DZ2: RL6982 | EA2: RL6982 | EB2: RL6982 | EC2: RL6982 | ED2: RL6982 | EE2: RL6982 | EF2: RL6982 | EG2: RL6982 | EH2: RL6982 | EI2: RL6982 | EJ2: RL6982 | EK2: RL6982 | EL2: RL6982 | EM2: RL6982 | EN2: RL6982 | EO2: RL6982 | EP2: RL6982 | EQ2: RL6982 | ER2: RL6982 | ES2: RL6982 | ET2: RL6982 | EU2: RL6982 | EV2: RL6982 | EW2: RL6982 | EX2: RL6982 | EY2: RL6982 | EZ2: RL6982 | FA2: RL6982 | FB2: RL6982 | FC2: RL6982 | FD2: RL6982 | FE2: RL6982 | FF2: RL6982 | FG2: RL6982 | FH2: RL6982 | FI2: RL6982 | FJ2: RL6982 | FK2: RL6982 | FL2: RL6982 | FM2: RL6982 | FN2: RL6982 | FO2: RL6982 | FP2: RL6982 | FQ2: RL6982 | FR2: RL6982 | FS2: RL6982 | FT2: RL6982 | FU2: RL6982 | FV2: RL6982 | FW2: RL6982 | FX2: RL6982 | FY2: RL6982 | FZ2: RL6982 | GA2: RL6982 | GB2: RL6982 | GC2: RL6982 | GD2: RL6982 | GE2: RL6982 | GF2: RL6982 | GG2: RL6982 | GH2: RL6982 | GI2: RL6982 | GJ2: RL6982 | GK2: RL6982 | GL2: RL6982 | GM2: RL6982 | GN2: RL6982 | GO2: RL6982 | GP2: RL6982 | GQ2: RL6982 | GR2: RL6982 | GS2: RL6982 | GT2: RL6982 | GU2: RL6982 | GV2: RL6982 | GW2: RL6982 | GX2: RL6982 | GY2: RL6982 | GZ2: RL6982 | HA2: RL6982 | HB2: RL6982 | HC2: RL6982 | HD2: RL6982 | HE2: RL6982 | HF2: RL6982 | HG2: RL6982 | HH2: RL6982 | HI2: RL6982 | HJ2: RL6982 | HK2: RL6982 | HL2: RL6982 | HM2: RL6982 | HN2: RL6982 | HO2: RL6982 | HP2: RL6982 | HQ2: RL6982 | HR2: RL6982 | HS2: RL6982 | HT2: RL6982 | HU2: RL6982 | HV2: RL6982 | HW2: RL6982 | HX2: RL6982 | HY2: RL6982 | HZ2: RL6982 | IA2: RL6982 | IB2: RL6982 | IC2: RL6982 | ID2: RL6982 | IE2: RL6982 | IF2: RL6982 | IG2: RL6982 | IH2: RL6982 | II2: RL6982 | IJ2: RL6982 | IK2: RL6982 | IL2: RL6982 | IM2: RL6982 | IN2: RL6982 | IO2: RL6982 | IP2: RL6982 | IQ2: RL6982 | IR2: RL6982 | IS2: RL6982 | IT2: RL6982 | IU2: RL6982 | IV2: RL6982 | IW2: RL6982 | IX2: RL6982 | IY2: RL6982 | IZ2: RL6982 | JA2: RL6982 | JB2: RL6982 | JC2: RL6982 | JD2: RL6982 | JE2: RL6982 | JF2: RL6982 | JG2: RL6982 | JH2: RL6982 | JI2: RL6982 | JJ2: RL6982 | JK2: RL6982 | JL2: RL6982 | JM2: RL6982 | JN2: RL6982 | JO2: RL6982 | JP2: RL6982 | JQ2: RL6982 | JR2: RL6982 | JS2: RL6982 | JT2: RL6982 | JU2: RL6982 | JV2: RL6982 | JW2: RL6982 | JX2: RL6982 | JY2: RL6982 | JZ2: RL6982 | KA2: RL6982 | KB2: RL6982 | KC2: RL6982 | KD2: RL6982 | KE2: RL6982 | KF2: RL6982 | KG2: RL6982 | KH2: RL6982 | KI2: RL6982 | KJ2: RL6982 | KK2: RL6982 | KL2: RL6982 | KM2: RL6982 | KN2: RL6982 | KO2: RL6982 | KP2: RL6982 | KQ2: RL6982 | KR2: RL6982 | KS2: RL6982 | KT2: RL6982 | KU2: RL6982 | KV2: RL6982 | KW2: RL6982 | KX2: RL6982 | KY2: RL6982 | KZ2: RL6982 | LA2: RL6982 | LB2: RL6982 | LC2: RL6982 | LD2: RL6982 | LE2: RL6982 | LF2: RL6982 | LG2: RL6982 | LH2: RL6982 | LI2: RL6982 | LJ2: RL6982 | LK2: RL6982 | LL2: RL6982 | LM2: RL6982 | LN2: RL6982 | LO2: RL6982 | LP2: RL6982 | LQ2: RL6982 | LR2: RL6982 | LS2: RL6982 | LT2: RL6982 | LU2: RL6982 | LV2: RL6982 | LW2: RL6982 | LX2: RL6982 | LY2: RL6982 | LZ2: RL6982 | MA2: RL6982 | MB2: RL6982 | MC2: RL6982 | MD2: RL6982 | ME2: RL6982 | MF2: RL6982 | MG2: RL6982 | MH2: RL6982 | MI2: RL6982 | MJ2: RL6982 | MK2: RL6982 | ML2: RL6982 | MM2: RL6982 | MN2: RL6982 | MO2: RL6982 | MP2: RL6982 | MQ2: RL6982 | MR2: RL6982 | MS2: RL6982 | MT2: RL6982 | MU2: RL6982 | MV2: RL6982 | MW2: RL6982 | MX2: RL6982 | MY2: RL6982 | MZ2: RL6982 | NA2: RL6982 | NB2: RL6982 | NC2: RL6982 | ND2: RL6982 | NE2: RL6982 | NF2: RL6982 | NG2: RL6982 | NH2: RL6982 | NI2: RL6982 | NJ2: RL6982 | NK2: RL6982 | NL2: RL6982 | NM2: RL6982 | NN2: RL6982 | NO2: RL6982 | NP2: RL6982 | NQ2: RL6982 | NR2: RL6982 | NS2: RL6982 | NT2: RL6982 | NU2: RL6982 | NV2: RL6982 | NW2: RL6982 | NX2: RL6982 | NY2: RL6982 | NZ2: RL6982 | OA2: RL6982 | OB2: RL6982 | OC2: RL6982 | OD2: RL6982 | OE2: RL6982 | OF2: RL6982 | OG2: RL6982 | OH2: RL6982 | OI2: RL6982 | OJ2: RL6982 | OK2: RL6982 | OL2: RL6982 | OM2: RL6982 | ON2: RL6982 | OO2: RL6982 | OP2: RL6982 | OQ2: RL6982 | OR2: RL6982 | OS2: RL6982 | OT2: RL6982 | OU2: RL6982 | OV2: RL6982 | OW2: RL6982 | OX2: RL6982 | OY2: RL6982 | OZ2: RL6982 | PA2: RL6982 | PB2: RL6982 | PC2: RL6982 | PD2: RL6982 | PE2: RL6982 | PF2: RL6982 | PG2: RL6982 | PH2: RL6982 | PI2: RL6982 | PJ2: RL6982
B3: OTHER | C3: 530 | D3: 0.0012 | N3: Short Lot ID | O3: P7FQ9 | P3: P7G70 | Q3: P7EM8 | R3: P7DQ5 | S3: P7EM8 | T3: P7E73 | U3: P7CM4 | V3: P7E95 | W3: P7G70 | X3: P7DN3 | Y3: P7F37 | Z3: P7E95 | AA3: P7EM8 | AB3: P7E95 | AC3: P7FQ9 | AD3: P7GG2 | AE3: P7GG2 | AF3: P7FQ9 | AG3: P7EM9 | AH3: P7FQ9 | AI3: P7CD0 | AJ3: P7E95 | AK3: P7E95 | AL3: P7E74 | AM3: P7E73 | AN3: P7E75 | AO3: P7FQ9 | AP3: P7CM0 | AQ3: P7DQ5 | AR3: P7E75 | AS3: P7E73 | AT3: P7EM8 | AU3: P7FQ9 | AV3: P7E73 | AW3: P7FQ9 | AX3: P7EM9 | AY3: P7E73 | AZ3: P7FQ9 | BA3: P7FQ9 | BB3: P7GG2 | BC3: P7CM4 | BD3: P7GG2 | BE3: P7CM4 | BF3: P7E73 | BG3: P7DQ5 | BH3: P7EM8 | BI3: P7F37 | BJ3: P7GG2 | BK3: P7E95 | BL3: P7DQ0 | BM3: P7E73 | BN3: P7F37 | BO3: P7DN3 | BP3: P7DQ5 | BQ3: P7F37 | BR3: P7DQ2 | BS3: P7FQ9 | BT3: P7DN3 | BU3: P7DN3 | BV3: P7G68 | BW3: P7F37 | BX3: P7DN3 | BY3: P7DQ2 | BZ3: P7E74 | CA3: P7FQ9 | CB3: P7E95 | CC3: P7EM9 | CD3: P7E73 | CE3: P7E95 | CF3: P7E95 | CG3: P7DN3 | CH3: P7E95 | CI3: P7EM9 | CJ3: P7DN3 | CK3: P7E95 | CL3: P7E73 | CM3: P7E73 | CN3: P7E73 | CO3: P7GG1 | CP3: P7DQ5 | CQ3: P7EM8 | CR3: P7DQ5 | CS3: P7CM4 | CT3: P7DQ0 | CU3: P7DQ2 | CV3: P7CM8 | CW3: P7E75 | CX3: P7GG2 | CY3: P7E75 | CZ3: P7DN3 | DA3: P7DQ5 | DB3: P7G70 | DC3: P7DQ3 | DD3: P7CM0 | DE3: P7G70 | DF3: P7DQ5 | DG3: P7DQ0 | DH3: P7DQ3 | DI3: P7DQ2 | DJ3: P7DQ3 | DK3: P7G70 | DL3: P7F37 | DM3: P7F37 | DN3: P7CD0 | DO3: P7DQ3 | DP3: P7G70 | DQ3: P7GG2 | DR3: P7GG2 | DS3: P7E95 | DT3: P7GG2 | DU3: P7FQ9 | DV3: P7E73 | DW3: P7EM8 | DX3: P7GG2 | DY3: P7DQ0 | DZ3: P7DQ2 | EA3: P7DN3 | EB3: P7DQ2 | EC3: P7F37 | ED3: P7GG2 | EE3: P7EM8 | EF3: P7CM0 | EG3: P7F37 | EH3: P7DQ2 | EI3: P7E95 | EJ3: P7E73 | EK3: P7CD1 | EL3: P7DQ3 | EM3: P7F37 | EN3: P7DQ5 | EO3: P7EM9 | EP3: P7GG1 | EQ3: P7G70 | ER3: P7F37 | ES3: P7E74 | ET3: P7FQ9 | EU3: P7F37 | EV3: P7EM9 | EW3: P7DQ3 | EX3: P7E74 | EY3: P7DQ5 | EZ3: P7EM8 | FA3: P7E73 | FB3: P7EM9 | FC3: P7DN3 | FD3: P7CM5 | FE3: P7DQ2 | FF3: P7EM8 | FG3: P7EM8 | FH3: P7G70 | FI3: P7F37 | FJ3: P7FQ9 | FK3: P7A61 | FL3: P7E95 | FM3: P7E73 | FN3: P7F37 | FO3: P7CM8 | FP3: P7DQ5 | FQ3: P7GG1 | FR3: P7E95 | FS3: P7G70 | FT3: P7E95 | FU3: P7E73 | FV3: P7DQ5 | FW3: P7E95 | FX3: P7DQ5 | FY3: P7E74 | FZ3: P7E74 | GA3: P7DQ5 | GB3: P7CD0 | GC3: P7FQ9 | GD3: P7E73 | GE3: P7GG2 | GF3: P7EM9 | GG3: P7DQ0 | GH3: P7DQ2 | GI3: P7G68 | GJ3: P7DN3 | GK3: P7DN3 | GL3: P7EM9 | GM3: P7EM8 | GN3: P7CM4 | GO3: P7E75 | GP3: P7E95 | GQ3: P7EM8 | GR3: P7CD0 | GS3: P7FQ9 | GT3: P7DQ3 | GU3: P7G68 | GV3: P7DQ0 | GW3: P7EM9 | GX3: P7EM9 | GY3: P7DQ0 | GZ3: P7DQ3 | HA3: P7E74 | HB3: P7E74 | HC3: P7FQ9 | HD3: P7DQ2 | HE3: P7E73 | HF3: P7EM9 | HG3: P7E73 | HH3: P7E73 | HI3: P7CD0 | HJ3: P7DQ0 | HK3: P7E75 | HL3: P7DN3 | HM3: P7DQ0 | HN3: P7E75 | HO3: P7DQ0 | HP3: P7E75 | HQ3: P7E75 | HR3: P7FQ9 | HS3: P7DQ2 | HT3: P7EM8 | HU3: P7G70 | HV3: P7DQ0 | HW3: P7FQ9 | HX3: P7EM8 | HY3: P7EM9 | HZ3: P7A61 | IA3: P7CM8 | IB3: P7EM9 | IC3: P7EM8 | ID3: P7E73 | IE3: P7CM0 | IF3: P7E75 | IG3: P7CM5 | IH3: P7DN3 | II3: P7CM0 | IJ3: P7DN3 | IK3: P7CD1 | IL3: P7GG2 | IM3: P7GG2 | IN3: P7G70 | IO3: P7DQ2 | IP3: P7CM0 | IQ3: P7DN3 | IR3: P7EM8 | IS3: P7E95 | IT3: P7E75 | IU3: P7DQ0 | IV3: P7F37 | IW3: P7DQ2 | IX3: P7DQ0 | IY3: P7DQ2 | IZ3: P7E95 | JA3: P7DQ2 | JB3: P7CM8 | JC3: P7FQ9 | JD3: P7CM4 | JE3: P7A61 | JF3: P7CD0 | JG3: P7CD0 | JH3: P7DQ3 | JI3: P7DQ3 | JJ3: P7GG2 | JK3: P7E75 | JL3: P7DQ0 | JM3: P7CM8 | JN3: P7E75 | JO3: P7E74 | JP3: P7E75 | JQ3: P7EM9 | JR3: P7DQ3 | JS3: P7FQ9 | JT3: P7CD0 | JU3: P7EM8 | JV3: P7DQ5 | JW3: P7E74 | JX3: P7CM8 | JY3: P7EM9 | JZ3: P7F37 | KA3: P7CM5 | KB3: P7DQ2 | KC3: P7CD1 | KD3: P7E73 | KE3: P7DN3 | KF3: P7E74 | KG3: P7E75 | KH3: P7GG2 | KI3: P7DN3 | KJ3: P7CM8 | KK3: P7DQ3 | KL3: P7DQ3 | KM3: P7F37 | KN3: P7EM9 | KO3: P7CM8 | KP3: P7DQ3 | KQ3: P7DQ3 | KR3: P7CM8 | KS3: P7F37 | KT3: P7DN3 | KU3: P7DQ3 | KV3: P7E73 | KW3: P7DQ0 | KX3: P7G68 | KY3: P7G70 | KZ3: P7DQ0 | LA3: P7E75 | LB3: P7GG2 | LC3: P7E74 | LD3: P7DQ3 | LE3: P7CM8 | LF3: P7F37 | LG3: P7EM9 | LH3: P7FQ9 | LI3: P7A61 | LJ3: P7EM9 | LK3: P7CM8 | LL3: P7EM8 | LM3: P7DN3 | LN3: P7DQ2 | LO3: P7DQ3 | LP3: P7DQ0 | LQ3: P7DQ5 | LR3: P7F37 | LS3: P7E75 | LT3: P7G68 | LU3: P7EM9 | LV3: P7CD0 | LW3: P7CM8 | LX3: P7DQ0 | LY3: P7E74 | LZ3: P7DQ3 | MA3: P7DN3 | MB3: P7DQ5 | MC3: P7DQ5 | MD3: P7E75 | ME3: P7F37 | MF3: P7E75 | MG3: P7EM9 | MH3: P7DQ3 | MI3: P7CM8 | MJ3: P7E73 | MK3: P7DQ2 | ML3: P7DQ5 | MM3: P7E75 | MN3: P7E95 | MO3: P7CD0 | MP3: P7F37 | MQ3: P7E75 | MR3: P7CD0 | MS3: P7CD1 | MT3: P7DQ2 | MU3: P7E74 | MV3: P7DQ0 | MW3: P7DQ0 | MX3: P7CM4 | MY3: P7FQ9 | MZ3: P7DN3 | NA3: P7CM8 | NB3: P7DN3 | NC3: P7DQ2 | ND3: P7DQ3 | NE3: P7DQ5 | NF3: P7DQ3 | NG3: P7EM8 | NH3: P7G68 | NI3: P7CD0 | NJ3: P7F37 | NK3: P7E73 | NL3: P7CM5 | NM3: P7E74 | NN3: P7CM7 | NO3: P7DQ2 | NP3: P7CD1 | NQ3: P7CM5 | NR3: P7DQ0 | NS3: P7GG1 | NT3: P7DN3 | NU3: P7DQ0 | NV3: P7DQ2 | NW3: P7EM8 | NX3: P7DN3 | NY3: P7DQ3 | NZ3: P7A61 | OA3: P7CD0 | OB3: P7DQ3 | OC3: P7E75 | OD3: P7DQ2 | OE3: P7DQ0 | OF3: P7DQ3 | OG3: P7E75 | OH3: P7E74 | OI3: P7DQ5 | OJ3: P7EM9 | OK3: P7DQ2 | OL3: P7DQ5 | OM3: P7DQ2 | ON3: P7DQ0 | OO3: P7EM8 | OP3: P7CM4 | OQ3: P7FQ9 | OR3: P7GG2 | OS3: P7EM8 | OT3: P7CD0 | OU3: P7DQ5 | OV3: P7DQ0 | OW3: P7CM5 | OX3: P7CM5 | OY3: P7CD0 | OZ3: P7CM8 | PA3: P7EM8 | PB3: P7CM5 | PC3: P7E74 | PD3: P7CD0 | PE3: P7E75 | PF3: P7DQ5 | PG3: P7EM8 | PH3: P7DQ5 | PI3: P7E75 | PJ3: P7CD1
B4: OS | C4: 1666 | D4: 0.0037 | N4: Lot ID | O4: P7FQ9 | P4: P7G70 | Q4: P7EM8 | R4: P7DQ5 | S4: P7EM8 | T4: P7E73 | U4: P7CM4 | V4: P7E95 | W4: P7G70 | X4: P7DN3 | Y4: P7F37 | Z4: P7E95 | AA4: P7EM8 | AB4: P7E95 | AC4: P7FQ9 | AD4: P7GG2 | AE4: P7GG2 | AF4: P7FQ9 | AG4: P7EM9 | AH4: P7FQ9 | AI4: P7CD0 | AJ4: P7E95 | AK4: P7E95 | AL4: P7E74 | AM4: P7E73 | AN4: P7E75 | AO4: P7FQ9 | AP4: P7CM0 | AQ4: P7DQ5 | AR4: P7E75 | AS4: P7E73 | AT4: P7EM8 | AU4: P7FQ9 | AV4: P7E73 | AW4: P7FQ9 | AX4: P7EM9 | AY4: P7E73 | AZ4: P7FQ9 | BA4: P7FQ9 | BB4: P7GG2 | BC4: P7CM4 | BD4: P7GG2 | BE4: P7CM4 | BF4: P7E73 | BG4: P7DQ5 | BH4: P7EM8 | BI4: P7F37 | BJ4: P7GG2 | BK4: P7E95 | BL4: P7DQ0 | BM4: P7E73 | BN4: P7F37 | BO4: P7DN3 | BP4: P7DQ5 | BQ4: P7F37 | BR4: P7DQ2 | BS4: P7FQ9 | BT4: P7DN3 | BU4: P7DN3 | BV4: P7G68 | BW4: P7F37 | BX4: P7DN3 | BY4: P7DQ2 | BZ4: P7E74 | CA4: P7FQ9 | CB4: P7E95 | CC4: P7EM9 | CD4: P7E73 | CE4: P7E95 | CF4: P7E95 | CG4: P7DN3 | CH4: P7E95 | CI4: P7EM9 | CJ4: P7DN3 | CK4: P7E95 | CL4: P7E73 | CM4: P7E73 | CN4: P7E73 | CO4: P7GG1 | CP4: P7DQ5 | CQ4: P7EM8 | CR4: P7DQ5 | CS4: P7CM4 | CT4: P7DQ0 | CU4: P7DQ2 | CV4: P7CM8 | CW4: P7E75 | CX4: P7GG2 | CY4: P7E75 | CZ4: P7DN3 | DA4: P7DQ5 | DB4: P7G70 | DC4: P7DQ3 | DD4: P7CM0 | DE4: P7G70 | DF4: P7DQ5 | DG4: P7DQ0 | DH4: P7DQ3 | DI4: P7DQ2 | DJ4: P7DQ3 | DK4: P7G70 | DL4: P7F37 | DM4: P7F37 | DN4: P7CD0 | DO4: P7DQ3 | DP4: P7G70 | DQ4: P7GG2 | DR4: P7GG2 | DS4: P7E95 | DT4: P7GG2 | DU4: P7FQ9 | DV4: P7E73 | DW4: P7EM8 | DX4: P7GG2 | DY4: P7DQ0 | DZ4: P7DQ2 | EA4: P7DN3 | EB4: P7DQ2 | EC4: P7F37 | ED4: P7GG2 | EE4: P7EM8 | EF4: P7CM0 | EG4: P7F37 | EH4: P7DQ2 | EI4: P7E95 | EJ4: P7E73 | EK4: P7CD1 | EL4: P7DQ3 | EM4: P7F37 | EN4: P7DQ5 | EO4: P7EM9 | EP4: P7GG1 | EQ4: P7G70 | ER4: P7F37 | ES4: P7E74 | ET4: P7FQ9 | EU4: P7F37 | EV4: P7EM9 | EW4: P7DQ3 | EX4: P7E74 | EY4: P7DQ5 | EZ4: P7EM8 | FA4: P7E73 | FB4: P7EM9 | FC4: P7DN3 | FD4: P7CM5 | FE4: P7DQ2 | FF4: P7EM8 | FG4: P7EM8 | FH4: P7G70 | FI4: P7F37 | FJ4: P7FQ9 | FK4: P7A61 | FL4: P7E95 | FM4: P7E73 | FN4: P7F37 | FO4: P7CM8 | FP4: P7DQ5 | FQ4: P7GG1 | FR4: P7E95 | FS4: P7G70 | FT4: P7E95 | FU4: P7E73 | FV4: P7DQ5 | FW4: P7E95 | FX4: P7DQ5 | FY4: P7E74 | FZ4: P7E74 | GA4: P7DQ5 | GB4: P7CD0 | GC4: P7FQ9 | GD4: P7E73 | GE4: P7GG2 | GF4: P7EM9 | GG4: P7DQ0 | GH4: P7DQ2 | GI4: P7G68 | GJ4: P7DN3 | GK4: P7DN3 | GL4: P7EM9 | GM4: P7EM8 | GN4: P7CM4 | GO4: P7E75 | GP4: P7E95 | GQ4: P7EM8 | GR4: P7CD0 | GS4: P7FQ9 | GT4: P7DQ3 | GU4: P7G68 | GV4: P7DQ0 | GW4: P7EM9 | GX4: P7EM9 | GY4: P7DQ0 | GZ4: P7DQ3 | HA4: P7E74 | HB4: P7E74 | HC4: P7FQ9 | HD4: P7DQ2 | HE4: P7E73 | HF4: P7EM9 | HG4: P7E73 | HH4: P7E73 | HI4: P7CD0 | HJ4: P7DQ0 | HK4: P7E75 | HL4: P7DN3 | HM4: P7DQ0 | HN4: P7E75 | HO4: P7DQ0 | HP4: P7E75 | HQ4: P7E75 | HR4: P7FQ9 | HS4: P7DQ2 | HT4: P7EM8 | HU4: P7G70 | HV4: P7DQ0 | HW4: P7FQ9 | HX4: P7EM8 | HY4: P7EM9 | HZ4: P7A61 | IA4: P7CM8 | IB4: P7EM9 | IC4: P7EM8 | ID4: P7E73 | IE4: P7CM0 | IF4: P7E75 | IG4: P7CM5 | IH4: P7DN3 | II4: P7CM0 | IJ4: P7DN3 | IK4: P7CD1 | IL4: P7GG2 | IM4: P7GG2 | IN4: P7G70 | IO4: P7DQ2 | IP4: P7CM0 | IQ4: P7DN3 | IR4: P7EM8 | IS4: P7E95 | IT4: P7E75 | IU4: P7DQ0 | IV4: P7F37 | IW4: P7DQ2 | IX4: P7DQ0 | IY4: P7DQ2 | IZ4: P7E95 | JA4: P7DQ2 | JB4: P7CM8 | JC4: P7FQ9 | JD4: P7CM4 | JE4: P7A61 | JF4: P7CD0 | JG4: P7CD0 | JH4: P7DQ3 | JI4: P7DQ3 | JJ4: P7GG2 | JK4: P7E75 | JL4: P7DQ0 | JM4: P7CM8 | JN4: P7E75 | JO4: P7E74 | JP4: P7E75 | JQ4: P7EM9 | JR4: P7DQ3 | JS4: P7FQ9 | JT4: P7CD0 | JU4: P7EM8 | JV4: P7DQ5 | JW4: P7E74 | JX4: P7CM8 | JY4: P7EM9 | JZ4: P7F37 | KA4: P7CM5 | KB4: P7DQ2 | KC4: P7CD1 | KD4: P7E73 | KE4: P7DN3 | KF4: P7E74 | KG4: P7E75 | KH4: P7GG2 | KI4: P7DN3 | KJ4: P7CM8 | KK4: P7DQ3 | KL4: P7DQ3 | KM4: P7F37 | KN4: P7EM9 | KO4: P7CM8 | KP4: P7DQ3 | KQ4: P7DQ3 | KR4: P7CM8 | KS4: P7F37 | KT4: P7DN3 | KU4: P7DQ3 | KV4: P7E73 | KW4: P7DQ0 | KX4: P7G68 | KY4: P7G70 | KZ4: P7DQ0 | LA4: P7E75 | LB4: P7GG2 | LC4: P7E74 | LD4: P7DQ3 | LE4: P7CM8 | LF4: P7F37 | LG4: P7EM9 | LH4: P7FQ9 | LI4: P7A61 | LJ4: P7EM9 | LK4: P7CM8 | LL4: P7EM8 | LM4: P7DN3 | LN4: P7DQ2 | LO4: P7DQ3 | LP4: P7DQ0 | LQ4: P7DQ5 | LR4: P7F37 | LS4: P7E75 | LT4: P7G68 | LU4: P7EM9 | LV4: P7CD0 | LW4: P7CM8 | LX4: P7DQ0 | LY4: P7E74 | LZ4: P7DQ3 | MA4: P7DN3 | MB4: P7DQ5 | MC4: P7DQ5 | MD4: P7E75 | ME4: P7F37 | MF4: P7E75 | MG4: P7EM9 | MH4: P7DQ3 | MI4: P7CM8 | MJ4: P7E73 | MK4: P7DQ2 | ML4: P7DQ5 | MM4: P7E75 | MN4: P7E95 | MO4: P7CD0 | MP4: P7F37 | MQ4: P7E75 | MR4: P7CD0 | MS4: P7CD1 | MT4: P7DQ2 | MU4: P7E74 | MV4: P7DQ0 | MW4: P7DQ0 | MX4: P7CM4 | MY4: P7FQ9 | MZ4: P7DN3 | NA4: P7CM8 | NB4: P7DN3 | NC4: P7DQ2 | ND4: P7DQ3 | NE4: P7DQ5 | NF4: P7DQ3 | NG4: P7EM8 | NH4: P7G68 | NI4: P7CD0 | NJ4: P7F37 | NK4: P7E73 | NL4: P7CM5 | NM4: P7E74 | NN4: P7CM7 | NO4: P7DQ2 | NP4: P7CD1 | NQ4: P7CM5 | NR4: P7DQ0 | NS4: P7GG1 | NT4: P7DN3 | NU4: P7DQ0 | NV4: P7DQ2 | NW4: P7EM8 | NX4: P7DN3 | NY4: P7DQ3 | NZ4: P7A61 | OA4: P7CD0 | OB4: P7DQ3 | OC4: P7E75 | OD4: P7DQ2 | OE4: P7DQ0 | OF4: P7DQ3 | OG4: P7E75 | OH4: P7E74 | OI4: P7DQ5 | OJ4: P7EM9 | OK4: P7DQ2 | OL4: P7DQ5 | OM4: P7DQ2 | ON4: P7DQ0 | OO4: P7EM8 | OP4: P7CM4 | OQ4: P7FQ9 | OR4: P7GG2 | OS4: P7EM8 | OT4: P7CD0 | OU4: P7DQ5 | OV4: P7DQ0 | OW4: P7CM5 | OX4: P7CM5 | OY4: P7CD0 | OZ4: P7CM8 | PA4: P7EM8 | PB4: P7CM5 | PC4: P7E74 | PD4: P7CD0 | PE4: P7E75 | PF4: P7DQ5 | PG4: P7EM8 | PH4: P7DQ5 | PI4: P7E75 | PJ4: P7CD1
B5: SD | C5: 1026 | D5: 0.0023 | N5: Wafer ID | O5: MAU668-03G6 | P5: MAU657-20C3 | Q5: MAS244-22D1 | R5: MAS268-04G0 | S5: MAS244-23C4 | T5: MAS257-02D5 | U5: MAS251-01G6 | V5: MAS260-08E3 | W5: MAU657-03D1 | X5: MAS246-21F3 | Y5: MAS264-13F6 | Z5: MAS260-15B2 | AA5: MAS244-03F1 | AB5: MAS260-12D1 | AC5: MAU668-07E2 | AD5: MAU661-03E6 | AE5: MAU661-19D3 | AF5: MAU668-22E6 | AG5: MAS265-21G4 | AH5: MAU668-21F3 | AI5: MAR895-07C0 | AJ5: MAS260-18G6 | AK5: MAS260-13C4 | AL5: MAS262-07G5 | AM5: MAS257-03D0 | AN5: MAS263-10D1 | AO5: MAU668-18G0 | AP5: MAS245-22A2 | AQ5: MAS268-16H1 | AR5: MAS263-13B2 | AS5: MAS257-07A4 | AT5: MAS244-19D6 | AU5: MAU668-20G0 | AV5: MAS257-19B5 | AW5: MAU668-14B1 | AX5: MAS265-09E1 | AY5: MAS257-18C2 | AZ5: MAU668-10D5 | BA5: MAU668-12C3 | BB5: MAU661-05D4 | BC5: MAS251-07D0 | BD5: MAU661-17E5 | BE5: MAS251-03F4 | BF5: MAS257-06B1 | BG5: MAS268-05F3 | BH5: MAS244-24B7 | BI5: MAS264-06B4 | BJ5: MAU661-02F3 | BK5: MAS260-02A6 | BL5: MAS258-18G6 | BM5: MAS257-01E2 | BN5: MAS264-18C5 | BO5: MAS246-16H2 | BP5: MAS268-21F2 | BQ5: MAS264-01E5 | BR5: MAS259-17E4 | BS5: MAU668-17G5 | BT5: MAS246-14B1 | BU5: MAS246-24D4 | BV5: MAU650-18A3 | BW5: MAS264-10A2 | BX5: MAS246-17G5 | BY5: MAS259-08B4 | BZ5: MAS262-23G4 | CA5: MAU668-23E1 | CB5: MAS260-06F5 | CC5: MAS265-10E6 | CD5: MAS257-16D4 | CE5: MAS260-24E2 | CF5: MAS260-19G1 | CG5: MAS246-12C3 | CH5: MAS260-04G7 | CI5: MAS265-14C2 | CJ5: MAS246-03G6 | CK5: MAS260-20G6 | CL5: MAS257-09G5 | CM5: MAS257-20C2 | CN5: MAS257-05B6 | CO5: MAU655-18A6 | CP5: MAS268-13B5 | CQ5: MAS244-17F0 | CR5: MAS268-24D3 | CS5: MAS251-02G1 | CT5: MAS258-24E2 | CU5: MAS259-04E0 | CV5: MAS267-17C0 | CW5: MAS263-18F4 | CX5: MAU661-07C2 | CY5: MAS263-20F4 | CZ5: MAS246-20G0 | DA5: MAS268-22E5 | DB5: MAU657-10A0 | DC5: MAS261-22C5 | DD5: MAS245-20B4 | DE5: MAU657-19B6 | DF5: MAS268-18F7 | DG5: MAS258-11D6 | DH5: MAS261-07C1 | DI5: MAS259-11A7 | DJ5: MAS261-02F2 | DK5: MAU657-12G1 | DL5: MAS264-17D2 | DM5: MAS264-09H0 | DN5: MAR895-14G2 | DO5: MAS261-01F7 | DP5: MAU657-18C3 | DQ5: MAU661-04E1 | DR5: MAU661-21D3 | DS5: MAS260-07F0 | DT5: MAU661-14G4 | DU5: MAU668-04G1 | DV5: MAS257-04C3 | DW5: MAS244-05D7 | DX5: MAU661-10B5 | DY5: MAS258-12D1 | DZ5: MAS259-24B3 | EA5: MAS246-22E6 | EB5: MAS259-18D7 | EC5: MAS264-15E4 | ED5: MAU661-20E0 | EE5: MAS244-04E4 | EF5: MAS245-24G3 | EG5: MAS264-25G7 | EH5: MAS259-10B4 | EI5: MAS260-05G2 | EJ5: MAS257-08H2 | EK5: MAS252-09G2 | EL5: MAS261-20D7 | EM5: MAS264-02E0 | EN5: MAS268-23E0 | EO5: MAS265-05G5 | EP5: MAU655-19A1 | EQ5: MAU657-01E3 | ER5: MAS264-11H0 | ES5: MAS262-16C2 | ET5: MAU668-11D0 | EU5: MAS264-19C0 | EV5: MAS265-01B6 | EW5: MAS261-03E5 | EX5: MAS262-19A3 | EY5: MAS268-09C7 | EZ5: MAS244-09B3 | FA5: MAS257-11G5 | FB5: MAS265-19G4 | FC5: MAS246-02A0 | FD5: MAS253-08E0 | FE5: MAS259-22C5 | FF5: MAS244-16F5 | FG5: MAS244-20E3 | FH5: MAU657-11G6 | FI5: MAS264-24A1 | FJ5: MAU668-24D4 | FK5: MAR890-14F7 | FL5: MAS260-22F4 | FM5: MAS257-17C7 | FN5: MAS264-08A2 | FO5: MAS267-24G2 | FP5: MAS268-20F7 | FQ5: MAU655-17B3 | FR5: MAS260-14B7 | FS5: MAU657-22B1 | FT5: MAS260-25D5 | FU5: MAS257-23A3 | FV5: MAS268-03G5 | FW5: MAS260-11D6 | FX5: MAS268-17G4 | FY5: MAS262-24F7 | FZ5: MAS262-22H1 | GA5: MAS268-02H2 | GB5: MAR895-05D2 | GC5: MAU668-09D0 | GD5: MAS257-14E6 | GE5: MAU661-12A3 | GF5: MAS265-15B5 | GG5: MAS258-20G6 | GH5: MAS259-09A7 | GI5: MAU650-11E6 | GJ5: MAS246-07E2 | GK5: MAS246-01A5 | GL5: MAS265-24E5 | GM5: MAS244-25B2 | GN5: MAS251-08C3 | GO5: MAS263-08D1 | GP5: MAS260-23E7 | GQ5: MAS244-08C0 | GR5: MAR895-25A5 | GS5: MAU668-19F3 | GT5: MAS261-10B4 | GU5: MAU650-01C3 | GV5: MAS258-13C4 | GW5: MAS265-13C7 | GX5: MAS265-12D4 | GY5: MAS258-16A5 | GZ5: MAS261-08B4 | HA5: MAS262-14D4 | HB5: MAS262-13E1 | HC5: MAU668-06E7 | HD5: MAS259-21D2 | HE5: MAS257-25G4 | HF5: MAS265-16B0 | HG5: MAS257-13F3 | HH5: MAS257-22B0 | HI5: MAR895-15F5 | HJ5: MAS258-17A0 | HK5: MAS263-12B7 | HL5: MAS246-23E1 | HM5: MAS258-03A1 | HN5: MAS263-04F5 | HO5: MAS258-08E3 | HP5: MAS263-03G2 | HQ5: MAS263-19E7 | HR5: MAU668-13B6 | HS5: MAS259-23C0 | HT5: MAS244-01G3 | HU5: MAU657-02D6 | HV5: MAS258-25D5 | HW5: MAU668-01A5 | HX5: MAS244-02F6 | HY5: MAS265-18H1 | HZ5: MAR890-12H1 | IA5: MAS267-07H0 | IB5: MAS265-02B1 | IC5: MAS244-13A1 | ID5: MAS257-15E1 | IE5: MAS245-21A7 | IF5: MAS263-23D5 | IG5: MAS253-23E4 | IH5: MAS246-05F4 | II5: MAS245-25F6 | IJ5: MAS246-19F3 | IK5: MAS252-08G7 | IL5: MAU661-11B0 | IM5: MAU661-09B0 | IN5: MAU657-21B6 | IO5: MAS259-03E5 | IP5: MAS245-23H0 | IQ5: MAS246-10D5 | IR5: MAS244-10C0 | IS5: MAS260-21G1 | IT5: MAS263-24D0 | IU5: MAS258-22F4 | IV5: MAS264-21C0 | IW5: MAS259-12A2 | IX5: MAS258-07F0 | IY5: MAS259-01F7 | IZ5: MAS260-16A5 | JA5: MAS259-14G3 | JB5: MAS267-06A2 | JC5: MAU668-05F4 | JD5: MAS251-04E7 | JE5: MAR890-15F2 | JF5: MAR895-06C5 | JG5: MAR895-22C4 | JH5: MAS261-21D2 | JI5: MAS261-09A7 | JJ5: MAU661-13H1 | JK5: MAS263-05F0 | JL5: MAS258-09D6 | JM5: MAS267-20B3 | JN5: MAS263-15A0 | JO5: MAS262-04B1 | JP5: MAS263-17G1 | JQ5: MAS265-22F7 | JR5: MAS261-24B3 | JS5: MAU668-02A0 | JT5: MAR895-16F0 | JU5: MAS244-14G7 | JV5: MAS268-06E6 | JW5: MAS262-20B0 | JX5: MAS267-02C6 | JY5: MAS265-07F3 | JZ5: MAS264-05C1 | KA5: MAS253-25D2 | KB5: MAS259-25A6 | KC5: MAS252-07A1 | KD5: MAS257-12G0 | KE5: MAS246-04G1 | KF5: MAS262-21A3 | KG5: MAS263-07D6 | KH5: MAU661-01G0 | KI5: MAS246-08D5 | KJ5: MAS267-23G7 | KK5: MAS261-04E0 | KL5: MAS261-13H0 | KM5: MAS264-20C5 | KN5: MAS265-03A4 | KO5: MAS267-21A6 | KP5: MAS261-16F1 | KQ5: MAS261-15F6 | KR5: MAS267-03C1 | KS5: MAS264-23A6 | KT5: MAS246-11D0 | KU5: MAS261-14G3 | KV5: MAS257-21B5 | KW5: MAS258-19G1 | KX5: MAU650-10F3 | KY5: MAU657-04C4 | KZ5: MAS258-05G2 | LA5: MAS263-09C4 | LB5: MAU661-06C7 | LC5: MAS262-12E6 | LD5: MAS261-25A6 | LE5: MAS267-18B3 | LF5: MAS264-07A7 | LG5: MAS265-06G0 | LH5: MAU668-08D5 | LI5: MAR890-13G4 | LJ5: MAS265-23F2 | LK5: MAS267-22A1 | LL5: MAS244-11B3 | LM5: MAS246-18G0 | LN5: MAS259-16F1 | LO5: MAS261-17E4 | LP5: MAS258-06F5 | LQ5: MAS268-25C6 | LR5: MAS264-04C6 | LS5: MAS263-11C4 | LT5: MAU650-09E6 | LU5: MAS265-20H1 | LV5: MAR895-24B2 | LW5: MAS267-04B4 | LX5: MAS258-21G1 | LY5: MAS262-08G0 | LZ5: MAS261-06C6 | MA5: MAS246-25C7 | MB5: MAS268-01A4 | MC5: MAS268-15A3 | MD5: MAS263-06E3 | ME5: MAS264-16D7 | MF5: MAS263-25C3 | MG5: MAS265-11E1 | MH5: MAS261-12A2 | MI5: MAS267-08G3 | MJ5: MAS257-24H1 | MK5: MAS259-13H0 | ML5: MAS268-12C2 | MM5: MAS263-22E2 | MN5: MAS260-03A1 | MO5: MAR895-04D7 | MP5: MAS264-03D3 | MQ5: MAS263-14A5 | MR5: MAR895-08B3 | MS5: MAS252-19B2 | MT5: MAS259-15F6 | MU5: MAS262-06H2 | MV5: MAS258-14B7 | MW5: MAS258-23E7 | MX5: MAS251-06D5 | MY5: MAU668-25C7 | MZ5: MAS246-13B6 | NA5: MAS267-05A7 | NB5: MAS246-06E7 | NC5: MAS259-07C1 | ND5: MAS261-18D7 | NE5: MAS268-08D4 | NF5: MAS261-05D3 | NG5: MAS244-18E3 | NH5: MAU650-17B0 | NI5: MAR895-23B7 | NJ5: MAS264-22B3 | NK5: MAS257-10H2 | NL5: MAS253-16A2 | NM5: MAS262-05A4 | NN5: MAS266-01G2 | NO5: MAS259-05D3 | NP5: MAS252-10G7 | NQ5: MAS253-15A7 | NR5: MAS258-10E3 | NS5: MAU655-02C1 | NT5: MAS246-15A4 | NU5: MAS258-04G7 | NV5: MAS259-02F2 | NW5: MAS244-12A6 | NX5: MAS246-09D0 | NY5: MAS261-19D2 | NZ5: MAR890-16E5 | OA5: MAR895-18D6 | OB5: MAS261-23C0 | OC5: MAS263-16G6 | OD5: MAS259-19D2 | OE5: MAS258-15B2 | OF5: MAS261-11A7 | OG5: MAS263-02G7 | OH5: MAS262-25F2 | OI5: MAS268-10D4 | OJ5: MAS265-04H2 | OK5: MAS259-06C6 | OL5: MAS268-07E1 | OM5: MAS259-20D7 | ON5: MAS258-01B3 | OO5: MAS244-06D2 | OP5: MAS251-05E2 | OQ5: MAU668-15A4 | OR5: MAU661-18E0 | OS5: MAS244-21D6 | OT5: MAR895-12A1 | OU5: MAS268-11C7 | OV5: MAS258-02A6 | OW5: MAS253-24D7 | OX5: MAS253-14B4 | OY5: MAR895-13G7 | OZ5: MAS267-25F5 | PA5: MAS244-15G2 | PB5: MAS253-13C1 | PC5: MAS262-15C7 | PD5: MAR895-21D1 | PE5: MAS263-01A1 | PF5: MAS268-14B0 | PG5: MAS244-07C5 | PH5: MAS268-19F2 | PI5: MAS263-21E7 | PJ5: MAS252-17C4
